Workbook

Sheet Set up check list
A1: Task | B1: Done | E1: should I delete
A2: Copy last years version rename to this year | B2: x | E2: translation 2021
A3: Clear Logs | B3: x
A4: -- Weekly Log | B4: x
A5: -- Proj Log | B5: x
A6: Hide Logs | B6: x
A7: New Teams Updates | B7: x
A8: --Team colors | B8: x
A9: -- Team Translations | B9: x
A10: Hide team data | B10: x
A11: Update actual conference alignment (use 10 person column) and proposed alignment | B11: x
A12: Use this to check actual conferences | B12: x
A13: Use this to check proposed changes | B13: x
A14: Hide the red tabs | B14: x
... A20: -- Set up draft order | B20: x
A21: GCP
A22: -- give gcp python correct spreadsheet | B22: x
A23: -- share spreadsheet with correct address for python to access | B23: x

Sheet TAB-le of contents
A1: Part of the Game | B1: Tab | C1: Description
A2: Draft | B2: DraftTracker | C2: (Player Input) Where we place picks by using the drop downs and checking the error section
A3: Draft | B3: OnTheClock's Eligable Teams | C3: A list of teams eligible for the player who's turn it is to draft
A4: Draft | B4: Conf WC Eligibility | C4: A tab that shows how many teams can be taken from each conference as a WildCard pick
A5: Draft | B5: Conferences Needed | C5: A list of conferences that each player has NOT drafted from
A6: Draft | B6: ALL Teams Available | C6: All the undrafted teams
A7: Draft | B7: Picks by Player | C7: A grouping of picks by player
A8: Draft | B8: Teams | C8: All teams in their conference
A9: Draft | B9: Email Opt-ins | C9: (Player Input) The place to update your email preferences
A10: Football | B10: Standings | C10: (Updated Live-ish!) The Standings of the pool - (sometimes takes an hour for a win to get updated)
A11: Football | B11: Current Week | C11: (Scores Updated Live!) A look at the games this week grouped by player
A12: Football | B12: Day of week tabs | C12: (Scores Updated Live!) A look at the games each day, grouped by time and network
A13: Football | B13: Weekday color codes | C13: Description of the color codes in teh Day of week Tabs

Sheet Standings
A1: =HYPERLINK("https://docs.google.com/document/d/1-e84tTr9zFoIfOR2Z7Z-1lI4YO7v6GoaThMqj1UrcXE/edit","Rules") -> Rules | B1: Season | F1: Current Week (Projections based on vegas lines) | M1: Actaul + Chalk Projections
A2: Players | B2: Wins | C2: Losses | D2: P5 Ws | E2: G5 Ws | F2: Games | G2: Games Played | H2: Wins | I2: Games Left | J2: Expected Wins | K2: Upsets Won | L2: Upsets Lost
A3: {=sort(A17:M29,2,false,3,true,7,false,8,true,1,true)} -> Dan | B3: 83 | C3: 36 | D3: 0 | E3: 0 | F3: 9 | G3: 9 | H3: 6 | I3: 0 | J3: 4 | K3: 3 | L3: 1 | M3: 6
A4: Gary | B4: 79 | C4: 41 | D4: 0 | E4: 0 | F4: 10 | G4: 10 | H4: 9 | I4: 0 | J4: 9 | K4: 0 | L4: 0 | M4: 9
A5: Josh | B5: 75 | C5: 45 | D5: 0 | E5: 0 | F5: 10 | G5: 10 | H5: 8 | I5: 0 | J5: 6 | K5: 2 | L5: 0 | M5: 8
A6: Nico | B6: 71 | C6: 49 | D6: 0 | E6: 0 | F6: 10 | G6: 10 | H6: 6 | I6: 0 | J6: 5 | K6: 2 | L6: 1 | M6: 6
A7: Brad | B7: 69 | C7: 51 | D7: 0 | E7: 0 | F7: 10 | G7: 10 | H7: 6 | I7: 0 | J7: 5 | K7: 1 | L7: 0 | M7: 6
A8: Nick A. | B8: 66 | C8: 54 | D8: 0 | E8: 0 | F8: 9 | G8: 9 | H8: 3 | I8: 0 | J8: 5 | K8: 1 | L8: 3 | M8: 3
A9: Justin | B9: 62 | C9: 57 | D9: 0 | E9: 0 | F9: 10 | G9: 10 | H9: 8 | I9: 0 | J9: 5 | K9: 2 | L9: 0 | M9: 8
A10: Mike | B10: 61 | C10: 59 | D10: 0 | E10: 0 | F10: 10 | G10: 10 | H10: 2 | I10: 0 | J10: 4 | K10: 1 | L10: 3 | M10: 2
A11: Masa | B11: 61 | C11: 59 | D11: 0 | E11: 0 | F11: 10 | G11: 10 | H11: 5 | I11: 0 | J11: 5 | K11: 2 | L11: 2 | M11: 5
A12: Jeannine | B12: 60 | C12: 60 | D12: 0 | E12: 0 | F12: 10 | G12: 10 | H12: 2 | I12: 0 | J12: 5 | K12: 0 | L12: 3 | M12: 2
A13: Vu | B13: 57 | C13: 63 | D13: 0 | E13: 0 | F13: 10 | G13: 10 | H13: 5 | I13: 0 | J13: 3 | K13: 2 | L13: 0 | M13: 5
A14: Nick G. | B14: 52 | C14: 68 | D14: 0 | E14: 0 | F14: 10 | G14: 10 | H14: 3 | I14: 0 | J14: 5 | K14: 0 | L14: 2 | M14: 3
B15: 0 | C15: 0 | D15: 0 | E15: 0 | F15: 10 | G15: 0 | H15: 0 | I15: 10 | J15: 0 | K15: 0 | L15: 0 | M15: 0
A17: {='Draft Order'!B2:B29} -> Nick G. | B17: =sumif('Current Week'!$B:$B,$A17,'Current Week'!D:D) -> 52 | C17: =sumif('Current Week'!$B:$B,$A17,'Current Week'!E:E) -> 68 | D17: =sumifs('Current Week'!D:D,'Current Week'!$B:$B,$A17,'Current Week'!T:T,"Power 5") -> 0 | E17: =sumifs('Current Week'!D:D,'Current Week'!$B:$B,$A17,'Current Week'!T:T,"Group of 5") -> 0 | F17: =10-countifs('Current Week'!B:B,A17,'Current Week'!G:G,"") -> 10 | G17: =IFERROR(__xludf.DUMMYFUNCTION("COUNTA(iferror(filter('Current Week'!B:B,'Current Week'!B:B=A17,left('Current Week'!G:G,5)=""FINAL"")))"),10.0) -> 10 | H17: =countifs('Current Week'!B:B,A17,'Current Week'!U:U,"=TRUE") -> 3 | I17: =F17-G17 -> 0 | J17: =IFERROR(__xludf.DUMMYFUNCTION("countifs('Current Week'!B:B,A17,'Current Week'!K:K,""<0"")+counta(iferror(filter('Current Week'!B:B,'Current Week'!B:B=A17,'Current Week'!F:F<>"""",'Current Week'!K:K="""",'Current Week'!H:H="""")))"),5.0) -> 5 | K17: =IFERROR(__xludf.DUMMYFUNCTION("counta(iferror(filter('Current Week'!B:B,'Current Week'!B:B=A17,'Current Week'!K:K>0,not(iserror(find(""FINAL"",'Current Week'!G:G))),'Current Week'!U:U=TRUE)))+counta(iferror(filter('Current Week'!B:B,'Current Week'!B:B=A17,'Current Week'!K:K="""",not(is"&"error(find(""FINAL"",'Current Week'!G:G))),'Current Week'!U:U=TRUE,'Current Week'!H:H="""")))"),0.0) -> 0 | L17: =IFERROR(__xludf.DUMMYFUNCTION("counta(iferror(filter('Current Week'!B:B,'Current Week'!B:B=A17,'Current Week'!K:K<0,not(iserror(find(""FINAL"",'Current Week'!G:G))),'Current Week'!U:U<>TRUE)))"),2.0) -> 2 | M17: =IFERROR(__xludf.DUMMYFUNCTION("H17+counta(iferror(filter('Current Week'!B:B,'Current Week'!B:B=A17,'Current Week'!K:K<0,iserror(find(""FINAL"",'Current Week'!G:G)))))+counta(iferror(filter('Current Week'!B:B,'Current Week'!B:B=A17,'Current Week'!F:F<>"""",'Current Week'!J:J="""",'Curre"&"nt Week'!H:H="""",iserror(find(""FINAL"",'Current Week'!G:G)))))"),3.0) -> 3
A18: Gary | B18: =sumif('Current Week'!$B:$B,$A18,'Current Week'!D:D) -> 79 | C18: =sumif('Current Week'!$B:$B,$A18,'Current Week'!E:E) -> 41 | D18: =sumifs('Current Week'!D:D,'Current Week'!$B:$B,$A18,'Current Week'!T:T,"Power 5") -> 0 | E18: =sumifs('Current Week'!D:D,'Current Week'!$B:$B,$A18,'Current Week'!T:T,"Group of 5") -> 0 | F18: =10-countifs('Current Week'!B:B,A18,'Current Week'!G:G,"") -> 10 | G18: =IFERROR(__xludf.DUMMYFUNCTION("COUNTA(iferror(filter('Current Week'!B:B,'Current Week'!B:B=A18,left('Current Week'!G:G,5)=""FINAL"")))"),10.0) -> 10 | H18: =countifs('Current Week'!B:B,A18,'Current Week'!U:U,"=TRUE") -> 9 | I18: =F18-G18 -> 0 | J18: =IFERROR(__xludf.DUMMYFUNCTION("countifs('Current Week'!B:B,A18,'Current Week'!K:K,""<0"")+counta(iferror(filter('Current Week'!B:B,'Current Week'!B:B=A18,'Current Week'!F:F<>"""",'Current Week'!K:K="""",'Current Week'!H:H="""")))"),9.0) -> 9 | K18: =IFERROR(__xludf.DUMMYFUNCTION("counta(iferror(filter('Current Week'!B:B,'Current Week'!B:B=A18,'Current Week'!K:K>0,not(iserror(find(""FINAL"",'Current Week'!G:G))),'Current Week'!U:U=TRUE)))+counta(iferror(filter('Current Week'!B:B,'Current Week'!B:B=A18,'Current Week'!K:K="""",not(is"&"error(find(""FINAL"",'Current Week'!G:G))),'Current Week'!U:U=TRUE,'Current Week'!H:H="""")))"),0.0) -> 0 | L18: =IFERROR(__xludf.DUMMYFUNCTION("counta(iferror(filter('Current Week'!B:B,'Current Week'!B:B=A18,'Current Week'!K:K<0,not(iserror(find(""FINAL"",'Current Week'!G:G))),'Current Week'!U:U<>TRUE)))"),0.0) -> 0 | M18: =IFERROR(__xludf.DUMMYFUNCTION("H18+counta(iferror(filter('Current Week'!B:B,'Current Week'!B:B=A18,'Current Week'!K:K<0,iserror(find(""FINAL"",'Current Week'!G:G)))))+counta(iferror(filter('Current Week'!B:B,'Current Week'!B:B=A18,'Current Week'!F:F<>"""",'Current Week'!J:J="""",'Curre"&"nt Week'!H:H="""",iserror(find(""FINAL"",'Current Week'!G:G)))))"),9.0) -> 9
A19: Vu | B19: =sumif('Current Week'!$B:$B,$A19,'Current Week'!D:D) -> 57 | C19: =sumif('Current Week'!$B:$B,$A19,'Current Week'!E:E) -> 63 | D19: =sumifs('Current Week'!D:D,'Current Week'!$B:$B,$A19,'Current Week'!T:T,"Power 5") -> 0 | E19: =sumifs('Current Week'!D:D,'Current Week'!$B:$B,$A19,'Current Week'!T:T,"Group of 5") -> 0 | F19: =10-countifs('Current Week'!B:B,A19,'Current Week'!G:G,"") -> 10 | G19: =IFERROR(__xludf.DUMMYFUNCTION("COUNTA(iferror(filter('Current Week'!B:B,'Current Week'!B:B=A19,left('Current Week'!G:G,5)=""FINAL"")))"),10.0) -> 10 | H19: =countifs('Current Week'!B:B,A19,'Current Week'!U:U,"=TRUE") -> 5 | I19: =F19-G19 -> 0 | J19: =IFERROR(__xludf.DUMMYFUNCTION("countifs('Current Week'!B:B,A19,'Current Week'!K:K,""<0"")+counta(iferror(filter('Current Week'!B:B,'Current Week'!B:B=A19,'Current Week'!F:F<>"""",'Current Week'!K:K="""",'Current Week'!H:H="""")))"),3.0) -> 3 | K19: =IFERROR(__xludf.DUMMYFUNCTION("counta(iferror(filter('Current Week'!B:B,'Current Week'!B:B=A19,'Current Week'!K:K>0,not(iserror(find(""FINAL"",'Current Week'!G:G))),'Current Week'!U:U=TRUE)))+counta(iferror(filter('Current Week'!B:B,'Current Week'!B:B=A19,'Current Week'!K:K="""",not(is"&"error(find(""FINAL"",'Current Week'!G:G))),'Current Week'!U:U=TRUE,'Current Week'!H:H="""")))"),2.0) -> 2 | L19: =IFERROR(__xludf.DUMMYFUNCTION("counta(iferror(filter('Current Week'!B:B,'Current Week'!B:B=A19,'Current Week'!K:K<0,not(iserror(find(""FINAL"",'Current Week'!G:G))),'Current Week'!U:U<>TRUE)))"),0.0) -> 0 | M19: =IFERROR(__xludf.DUMMYFUNCTION("H19+counta(iferror(filter('Current Week'!B:B,'Current Week'!B:B=A19,'Current Week'!K:K<0,iserror(find(""FINAL"",'Current Week'!G:G)))))+counta(iferror(filter('Current Week'!B:B,'Current Week'!B:B=A19,'Current Week'!F:F<>"""",'Current Week'!J:J="""",'Curre"&"nt Week'!H:H="""",iserror(find(""FINAL"",'Current Week'!G:G)))))"),5.0) -> 5
A20: Nick A. | B20: =sumif('Current Week'!$B:$B,$A20,'Current Week'!D:D) -> 66 | C20: =sumif('Current Week'!$B:$B,$A20,'Current Week'!E:E) -> 54 | D20: =sumifs('Current Week'!D:D,'Current Week'!$B:$B,$A20,'Current Week'!T:T,"Power 5") -> 0 | E20: =sumifs('Current Week'!D:D,'Current Week'!$B:$B,$A20,'Current Week'!T:T,"Group of 5") -> 0 | F20: =10-countifs('Current Week'!B:B,A20,'Current Week'!G:G,"") -> 9 | G20: =IFERROR(__xludf.DUMMYFUNCTION("COUNTA(iferror(filter('Current Week'!B:B,'Current Week'!B:B=A20,left('Current Week'!G:G,5)=""FINAL"")))"),9.0) -> 9 | H20: =countifs('Current Week'!B:B,A20,'Current Week'!U:U,"=TRUE") -> 3 | I20: =F20-G20 -> 0 | J20: =IFERROR(__xludf.DUMMYFUNCTION("countifs('Current Week'!B:B,A20,'Current Week'!K:K,""<0"")+counta(iferror(filter('Current Week'!B:B,'Current Week'!B:B=A20,'Current Week'!F:F<>"""",'Current Week'!K:K="""",'Current Week'!H:H="""")))"),5.0) -> 5 | K20: =IFERROR(__xludf.DUMMYFUNCTION("counta(iferror(filter('Current Week'!B:B,'Current Week'!B:B=A20,'Current Week'!K:K>0,not(iserror(find(""FINAL"",'Current Week'!G:G))),'Current Week'!U:U=TRUE)))+counta(iferror(filter('Current Week'!B:B,'Current Week'!B:B=A20,'Current Week'!K:K="""",not(is"&"error(find(""FINAL"",'Current Week'!G:G))),'Current Week'!U:U=TRUE,'Current Week'!H:H="""")))"),1.0) -> 1 | L20: =IFERROR(__xludf.DUMMYFUNCTION("counta(iferror(filter('Current Week'!B:B,'Current Week'!B:B=A20,'Current Week'!K:K<0,not(iserror(find(""FINAL"",'Current Week'!G:G))),'Current Week'!U:U<>TRUE)))"),3.0) -> 3 | M20: =IFERROR(__xludf.DUMMYFUNCTION("H20+counta(iferror(filter('Current Week'!B:B,'Current Week'!B:B=A20,'Current Week'!K:K<0,iserror(find(""FINAL"",'Current Week'!G:G)))))+counta(iferror(filter('Current Week'!B:B,'Current Week'!B:B=A20,'Current Week'!F:F<>"""",'Current Week'!J:J="""",'Curre"&"nt Week'!H:H="""",iserror(find(""FINAL"",'Current Week'!G:G)))))"),3.0) -> 3
A21: Jeannine | B21: =sumif('Current Week'!$B:$B,$A21,'Current Week'!D:D) -> 60 | C21: =sumif('Current Week'!$B:$B,$A21,'Current Week'!E:E) -> 60 | D21: =sumifs('Current Week'!D:D,'Current Week'!$B:$B,$A21,'Current Week'!T:T,"Power 5") -> 0 | E21: =sumifs('Current Week'!D:D,'Current Week'!$B:$B,$A21,'Current Week'!T:T,"Group of 5") -> 0 | F21: =10-countifs('Current Week'!B:B,A21,'Current Week'!G:G,"") -> 10 | G21: =IFERROR(__xludf.DUMMYFUNCTION("COUNTA(iferror(filter('Current Week'!B:B,'Current Week'!B:B=A21,left('Current Week'!G:G,5)=""FINAL"")))"),10.0) -> 10 | H21: =countifs('Current Week'!B:B,A21,'Current Week'!U:U,"=TRUE") -> 2 | I21: =F21-G21 -> 0 | J21: =IFERROR(__xludf.DUMMYFUNCTION("countifs('Current Week'!B:B,A21,'Current Week'!K:K,""<0"")+counta(iferror(filter('Current Week'!B:B,'Current Week'!B:B=A21,'Current Week'!F:F<>"""",'Current Week'!K:K="""",'Current Week'!H:H="""")))"),5.0) -> 5 | K21: =IFERROR(__xludf.DUMMYFUNCTION("counta(iferror(filter('Current Week'!B:B,'Current Week'!B:B=A21,'Current Week'!K:K>0,not(iserror(find(""FINAL"",'Current Week'!G:G))),'Current Week'!U:U=TRUE)))+counta(iferror(filter('Current Week'!B:B,'Current Week'!B:B=A21,'Current Week'!K:K="""",not(is"&"error(find(""FINAL"",'Current Week'!G:G))),'Current Week'!U:U=TRUE,'Current Week'!H:H="""")))"),0.0) -> 0 | L21: =IFERROR(__xludf.DUMMYFUNCTION("counta(iferror(filter('Current Week'!B:B,'Current Week'!B:B=A21,'Current Week'!K:K<0,not(iserror(find(""FINAL"",'Current Week'!G:G))),'Current Week'!U:U<>TRUE)))"),3.0) -> 3 | M21: =IFERROR(__xludf.DUMMYFUNCTION("H21+counta(iferror(filter('Current Week'!B:B,'Current Week'!B:B=A21,'Current Week'!K:K<0,iserror(find(""FINAL"",'Current Week'!G:G)))))+counta(iferror(filter('Current Week'!B:B,'Current Week'!B:B=A21,'Current Week'!F:F<>"""",'Current Week'!J:J="""",'Curre"&"nt Week'!H:H="""",iserror(find(""FINAL"",'Current Week'!G:G)))))"),2.0) -> 2
A22: Justin | B22: =sumif('Current Week'!$B:$B,$A22,'Current Week'!D:D) -> 62 | C22: =sumif('Current Week'!$B:$B,$A22,'Current Week'!E:E) -> 57 | D22: =sumifs('Current Week'!D:D,'Current Week'!$B:$B,$A22,'Current Week'!T:T,"Power 5") -> 0 | E22: =sumifs('Current Week'!D:D,'Current Week'!$B:$B,$A22,'Current Week'!T:T,"Group of 5") -> 0 | F22: =10-countifs('Current Week'!B:B,A22,'Current Week'!G:G,"") -> 10 | G22: =IFERROR(__xludf.DUMMYFUNCTION("COUNTA(iferror(filter('Current Week'!B:B,'Current Week'!B:B=A22,left('Current Week'!G:G,5)=""FINAL"")))"),10.0) -> 10 | H22: =countifs('Current Week'!B:B,A22,'Current Week'!U:U,"=TRUE") -> 8 | I22: =F22-G22 -> 0 | J22: =IFERROR(__xludf.DUMMYFUNCTION("countifs('Current Week'!B:B,A22,'Current Week'!K:K,""<0"")+counta(iferror(filter('Current Week'!B:B,'Current Week'!B:B=A22,'Current Week'!F:F<>"""",'Current Week'!K:K="""",'Current Week'!H:H="""")))"),5.0) -> 5 | K22: =IFERROR(__xludf.DUMMYFUNCTION("counta(iferror(filter('Current Week'!B:B,'Current Week'!B:B=A22,'Current Week'!K:K>0,not(iserror(find(""FINAL"",'Current Week'!G:G))),'Current Week'!U:U=TRUE)))+counta(iferror(filter('Current Week'!B:B,'Current Week'!B:B=A22,'Current Week'!K:K="""",not(is"&"error(find(""FINAL"",'Current Week'!G:G))),'Current Week'!U:U=TRUE,'Current Week'!H:H="""")))"),2.0) -> 2 | L22: =IFERROR(__xludf.DUMMYFUNCTION("counta(iferror(filter('Current Week'!B:B,'Current Week'!B:B=A22,'Current Week'!K:K<0,not(iserror(find(""FINAL"",'Current Week'!G:G))),'Current Week'!U:U<>TRUE)))"),0.0) -> 0 | M22: =IFERROR(__xludf.DUMMYFUNCTION("H22+counta(iferror(filter('Current Week'!B:B,'Current Week'!B:B=A22,'Current Week'!K:K<0,iserror(find(""FINAL"",'Current Week'!G:G)))))+counta(iferror(filter('Current Week'!B:B,'Current Week'!B:B=A22,'Current Week'!F:F<>"""",'Current Week'!J:J="""",'Curre"&"nt Week'!H:H="""",iserror(find(""FINAL"",'Current Week'!G:G)))))"),8.0) -> 8
A23: Josh | B23: =sumif('Current Week'!$B:$B,$A23,'Current Week'!D:D) -> 75 | C23: =sumif('Current Week'!$B:$B,$A23,'Current Week'!E:E) -> 45 | D23: =sumifs('Current Week'!D:D,'Current Week'!$B:$B,$A23,'Current Week'!T:T,"Power 5") -> 0 | E23: =sumifs('Current Week'!D:D,'Current Week'!$B:$B,$A23,'Current Week'!T:T,"Group of 5") -> 0 | F23: =10-countifs('Current Week'!B:B,A23,'Current Week'!G:G,"") -> 10 | G23: =IFERROR(__xludf.DUMMYFUNCTION("COUNTA(iferror(filter('Current Week'!B:B,'Current Week'!B:B=A23,left('Current Week'!G:G,5)=""FINAL"")))"),10.0) -> 10 | H23: =countifs('Current Week'!B:B,A23,'Current Week'!U:U,"=TRUE") -> 8 | I23: =F23-G23 -> 0 | J23: =IFERROR(__xludf.DUMMYFUNCTION("countifs('Current Week'!B:B,A23,'Current Week'!K:K,""<0"")+counta(iferror(filter('Current Week'!B:B,'Current Week'!B:B=A23,'Current Week'!F:F<>"""",'Current Week'!K:K="""",'Current Week'!H:H="""")))"),6.0) -> 6 | K23: =IFERROR(__xludf.DUMMYFUNCTION("counta(iferror(filter('Current Week'!B:B,'Current Week'!B:B=A23,'Current Week'!K:K>0,not(iserror(find(""FINAL"",'Current Week'!G:G))),'Current Week'!U:U=TRUE)))+counta(iferror(filter('Current Week'!B:B,'Current Week'!B:B=A23,'Current Week'!K:K="""",not(is"&"error(find(""FINAL"",'Current Week'!G:G))),'Current Week'!U:U=TRUE,'Current Week'!H:H="""")))"),2.0) -> 2 | L23: =IFERROR(__xludf.DUMMYFUNCTION("counta(iferror(filter('Current Week'!B:B,'Current Week'!B:B=A23,'Current Week'!K:K<0,not(iserror(find(""FINAL"",'Current Week'!G:G))),'Current Week'!U:U<>TRUE)))"),0.0) -> 0 | M23: =IFERROR(__xludf.DUMMYFUNCTION("H23+counta(iferror(filter('Current Week'!B:B,'Current Week'!B:B=A23,'Current Week'!K:K<0,iserror(find(""FINAL"",'Current Week'!G:G)))))+counta(iferror(filter('Current Week'!B:B,'Current Week'!B:B=A23,'Current Week'!F:F<>"""",'Current Week'!J:J="""",'Curre"&"nt Week'!H:H="""",iserror(find(""FINAL"",'Current Week'!G:G)))))"),8.0) -> 8
A24: Mike | B24: =sumif('Current Week'!$B:$B,$A24,'Current Week'!D:D) -> 61 | C24: =sumif('Current Week'!$B:$B,$A24,'Current Week'!E:E) -> 59 | D24: =sumifs('Current Week'!D:D,'Current Week'!$B:$B,$A24,'Current Week'!T:T,"Power 5") -> 0 | E24: =sumifs('Current Week'!D:D,'Current Week'!$B:$B,$A24,'Current Week'!T:T,"Group of 5") -> 0 | F24: =10-countifs('Current Week'!B:B,A24,'Current Week'!G:G,"") -> 10 | G24: =IFERROR(__xludf.DUMMYFUNCTION("COUNTA(iferror(filter('Current Week'!B:B,'Current Week'!B:B=A24,left('Current Week'!G:G,5)=""FINAL"")))"),10.0) -> 10 | H24: =countifs('Current Week'!B:B,A24,'Current Week'!U:U,"=TRUE") -> 2 | I24: =F24-G24 -> 0 | J24: =IFERROR(__xludf.DUMMYFUNCTION("countifs('Current Week'!B:B,A24,'Current Week'!K:K,""<0"")+counta(iferror(filter('Current Week'!B:B,'Current Week'!B:B=A24,'Current Week'!F:F<>"""",'Current Week'!K:K="""",'Current Week'!H:H="""")))"),4.0) -> 4 | K24: =IFERROR(__xludf.DUMMYFUNCTION("counta(iferror(filter('Current Week'!B:B,'Current Week'!B:B=A24,'Current Week'!K:K>0,not(iserror(find(""FINAL"",'Current Week'!G:G))),'Current Week'!U:U=TRUE)))+counta(iferror(filter('Current Week'!B:B,'Current Week'!B:B=A24,'Current Week'!K:K="""",not(is"&"error(find(""FINAL"",'Current Week'!G:G))),'Current Week'!U:U=TRUE,'Current Week'!H:H="""")))"),1.0) -> 1 | L24: =IFERROR(__xludf.DUMMYFUNCTION("counta(iferror(filter('Current Week'!B:B,'Current Week'!B:B=A24,'Current Week'!K:K<0,not(iserror(find(""FINAL"",'Current Week'!G:G))),'Current Week'!U:U<>TRUE)))"),3.0) -> 3 | M24: =IFERROR(__xludf.DUMMYFUNCTION("H24+counta(iferror(filter('Current Week'!B:B,'Current Week'!B:B=A24,'Current Week'!K:K<0,iserror(find(""FINAL"",'Current Week'!G:G)))))+counta(iferror(filter('Current Week'!B:B,'Current Week'!B:B=A24,'Current Week'!F:F<>"""",'Current Week'!J:J="""",'Curre"&"nt Week'!H:H="""",iserror(find(""FINAL"",'Current Week'!G:G)))))"),2.0) -> 2
A25: Brad | B25: =sumif('Current Week'!$B:$B,$A25,'Current Week'!D:D) -> 69 | C25: =sumif('Current Week'!$B:$B,$A25,'Current Week'!E:E) -> 51 | D25: =sumifs('Current Week'!D:D,'Current Week'!$B:$B,$A25,'Current Week'!T:T,"Power 5") -> 0 | E25: =sumifs('Current Week'!D:D,'Current Week'!$B:$B,$A25,'Current Week'!T:T,"Group of 5") -> 0 | F25: =10-countifs('Current Week'!B:B,A25,'Current Week'!G:G,"") -> 10 | G25: =IFERROR(__xludf.DUMMYFUNCTION("COUNTA(iferror(filter('Current Week'!B:B,'Current Week'!B:B=A25,left('Current Week'!G:G,5)=""FINAL"")))"),10.0) -> 10 | H25: =countifs('Current Week'!B:B,A25,'Current Week'!U:U,"=TRUE") -> 6 | I25: =F25-G25 -> 0 | J25: =IFERROR(__xludf.DUMMYFUNCTION("countifs('Current Week'!B:B,A25,'Current Week'!K:K,""<0"")+counta(iferror(filter('Current Week'!B:B,'Current Week'!B:B=A25,'Current Week'!F:F<>"""",'Current Week'!K:K="""",'Current Week'!H:H="""")))"),5.0) -> 5 | K25: =IFERROR(__xludf.DUMMYFUNCTION("counta(iferror(filter('Current Week'!B:B,'Current Week'!B:B=A25,'Current Week'!K:K>0,not(iserror(find(""FINAL"",'Current Week'!G:G))),'Current Week'!U:U=TRUE)))+counta(iferror(filter('Current Week'!B:B,'Current Week'!B:B=A25,'Current Week'!K:K="""",not(is"&"error(find(""FINAL"",'Current Week'!G:G))),'Current Week'!U:U=TRUE,'Current Week'!H:H="""")))"),1.0) -> 1 | L25: =IFERROR(__xludf.DUMMYFUNCTION("counta(iferror(filter('Current Week'!B:B,'Current Week'!B:B=A25,'Current Week'!K:K<0,not(iserror(find(""FINAL"",'Current Week'!G:G))),'Current Week'!U:U<>TRUE)))"),0.0) -> 0 | M25: =IFERROR(__xludf.DUMMYFUNCTION("H25+counta(iferror(filter('Current Week'!B:B,'Current Week'!B:B=A25,'Current Week'!K:K<0,iserror(find(""FINAL"",'Current Week'!G:G)))))+counta(iferror(filter('Current Week'!B:B,'Current Week'!B:B=A25,'Current Week'!F:F<>"""",'Current Week'!J:J="""",'Curre"&"nt Week'!H:H="""",iserror(find(""FINAL"",'Current Week'!G:G)))))"),6.0) -> 6
A26: Masa | B26: =sumif('Current Week'!$B:$B,$A26,'Current Week'!D:D) -> 61 | C26: =sumif('Current Week'!$B:$B,$A26,'Current Week'!E:E) -> 59 | D26: =sumifs('Current Week'!D:D,'Current Week'!$B:$B,$A26,'Current Week'!T:T,"Power 5") -> 0 | E26: =sumifs('Current Week'!D:D,'Current Week'!$B:$B,$A26,'Current Week'!T:T,"Group of 5") -> 0 | F26: =10-countifs('Current Week'!B:B,A26,'Current Week'!G:G,"") -> 10 | G26: =IFERROR(__xludf.DUMMYFUNCTION("COUNTA(iferror(filter('Current Week'!B:B,'Current Week'!B:B=A26,left('Current Week'!G:G,5)=""FINAL"")))"),10.0) -> 10 | H26: =countifs('Current Week'!B:B,A26,'Current Week'!U:U,"=TRUE") -> 5 | I26: =F26-G26 -> 0 | J26: =IFERROR(__xludf.DUMMYFUNCTION("countifs('Current Week'!B:B,A26,'Current Week'!K:K,""<0"")+counta(iferror(filter('Current Week'!B:B,'Current Week'!B:B=A26,'Current Week'!F:F<>"""",'Current Week'!K:K="""",'Current Week'!H:H="""")))"),5.0) -> 5 | K26: =IFERROR(__xludf.DUMMYFUNCTION("counta(iferror(filter('Current Week'!B:B,'Current Week'!B:B=A26,'Current Week'!K:K>0,not(iserror(find(""FINAL"",'Current Week'!G:G))),'Current Week'!U:U=TRUE)))+counta(iferror(filter('Current Week'!B:B,'Current Week'!B:B=A26,'Current Week'!K:K="""",not(is"&"error(find(""FINAL"",'Current Week'!G:G))),'Current Week'!U:U=TRUE,'Current Week'!H:H="""")))"),2.0) -> 2 | L26: =IFERROR(__xludf.DUMMYFUNCTION("counta(iferror(filter('Current Week'!B:B,'Current Week'!B:B=A26,'Current Week'!K:K<0,not(iserror(find(""FINAL"",'Current Week'!G:G))),'Current Week'!U:U<>TRUE)))"),2.0) -> 2 | M26: =IFERROR(__xludf.DUMMYFUNCTION("H26+counta(iferror(filter('Current Week'!B:B,'Current Week'!B:B=A26,'Current Week'!K:K<0,iserror(find(""FINAL"",'Current Week'!G:G)))))+counta(iferror(filter('Current Week'!B:B,'Current Week'!B:B=A26,'Current Week'!F:F<>"""",'Current Week'!J:J="""",'Curre"&"nt Week'!H:H="""",iserror(find(""FINAL"",'Current Week'!G:G)))))"),5.0) -> 5
A27: Dan | B27: =sumif('Current Week'!$B:$B,$A27,'Current Week'!D:D) -> 83 | C27: =sumif('Current Week'!$B:$B,$A27,'Current Week'!E:E) -> 36 | D27: =sumifs('Current Week'!D:D,'Current Week'!$B:$B,$A27,'Current Week'!T:T,"Power 5") -> 0 | E27: =sumifs('Current Week'!D:D,'Current Week'!$B:$B,$A27,'Current Week'!T:T,"Group of 5") -> 0 | F27: =10-countifs('Current Week'!B:B,A27,'Current Week'!G:G,"") -> 9 | G27: =IFERROR(__xludf.DUMMYFUNCTION("COUNTA(iferror(filter('Current Week'!B:B,'Current Week'!B:B=A27,left('Current Week'!G:G,5)=""FINAL"")))"),9.0) -> 9 | H27: =countifs('Current Week'!B:B,A27,'Current Week'!U:U,"=TRUE") -> 6 | I27: =F27-G27 -> 0 | J27: =IFERROR(__xludf.DUMMYFUNCTION("countifs('Current Week'!B:B,A27,'Current Week'!K:K,""<0"")+counta(iferror(filter('Current Week'!B:B,'Current Week'!B:B=A27,'Current Week'!F:F<>"""",'Current Week'!K:K="""",'Current Week'!H:H="""")))"),4.0) -> 4 | K27: =IFERROR(__xludf.DUMMYFUNCTION("counta(iferror(filter('Current Week'!B:B,'Current Week'!B:B=A27,'Current Week'!K:K>0,not(iserror(find(""FINAL"",'Current Week'!G:G))),'Current Week'!U:U=TRUE)))+counta(iferror(filter('Current Week'!B:B,'Current Week'!B:B=A27,'Current Week'!K:K="""",not(is"&"error(find(""FINAL"",'Current Week'!G:G))),'Current Week'!U:U=TRUE,'Current Week'!H:H="""")))"),3.0) -> 3 | L27: =IFERROR(__xludf.DUMMYFUNCTION("counta(iferror(filter('Current Week'!B:B,'Current Week'!B:B=A27,'Current Week'!K:K<0,not(iserror(find(""FINAL"",'Current Week'!G:G))),'Current Week'!U:U<>TRUE)))"),1.0) -> 1 | M27: =IFERROR(__xludf.DUMMYFUNCTION("H27+counta(iferror(filter('Current Week'!B:B,'Current Week'!B:B=A27,'Current Week'!K:K<0,iserror(find(""FINAL"",'Current Week'!G:G)))))+counta(iferror(filter('Current Week'!B:B,'Current Week'!B:B=A27,'Current Week'!F:F<>"""",'Current Week'!J:J="""",'Curre"&"nt Week'!H:H="""",iserror(find(""FINAL"",'Current Week'!G:G)))))"),6.0) -> 6
A28: Nico | B28: =sumif('Current Week'!$B:$B,$A28,'Current Week'!D:D) -> 71 | C28: =sumif('Current Week'!$B:$B,$A28,'Current Week'!E:E) -> 49 | D28: =sumifs('Current Week'!D:D,'Current Week'!$B:$B,$A28,'Current Week'!T:T,"Power 5") -> 0 | E28: =sumifs('Current Week'!D:D,'Current Week'!$B:$B,$A28,'Current Week'!T:T,"Group of 5") -> 0 | F28: =10-countifs('Current Week'!B:B,A28,'Current Week'!G:G,"") -> 10 | G28: =IFERROR(__xludf.DUMMYFUNCTION("COUNTA(iferror(filter('Current Week'!B:B,'Current Week'!B:B=A28,left('Current Week'!G:G,5)=""FINAL"")))"),10.0) -> 10 | H28: =countifs('Current Week'!B:B,A28,'Current Week'!U:U,"=TRUE") -> 6 | I28: =F28-G28 -> 0 | J28: =IFERROR(__xludf.DUMMYFUNCTION("countifs('Current Week'!B:B,A28,'Current Week'!K:K,""<0"")+counta(iferror(filter('Current Week'!B:B,'Current Week'!B:B=A28,'Current Week'!F:F<>"""",'Current Week'!K:K="""",'Current Week'!H:H="""")))"),5.0) -> 5 | K28: =IFERROR(__xludf.DUMMYFUNCTION("counta(iferror(filter('Current Week'!B:B,'Current Week'!B:B=A28,'Current Week'!K:K>0,not(iserror(find(""FINAL"",'Current Week'!G:G))),'Current Week'!U:U=TRUE)))+counta(iferror(filter('Current Week'!B:B,'Current Week'!B:B=A28,'Current Week'!K:K="""",not(is"&"error(find(""FINAL"",'Current Week'!G:G))),'Current Week'!U:U=TRUE,'Current Week'!H:H="""")))"),2.0) -> 2 | L28: =IFERROR(__xludf.DUMMYFUNCTION("counta(iferror(filter('Current Week'!B:B,'Current Week'!B:B=A28,'Current Week'!K:K<0,not(iserror(find(""FINAL"",'Current Week'!G:G))),'Current Week'!U:U<>TRUE)))"),1.0) -> 1 | M28: =IFERROR(__xludf.DUMMYFUNCTION("H28+counta(iferror(filter('Current Week'!B:B,'Current Week'!B:B=A28,'Current Week'!K:K<0,iserror(find(""FINAL"",'Current Week'!G:G)))))+counta(iferror(filter('Current Week'!B:B,'Current Week'!B:B=A28,'Current Week'!F:F<>"""",'Current Week'!J:J="""",'Curre"&"nt Week'!H:H="""",iserror(find(""FINAL"",'Current Week'!G:G)))))"),6.0) -> 6
B29: =sumif('Current Week'!$B:$B,$A29,'Current Week'!D:D) -> 0 | C29: =sumif('Current Week'!$B:$B,$A29,'Current Week'!E:E) -> 0 | D29: =sumifs('Current Week'!D:D,'Current Week'!$B:$B,$A29,'Current Week'!T:T,"Power 5") -> 0 | E29: =sumifs('Current Week'!D:D,'Current Week'!$B:$B,$A29,'Current Week'!T:T,"Group of 5") -> 0 | F29: =10-countifs('Current Week'!B:B,A29,'Current Week'!G:G,"") -> 10 | G29: =IFERROR(__xludf.DUMMYFUNCTION("COUNTA(iferror(filter('Current Week'!B:B,'Current Week'!B:B=A29,left('Current Week'!G:G,5)=""FINAL"")))"),0.0) -> 0 | H29: =countifs('Current Week'!B:B,A29,'Current Week'!U:U,"=TRUE") -> 0 | I29: =F29-G29 -> 10 | J29: =IFERROR(__xludf.DUMMYFUNCTION("countifs('Current Week'!B:B,A29,'Current Week'!K:K,""<0"")+counta(iferror(filter('Current Week'!B:B,'Current Week'!B:B=A29,'Current Week'!F:F<>"""",'Current Week'!K:K="""",'Current Week'!H:H="""")))"),0.0) -> 0 | K29: =IFERROR(__xludf.DUMMYFUNCTION("counta(iferror(filter('Current Week'!B:B,'Current Week'!B:B=A29,'Current Week'!K:K>0,not(iserror(find(""FINAL"",'Current Week'!G:G))),'Current Week'!U:U=TRUE)))+counta(iferror(filter('Current Week'!B:B,'Current Week'!B:B=A29,'Current Week'!K:K="""",not(is"&"error(find(""FINAL"",'Current Week'!G:G))),'Current Week'!U:U=TRUE,'Current Week'!H:H="""")))"),0.0) -> 0 | L29: =IFERROR(__xludf.DUMMYFUNCTION("counta(iferror(filter('Current Week'!B:B,'Current Week'!B:B=A29,'Current Week'!K:K<0,not(iserror(find(""FINAL"",'Current Week'!G:G))),'Current Week'!U:U<>TRUE)))"),0.0) -> 0 | M29: =IFERROR(__xludf.DUMMYFUNCTION("H29+counta(iferror(filter('Current Week'!B:B,'Current Week'!B:B=A29,'Current Week'!K:K<0,iserror(find(""FINAL"",'Current Week'!G:G)))))+counta(iferror(filter('Current Week'!B:B,'Current Week'!B:B=A29,'Current Week'!F:F<>"""",'Current Week'!J:J="""",'Curre"&"nt Week'!H:H="""",iserror(find(""FINAL"",'Current Week'!G:G)))))"),0.0) -> 0

Sheet Current Week
A1: 100 | B1: Player | C1: Team | D1: W | E1: L | F1: matchup | G1: Status | H1: opponent | I1: network | J1: Opening Spread | K1: Spread | L1: Current Total | M1: Total | N1: PF | O1: PA | P1: sort2 | Q1: dupe | R1: activeSort | S1: Conf | T1: Conf type | U1: Win
A2: 101 | B2: Nick G. | C2: Auburn | D2: 5 | E2: 7 | F2: (10) Alabama 27 Auburn 20 | G2: FINAL | H2: Vu | K2: 5.5 | M2: 46.5 | N2: 321 | O2: 248 | P2: 2 | Q2: TRUE | R2: 100 | S2: {=byrow(C2:C150,lambda(rw,iferror(vlookup(rw,{DraftTracker!F:F,DraftTracker!E:E},2,0),"")))} -> SEC | T2: {=byrow(S2:S150,lambda(rw,iferror(VLOOKUP(rw,P5G5!A:B,2,0),"")))} -> Power 4 | U2: =IFERROR(__xludf.DUMMYFUNCTION("iferror(if(not(iserror(find(""FINAL"",G2))),max(arrayformula(value(REGEXEXTRACT(F2,""^""&C2&"" ([\d]+)|[^a-zA-Z] ""&C2&"" ([\d]+)""))))=max(value(REGEXEXTRACT(F2,"" ([\d]+)"")),value(REGEXEXTRACT(F2,""([\d]+)$""))),""""))"),FALSE) -> FALSE
A3: 101 | B3: Nick G. | C3: North Carolina | D3: 4 | E3: 8 | F3: North Carolina 19 NC State 42 | G3: FINAL | H3: Gary | K3: 7.5 | M3: 47.5 | N3: 231 | O3: 294 | P3: 2 | Q3: FALSE | R3: 100 | S3: ACC | T3: Power 4 | U3: =IFERROR(__xludf.DUMMYFUNCTION("iferror(if(not(iserror(find(""FINAL"",G3))),max(arrayformula(value(REGEXEXTRACT(F3,""^""&C3&"" ([\d]+)|[^a-zA-Z] ""&C3&"" ([\d]+)""))))=max(value(REGEXEXTRACT(F3,"" ([\d]+)"")),value(REGEXEXTRACT(F3,""([\d]+)$""))),""""))"),FALSE) -> FALSE
A4: 101 | B4: Nick G. | C4: Rice | D4: 5 | E4: 7 | F4: Rice 3 South Florida 52 | G4: FINAL | H4: Josh | K4: 28.5 | M4: 59.5 | N4: 238 | O4: 387 | P4: 2 | Q4: FALSE | R4: 100 | S4: AAC | T4: Group of 6 | U4: =IFERROR(__xludf.DUMMYFUNCTION("iferror(if(not(iserror(find(""FINAL"",G4))),max(arrayformula(value(REGEXEXTRACT(F4,""^""&C4&"" ([\d]+)|[^a-zA-Z] ""&C4&"" ([\d]+)""))))=max(value(REGEXEXTRACT(F4,"" ([\d]+)"")),value(REGEXEXTRACT(F4,""([\d]+)$""))),""""))"),FALSE) -> FALSE
A5: 101 | B5: Nick G. | C5: Penn State | D5: 6 | E5: 6 | F5: Penn State 40 Rutgers 36 | G5: FINAL | H5: Dan | K5: -14 | M5: 55.5 | N5: 381 | O5: 257 | P5: 2 | Q5: TRUE | R5: 100 | S5: Big Ten | T5: Power 4 | U5: =IFERROR(__xludf.DUMMYFUNCTION("iferror(if(not(iserror(find(""FINAL"",G5))),max(arrayformula(value(REGEXEXTRACT(F5,""^""&C5&"" ([\d]+)|[^a-zA-Z] ""&C5&"" ([\d]+)""))))=max(value(REGEXEXTRACT(F5,"" ([\d]+)"")),value(REGEXEXTRACT(F5,""([\d]+)$""))),""""))"),TRUE) -> TRUE
A6: 101 | B6: Nick G. | C6: Appalachian State | D6: 5 | E6: 7 | F6: Arkansas State 30 Appalachian State 29 | G6: FINAL | H6: Nico | K6: -1.5 | M6: 54.5 | N6: 304 | O6: 358 | P6: 2 | Q6: FALSE | R6: 100 | S6: Sun Belt | T6: Group of 6 | U6: =IFERROR(__xludf.DUMMYFUNCTION("iferror(if(not(iserror(find(""FINAL"",G6))),max(arrayformula(value(REGEXEXTRACT(F6,""^""&C6&"" ([\d]+)|[^a-zA-Z] ""&C6&"" ([\d]+)""))))=max(value(REGEXEXTRACT(F6,"" ([\d]+)"")),value(REGEXEXTRACT(F6,""([\d]+)$""))),""""))"),FALSE) -> FALSE
A7: 101 | B7: Nick G. | C7: Texas Tech | D7: 11 | E7: 1 | F7: (7) Texas Tech 49 West Virginia 0 | G7: FINAL | H7: Nico | K7: -23.5 | M7: 52.5 | N7: 518 | O7: 135 | P7: 2 | Q7: FALSE | R7: 100 | S7: Big 12 | T7: Power 4 | U7: =IFERROR(__xludf.DUMMYFUNCTION("iferror(if(not(iserror(find(""FINAL"",G7))),max(arrayformula(value(REGEXEXTRACT(F7,""^""&C7&"" ([\d]+)|[^a-zA-Z] ""&C7&"" ([\d]+)""))))=max(value(REGEXEXTRACT(F7,"" ([\d]+)"")),value(REGEXEXTRACT(F7,""([\d]+)$""))),""""))"),TRUE) -> TRUE
A8: 101 | B8: Nick G. | C8: Arizona State | D8: 8 | E8: 4 | F8: Arizona 23 Arizona State 7 | G8: FINAL | H8: Undrafted | K8: 1.5 | M8: 47.5 | N8: 296 | O8: 276 | P8: 2 | Q8: TRUE | R8: 100 | S8: Big 12 | T8: Power 4 | U8: =IFERROR(__xludf.DUMMYFUNCTION("iferror(if(not(iserror(find(""FINAL"",G8))),max(arrayformula(value(REGEXEXTRACT(F8,""^""&C8&"" ([\d]+)|[^a-zA-Z] ""&C8&"" ([\d]+)""))))=max(value(REGEXEXTRACT(F8,"" ([\d]+)"")),value(REGEXEXTRACT(F8,""([\d]+)$""))),""""))"),FALSE) -> FALSE
A9: 101 | B9: Nick G. | C9: Air Force | D9: 4 | E9: 8 | F9: Air Force 42 Colorado State 21 | G9: FINAL | H9: Vu | K9: -2.5 | M9: 46.5 | N9: 358 | O9: 364 | P9: 2 | Q9: TRUE | R9: 100 | S9: MWC | T9: Group of 6 | U9: =IFERROR(__xludf.DUMMYFUNCTION("iferror(if(not(iserror(find(""FINAL"",G9))),max(arrayformula(value(REGEXEXTRACT(F9,""^""&C9&"" ([\d]+)|[^a-zA-Z] ""&C9&"" ([\d]+)""))))=max(value(REGEXEXTRACT(F9,"" ([\d]+)"")),value(REGEXEXTRACT(F9,""([\d]+)$""))),""""))"),TRUE) -> TRUE
A10: 101 | B10: Nick G. | C10: UMASS | D10: 0 | E10: 12 | F10: Bowling Green 45 UMASS 14 | G10: FINAL | H10: Justin | K10: 14.5 | M10: 44.5 | N10: 133 | O10: 463 | P10: 2 | Q10: FALSE | R10: 100 | S10: MAC | T10: Group of 6 | U10: =IFERROR(__xludf.DUMMYFUNCTION("iferror(if(not(iserror(find(""FINAL"",G10))),max(arrayformula(value(REGEXEXTRACT(F10,""^""&C10&"" ([\d]+)|[^a-zA-Z] ""&C10&"" ([\d]+)""))))=max(value(REGEXEXTRACT(F10,"" ([\d]+)"")),value(REGEXEXTRACT(F10,""([\d]+)$""))),""""))"),FALSE) -> FALSE
A11: 101 | B11: Nick G. | C11: New Mexico State | D11: 4 | E11: 8 | F11: Middle Tennessee 31 New Mexico State 24 | G11: FINAL - OT | H11: Josh | K11: -3.5 | M11: 52.5 | N11: 259 | O11: 331 | P11: 2 | Q11: FALSE | R11: 100 | S11: CUSA | T11: Group of 6 | U11: =IFERROR(__xludf.DUMMYFUNCTION("iferror(if(not(iserror(find(""FINAL"",G11))),max(arrayformula(value(REGEXEXTRACT(F11,""^""&C11&"" ([\d]+)|[^a-zA-Z] ""&C11&"" ([\d]+)""))))=max(value(REGEXEXTRACT(F11,"" ([\d]+)"")),value(REGEXEXTRACT(F11,""([\d]+)$""))),""""))"),FALSE) -> FALSE
A12: 102 | U12: =IFERROR(__xludf.DUMMYFUNCTION("iferror(if(not(iserror(find(""FINAL"",G12))),max(arrayformula(value(REGEXEXTRACT(F12,""^""&C12&"" ([\d]+)|[^a-zA-Z] ""&C12&"" ([\d]+)""))))=max(value(REGEXEXTRACT(F12,"" ([\d]+)"")),value(REGEXEXTRACT(F12,""([\d]+)$""))),""""))"),"")
A13: 103 | B13: Gary | C13: NC State | D13: 7 | E13: 5 | F13: North Carolina 19 NC State 42 | G13: FINAL | H13: Nick G. | K13: -7.5 | M13: 47.5 | N13: 362 | O13: 346 | P13: 2 | Q13: TRUE | R13: 100 | S13: ACC | T13: Power 4 | U13: =IFERROR(__xludf.DUMMYFUNCTION("iferror(if(not(iserror(find(""FINAL"",G13))),max(arrayformula(value(REGEXEXTRACT(F13,""^""&C13&"" ([\d]+)|[^a-zA-Z] ""&C13&"" ([\d]+)""))))=max(value(REGEXEXTRACT(F13,"" ([\d]+)"")),value(REGEXEXTRACT(F13,""([\d]+)$""))),""""))"),TRUE) -> TRUE
A14: 103 | B14: Gary | C14: USC | D14: 9 | E14: 3 | F14: UCLA 10 (20) USC 29 | G14: FINAL | H14: Vu | K14: -21.5 | M14: 58.5 | N14: 438 | O14: 269 | P14: 2 | Q14: TRUE | R14: 100 | S14: Big Ten | T14: Power 4 | U14: =IFERROR(__xludf.DUMMYFUNCTION("iferror(if(not(iserror(find(""FINAL"",G14))),max(arrayformula(value(REGEXEXTRACT(F14,""^""&C14&"" ([\d]+)|[^a-zA-Z] ""&C14&"" ([\d]+)""))))=max(value(REGEXEXTRACT(F14,"" ([\d]+)"")),value(REGEXEXTRACT(F14,""([\d]+)$""))),""""))"),TRUE) -> TRUE
A15: 103 | B15: Gary | C15: TCU | D15: 8 | E15: 4 | F15: Cincinnati 23 TCU 45 | G15: FINAL | H15: Mike | K15: -3.5 | M15: 57.5 | N15: 369 | O15: 302 | P15: 2 | Q15: TRUE | R15: 100 | S15: Big 12 | T15: Power 4 | U15: =IFERROR(__xludf.DUMMYFUNCTION("iferror(if(not(iserror(find(""FINAL"",G15))),max(arrayformula(value(REGEXEXTRACT(F15,""^""&C15&"" ([\d]+)|[^a-zA-Z] ""&C15&"" ([\d]+)""))))=max(value(REGEXEXTRACT(F15,"" ([\d]+)"")),value(REGEXEXTRACT(F15,""([\d]+)$""))),""""))"),TRUE) -> TRUE
A16: 103 | B16: Gary | C16: Oklahoma | D16: 10 | E16: 2 | F16: LSU 13 (8) Oklahoma 17 | G16: FINAL | H16: Jeannine | K16: -10.5 | M16: 35.5 | N16: 317 | O16: 167 | P16: 2 | Q16: FALSE | R16: 100 | S16: SEC | T16: Power 4 | U16: =IFERROR(__xludf.DUMMYFUNCTION("iferror(if(not(iserror(find(""FINAL"",G16))),max(arrayformula(value(REGEXEXTRACT(F16,""^""&C16&"" ([\d]+)|[^a-zA-Z] ""&C16&"" ([\d]+)""))))=max(value(REGEXEXTRACT(F16,"" ([\d]+)"")),value(REGEXEXTRACT(F16,""([\d]+)$""))),""""))"),TRUE) -> TRUE
A17: 103 | B17: Gary | C17: Texas State | D17: 6 | E17: 6 | F17: South Alabama 26 Texas State 49 | G17: FINAL | H17: Mike | K17: -8.5 | M17: 62.5 | N17: 433 | O17: 367 | P17: 2 | Q17: FALSE | R17: 100 | S17: Sun Belt | T17: Group of 6 | U17: =IFERROR(__xludf.DUMMYFUNCTION("iferror(if(not(iserror(find(""FINAL"",G17))),max(arrayformula(value(REGEXEXTRACT(F17,""^""&C17&"" ([\d]+)|[^a-zA-Z] ""&C17&"" ([\d]+)""))))=max(value(REGEXEXTRACT(F17,"" ([\d]+)"")),value(REGEXEXTRACT(F17,""([\d]+)$""))),""""))"),TRUE) -> TRUE
A18: 103 | B18: Gary | C18: Ball State | D18: 4 | E18: 8 | F18: Ball State 24 Miami-OH 45 | G18: FINAL | H18: Mike | K18: 17.5 | M18: 41.5 | N18: 190 | O18: 358 | P18: 2 | Q18: FALSE | R18: 100 | S18: MAC | T18: Group of 6 | U18: =IFERROR(__xludf.DUMMYFUNCTION("iferror(if(not(iserror(find(""FINAL"",G18))),max(arrayformula(value(REGEXEXTRACT(F18,""^""&C18&"" ([\d]+)|[^a-zA-Z] ""&C18&"" ([\d]+)""))))=max(value(REGEXEXTRACT(F18,"" ([\d]+)"")),value(REGEXEXTRACT(F18,""([\d]+)$""))),""""))"),FALSE) -> FALSE
A19: 103 | B19: Gary | C19: East Carolina | D19: 8 | E19: 4 | F19: East Carolina 42 Florida Atlantic 3 | G19: FINAL | H19: Nick A. | K19: -6.5 | M19: 65.5 | N19: 402 | O19: 244 | P19: 2 | Q19: TRUE | R19: 100 | S19: AAC | T19: Group of 6 | U19: =IFERROR(__xludf.DUMMYFUNCTION("iferror(if(not(iserror(find(""FINAL"",G19))),max(arrayformula(value(REGEXEXTRACT(F19,""^""&C19&"" ([\d]+)|[^a-zA-Z] ""&C19&"" ([\d]+)""))))=max(value(REGEXEXTRACT(F19,"" ([\d]+)"")),value(REGEXEXTRACT(F19,""([\d]+)$""))),""""))"),TRUE) -> TRUE
A20: 103 | B20: Gary | C20: Boise State | D20: 8 | E20: 4 | F20: Boise State 25 Utah State 24 | G20: FINAL | H20: Jeannine | K20: -2.5 | M20: 55.5 | N20: 370 | O20: 278 | P20: 2 | Q20: TRUE | R20: 100 | S20: MWC | T20: Group of 6 | U20: =IFERROR(__xludf.DUMMYFUNCTION("iferror(if(not(iserror(find(""FINAL"",G20))),max(arrayformula(value(REGEXEXTRACT(F20,""^""&C20&"" ([\d]+)|[^a-zA-Z] ""&C20&"" ([\d]+)""))))=max(value(REGEXEXTRACT(F20,"" ([\d]+)"")),value(REGEXEXTRACT(F20,""([\d]+)$""))),""""))"),TRUE) -> TRUE
A21: 103 | B21: Gary | C21: Utah | D21: 10 | E21: 2 | F21: (14) Utah 31 Kansas 21 | G21: FINAL | H21: Nick A. | K21: -10.5 | M21: 60.5 | N21: 493 | O21: 224 | P21: 2 | Q21: FALSE | R21: 100 | S21: Big 12 | T21: Power 4 | U21: =IFERROR(__xludf.DUMMYFUNCTION("iferror(if(not(iserror(find(""FINAL"",G21))),max(arrayformula(value(REGEXEXTRACT(F21,""^""&C21&"" ([\d]+)|[^a-zA-Z] ""&C21&"" ([\d]+)""))))=max(value(REGEXEXTRACT(F21,"" ([\d]+)"")),value(REGEXEXTRACT(F21,""([\d]+)$""))),""""))"),TRUE) -> TRUE
A22: 103 | B22: Gary | C22: Kennesaw State | D22: 9 | E22: 3 | F22: Kennesaw State 48 Liberty 42 | G22: FINAL - 2ND OT | H22: Vu | K22: -1.5 | M22: 55.5 | N22: 349 | O22: 301 | P22: 2 | Q22: TRUE | R22: 100 | S22: CUSA | T22: Group of 6 | U22: =IFERROR(__xludf.DUMMYFUNCTION("iferror(if(not(iserror(find(""FINAL"",G22))),max(arrayformula(value(REGEXEXTRACT(F22,""^""&C22&"" ([\d]+)|[^a-zA-Z] ""&C22&"" ([\d]+)""))))=max(value(REGEXEXTRACT(F22,"" ([\d]+)"")),value(REGEXEXTRACT(F22,""([\d]+)$""))),""""))"),TRUE) -> TRUE
A23: 104 | U23: =IFERROR(__xludf.DUMMYFUNCTION("iferror(if(not(iserror(find(""FINAL"",G23))),max(arrayformula(value(REGEXEXTRACT(F23,""^""&C23&"" ([\d]+)|[^a-zA-Z] ""&C23&"" ([\d]+)""))))=max(value(REGEXEXTRACT(F23,"" ([\d]+)"")),value(REGEXEXTRACT(F23,""([\d]+)$""))),""""))"),"")
A24: 105 | B24: Vu | C24: California | D24: 7 | E24: 5 | F24: (25) SMU 35 California 38 | G24: FINAL | H24: Nick A. | K24: 13.5 | M24: 53.5 | N24: 298 | O24: 318 | P24: 2 | Q24: FALSE | R24: 100 | S24: ACC | T24: Power 4 | U24: =IFERROR(__xludf.DUMMYFUNCTION("iferror(if(not(iserror(find(""FINAL"",G24))),max(arrayformula(value(REGEXEXTRACT(F24,""^""&C24&"" ([\d]+)|[^a-zA-Z] ""&C24&"" ([\d]+)""))))=max(value(REGEXEXTRACT(F24,"" ([\d]+)"")),value(REGEXEXTRACT(F24,""([\d]+)$""))),""""))"),TRUE) -> TRUE
A25: 105 | B25: Vu | C25: Alabama | D25: 10 | E25: 2 | F25: (10) Alabama 27 Auburn 20 | G25: FINAL | H25: Nick G. | K25: -5.5 | M25: 46.5 | N25: 399 | O25: 198 | P25: 2 | Q25: FALSE | R25: 100 | S25: SEC | T25: Power 4 | U25: =IFERROR(__xludf.DUMMYFUNCTION("iferror(if(not(iserror(find(""FINAL"",G25))),max(arrayformula(value(REGEXEXTRACT(F25,""^""&C25&"" ([\d]+)|[^a-zA-Z] ""&C25&"" ([\d]+)""))))=max(value(REGEXEXTRACT(F25,"" ([\d]+)"")),value(REGEXEXTRACT(F25,""([\d]+)$""))),""""))"),TRUE) -> TRUE
A26: 105 | B26: Vu | C26: UCLA | D26: 3 | E26: 9 | F26: UCLA 10 (20) USC 29 | G26: FINAL | H26: Gary | K26: 21.5 | M26: 58.5 | N26: 218 | O26: 401 | P26: 2 | Q26: FALSE | R26: 100 | S26: Big Ten | T26: Power 4 | U26: =IFERROR(__xludf.DUMMYFUNCTION("iferror(if(not(iserror(find(""FINAL"",G26))),max(arrayformula(value(REGEXEXTRACT(F26,""^""&C26&"" ([\d]+)|[^a-zA-Z] ""&C26&"" ([\d]+)""))))=max(value(REGEXEXTRACT(F26,"" ([\d]+)"")),value(REGEXEXTRACT(F26,""([\d]+)$""))),""""))"),FALSE) -> FALSE
A27: 105 | B27: Vu | C27: Washington | D27: 8 | E27: 4 | F27: (5) Oregon 26 Washington 14 | G27: FINAL | H27: Jeannine | K27: 7 | M27: 51.5 | N27: 405 | O27: 233 | P27: 2 | Q27: FALSE | R27: 100 | S27: Big Ten | T27: Power 4 | U27: =IFERROR(__xludf.DUMMYFUNCTION("iferror(if(not(iserror(find(""FINAL"",G27))),max(arrayformula(value(REGEXEXTRACT(F27,""^""&C27&"" ([\d]+)|[^a-zA-Z] ""&C27&"" ([\d]+)""))))=max(value(REGEXEXTRACT(F27,"" ([\d]+)"")),value(REGEXEXTRACT(F27,""([\d]+)$""))),""""))"),FALSE) -> FALSE
A28: 105 | B28: Vu | C28: UAB | D28: 4 | E28: 8 | F28: UAB 31 Tulsa 24 | G28: FINAL | H28: Undrafted | K28: 9.5 | M28: 58.5 | N28: 317 | O28: 459 | P28: 2 | Q28: TRUE | R28: 100 | S28: AAC | T28: Group of 6 | U28: =IFERROR(__xludf.DUMMYFUNCTION("iferror(if(not(iserror(find(""FINAL"",G28))),max(arrayformula(value(REGEXEXTRACT(F28,""^""&C28&"" ([\d]+)|[^a-zA-Z] ""&C28&"" ([\d]+)""))))=max(value(REGEXEXTRACT(F28,"" ([\d]+)"")),value(REGEXEXTRACT(F28,""([\d]+)$""))),""""))"),TRUE) -> TRUE
A29: 105 | B29: Vu | C29: Old Dominion | D29: 9 | E29: 3 | F29: Georgia State 10 Old Dominion 27 | G29: FINAL | H29: Masa | K29: -27.5 | M29: 58.5 | N29: 392 | O29: 231 | P29: 2 | Q29: TRUE | R29: 100 | S29: Sun Belt | T29: Group of 6 | U29: =IFERROR(__xludf.DUMMYFUNCTION("iferror(if(not(iserror(find(""FINAL"",G29))),max(arrayformula(value(REGEXEXTRACT(F29,""^""&C29&"" ([\d]+)|[^a-zA-Z] ""&C29&"" ([\d]+)""))))=max(value(REGEXEXTRACT(F29,"" ([\d]+)"")),value(REGEXEXTRACT(F29,""([\d]+)$""))),""""))"),TRUE) -> TRUE
A30: 105 | B30: Vu | C30: Kansas State | D30: 6 | E30: 6 | F30: Colorado 14 Kansas State 24 | G30: FINAL | H30: Justin | K30: -16.5 | M30: 50.5 | N30: 353 | O30: 320 | P30: 2 | Q30: FALSE | R30: 100 | S30: Big 12 | T30: Power 4 | U30: =IFERROR(__xludf.DUMMYFUNCTION("iferror(if(not(iserror(find(""FINAL"",G30))),max(arrayformula(value(REGEXEXTRACT(F30,""^""&C30&"" ([\d]+)|[^a-zA-Z] ""&C30&"" ([\d]+)""))))=max(value(REGEXEXTRACT(F30,"" ([\d]+)"")),value(REGEXEXTRACT(F30,""([\d]+)$""))),""""))"),TRUE) -> TRUE
A31: 105 | B31: Vu | C31: Colorado State | D31: 2 | E31: 10 | F31: Air Force 42 Colorado State 21 | G31: FINAL | H31: Nick G. | K31: 2.5 | M31: 46.5 | N31: 222 | O31: 370 | P31: 2 | Q31: FALSE | R31: 100 | S31: MWC | T31: Group of 6 | U31: =IFERROR(__xludf.DUMMYFUNCTION("iferror(if(not(iserror(find(""FINAL"",G31))),max(arrayformula(value(REGEXEXTRACT(F31,""^""&C31&"" ([\d]+)|[^a-zA-Z] ""&C31&"" ([\d]+)""))))=max(value(REGEXEXTRACT(F31,"" ([\d]+)"")),value(REGEXEXTRACT(F31,""([\d]+)$""))),""""))"),FALSE) -> FALSE
A32: 105 | B32: Vu | C32: EMU | D32: 4 | E32: 8 | F32: Western Michigan 31 EMU 21 | G32: FINAL | H32: Dan | K32: 7.5 | M32: 46.5 | N32: 289 | O32: 357 | P32: 2 | Q32: FALSE | R32: 100 | S32: MAC | T32: Group of 6 | U32: =IFERROR(__xludf.DUMMYFUNCTION("iferror(if(not(iserror(find(""FINAL"",G32))),max(arrayformula(value(REGEXEXTRACT(F32,""^""&C32&"" ([\d]+)|[^a-zA-Z] ""&C32&"" ([\d]+)""))))=max(value(REGEXEXTRACT(F32,"" ([\d]+)"")),value(REGEXEXTRACT(F32,""([\d]+)$""))),""""))"),FALSE) -> FALSE
A33: 105 | B33: Vu | C33: Liberty | D33: 4 | E33: 8 | F33: Kennesaw State 48 Liberty 42 | G33: FINAL - 2ND OT | H33: Gary | K33: 1.5 | M33: 55.5 | N33: 307 | O33: 318 | P33: 2 | Q33: FALSE | R33: 100 | S33: CUSA | T33: Group of 6 | U33: =IFERROR(__xludf.DUMMYFUNCTION("iferror(if(not(iserror(find(""FINAL"",G33))),max(arrayformula(value(REGEXEXTRACT(F33,""^""&C33&"" ([\d]+)|[^a-zA-Z] ""&C33&"" ([\d]+)""))))=max(value(REGEXEXTRACT(F33,"" ([\d]+)"")),value(REGEXEXTRACT(F33,""([\d]+)$""))),""""))"),FALSE) -> FALSE
A34: 106 | U34: =IFERROR(__xludf.DUMMYFUNCTION("iferror(if(not(iserror(find(""FINAL"",G34))),max(arrayformula(value(REGEXEXTRACT(F34,""^""&C34&"" ([\d]+)|[^a-zA-Z] ""&C34&"" ([\d]+)""))))=max(value(REGEXEXTRACT(F34,"" ([\d]+)"")),value(REGEXEXTRACT(F34,""([\d]+)$""))),""""))"),"")
A35: 107 | B35: Nick A. | C35: Akron | D35: 5 | E35: 7 | N35: 267 | O35: 329 | P35: 0 | Q35: FALSE | R35: 59 | S35: MAC | T35: Group of 6 | U35: =IFERROR(__xludf.DUMMYFUNCTION("iferror(if(not(iserror(find(""FINAL"",G35))),max(arrayformula(value(REGEXEXTRACT(F35,""^""&C35&"" ([\d]+)|[^a-zA-Z] ""&C35&"" ([\d]+)""))))=max(value(REGEXEXTRACT(F35,"" ([\d]+)"")),value(REGEXEXTRACT(F35,""([\d]+)$""))),""""))"),"")
A36: 107 | B36: Nick A. | C36: SMU | D36: 8 | E36: 4 | F36: (25) SMU 35 California 38 | G36: FINAL | H36: Vu | K36: -13.5 | M36: 53.5 | N36: 395 | O36: 248 | P36: 2 | Q36: TRUE | R36: 100 | S36: ACC | T36: Power 4 | U36: =IFERROR(__xludf.DUMMYFUNCTION("iferror(if(not(iserror(find(""FINAL"",G36))),max(arrayformula(value(REGEXEXTRACT(F36,""^""&C36&"" ([\d]+)|[^a-zA-Z] ""&C36&"" ([\d]+)""))))=max(value(REGEXEXTRACT(F36,"" ([\d]+)"")),value(REGEXEXTRACT(F36,""([\d]+)$""))),""""))"),FALSE) -> FALSE
A37: 107 | B37: Nick A. | C37: Oregon State | D37: 2 | E37: 10 | F37: Oregon State 8 Washington State 32 | G37: FINAL | H37: Undrafted | K37: 13.5 | M37: 43.5 | N37: 218 | O37: 353 | P37: 2 | Q37: FALSE | R37: 100 | S37: Pac12 | T37: Group of 6 | U37: =IFERROR(__xludf.DUMMYFUNCTION("iferror(if(not(iserror(find(""FINAL"",G37))),max(arrayformula(value(REGEXEXTRACT(F37,""^""&C37&"" ([\d]+)|[^a-zA-Z] ""&C37&"" ([\d]+)""))))=max(value(REGEXEXTRACT(F37,"" ([\d]+)"")),value(REGEXEXTRACT(F37,""([\d]+)$""))),""""))"),FALSE) -> FALSE
A38: 107 | B38: Nick A. | C38: Tennessee | D38: 8 | E38: 4 | F38: (12) Vanderbilt 45 (18) Tennessee 24 | G38: FINAL | H38: Dan | K38: -3 | M38: 65.5 | N38: 489 | O38: 345 | P38: 2 | Q38: TRUE | R38: 100 | S38: SEC | T38: Power 4 | U38: =IFERROR(__xludf.DUMMYFUNCTION("iferror(if(not(iserror(find(""FINAL"",G38))),max(arrayformula(value(REGEXEXTRACT(F38,""^""&C38&"" ([\d]+)|[^a-zA-Z] ""&C38&"" ([\d]+)""))))=max(value(REGEXEXTRACT(F38,"" ([\d]+)"")),value(REGEXEXTRACT(F38,""([\d]+)$""))),""""))"),FALSE) -> FALSE
A39: 107 | B39: Nick A. | C39: Missouri State | D39: 7 | E39: 5 | F39: Louisiana Tech 42 Missouri State 30 | G39: FINAL | H39: Masa | K39: -1.5 | M39: 47.5 | N39: 305 | O39: 340 | P39: 2 | Q39: TRUE | R39: 100 | S39: CUSA | T39: Group of 6 | U39: =IFERROR(__xludf.DUMMYFUNCTION("iferror(if(not(iserror(find(""FINAL"",G39))),max(arrayformula(value(REGEXEXTRACT(F39,""^""&C39&"" ([\d]+)|[^a-zA-Z] ""&C39&"" ([\d]+)""))))=max(value(REGEXEXTRACT(F39,"" ([\d]+)"")),value(REGEXEXTRACT(F39,""([\d]+)$""))),""""))"),FALSE) -> FALSE
A40: 107 | B40: Nick A. | C40: Ohio State | D40: 12 | E40: 0 | F40: (1) Ohio State 27 (15) Michigan 9 | G40: FINAL | H40: Jeannine | K40: -10.5 | M40: 43.5 | N40: 444 | O40: 93 | P40: 2 | Q40: TRUE | R40: 100 | S40: Big Ten | T40: Power 4 | U40: =IFERROR(__xludf.DUMMYFUNCTION("iferror(if(not(iserror(find(""FINAL"",G40))),max(arrayformula(value(REGEXEXTRACT(F40,""^""&C40&"" ([\d]+)|[^a-zA-Z] ""&C40&"" ([\d]+)""))))=max(value(REGEXEXTRACT(F40,"" ([\d]+)"")),value(REGEXEXTRACT(F40,""([\d]+)$""))),""""))"),TRUE) -> TRUE
...

Sheet Translation
A1: Bottom Line | B1: Cincinnati | C1: UConn | D1: East Carolina | E1: Houston | F1: Memphis | G1: Navy | H1: SMU | I1: South Florida | J1: Temple | K1: Tulane | L1: Tulsa | M1: UCF | N1: Boston College | O1: Clemson | P1: Duke | Q1: Florida State | R1: Georgia Tech | S1: Louisville | T1: Miami | U1: NC State | V1: North Carolina | W1: Pittsburgh | X1: Syracuse | Y1: Virginia | Z1: Virginia Tech | AA1: Wake Forest | AB1: Baylor | AC1: Iowa State | AD1: Kansas | AE1: Kansas State | AF1: Oklahoma | AG1: Oklahoma State | AH1: TCU | AI1: Texas | AJ1: Texas Tech | AK1: West Virginia | AL1: Illinois | AM1: Indiana | AN1: Iowa | AO1: Maryland | AP1: Michigan | AQ1: Michigan State | AR1: Minnesota | AS1: Nebraska | AT1: Northwestern | AU1: Ohio State | AV1: Penn State | AW1: Purdue | AX1: Rutgers | AY1: Wisconsin | AZ1: Florida International | BA1: Florida Atlantic | BB1: Louisiana Tech | BC1: Marshall | BD1: Middle Tennessee | BE1: North Texas | BF1: Old Dominion | BG1: Rice | BH1: Southern Miss | BI1: Charlotte | BJ1: UTEP | BK1: UTSA | BL1: Western Kentucky | BM1: UAB | BN1: Akron | BO1: Ball State | BP1: Bowling Green | BQ1: Buffalo | BR1: Central Michigan | BS1: Eastern Michigan | BT1: Kent State | BU1: Miami OH | BV1: Northern Illinois | BW1: Ohio | BX1: Toledo | BY1: Western Michigan | BZ1: Air Force | CA1: Boise State | CB1: Colorado State | CC1: Fresno State | CD1: Hawai'i | CE1: Nevada | CF1: New Mexico | CG1: San Diego State | CH1: San Jose State | CI1: UNLV | CJ1: Utah State | CK1: Wyoming | CL1: Arizona | CM1: Arizona State | CN1: California | CO1: Colorado | CP1: Oregon | CQ1: Oregon State | CR1: Stanford | CS1: UCLA | CT1: USC | CU1: Utah | CV1: Washington | CW1: Washington State | CX1: Alabama | CY1: Arkansas | CZ1: Auburn | DA1: Florida | DB1: Georgia | DC1: Kentucky | DD1: LSU | DE1: Mississippi State | DF1: Missouri | DG1: Ole Miss | DH1: South Carolina | DI1: Tennessee | DJ1: Texas AM | DK1: Vanderbilt | DL1: App State | DM1: Arkansas State | DN1: Georgia Southern | DO1: Georgia State | DP1: Louisiana | DQ1: UL Monroe | DR1: South Alabama | DS1: Texas State | DT1: Troy | DU1: Coastal Carolina | DV1: Army | DW1: BYU | DX1: Liberty | DY1: New Mexico State | DZ1: Notre Dame | EA1: Massachusetts | EB1: James Madison | EC1: Jacksonville State | ED1: Kennesaw State | EE1: Sam Houston | EF1: Delaware | EG1: Missouri State
A2: ESPNs HTML | B2: CIN | C2: CONN | D2: ECU | E2: HOU | F2: MEM | G2: NAVY | H2: SMU | I2: USF | J2: TEM | K2: TULN | L2: TLSA | M2: UCF | N2: BC | O2: CLEM | P2: DUKE | Q2: FSU | R2: GT | S2: LOU | T2: MIA | U2: NCSU | V2: UNC | W2: PITT | X2: SYR | Y2: UVA | Z2: VT | AA2: WAKE | AB2: BAY | AC2: ISU | AD2: KU | AE2: KSU | AF2: OU | AG2: OKST | AH2: TCU | AI2: TEX | AJ2: TTU | AK2: WVU | AL2: ILL | AM2: IU | AN2: IOWA | AO2: MD | AP2: MICH | AQ2: MSU | AR2: MINN | AS2: NEB | AT2: NU | AU2: OSU | AV2: PSU | AW2: PUR | AX2: RUTG | AY2: WIS | AZ2: FIU | BA2: FAU | BB2: LT | BC2: MRSH | BD2: MTSU | BE2: UNT | BF2: ODU | BG2: RICE | BH2: USM | BI2: CLT | BJ2: UTEP | BK2: UTSA | BL2: WKU | BM2: UAB | BN2: AKR | BO2: BALL | BP2: BGSU | BQ2: BUFF | BR2: CMU | BS2: EMU | BT2: KENT | BU2: M-OH | BV2: NIU | BW2: OHIO | BX2: TOL | BY2: WMU | BZ2: AFA | CA2: BOIS | CB2: CSU | CC2: FRES | CD2: HAW | CE2: NEV | CF2: UNM | CG2: SDSU | CH2: SJSU | CI2: UNLV | CJ2: USU | CK2: WYO | CL2: ARIZ | CM2: ASU | CN2: CAL | CO2: COLO | CP2: ORE | CQ2: ORST | CR2: STAN | CS2: UCLA | CT2: USC | CU2: UTAH | CV2: WASH | CW2: WSU | CX2: ALA | CY2: ARK | CZ2: AUB | DA2: FLA | DB2: UGA | DC2: UK | DD2: LSU | DE2: MSST | DF2: MIZ | DG2: MISS | DH2: SC | DI2: TENN | DJ2: TA&M | DK2: VAN | DL2: APP | DM2: ARST | DN2: GASO | DO2: GAST | DP2: UL | DQ2: ULM | DR2: USA | DS2: TXST | DT2: TROY | DU2: CCU | DV2: ARMY | DW2: BYU | DX2: LIB | DY2: NMSU | DZ2: ND | EA2: MASS | EB2: JMU | EC2: JVST | ED2: KENN | EE2: SHSU | EF2: DEL | EG2: MOST
A3: Lines | B3: Cincinnati Bearcats | C3: UConn Huskies | D3: East Carolina Pirates | E3: Houston Cougars | F3: Memphis Tigers | G3: Navy Midshipmen | H3: SMU Mustangs | I3: South Florida Bulls | J3: Temple Owls | K3: Tulane Green Wave | L3: Tulsa Golden Hurricane | M3: UCF Knights | N3: Boston College Eagles | O3: Clemson Tigers | P3: Duke Blue Devils | Q3: Florida State Seminoles | R3: Georgia Tech Yellow Jackets | S3: Louisville Cardinals | T3: Miami Hurricanes | U3: NC State Wolfpack | V3: North Carolina Tar Heels | W3: Pittsburgh Panthers | X3: Syracuse Orange | Y3: Virginia Cavaliers | Z3: Virginia Tech Hokies | AA3: Wake Forest Demon Deacons | AB3: Baylor Bears | AC3: Iowa State Cyclones | AD3: Kansas Jayhawks | AE3: Kansas State Wildcats | AF3: Oklahoma Sooners | AG3: Oklahoma State Cowboys | AH3: TCU Horned Frogs | AI3: Texas Longhorns | AJ3: Texas Tech Red Raiders | AK3: West Virginia Mountaineers | AL3: Illinois Fighting Illini | AM3: Indiana Hoosiers | AN3: Iowa Hawkeyes | AO3: Maryland Terrapins | AP3: Michigan Wolverines | AQ3: Michigan State Spartans | AR3: Minnesota Golden Gophers | AS3: Nebraska Cornhuskers | AT3: Northwestern Wildcats | AU3: Ohio State Buckeyes | AV3: Penn State Nittany Lions | AW3: Purdue Boilermakers | AX3: Rutgers Scarlet Knights | AY3: Wisconsin Badgers | AZ3: Florida International Panthers | BA3: Florida Atlantic Owls | BB3: Louisiana Tech Bulldogs | BC3: Marshall Thundering Herd | BD3: Middle Tennessee Blue Raiders | BE3: North Texas Mean Green | BF3: Old Dominion Monarchs | BG3: Rice Owls | BH3: Southern Mississippi Golden Eagles | BI3: Charlotte 49ers | BJ3: UTEP Miners | BK3: UTSA Roadrunners | BL3: Western Kentucky Hilltoppers | BM3: UAB Blazers | BN3: Akron Zips | BO3: Ball State Cardinals | BP3: Bowling Green Falcons | BQ3: Buffalo Bulls | BR3: Central Michigan Chippewas | BS3: Eastern Michigan Eagles | BT3: Kent State Golden Flashes | BU3: Miami (OH) RedHawks | BV3: Northern Illinois Huskies | BW3: Ohio Bobcats | BX3: Toledo Rockets | BY3: Western Michigan Broncos | BZ3: Air Force Falcons | CA3: Boise State Broncos | CB3: Colorado State Rams | CC3: Fresno State Bulldogs | CD3: Hawaii Rainbow Warriors | CE3: Nevada Wolf Pack | CF3: New Mexico Lobos | CG3: San Diego State Aztecs | CH3: San Jose State Spartans | CI3: UNLV Rebels | CJ3: Utah State Aggies | CK3: Wyoming Cowboys | CL3: Arizona Wildcats | CM3: Arizona State Sun Devils | CN3: California Golden Bears | CO3: Colorado Buffaloes | CP3: Oregon Ducks | CQ3: Oregon State Beavers | CR3: Stanford Cardinal | CS3: UCLA Bruins | CT3: USC Trojans | CU3: Utah Utes | CV3: Washington Huskies | CW3: Washington State Cougars | CX3: Alabama Crimson Tide | CY3: Arkansas Razorbacks | CZ3: Auburn Tigers | DA3: Florida Gators | DB3: Georgia Bulldogs | DC3: Kentucky Wildcats | DD3: LSU Tigers | DE3: Mississippi State Bulldogs | DF3: Missouri Tigers | DG3: Ole Miss Rebels | DH3: South Carolina Gamecocks | DI3: Tennessee Volunteers | DJ3: Texas A&M Aggies | DK3: Vanderbilt Commodores | DL3: Appalachian State Mountaineers | DM3: Arkansas State Red Wolves | DN3: Georgia Southern Eagles | DO3: Georgia State Panthers | DP3: Louisiana Ragin Cajuns | DQ3: UL Monroe Warhawks | DR3: South Alabama Jaguars | DS3: Texas State Bobcats | DT3: Troy Trojans | DU3: Coastal Carolina Chanticleers | DV3: Army Black Knights | DW3: BYU Cougars | DX3: Liberty Flames | DY3: New Mexico State Aggies | DZ3: Notre Dame Fighting Irish | EA3: UMass Minutemen | EB3: James Madison Dukes | EC3: Jacksonville State Gamecocks | ED3: Kennesaw State Owls | EE3: Sam Houston State Bearkats | EF3: Delaware Fightin' Blue Hens | EG3: Missouri State Bears
A4: Channel | B4: Cincinnati | C4: UConn | D4: East Carolina | E4: Houston | F4: Memphis | G4: Navy | H4: SMU | I4: South Florida | J4: Temple | K4: Tulane | L4: Tulsa | M4: UCF | N4: Boston College | O4: Clemson | P4: Duke | Q4: Florida State | R4: Georgia Tech | S4: Louisville | T4: Miami | U4: NC State | V4: North Carolina | W4: Pittsburgh | X4: Syracuse | Y4: Virginia | Z4: Virginia Tech | AA4: Wake Forest | AB4: Baylor | AC4: Iowa State | AD4: Kansas | AE4: Kansas State | AF4: Oklahoma | AG4: Oklahoma State | AH4: TCU | AI4: Texas | AJ4: Texas Tech | AK4: West Virginia | AL4: Illinois | AM4: Indiana | AN4: Iowa | AO4: Maryland | AP4: Michigan | AQ4: Michigan State | AR4: Minnesota | AS4: Nebraska | AT4: Northwestern | AU4: Ohio State | AV4: Penn State | AW4: Purdue | AX4: Rutgers | AY4: Wisconsin | AZ4: FIU | BA4: Florida Atlantic | BB4: Louisiana Tech | BC4: Marshall | BD4: MTSU | BE4: North Texas | BF4: Old Dominion | BG4: Rice | BH4: Southern Miss | BI4: Charlotte | BJ4: UTEP | BK4: UTSA | BL4: Western Kentucky | BM4: UAB | BN4: Akron | BO4: Ball State | BP4: Bowling Green | BQ4: Buffalo | BR4: Central Michigan | BS4: Eastern Michigan | BT4: Kent State | BU4: Miami Ohio | BV4: Northern Illinois | BW4: Ohio | BX4: Toledo | BY4: Western Michigan | BZ4: Air Force | CA4: Boise State | CB4: Colorado State | CC4: Fresno State | CD4: Hawaii | CE4: Nevada | CF4: New Mexico | CG4: San Diego State | CH4: San Jose State | CI4: UNLV | CJ4: Utah State | CK4: Wyoming | CL4: Arizona | CM4: Arizona State | CN4: Cal | CO4: Colorado | CP4: Oregon | CQ4: Oregon State | CR4: Stanford | CS4: UCLA | CT4: USC | CU4: Utah | CV4: Washington | CW4: Washington State | CX4: Alabama | CY4: Arkansas | CZ4: Auburn | DA4: Florida | DB4: Georgia | DC4: Kentucky | DD4: LSU | DE4: Mississippi State | DF4: Missouri | DG4: Ole Miss | DH4: South Carolina | DI4: Tennessee | DJ4: Texas A&M | DK4: Vanderbilt | DL4: Appalachian State | DM4: Arkansas State | DN4: Georgia Southern | DO4: Georgia State | DP4: Louisiana Lafayette | DQ4: Louisiana Monroe | DR4: South Alabama | DS4: Texas State | DT4: Troy | DU4: Coastal Carolina | DV4: Army | DW4: BYU | DX4: Liberty | DY4: New Mexico State | DZ4: Notre Dame | EA4: UMass | EB4: James Madison | EC4: Jacksonville State | ED4: Kennesaw State | EE4: Sam Houston | EF4: Delaware | EG4: Missouri State
