Workbook

Sheet Teams-Conference
A1: Players | B1: 10 | C1: Players | D1: 11 | E1: Players | F1: 12 | G1: Players | H1: 13
A2: Cincinnati | B2: AAC | C2: Cincinnati | D2: AAC | E2: Cincinnati | F2: AAC | G2: Cincinnati | H2: AAC
A3: UConn | B3: AAC | C3: UConn | D3: AAC | E3: UConn | F3: AAC | G3: UConn | H3: AAC
A4: East Carolina | B4: AAC | C4: East Carolina | D4: AAC | E4: East Carolina | F4: AAC | G4: East Carolina | H4: AAC
A5: Houston | B5: AAC | C5: Houston | D5: AAC | E5: Houston | F5: AAC | G5: Houston | H5: AAC
A6: Memphis | B6: AAC | C6: Memphis | D6: AAC | E6: Memphis | F6: AAC | G6: Memphis | H6: AAC
A7: Navy | B7: AAC | C7: Navy | D7: AAC | E7: Navy | F7: AAC | G7: Navy | H7: AAC
A8: SMU | B8: AAC | C8: SMU | D8: AAC | E8: SMU | F8: AAC | G8: SMU | H8: AAC
A9: South Florida | B9: AAC | C9: South Florida | D9: AAC | E9: South Florida | F9: AAC | G9: South Florida | H9: AAC
A10: Temple | B10: AAC | C10: Temple | D10: AAC | E10: Temple | F10: AAC | G10: Temple | H10: AAC
A11: Tulane | B11: AAC | C11: Tulane | D11: AAC | E11: Tulane | F11: AAC | G11: Tulane | H11: AAC
A12: Tulsa | B12: AAC | C12: Tulsa | D12: AAC | E12: Tulsa | F12: AAC | G12: Tulsa | H12: AAC
A13: UCF | B13: AAC | C13: UCF | D13: AAC | E13: UCF | F13: AAC | G13: UCF | H13: AAC
... A131: UMASS | B131: Independent | C131: UMASS | D131: Independent | E131: UMASS | F131: Independent | G131: Arkansas | H131: Sun Belt

Sheet Draft Order
B1: Player | C1: Order Rnd()
A2: =A1+1 -> 1 | B2: DavEmily | C2: =RAND() -> 0.88456628
A3: =A2+1 -> 2 | B3: Nick A. | C3: =RAND() -> 0.33083735
A4: =A3+1 -> 3 | B4: Gary | C4: =RAND() -> 0.1875828
A5: =A4+1 -> 4 | B5: Janice/Mike | C5: =RAND() -> 0.41252181
A6: =A5+1 -> 5 | B6: Nico | C6: =RAND() -> 0.071142071
A7: =A6+1 -> 6 | B7: Jeannine | C7: =RAND() -> 0.86464284
A8: =A7+1 -> 7 | B8: Justin | C8: =RAND() -> 0.13947819
A9: =A8+1 -> 8 | B9: Adam | C9: =RAND() -> 0.46390222
A10: =A9+1 -> 9 | B10: Vu | C10: =RAND() -> 0.8328657
A11: =A10+1 -> 10 | B11: Josh R. | C11: =RAND() -> 0.80585336
A12: =A11+1 -> 11 | B12: Brad | C12: =RAND() -> 0.21031979
A13: 12 | B13: Nick G.

Sheet DraftTracker
A1: draft | B1: rnd | C1: pick | D1: player | E1: conf | F1: team | G1: Error Check | H1: Same confs picked within 10 after | I1: Same confs picked within 20 after | J1: Same confs picked within 10 before | K1: Same confs picked within 20 before | L1: wins | M1: picks_better_than | N1: no_teams_slept_on | O1: W | P1: L | Q1: matchup | R1: Status (Time ET) | S1: opponent | T1: network | U1: Opening Spread | V1: Spread | W1: Current Total | X1: Total | Y1: PF | Z1: PA | AA1: wins_missed | AB1: picks_better_than | AC1: no_teams_slept_on | AD1: bestpick | AE1: wins_gained | AF1: teams_slept_on | AG1: wins_missed_conf | AH1: picks_better_than_conf | AI1: no_teams_slept_on_conf | AJ1: bestpick_conf | AK1: wins_gained_conf | AL1: teams_slept_on_conf | AM1: confs_avail | AN1: wins_missed_confs_avail | AO1: picks_better_than_confs_avail | AP1: no_teams_slept_on_confs_avail | AQ1: bestpick_confs_avail | AR1: wins_gained_confs_avail | AS1: teams_slept_on_confs_avail
A2: 1 | B2: 1 | C2: 1 | D2: ='Draft Order'!B2 -> DavEmily | E2: =if(F2<>"",VLOOKUP(F2,offset('Teams-Conference'!A:B,0,(counta('Draft Order'!B$2:B129)-10)*2),2,0),"") -> SEC | F2: Alabama | H2: =countif(E3:E12,E2) -> 1 | I2: =countif(E3:E24,E2) -> 1 | L2: {=iferror(VLOOKUP(F2:F129,'Current Week'!C:D,2,0),"")} | M2: =IFERROR(__xludf.DUMMYFUNCTION("counta(iferror(filter(L1:L$2,E1:E$2=E2,L1:L$2<L2)))"),0.0) -> 0 | N2: =IFERROR(__xludf.DUMMYFUNCTION("counta(iferror(filter(L3:L$129,E3:E$129=E2,L3:L$131>L2)))"),0.0) -> 0 | O2: {=XLOOKUP(F2,'Current Week'!B:B,'Current Week'!C:N)} -> 10 | P2: 2 | Q2: ESPN | R2: BYE | T2: bye | U2: bye | W2: 9999 | AA2: =$O2-max($O2:$O$392) -> -2 | AB2: =countif($O1:$O$2,"<"&$O2) -> 0 | AC2: =IFERROR(__xludf.DUMMYFUNCTION("iferror(COUNT(filter($O3:$O$392,$O3:$O$392>$O2)))"),10.0) -> 10 | AD2: =if(AA2=0,1,0) -> 0 | AE2: =$O2-min($O$2:$O2) -> 0 | AF2: =IFERROR(__xludf.DUMMYFUNCTION("iferror(join("","",index(sort(filter($F3:$F$392,$O3:$O$392>$O2),2,false),0,1)))"),"Clemson,Boise State,Georgia,Oklahoma,Appalachian State,Memphis,Ohio State,Utah,LSU,Baylor") -> Clemson,Boise State,Georgia,Oklahoma,Appalachian State,Memphis,Ohio State,Utah,LSU,Baylor | AG2: =IFERROR(__xludf.DUMMYFUNCTION("iferror($O2-max(filter($O2:$O$392,$E2:$E$392=$E$2)))"),-2.0) -> -2 | AH2: =countifs($O1:$O$2,"<"&$O2,$E1:$E$2,$E$2) -> 0 | AI2: =IFERROR(__xludf.DUMMYFUNCTION("iferror(COUNT(filter($O3:$O$392,$O3:$O$392>$O2,$E2:$E$392=$E$2)))"),0.0) -> 0 | AJ2: =if(AG2=0,1,0) -> 0 | AK2: =IFERROR(__xludf.DUMMYFUNCTION("iferror($O2-min(filter($O2:$O$392,$E2:$E$392=$E$2)))"),8.0) -> 8 | AL2: =IFERROR(__xludf.DUMMYFUNCTION("iferror(join("","",index(sort(filter($F3:$F$392,$O3:$O$392>$O2,$E3:$E$392=$E$2),2,false),0,1)))"),"Georgia,LSU") -> Georgia,LSU | AM2: =IFERROR(__xludf.DUMMYFUNCTION("REGEXREPLACE(join("","",unique({let(conf_picked,filter(E$1:E1,D$1:D1=D2), byrow(unique(TRANSPOSe(Teams!$1:$1)),lambda(rw,if(ISERROR(match(rw,conf_picked,0)),rw,))));iferror(if(#REF!,,transpose(split(#REF!,"","",1,1))))})), ""^,"", """")"),"AAC,ACC,Big 12,Big Ten,CUSA,MAC,MWC,Pac12,SEC,Sun Belt,Independent,") -> AAC,ACC,Big 12,Big Ten,CUSA,MAC,MWC,Pac12,SEC,Sun Belt,Independent, | AN2: =IFERROR(__xludf.DUMMYFUNCTION("iferror($O2-max(filter($O2:$O$392,arrayformula(isnumber(FIND($E2:$E$392,AM2))))))"),-2.0) -> -2 | AO2: {=countifs($O1:$O$2,"<"&$O2,isnumber(FIND($E1:$E$2,AM2)),TRUE)} -> 0 | AP2: =IFERROR(__xludf.DUMMYFUNCTION("iferror(COUNT(filter($O3:$O$392,$O3:$O$392>$O2,arrayformula(isnumber(FIND($E3:$E$392,AM2))))))"),10.0) -> 10 | AQ2: =if(AN2=0,1,0) -> 0 | AR2: =IFERROR(__xludf.DUMMYFUNCTION("iferror($O2-min(filter($O2:$O$392,arrayformula(isnumber(FIND($E2:$E$392,AM2))))))"),10.0) -> 10 | AS2: =IFERROR(__xludf.DUMMYFUNCTION("iferror(join("","",index(sort(filter($F3:$F$392,$O3:$O$392>$O2,arrayformula(isnumber(FIND($E3:$E$392,AM2)))),2,false),0,1)))"),"Clemson,Boise State,Georgia,Oklahoma,Appalachian State,Memphis,Ohio State,Utah,LSU,Baylor") -> Clemson,Boise State,Georgia,Oklahoma,Appalachian State,Memphis,Ohio State,Utah,LSU,Baylor
A3: =A2+1 -> 2 | B3: 1 | C3: 2 | D3: ='Draft Order'!B3 -> Nick A. | E3: =if(F3<>"",VLOOKUP(F3,offset('Teams-Conference'!A:B,0,(counta('Draft Order'!B$2:B129)-10)*2),2,0),"") -> ACC | F3: Clemson | H3: =countif(E4:E13,E3) -> 0 | I3: =countif(E4:E25,E3) -> 0 | M3: =IFERROR(__xludf.DUMMYFUNCTION("counta(iferror(filter(L2:L$2,E2:E$2=E3,L2:L$2<L3)))"),0.0) -> 0 | N3: =IFERROR(__xludf.DUMMYFUNCTION("counta(iferror(filter(L4:L$129,E4:E$129=E3,L4:L$131>L3)))"),0.0) -> 0 | O3: {=XLOOKUP(F3,'Current Week'!B:B,'Current Week'!C:N)} -> 12 | P3: 0 | Q3: ABC | R3: (22) Virginia at (3) Clemson | S3: SAT, DEC 7 7:30 PM ET | T3: -29 | U3: 54 | V3: Jeannine | W3: SAT, DEC 7 7:30 PM ET | AA3: =$O3-max($O3:$O$392) -> 0 | AB3: =countif($O2:$O$2,"<"&$O3) -> 1 | AC3: =IFERROR(__xludf.DUMMYFUNCTION("iferror(COUNT(filter($O4:$O$392,$O4:$O$392>$O3)))"),0.0) -> 0 | AD3: =if(AA3=0,1,0) -> 1 | AE3: =$O3-min($O$2:$O3) -> 2 | AF3: =IFERROR(__xludf.DUMMYFUNCTION("iferror(join("","",index(sort(filter($F4:$F$393,$O4:$O$393>$O3),2,false),0,1)))"),"") | AG3: =IFERROR(__xludf.DUMMYFUNCTION("iferror($O3-max(filter($O3:$O$392,$E3:$E$392=$E$2)))"),0.0) -> 0 | AH3: =countifs($O2:$O$2,"<"&$O3,$E2:$E$2,$E$2) -> 1 | AI3: =IFERROR(__xludf.DUMMYFUNCTION("iferror(COUNT(filter($O4:$O$392,$O4:$O$392>$O3,$E3:$E$392=$E$2)))"),0.0) -> 0 | AJ3: =if(AG3=0,1,0) -> 1 | AK3: =IFERROR(__xludf.DUMMYFUNCTION("iferror($O3-min(filter($O3:$O$392,$E3:$E$392=$E$2)))"),10.0) -> 10 | AL3: =IFERROR(__xludf.DUMMYFUNCTION("iferror(join("","",index(sort(filter($F4:$F$392,$O4:$O$392>$O3,$E4:$E$392=$E$2),2,false),0,1)))"),"") | AM3: =IFERROR(__xludf.DUMMYFUNCTION("REGEXREPLACE(join("","",unique({let(conf_picked,filter(E$1:E2,D$1:D2=D3), byrow(unique(TRANSPOSe(Teams!$1:$1)),lambda(rw,if(ISERROR(match(rw,conf_picked,0)),rw,))));iferror(if(#REF!,,transpose(split(#REF!,"","",1,1))))})), ""^,"", """")"),"AAC,ACC,Big 12,Big Ten,CUSA,MAC,MWC,Pac12,SEC,Sun Belt,Independent,") -> AAC,ACC,Big 12,Big Ten,CUSA,MAC,MWC,Pac12,SEC,Sun Belt,Independent, | AN3: =IFERROR(__xludf.DUMMYFUNCTION("iferror($O3-max(filter($O3:$O$392,arrayformula(isnumber(FIND($E3:$E$392,AM3))))))"),0.0) -> 0 | AO3: {=countifs($O2:$O$2,"<"&$O3,isnumber(FIND($E2:$E$2,AM3)),TRUE)} -> 1 | AP3: =IFERROR(__xludf.DUMMYFUNCTION("iferror(COUNT(filter($O4:$O$392,$O4:$O$392>$O3,arrayformula(isnumber(FIND($E4:$E$392,AM3))))))"),0.0) -> 0 | AQ3: =if(AN3=0,1,0) -> 1 | AR3: =IFERROR(__xludf.DUMMYFUNCTION("iferror($O3-min(filter($O3:$O$392,arrayformula(isnumber(FIND($E3:$E$392,AM3))))))"),12.0) -> 12 | AS3: =IFERROR(__xludf.DUMMYFUNCTION("iferror(join("","",index(sort(filter($F4:$F$392,$O4:$O$392>$O3,arrayformula(isnumber(FIND($E4:$E$392,AM3)))),2,false),0,1)))"),"")
A4: =A3+1 -> 3 | B4: 1 | C4: 3 | D4: ='Draft Order'!B4 -> Gary | E4: =if(F4<>"",VLOOKUP(F4,offset('Teams-Conference'!A:B,0,(counta('Draft Order'!B$2:B129)-10)*2),2,0),"") -> MAC | F4: Ohio | H4: =countif(E5:E14,E4) -> 0 | I4: =countif(E5:E26,E4) -> 2 | M4: =IFERROR(__xludf.DUMMYFUNCTION("counta(iferror(filter(L$2:L3,E$2:E3=E4,L$2:L3<L4)))"),0.0) -> 0 | N4: =IFERROR(__xludf.DUMMYFUNCTION("counta(iferror(filter(L5:L$129,E5:E$129=E4,L5:L$131>L4)))"),0.0) -> 0 | O4: {=XLOOKUP(F4,'Current Week'!B:B,'Current Week'!C:N)} -> 6 | P4: 6 | Q4: ESPN2 | R4: BYE | T4: bye | U4: bye | W4: 9999 | AA4: =$O4-max($O4:$O$392) -> -6 | AB4: =countif($O3:$O$2,"<"&$O4) -> 0 | AC4: =IFERROR(__xludf.DUMMYFUNCTION("iferror(COUNT(filter($O5:$O$392,$O5:$O$392>$O4)))"),60.0) -> 60 | AD4: =if(AA4=0,1,0) -> 0 | AE4: =$O4-min($O$2:$O4) -> 0 | AF4: =IFERROR(__xludf.DUMMYFUNCTION("iferror(join("","",index(sort(filter($F5:$F$393,$O5:$O$393>$O4),2,false),0,1)))"),"Boise State,Georgia,Oklahoma,Appalachian State,UCF,Washington,Memphis,Ohio State,Utah,Michigan,Texas,Oregon,Western Michigan,Georgia Southern,Notre Dame,San Diego State,Utah State,Air Force,Cincinnati,Nevada,Florida Atlantic,Wyoming,Temple,Hawaii,Buffalo,"&"SMU,Miami-OH,Navy,Iowa State,Virginia Tech,LSU,Marshall,Wisconsin,Penn State,Georgia State,USC,Oklahoma State,Auburn,Louisiana Tech,Southern Mississippi,Florida,Baylor,UAB,Arizona State,California,BYU,Iowa,Texas A&M,Minnesota,Kansas State,Indiana,Wake For"&"est,Western Kentucky,Virginia,Charlotte,Pittsburgh,Tennessee,Kentucky,Central Michigan,Louisville") -> Boise State,Georgia,Oklahoma,Appalachian State,UCF,Washington,Memphis,Ohio State,Utah,Michigan,Texas,Oregon,Western Michigan,Georgia Southern,Notre Dame,San Diego State,Utah State,Air Force,Cincinnati,Nevada,Florida Atlantic,Wyoming,Temple,Hawaii,Buffalo,SMU,Miami-OH,Navy,Iowa State,Virginia Tech,LSU,Marshall,Wisconsin,Penn State,Georgia State,USC,Oklahoma State,Auburn,Louisiana Tech,Southern Mississippi,Florida,Baylor,UAB,Arizona State,California,BYU,Iowa,Texas A&M,Minnesota,Kansas State,Indiana,Wake Forest,Western Kentucky,Virginia,Charlotte,Pittsburgh,Tennessee,Kentucky,Central Michigan,Louisville | AG4: =IFERROR(__xludf.DUMMYFUNCTION("iferror($O4-max(filter($O4:$O$392,$E4:$E$392=$E$2)))"),-6.0) -> -6 | AH4: =countifs($O3:$O$2,"<"&$O4,$E3:$E$2,$E$2) -> 0 | AI4: =IFERROR(__xludf.DUMMYFUNCTION("iferror(COUNT(filter($O5:$O$392,$O5:$O$392>$O4,$E4:$E$392=$E$2)))"),0.0) -> 0 | AJ4: =if(AG4=0,1,0) -> 0 | AK4: =IFERROR(__xludf.DUMMYFUNCTION("iferror($O4-min(filter($O4:$O$392,$E4:$E$392=$E$2)))"),4.0) -> 4 | AL4: =IFERROR(__xludf.DUMMYFUNCTION("iferror(join("","",index(sort(filter($F5:$F$392,$O5:$O$392>$O4,$E5:$E$392=$E$2),2,false),0,1)))"),"Georgia,LSU,Auburn,Florida,Texas A&M,Tennessee,Kentucky") -> Georgia,LSU,Auburn,Florida,Texas A&M,Tennessee,Kentucky | AM4: =IFERROR(__xludf.DUMMYFUNCTION("REGEXREPLACE(join("","",unique({let(conf_picked,filter(E$1:E3,D$1:D3=D4), byrow(unique(TRANSPOSe(Teams!$1:$1)),lambda(rw,if(ISERROR(match(rw,conf_picked,0)),rw,))));iferror(if(#REF!,,transpose(split(#REF!,"","",1,1))))})), ""^,"", """")"),"AAC,ACC,Big 12,Big Ten,CUSA,MAC,MWC,Pac12,SEC,Sun Belt,Independent,") -> AAC,ACC,Big 12,Big Ten,CUSA,MAC,MWC,Pac12,SEC,Sun Belt,Independent, | AN4: =IFERROR(__xludf.DUMMYFUNCTION("iferror($O4-max(filter($O4:$O$392,arrayformula(isnumber(FIND($E4:$E$392,AM4))))))"),-6.0) -> -6 | AO4: {=countifs($O$2:$O3,"<"&$O4,isnumber(FIND($E$2:$E3,AM4)),TRUE)} -> 0 | AP4: =IFERROR(__xludf.DUMMYFUNCTION("iferror(COUNT(filter($O5:$O$392,$O5:$O$392>$O4,arrayformula(isnumber(FIND($E5:$E$392,AM4))))))"),60.0) -> 60 | AQ4: =if(AN4=0,1,0) -> 0 | AR4: =IFERROR(__xludf.DUMMYFUNCTION("iferror($O4-min(filter($O4:$O$392,arrayformula(isnumber(FIND($E4:$E$392,AM4))))))"),6.0) -> 6 | AS4: =IFERROR(__xludf.DUMMYFUNCTION("iferror(join("","",index(sort(filter($F5:$F$392,$O5:$O$392>$O4,arrayformula(isnumber(FIND($E5:$E$392,AM4)))),2,false),0,1)))"),"Boise State,Georgia,Oklahoma,Appalachian State,UCF,Washington,Memphis,Ohio State,Utah,Michigan,Texas,Oregon,Western Michigan,Georgia Southern,Notre Dame,San Diego State,Utah State,Air Force,Cincinnati,Nevada,Florida Atlantic,Wyoming,Temple,Hawaii,Buffalo,"&"SMU,Miami-OH,Navy,Iowa State,Virginia Tech,LSU,Marshall,Wisconsin,Penn State,Georgia State,USC,Oklahoma State,Auburn,Louisiana Tech,Southern Mississippi,Florida,Baylor,UAB,Arizona State,California,BYU,Iowa,Texas A&M,Minnesota,Kansas State,Indiana,Wake For"&"est,Western Kentucky,Virginia,Charlotte,Pittsburgh,Tennessee,Kentucky,Central Michigan,Louisville") -> Boise State,Georgia,Oklahoma,Appalachian State,UCF,Washington,Memphis,Ohio State,Utah,Michigan,Texas,Oregon,Western Michigan,Georgia Southern,Notre Dame,San Diego State,Utah State,Air Force,Cincinnati,Nevada,Florida Atlantic,Wyoming,Temple,Hawaii,Buffalo,SMU,Miami-OH,Navy,Iowa State,Virginia Tech,LSU,Marshall,Wisconsin,Penn State,Georgia State,USC,Oklahoma State,Auburn,Louisiana Tech,Southern Mississippi,Florida,Baylor,UAB,Arizona State,California,BYU,Iowa,Texas A&M,Minnesota,Kansas State,Indiana,Wake Forest,Western Kentucky,Virginia,Charlotte,Pittsburgh,Tennessee,Kentucky,Central Michigan,Louisville
A5: =A4+1 -> 4 | B5: 1 | C5: 4 | D5: ='Draft Order'!B5 -> Janice/Mike | E5: =if(F5<>"",VLOOKUP(F5,offset('Teams-Conference'!A:B,0,(counta('Draft Order'!B$2:B129)-10)*2),2,0),"") -> MWC | F5: Boise State | H5: =countif(E6:E15,E5) -> 0 | I5: =countif(E6:E27,E5) -> 2 | M5: =IFERROR(__xludf.DUMMYFUNCTION("counta(iferror(filter(L$2:L4,E$2:E4=E5,L$2:L4<L5)))"),0.0) -> 0 | N5: =IFERROR(__xludf.DUMMYFUNCTION("counta(iferror(filter(L6:L$129,E6:E$129=E5,L6:L$131>L5)))"),0.0) -> 0 | O5: {=XLOOKUP(F5,'Current Week'!B:B,'Current Week'!C:N)} -> 11 | P5: 1 | Q5: ESPN2 | R5: Hawaii at (17) Boise State | S5: SAT, DEC 7 4:00 PM ET | T5: -13½ | U5: 64 | V5: Vu | W5: SAT, DEC 7 4:00 PM ET | AA5: =$O5-max($O5:$O$392) -> -1 | AB5: =countif($O4:$O$2,"<"&$O5) -> 2 | AC5: =IFERROR(__xludf.DUMMYFUNCTION("iferror(COUNT(filter($O6:$O$392,$O6:$O$392>$O5)))"),2.0) -> 2 | AD5: =if(AA5=0,1,0) -> 0 | AE5: =$O5-min($O$2:$O5) -> 5 | AF5: =IFERROR(__xludf.DUMMYFUNCTION("iferror(join("","",index(sort(filter($F6:$F$393,$O6:$O$393>$O5),2,false),0,1)))"),"Ohio State,LSU") -> Ohio State,LSU | AG5: =IFERROR(__xludf.DUMMYFUNCTION("iferror($O5-max(filter($O5:$O$392,$E5:$E$392=$E$2)))"),-1.0) -> -1 | AH5: =countifs($O4:$O$2,"<"&$O5,$E4:$E$2,$E$2) -> 1 | AI5: =IFERROR(__xludf.DUMMYFUNCTION("iferror(COUNT(filter($O6:$O$392,$O6:$O$392>$O5,$E5:$E$392=$E$2)))"),0.0) -> 0 | AJ5: =if(AG5=0,1,0) -> 0 | AK5: =IFERROR(__xludf.DUMMYFUNCTION("iferror($O5-min(filter($O5:$O$392,$E5:$E$392=$E$2)))"),9.0) -> 9 | AL5: =IFERROR(__xludf.DUMMYFUNCTION("iferror(join("","",index(sort(filter($F6:$F$392,$O6:$O$392>$O5,$E6:$E$392=$E$2),2,false),0,1)))"),"LSU") -> LSU | AM5: =IFERROR(__xludf.DUMMYFUNCTION("REGEXREPLACE(join("","",unique({let(conf_picked,filter(E$1:E4,D$1:D4=D5), byrow(unique(TRANSPOSe(Teams!$1:$1)),lambda(rw,if(ISERROR(match(rw,conf_picked,0)),rw,))));iferror(if(#REF!,,transpose(split(#REF!,"","",1,1))))})), ""^,"", """")"),"AAC,ACC,Big 12,Big Ten,CUSA,MAC,MWC,Pac12,SEC,Sun Belt,Independent,") -> AAC,ACC,Big 12,Big Ten,CUSA,MAC,MWC,Pac12,SEC,Sun Belt,Independent, | AN5: =IFERROR(__xludf.DUMMYFUNCTION("iferror($O5-max(filter($O5:$O$392,arrayformula(isnumber(FIND($E5:$E$392,AM5))))))"),-1.0) -> -1 | AO5: {=countifs($O$2:$O4,"<"&$O5,isnumber(FIND($E$2:$E4,AM5)),TRUE)} -> 2 | AP5: =IFERROR(__xludf.DUMMYFUNCTION("iferror(COUNT(filter($O6:$O$392,$O6:$O$392>$O5,arrayformula(isnumber(FIND($E6:$E$392,AM5))))))"),2.0) -> 2 | AQ5: =if(AN5=0,1,0) -> 0 | AR5: =IFERROR(__xludf.DUMMYFUNCTION("iferror($O5-min(filter($O5:$O$392,arrayformula(isnumber(FIND($E5:$E$392,AM5))))))"),11.0) -> 11 | AS5: =IFERROR(__xludf.DUMMYFUNCTION("iferror(join("","",index(sort(filter($F6:$F$392,$O6:$O$392>$O5,arrayformula(isnumber(FIND($E6:$E$392,AM5)))),2,false),0,1)))"),"Ohio State,LSU") -> Ohio State,LSU
A6: =A5+1 -> 5 | B6: 1 | C6: 5 | D6: ='Draft Order'!B6 -> Nico | E6: =if(F6<>"",VLOOKUP(F6,offset('Teams-Conference'!A:B,0,(counta('Draft Order'!B$2:B129)-10)*2),2,0),"") -> SEC | F6: Georgia | H6: =countif(E7:E16,E6) -> 0 | I6: =countif(E7:E28,E6) -> 0 | M6: =IFERROR(__xludf.DUMMYFUNCTION("counta(iferror(filter(L$2:L5,E$2:E5=E6,L$2:L5<L6)))"),0.0) -> 0 | N6: =IFERROR(__xludf.DUMMYFUNCTION("counta(iferror(filter(L7:L$129,E7:E$129=E6,L7:L$131>L6)))"),0.0) -> 0 | O6: {=XLOOKUP(F6,'Current Week'!B:B,'Current Week'!C:N)} -> 11 | P6: 1 | Q6: CBS | R6: (4) Georgia at (1) LSU | S6: SAT, DEC 7 4:00 PM ET | T6: 7½ +0 | U6: 54½ | V6: Nick A. | W6: SAT, DEC 7 4:00 PM ET | AA6: =$O6-max($O6:$O$392) -> -1 | AB6: =countif($O5:$O$2,"<"&$O6) -> 2 | AC6: =IFERROR(__xludf.DUMMYFUNCTION("iferror(COUNT(filter($O7:$O$392,$O7:$O$392>$O6)))"),2.0) -> 2 | AD6: =if(AA6=0,1,0) -> 0 | AE6: =$O6-min($O$2:$O6) -> 5 | AF6: =IFERROR(__xludf.DUMMYFUNCTION("iferror(join("","",index(sort(filter($F7:$F$393,$O7:$O$393>$O6),2,false),0,1)))"),"Ohio State,LSU") -> Ohio State,LSU | AG6: =IFERROR(__xludf.DUMMYFUNCTION("iferror($O6-max(filter($O6:$O$392,$E6:$E$392=$E$2)))"),-1.0) -> -1 | AH6: =countifs($O5:$O$2,"<"&$O6,$E5:$E$2,$E$2) -> 1 | AI6: =IFERROR(__xludf.DUMMYFUNCTION("iferror(COUNT(filter($O7:$O$392,$O7:$O$392>$O6,$E6:$E$392=$E$2)))"),0.0) -> 0 | AJ6: =if(AG6=0,1,0) -> 0 | AK6: =IFERROR(__xludf.DUMMYFUNCTION("iferror($O6-min(filter($O6:$O$392,$E6:$E$392=$E$2)))"),9.0) -> 9 | AL6: =IFERROR(__xludf.DUMMYFUNCTION("iferror(join("","",index(sort(filter($F7:$F$392,$O7:$O$392>$O6,$E7:$E$392=$E$2),2,false),0,1)))"),"LSU") -> LSU | AM6: =IFERROR(__xludf.DUMMYFUNCTION("REGEXREPLACE(join("","",unique({let(conf_picked,filter(E$1:E5,D$1:D5=D6), byrow(unique(TRANSPOSe(Teams!$1:$1)),lambda(rw,if(ISERROR(match(rw,conf_picked,0)),rw,))));iferror(if(#REF!,,transpose(split(#REF!,"","",1,1))))})), ""^,"", """")"),"AAC,ACC,Big 12,Big Ten,CUSA,MAC,MWC,Pac12,SEC,Sun Belt,Independent,") -> AAC,ACC,Big 12,Big Ten,CUSA,MAC,MWC,Pac12,SEC,Sun Belt,Independent, | AN6: =IFERROR(__xludf.DUMMYFUNCTION("iferror($O6-max(filter($O6:$O$392,arrayformula(isnumber(FIND($E6:$E$392,AM6))))))"),-1.0) -> -1 | AO6: {=countifs($O$2:$O5,"<"&$O6,isnumber(FIND($E$2:$E5,AM6)),TRUE)} -> 2 | AP6: =IFERROR(__xludf.DUMMYFUNCTION("iferror(COUNT(filter($O7:$O$392,$O7:$O$392>$O6,arrayformula(isnumber(FIND($E7:$E$392,AM6))))))"),2.0) -> 2 | AQ6: =if(AN6=0,1,0) -> 0 | AR6: =IFERROR(__xludf.DUMMYFUNCTION("iferror($O6-min(filter($O6:$O$392,arrayformula(isnumber(FIND($E6:$E$392,AM6))))))"),11.0) -> 11 | AS6: =IFERROR(__xludf.DUMMYFUNCTION("iferror(join("","",index(sort(filter($F7:$F$392,$O7:$O$392>$O6,arrayformula(isnumber(FIND($E7:$E$392,AM6)))),2,false),0,1)))"),"Ohio State,LSU") -> Ohio State,LSU
A7: =A6+1 -> 6 | B7: 1 | C7: 6 | D7: ='Draft Order'!B7 -> Jeannine | E7: =if(F7<>"",VLOOKUP(F7,offset('Teams-Conference'!A:B,0,(counta('Draft Order'!B$2:B129)-10)*2),2,0),"") -> Big 12 | F7: Oklahoma | H7: =countif(E8:E17,E7) -> 0 | I7: =countif(E8:E29,E7) -> 2 | M7: =IFERROR(__xludf.DUMMYFUNCTION("counta(iferror(filter(L$2:L6,E$2:E6=E7,L$2:L6<L7)))"),0.0) -> 0 | N7: =IFERROR(__xludf.DUMMYFUNCTION("counta(iferror(filter(L8:L$129,E8:E$129=E7,L8:L$131>L7)))"),0.0) -> 0 | O7: {=XLOOKUP(F7,'Current Week'!B:B,'Current Week'!C:N)} -> 11 | P7: 1 | Q7: ABC | R7: (8) Baylor at (6) Oklahoma | S7: SAT, DEC 7 12:00 PM ET | T7: -9 | U7: 62½ | V7: Justin | W7: SAT, DEC 7 12:00 PM ET | AA7: =$O7-max($O7:$O$392) -> -1 | AB7: =countif($O6:$O$2,"<"&$O7) -> 2 | AC7: =IFERROR(__xludf.DUMMYFUNCTION("iferror(COUNT(filter($O8:$O$392,$O8:$O$392>$O7)))"),2.0) -> 2 | AD7: =if(AA7=0,1,0) -> 0 | AE7: =$O7-min($O$2:$O7) -> 5 | AF7: =IFERROR(__xludf.DUMMYFUNCTION("iferror(join("","",index(sort(filter($F8:$F$393,$O8:$O$393>$O7),2,false),0,1)))"),"Ohio State,LSU") -> Ohio State,LSU | AG7: =IFERROR(__xludf.DUMMYFUNCTION("iferror($O7-max(filter($O7:$O$392,$E7:$E$392=$E$2)))"),-1.0) -> -1 | AH7: =countifs($O6:$O$2,"<"&$O7,$E6:$E$2,$E$2) -> 1 | AI7: =IFERROR(__xludf.DUMMYFUNCTION("iferror(COUNT(filter($O8:$O$392,$O8:$O$392>$O7,$E7:$E$392=$E$2)))"),0.0) -> 0 | AJ7: =if(AG7=0,1,0) -> 0 | AK7: =IFERROR(__xludf.DUMMYFUNCTION("iferror($O7-min(filter($O7:$O$392,$E7:$E$392=$E$2)))"),9.0) -> 9 | AL7: =IFERROR(__xludf.DUMMYFUNCTION("iferror(join("","",index(sort(filter($F8:$F$392,$O8:$O$392>$O7,$E8:$E$392=$E$2),2,false),0,1)))"),"LSU") -> LSU | AM7: =IFERROR(__xludf.DUMMYFUNCTION("REGEXREPLACE(join("","",unique({let(conf_picked,filter(E$1:E6,D$1:D6=D7), byrow(unique(TRANSPOSe(Teams!$1:$1)),lambda(rw,if(ISERROR(match(rw,conf_picked,0)),rw,))));iferror(if(#REF!,,transpose(split(#REF!,"","",1,1))))})), ""^,"", """")"),"AAC,ACC,Big 12,Big Ten,CUSA,MAC,MWC,Pac12,SEC,Sun Belt,Independent,") -> AAC,ACC,Big 12,Big Ten,CUSA,MAC,MWC,Pac12,SEC,Sun Belt,Independent, | AN7: =IFERROR(__xludf.DUMMYFUNCTION("iferror($O7-max(filter($O7:$O$392,arrayformula(isnumber(FIND($E7:$E$392,AM7))))))"),-1.0) -> -1 | AO7: {=countifs($O$2:$O6,"<"&$O7,isnumber(FIND($E$2:$E6,AM7)),TRUE)} -> 2 | AP7: =IFERROR(__xludf.DUMMYFUNCTION("iferror(COUNT(filter($O8:$O$392,$O8:$O$392>$O7,arrayformula(isnumber(FIND($E8:$E$392,AM7))))))"),2.0) -> 2 | AQ7: =if(AN7=0,1,0) -> 0 | AR7: =IFERROR(__xludf.DUMMYFUNCTION("iferror($O7-min(filter($O7:$O$392,arrayformula(isnumber(FIND($E7:$E$392,AM7))))))"),11.0) -> 11 | AS7: =IFERROR(__xludf.DUMMYFUNCTION("iferror(join("","",index(sort(filter($F8:$F$392,$O8:$O$392>$O7,arrayformula(isnumber(FIND($E8:$E$392,AM7)))),2,false),0,1)))"),"Ohio State,LSU") -> Ohio State,LSU
A8: =A7+1 -> 7 | B8: 1 | C8: 7 | D8: ='Draft Order'!B8 -> Justin | E8: =if(F8<>"",VLOOKUP(F8,offset('Teams-Conference'!A:B,0,(counta('Draft Order'!B$2:B129)-10)*2),2,0),"") -> Sun Belt | F8: Appalachian State | H8: =countif(E9:E18,E8) -> 2 | I8: =countif(E9:E30,E8) -> 5 | M8: =IFERROR(__xludf.DUMMYFUNCTION("counta(iferror(filter(L$2:L7,E$2:E7=E8,L$2:L7<L8)))"),0.0) -> 0 | N8: =IFERROR(__xludf.DUMMYFUNCTION("counta(iferror(filter(L9:L$129,E9:E$129=E8,L9:L$131>L8)))"),0.0) -> 0 | O8: {=XLOOKUP(F8,'Current Week'!B:B,'Current Week'!C:N)} -> 11 | P8: 1 | Q8: ESPNU | R8: UL Lafayette at (20) Appalachian State | S8: SAT, DEC 7 12:00 PM ET | T8: -6½ | U8: 56 | V8: Gary | W8: SAT, DEC 7 12:00 PM ET | AA8: =$O8-max($O8:$O$392) -> -1 | AB8: =countif($O7:$O$2,"<"&$O8) -> 2 | AC8: =IFERROR(__xludf.DUMMYFUNCTION("iferror(COUNT(filter($O9:$O$392,$O9:$O$392>$O8)))"),2.0) -> 2 | AD8: =if(AA8=0,1,0) -> 0 | AE8: =$O8-min($O$2:$O8) -> 5 | AF8: =IFERROR(__xludf.DUMMYFUNCTION("iferror(join("","",index(sort(filter($F9:$F$393,$O9:$O$393>$O8),2,false),0,1)))"),"Ohio State,LSU") -> Ohio State,LSU | AG8: =IFERROR(__xludf.DUMMYFUNCTION("iferror($O8-max(filter($O8:$O$392,$E8:$E$392=$E$2)))"),-1.0) -> -1 | AH8: =countifs($O7:$O$2,"<"&$O8,$E7:$E$2,$E$2) -> 1 | AI8: =IFERROR(__xludf.DUMMYFUNCTION("iferror(COUNT(filter($O9:$O$392,$O9:$O$392>$O8,$E8:$E$392=$E$2)))"),0.0) -> 0 | AJ8: =if(AG8=0,1,0) -> 0 | AK8: =IFERROR(__xludf.DUMMYFUNCTION("iferror($O8-min(filter($O8:$O$392,$E8:$E$392=$E$2)))"),9.0) -> 9 | AL8: =IFERROR(__xludf.DUMMYFUNCTION("iferror(join("","",index(sort(filter($F9:$F$392,$O9:$O$392>$O8,$E9:$E$392=$E$2),2,false),0,1)))"),"LSU") -> LSU | AM8: =IFERROR(__xludf.DUMMYFUNCTION("REGEXREPLACE(join("","",unique({let(conf_picked,filter(E$1:E7,D$1:D7=D8), byrow(unique(TRANSPOSe(Teams!$1:$1)),lambda(rw,if(ISERROR(match(rw,conf_picked,0)),rw,))));iferror(if(#REF!,,transpose(split(#REF!,"","",1,1))))})), ""^,"", """")"),"AAC,ACC,Big 12,Big Ten,CUSA,MAC,MWC,Pac12,SEC,Sun Belt,Independent,") -> AAC,ACC,Big 12,Big Ten,CUSA,MAC,MWC,Pac12,SEC,Sun Belt,Independent, | AN8: =IFERROR(__xludf.DUMMYFUNCTION("iferror($O8-max(filter($O8:$O$392,arrayformula(isnumber(FIND($E8:$E$392,AM8))))))"),-1.0) -> -1 | AO8: {=countifs($O$2:$O7,"<"&$O8,isnumber(FIND($E$2:$E7,AM8)),TRUE)} -> 2 | AP8: =IFERROR(__xludf.DUMMYFUNCTION("iferror(COUNT(filter($O9:$O$392,$O9:$O$392>$O8,arrayformula(isnumber(FIND($E9:$E$392,AM8))))))"),2.0) -> 2 | AQ8: =if(AN8=0,1,0) -> 0 | AR8: =IFERROR(__xludf.DUMMYFUNCTION("iferror($O8-min(filter($O8:$O$392,arrayformula(isnumber(FIND($E8:$E$392,AM8))))))"),11.0) -> 11 | AS8: =IFERROR(__xludf.DUMMYFUNCTION("iferror(join("","",index(sort(filter($F9:$F$392,$O9:$O$392>$O8,arrayformula(isnumber(FIND($E9:$E$392,AM8)))),2,false),0,1)))"),"Ohio State,LSU") -> Ohio State,LSU
A9: =A8+1 -> 8 | B9: 1 | C9: 8 | D9: ='Draft Order'!B9 -> Adam | E9: =if(F9<>"",VLOOKUP(F9,offset('Teams-Conference'!A:B,0,(counta('Draft Order'!B$2:B129)-10)*2),2,0),"") -> AAC | F9: UCF | H9: =countif(E10:E19,E9) -> 1 | I9: =countif(E10:E31,E9) -> 2 | M9: =IFERROR(__xludf.DUMMYFUNCTION("counta(iferror(filter(L$2:L8,E$2:E8=E9,L$2:L8<L9)))"),0.0) -> 0 | N9: =IFERROR(__xludf.DUMMYFUNCTION("counta(iferror(filter(L10:L$129,E10:E$129=E9,L10:L$131>L9)))"),0.0) -> 0 | O9: {=XLOOKUP(F9,'Current Week'!B:B,'Current Week'!C:N)} -> 9 | P9: 3 | Q9: NA | R9: BYE | T9: bye | U9: bye | W9: 9999 | AA9: =$O9-max($O9:$O$392) -> -3 | AB9: =countif($O8:$O$2,"<"&$O9) -> 1 | AC9: =IFERROR(__xludf.DUMMYFUNCTION("iferror(COUNT(filter($O10:$O$392,$O10:$O$392>$O9)))"),15.0) -> 15 | AD9: =if(AA9=0,1,0) -> 0 | AE9: =$O9-min($O$2:$O9) -> 3 | AF9: =IFERROR(__xludf.DUMMYFUNCTION("iferror(join("","",index(sort(filter($F10:$F$393,$O10:$O$393>$O9),2,false),0,1)))"),"Memphis,Ohio State,Utah,Oregon,Notre Dame,Air Force,Cincinnati,SMU,Navy,LSU,Wisconsin,Penn State,Florida,Baylor,Minnesota") -> Memphis,Ohio State,Utah,Oregon,Notre Dame,Air Force,Cincinnati,SMU,Navy,LSU,Wisconsin,Penn State,Florida,Baylor,Minnesota | AG9: =IFERROR(__xludf.DUMMYFUNCTION("iferror($O9-max(filter($O9:$O$392,$E9:$E$392=$E$2)))"),-3.0) -> -3 | AH9: =countifs($O8:$O$2,"<"&$O9,$E8:$E$2,$E$2) -> 0 | AI9: =IFERROR(__xludf.DUMMYFUNCTION("iferror(COUNT(filter($O10:$O$392,$O10:$O$392>$O9,$E9:$E$392=$E$2)))"),0.0) -> 0 | AJ9: =if(AG9=0,1,0) -> 0 | AK9: =IFERROR(__xludf.DUMMYFUNCTION("iferror($O9-min(filter($O9:$O$392,$E9:$E$392=$E$2)))"),7.0) -> 7 | AL9: =IFERROR(__xludf.DUMMYFUNCTION("iferror(join("","",index(sort(filter($F10:$F$392,$O10:$O$392>$O9,$E10:$E$392=$E$2),2,false),0,1)))"),"LSU,Florida") -> LSU,Florida | AM9: =IFERROR(__xludf.DUMMYFUNCTION("REGEXREPLACE(join("","",unique({let(conf_picked,filter(E$1:E8,D$1:D8=D9), byrow(unique(TRANSPOSe(Teams!$1:$1)),lambda(rw,if(ISERROR(match(rw,conf_picked,0)),rw,))));iferror(if(#REF!,,transpose(split(#REF!,"","",1,1))))})), ""^,"", """")"),"AAC,ACC,Big 12,Big Ten,CUSA,MAC,MWC,Pac12,SEC,Sun Belt,Independent,") -> AAC,ACC,Big 12,Big Ten,CUSA,MAC,MWC,Pac12,SEC,Sun Belt,Independent, | AN9: =IFERROR(__xludf.DUMMYFUNCTION("iferror($O9-max(filter($O9:$O$392,arrayformula(isnumber(FIND($E9:$E$392,AM9))))))"),-3.0) -> -3 | AO9: {=countifs($O$2:$O8,"<"&$O9,isnumber(FIND($E$2:$E8,AM9)),TRUE)} -> 1 | AP9: =IFERROR(__xludf.DUMMYFUNCTION("iferror(COUNT(filter($O10:$O$392,$O10:$O$392>$O9,arrayformula(isnumber(FIND($E10:$E$392,AM9))))))"),15.0) -> 15 | AQ9: =if(AN9=0,1,0) -> 0 | AR9: =IFERROR(__xludf.DUMMYFUNCTION("iferror($O9-min(filter($O9:$O$392,arrayformula(isnumber(FIND($E9:$E$392,AM9))))))"),9.0) -> 9 | AS9: =IFERROR(__xludf.DUMMYFUNCTION("iferror(join("","",index(sort(filter($F10:$F$392,$O10:$O$392>$O9,arrayformula(isnumber(FIND($E10:$E$392,AM9)))),2,false),0,1)))"),"Memphis,Ohio State,Utah,Oregon,Notre Dame,Air Force,Cincinnati,SMU,Navy,LSU,Wisconsin,Penn State,Florida,Baylor,Minnesota") -> Memphis,Ohio State,Utah,Oregon,Notre Dame,Air Force,Cincinnati,SMU,Navy,LSU,Wisconsin,Penn State,Florida,Baylor,Minnesota
A10: =A9+1 -> 9 | B10: 1 | C10: 9 | D10: ='Draft Order'!B10 -> Vu | E10: =if(F10<>"",VLOOKUP(F10,offset('Teams-Conference'!A:B,0,(counta('Draft Order'!B$2:B129)-10)*2),2,0),"") -> Pac12 | F10: Washington | H10: =countif(E11:E20,E10) -> 2 | I10: =countif(E11:E32,E10) -> 3 | M10: =IFERROR(__xludf.DUMMYFUNCTION("counta(iferror(filter(L$2:L10,E$2:E10=E10,L$2:L10<L10)))"),0.0) -> 0 | N10: =IFERROR(__xludf.DUMMYFUNCTION("counta(iferror(filter(L11:L$129,E11:E$129=E10,L11:L$131>L10)))"),0.0) -> 0 | O10: {=XLOOKUP(F10,'Current Week'!B:B,'Current Week'!C:N)} -> 7 | P10: 5 | Q10: NA | R10: BYE | T10: bye | U10: bye | W10: 9999 | AA10: =$O10-max($O10:$O$392) -> -5 | AB10: =countif($O9:$O$2,"<"&$O10) -> 1 | AC10: =IFERROR(__xludf.DUMMYFUNCTION("iferror(COUNT(filter($O11:$O$392,$O11:$O$392>$O10)))"),35.0) -> 35 | AD10: =if(AA10=0,1,0) -> 0 | AE10: =$O10-min($O$2:$O10) -> 1 | AF10: =IFERROR(__xludf.DUMMYFUNCTION("iferror(join("","",index(sort(filter($F11:$F$393,$O11:$O$393>$O10),2,false),0,1)))"),"Memphis,Ohio State,Utah,Michigan,Oregon,Notre Dame,San Diego State,Air Force,Cincinnati,Florida Atlantic,Temple,Hawaii,SMU,Navy,Virginia Tech,LSU,Marshall,Wisconsin,Penn State,USC,Oklahoma State,Auburn,Louisiana Tech,Florida,Baylor,UAB,Iowa,Minnesota,Kans"&"as State,Indiana,Wake Forest,Western Kentucky,Virginia,Central Michigan,Louisville") -> Memphis,Ohio State,Utah,Michigan,Oregon,Notre Dame,San Diego State,Air Force,Cincinnati,Florida Atlantic,Temple,Hawaii,SMU,Navy,Virginia Tech,LSU,Marshall,Wisconsin,Penn State,USC,Oklahoma State,Auburn,Louisiana Tech,Florida,Baylor,UAB,Iowa,Minnesota,Kansas State,Indiana,Wake Forest,Western Kentucky,Virginia,Central Michigan,Louisville | AG10: =IFERROR(__xludf.DUMMYFUNCTION("iferror($O10-max(filter($O10:$O$392,$E10:$E$392=$E$2)))"),-5.0) -> -5 | AH10: =countifs($O9:$O$2,"<"&$O10,$E9:$E$2,$E$2) -> 0 | AI10: =IFERROR(__xludf.DUMMYFUNCTION("iferror(COUNT(filter($O11:$O$392,$O11:$O$392>$O10,$E10:$E$392=$E$2)))"),0.0) -> 0 | AJ10: =if(AG10=0,1,0) -> 0 | AK10: =IFERROR(__xludf.DUMMYFUNCTION("iferror($O10-min(filter($O10:$O$392,$E10:$E$392=$E$2)))"),5.0) -> 5 | AL10: =IFERROR(__xludf.DUMMYFUNCTION("iferror(join("","",index(sort(filter($F11:$F$392,$O11:$O$392>$O10,$E11:$E$392=$E$2),2,false),0,1)))"),"LSU,Auburn,Florida") -> LSU,Auburn,Florida | AM10: =IFERROR(__xludf.DUMMYFUNCTION("REGEXREPLACE(join("","",unique({let(conf_picked,filter(E$1:E9,D$1:D9=D10), byrow(unique(TRANSPOSe(Teams!$1:$1)),lambda(rw,if(ISERROR(match(rw,conf_picked,0)),rw,))));iferror(if(#REF!,,transpose(split(#REF!,"","",1,1))))})), ""^,"", """")"),"AAC,ACC,Big 12,Big Ten,CUSA,MAC,MWC,Pac12,SEC,Sun Belt,Independent,") -> AAC,ACC,Big 12,Big Ten,CUSA,MAC,MWC,Pac12,SEC,Sun Belt,Independent, | AN10: =IFERROR(__xludf.DUMMYFUNCTION("iferror($O10-max(filter($O10:$O$392,arrayformula(isnumber(FIND($E10:$E$392,AM10))))))"),-5.0) -> -5 | AO10: {=countifs($O$2:$O9,"<"&$O10,isnumber(FIND($E$2:$E9,AM10)),TRUE)} -> 1 | AP10: =IFERROR(__xludf.DUMMYFUNCTION("iferror(COUNT(filter($O11:$O$392,$O11:$O$392>$O10,arrayformula(isnumber(FIND($E11:$E$392,AM10))))))"),35.0) -> 35 | AQ10: =if(AN10=0,1,0) -> 0 | AR10: =IFERROR(__xludf.DUMMYFUNCTION("iferror($O10-min(filter($O10:$O$392,arrayformula(isnumber(FIND($E10:$E$392,AM10))))))"),7.0) -> 7 | AS10: =IFERROR(__xludf.DUMMYFUNCTION("iferror(join("","",index(sort(filter($F11:$F$392,$O11:$O$392>$O10,arrayformula(isnumber(FIND($E11:$E$392,AM10)))),2,false),0,1)))"),"Memphis,Ohio State,Utah,Michigan,Oregon,Notre Dame,San Diego State,Air Force,Cincinnati,Florida Atlantic,Temple,Hawaii,SMU,Navy,Virginia Tech,LSU,Marshall,Wisconsin,Penn State,USC,Oklahoma State,Auburn,Louisiana Tech,Florida,Baylor,UAB,Iowa,Minnesota,Kans"&"as State,Indiana,Wake Forest,Western Kentucky,Virginia,Central Michigan,Louisville") -> Memphis,Ohio State,Utah,Michigan,Oregon,Notre Dame,San Diego State,Air Force,Cincinnati,Florida Atlantic,Temple,Hawaii,SMU,Navy,Virginia Tech,LSU,Marshall,Wisconsin,Penn State,USC,Oklahoma State,Auburn,Louisiana Tech,Florida,Baylor,UAB,Iowa,Minnesota,Kansas State,Indiana,Wake Forest,Western Kentucky,Virginia,Central Michigan,Louisville
A11: =A10+1 -> 10 | B11: 1 | C11: 10 | D11: ='Draft Order'!B11 -> Josh R. | E11: =if(F11<>"",VLOOKUP(F11,offset('Teams-Conference'!A:B,0,(counta('Draft Order'!B$2:B129)-10)*2),2,0),"") -> Sun Belt | F11: Army | H11: =countif(E12:E21,E11) -> 2 | I11: =countif(E12:E33,E11) -> 5 | M11: =IFERROR(__xludf.DUMMYFUNCTION("counta(iferror(filter(L$2:L10,E$2:E10=E11,L$2:L10<L11)))"),0.0) -> 0 | N11: =IFERROR(__xludf.DUMMYFUNCTION("counta(iferror(filter(L12:L$129,E12:E$129=E11,L12:L$131>L11)))"),0.0) -> 0 | O11: {=XLOOKUP(F11,'Current Week'!B:B,'Current Week'!C:N)} -> 5 | P11: 8 | Q11: CBSSN | R11: Army at (23) Navy | S11: SAT, DEC 14 3:00 PM ET | T11: bye | U11: bye | V11: Janice/Mike | W11: SAT, DEC 14 3:00 PM ET | AA11: =$O11-max($O11:$O$392) -> -7 | AB11: =countif($O10:$O$2,"<"&$O11) -> 0 | AC11: =IFERROR(__xludf.DUMMYFUNCTION("iferror(COUNT(filter($O12:$O$392,$O12:$O$392>$O11)))"),68.0) -> 68 | AD11: =if(AA11=0,1,0) -> 0 | AE11: =$O11-min($O$2:$O11) -> 0 | AF11: =IFERROR(__xludf.DUMMYFUNCTION("iferror(join("","",index(sort(filter($F12:$F$393,$O12:$O$393>$O11),2,false),0,1)))"),"Memphis,Ohio State,Utah,Toledo,Michigan,Texas,Oregon,Western Michigan,Georgia Southern,Washington State,Notre Dame,San Diego State,Utah State,Air Force,Cincinnati,Nevada,Miami,Florida Atlantic,Wyoming,EMU,Temple,Hawaii,Florida Intl,Buffalo,SMU,Miami-OH,Na"&"vy,Tulane,Iowa State,Virginia Tech,LSU,Marshall,Wisconsin,Penn State,Georgia State,USC,Oklahoma State,Auburn,Louisiana Tech,Southern Mississippi,Florida,Baylor,UAB,Arizona State,California,Michigan State,BYU,Iowa,Texas A&M,Minnesota,Kansas State,Indiana,F"&"lorida State,Wake Forest,Western Kentucky,Virginia,Charlotte,Pittsburgh,Missouri,Boston College,Mississippi State,Tennessee,Kent State,Kentucky,Central Michigan,North Carolina,Louisville,Illinois") -> Memphis,Ohio State,Utah,Toledo,Michigan,Texas,Oregon,Western Michigan,Georgia Southern,Washington State,Notre Dame,San Diego State,Utah State,Air Force,Cincinnati,Nevada,Miami,Florida Atlantic,Wyoming,EMU,Temple,Hawaii,Florida Intl,Buffalo,SMU,Miami-OH,Navy,Tulane,Iowa State,Virginia Tech,LSU,Marshall,Wisconsin,Penn State,Georgia State,USC,Oklahoma State,Auburn,Louisiana Tech,Southern Mississippi,Florida,Baylor,UAB,Arizona State,California,Michigan State,BYU,Iowa,Texas A&M,Minnesota,Kansas State,Indiana,Florida State,Wake Forest,Western Kentucky,Virginia,Charlotte,Pittsburgh,Missouri,Boston College,Mississippi State,Tennessee,Kent State,Kentucky,Central Michigan,North Carolina,Louisville,Illinois | AG11: =IFERROR(__xludf.DUMMYFUNCTION("iferror($O11-max(filter($O11:$O$392,$E11:$E$392=$E$2)))"),-7.0) -> -7 | AH11: =countifs($O10:$O$2,"<"&$O11,$E10:$E$2,$E$2) -> 0 | AI11: =IFERROR(__xludf.DUMMYFUNCTION("iferror(COUNT(filter($O12:$O$392,$O12:$O$392>$O11,$E11:$E$392=$E$2)))"),0.0) -> 0 | AJ11: =if(AG11=0,1,0) -> 0 | AK11: =IFERROR(__xludf.DUMMYFUNCTION("iferror($O11-min(filter($O11:$O$392,$E11:$E$392=$E$2)))"),3.0) -> 3 | AL11: =IFERROR(__xludf.DUMMYFUNCTION("iferror(join("","",index(sort(filter($F12:$F$392,$O12:$O$392>$O11,$E12:$E$392=$E$2),2,false),0,1)))"),"LSU,Auburn,Florida,Texas A&M,Missouri,Mississippi State,Tennessee,Kentucky") -> LSU,Auburn,Florida,Texas A&M,Missouri,Mississippi State,Tennessee,Kentucky | AM11: =IFERROR(__xludf.DUMMYFUNCTION("REGEXREPLACE(join("","",unique({let(conf_picked,filter(E$1:E10,D$1:D10=D11), byrow(unique(TRANSPOSe(Teams!$1:$1)),lambda(rw,if(ISERROR(match(rw,conf_picked,0)),rw,))));iferror(if(#REF!,,transpose(split(#REF!,"","",1,1))))})), ""^,"", """")"),"AAC,ACC,Big 12,Big Ten,CUSA,MAC,MWC,Pac12,SEC,Sun Belt,Independent,") -> AAC,ACC,Big 12,Big Ten,CUSA,MAC,MWC,Pac12,SEC,Sun Belt,Independent, | AN11: =IFERROR(__xludf.DUMMYFUNCTION("iferror($O11-max(filter($O11:$O$392,arrayformula(isnumber(FIND($E11:$E$392,AM11))))))"),-7.0) -> -7 | AO11: {=countifs($O$2:$O10,"<"&$O11,isnumber(FIND($E$2:$E10,AM11)),TRUE)} -> 0 | AP11: =IFERROR(__xludf.DUMMYFUNCTION("iferror(COUNT(filter($O12:$O$392,$O12:$O$392>$O11,arrayformula(isnumber(FIND($E12:$E$392,AM11))))))"),68.0) -> 68 | AQ11: =if(AN11=0,1,0) -> 0 | AR11: =IFERROR(__xludf.DUMMYFUNCTION("iferror($O11-min(filter($O11:$O$392,arrayformula(isnumber(FIND($E11:$E$392,AM11))))))"),5.0) -> 5 | AS11: =IFERROR(__xludf.DUMMYFUNCTION("iferror(join("","",index(sort(filter($F12:$F$392,$O12:$O$392>$O11,arrayformula(isnumber(FIND($E12:$E$392,AM11)))),2,false),0,1)))"),"Memphis,Ohio State,Utah,Toledo,Michigan,Texas,Oregon,Western Michigan,Georgia Southern,Washington State,Notre Dame,San Diego State,Utah State,Air Force,Cincinnati,Nevada,Miami,Florida Atlantic,Wyoming,EMU,Temple,Hawaii,Florida Intl,Buffalo,SMU,Miami-OH,Na"&"vy,Tulane,Iowa State,Virginia Tech,LSU,Marshall,Wisconsin,Penn State,Georgia State,USC,Oklahoma State,Auburn,Louisiana Tech,Southern Mississippi,Florida,Baylor,UAB,Arizona State,California,Michigan State,BYU,Iowa,Texas A&M,Minnesota,Kansas State,Indiana,F"&"lorida State,Wake Forest,Western Kentucky,Virginia,Charlotte,Pittsburgh,Missouri,Boston College,Mississippi State,Tennessee,Kent State,Kentucky,Central Michigan,North Carolina,Louisville,Illinois") -> Memphis,Ohio State,Utah,Toledo,Michigan,Texas,Oregon,Western Michigan,Georgia Southern,Washington State,Notre Dame,San Diego State,Utah State,Air Force,Cincinnati,Nevada,Miami,Florida Atlantic,Wyoming,EMU,Temple,Hawaii,Florida Intl,Buffalo,SMU,Miami-OH,Navy,Tulane,Iowa State,Virginia Tech,LSU,Marshall,Wisconsin,Penn State,Georgia State,USC,Oklahoma State,Auburn,Louisiana Tech,Southern Mississippi,Florida,Baylor,UAB,Arizona State,California,Michigan State,BYU,Iowa,Texas A&M,Minnesota,Kansas State,Indiana,Florida State,Wake Forest,Western Kentucky,Virginia,Charlotte,Pittsburgh,Missouri,Boston College,Mississippi State,Tennessee,Kent State,Kentucky,Central Michigan,North Carolina,Louisville,Illinois
A12: =A11+1 -> 11 | B12: 1 | C12: 11 | D12: ='Draft Order'!B12 -> Brad | E12: =if(F12<>"",VLOOKUP(F12,offset('Teams-Conference'!A:B,0,(counta('Draft Order'!B$2:B129)-10)*2),2,0),"") -> AAC | F12: Memphis | H12: =countif(E13:E22,E12) -> 0 | I12: =countif(E13:E34,E12) -> 3 | J12: =countif(E2:E11,E12) -> 1 | M12: =IFERROR(__xludf.DUMMYFUNCTION("counta(iferror(filter(L$2:L11,E$2:E11=E12,L$2:L11<L12)))"),0.0) -> 0 | N12: =IFERROR(__xludf.DUMMYFUNCTION("counta(iferror(filter(L13:L$129,E13:E$129=E12,L13:L$131>L12)))"),0.0) -> 0 | O12: {=XLOOKUP(F12,'Current Week'!B:B,'Current Week'!C:N)} -> 11 | P12: 1 | Q12: ESPN2 | R12: (21) Cincinnati at (16) Memphis | S12: SAT, DEC 7 3:30 PM ET | T12: -9½ | U12: 57½ | V12: Vu | W12: SAT, DEC 7 3:30 PM ET | AA12: =$O12-max($O12:$O$392) -> -1 | AB12: =countif($O11:$O$2,"<"&$O12) -> 5 | AC12: =IFERROR(__xludf.DUMMYFUNCTION("iferror(COUNT(filter($O13:$O$392,$O13:$O$392>$O12)))"),2.0) -> 2 | AD12: =if(AA12=0,1,0) -> 0 | AE12: =$O12-min($O$2:$O12) -> 6 | AF12: =IFERROR(__xludf.DUMMYFUNCTION("iferror(join("","",index(sort(filter($F13:$F$393,$O13:$O$393>$O12),2,false),0,1)))"),"Ohio State,LSU") -> Ohio State,LSU | AG12: =IFERROR(__xludf.DUMMYFUNCTION("iferror($O12-max(filter($O12:$O$392,$E12:$E$392=$E$2)))"),-1.0) -> -1 | AH12: =countifs($O11:$O$2,"<"&$O12,$E11:$E$2,$E$2) -> 1 | AI12: =IFERROR(__xludf.DUMMYFUNCTION("iferror(COUNT(filter($O13:$O$392,$O13:$O$392>$O12,$E12:$E$392=$E$2)))"),0.0) -> 0 | AJ12: =if(AG12=0,1,0) -> 0 | AK12: =IFERROR(__xludf.DUMMYFUNCTION("iferror($O12-min(filter($O12:$O$392,$E12:$E$392=$E$2)))"),9.0) -> 9 | AL12: =IFERROR(__xludf.DUMMYFUNCTION("iferror(join("","",index(sort(filter($F13:$F$392,$O13:$O$392>$O12,$E13:$E$392=$E$2),2,false),0,1)))"),"LSU") -> LSU | AM12: =IFERROR(__xludf.DUMMYFUNCTION("REGEXREPLACE(join("","",unique({let(conf_picked,filter(E$1:E11,D$1:D11=D12), byrow(unique(TRANSPOSe(Teams!$1:$1)),lambda(rw,if(ISERROR(match(rw,conf_picked,0)),rw,))));iferror(if(#REF!,,transpose(split(#REF!,"","",1,1))))})), ""^,"", """")"),"AAC,ACC,Big 12,Big Ten,CUSA,MAC,MWC,Pac12,SEC,Sun Belt,Independent,") -> AAC,ACC,Big 12,Big Ten,CUSA,MAC,MWC,Pac12,SEC,Sun Belt,Independent, | AN12: =IFERROR(__xludf.DUMMYFUNCTION("iferror($O12-max(filter($O12:$O$392,arrayformula(isnumber(FIND($E12:$E$392,AM12))))))"),-1.0) -> -1 | AO12: {=countifs($O$2:$O11,"<"&$O12,isnumber(FIND($E$2:$E11,AM12)),TRUE)} -> 5 | AP12: =IFERROR(__xludf.DUMMYFUNCTION("iferror(COUNT(filter($O13:$O$392,$O13:$O$392>$O12,arrayformula(isnumber(FIND($E13:$E$392,AM12))))))"),2.0) -> 2 | AQ12: =if(AN12=0,1,0) -> 0 | AR12: =IFERROR(__xludf.DUMMYFUNCTION("iferror($O12-min(filter($O12:$O$392,arrayformula(isnumber(FIND($E12:$E$392,AM12))))))"),11.0) -> 11 | AS12: =IFERROR(__xludf.DUMMYFUNCTION("iferror(join("","",index(sort(filter($F13:$F$392,$O13:$O$392>$O12,arrayformula(isnumber(FIND($E13:$E$392,AM12)))),2,false),0,1)))"),"Ohio State,LSU") -> Ohio State,LSU
A13: =A12+1 -> 12 | B13: 1 | C13: 12 | D13: ='Draft Order'!B13 -> Nick G. | E13: =if(F13<>"",VLOOKUP(F13,offset('Teams-Conference'!A:B,0,(counta('Draft Order'!B$2:B129)-10)*2),2,0),"") -> Big Ten | F13: Ohio State | H13: =countif(E14:E23,E13) -> 1 | I13: =countif(E14:E35,E13) -> 1 | J13: =countif(E3:E12,E13) -> 0 | M13: =IFERROR(__xludf.DUMMYFUNCTION("counta(iferror(filter(L$2:L12,E$2:E12=E13,L$2:L12<L13)))"),0.0) -> 0 | N13: =IFERROR(__xludf.DUMMYFUNCTION("counta(iferror(filter(L14:L$129,E14:E$129=E13,L14:L$131>L13)))"),0.0) -> 0 | O13: {=XLOOKUP(F13,'Current Week'!B:B,'Current Week'!C:N)} -> 12 | P13: 0 | Q13: BTN | R13: (2) Ohio State at (10) Wisconsin | S13: SAT, DEC 7 8:00 PM ET | T13: -15½ | U13: 56½ | V13: Janice/Mike | W13: SAT, DEC 7 8:00 PM ET | AA13: =$O13-max($O13:$O$392) -> 0 | AB13: =countif($O12:$O$2,"<"&$O13) -> 10 | AC13: =IFERROR(__xludf.DUMMYFUNCTION("iferror(COUNT(filter($O14:$O$392,$O14:$O$392>$O13)))"),0.0) -> 0 | AD13: =if(AA13=0,1,0) -> 1 | AE13: =$O13-min($O$2:$O13) -> 7 | AF13: =IFERROR(__xludf.DUMMYFUNCTION("iferror(join("","",index(sort(filter($F14:$F$393,$O14:$O$393>$O13),2,false),0,1)))"),"") | AG13: =IFERROR(__xludf.DUMMYFUNCTION("iferror($O13-max(filter($O13:$O$392,$E13:$E$392=$E$2)))"),0.0) -> 0 | AH13: =countifs($O12:$O$2,"<"&$O13,$E12:$E$2,$E$2) -> 2 | AI13: =IFERROR(__xludf.DUMMYFUNCTION("iferror(COUNT(filter($O14:$O$392,$O14:$O$392>$O13,$E13:$E$392=$E$2)))"),0.0) -> 0 | AJ13: =if(AG13=0,1,0) -> 1 | AK13: =IFERROR(__xludf.DUMMYFUNCTION("iferror($O13-min(filter($O13:$O$392,$E13:$E$392=$E$2)))"),10.0) -> 10 | AL13: =IFERROR(__xludf.DUMMYFUNCTION("iferror(join("","",index(sort(filter($F14:$F$392,$O14:$O$392>$O13,$E14:$E$392=$E$2),2,false),0,1)))"),"") | AM13: =IFERROR(__xludf.DUMMYFUNCTION("REGEXREPLACE(join("","",unique({let(conf_picked,filter(E$1:E12,D$1:D12=D13), byrow(unique(TRANSPOSe(Teams!$1:$1)),lambda(rw,if(ISERROR(match(rw,conf_picked,0)),rw,))));iferror(if(#REF!,,transpose(split(#REF!,"","",1,1))))})), ""^,"", """")"),"AAC,ACC,Big 12,Big Ten,CUSA,MAC,MWC,Pac12,SEC,Sun Belt,Independent,") -> AAC,ACC,Big 12,Big Ten,CUSA,MAC,MWC,Pac12,SEC,Sun Belt,Independent, | AN13: =IFERROR(__xludf.DUMMYFUNCTION("iferror($O13-max(filter($O13:$O$392,arrayformula(isnumber(FIND($E13:$E$392,AM13))))))"),0.0) -> 0 | AO13: {=countifs($O$2:$O12,"<"&$O13,isnumber(FIND($E$2:$E12,AM13)),TRUE)} -> 10 | AP13: =IFERROR(__xludf.DUMMYFUNCTION("iferror(COUNT(filter($O14:$O$392,$O14:$O$392>$O13,arrayformula(isnumber(FIND($E14:$E$392,AM13))))))"),0.0) -> 0 | AQ13: =if(AN13=0,1,0) -> 1 | AR13: =IFERROR(__xludf.DUMMYFUNCTION("iferror($O13-min(filter($O13:$O$392,arrayformula(isnumber(FIND($E13:$E$392,AM13))))))"),12.0) -> 12 | AS13: =IFERROR(__xludf.DUMMYFUNCTION("iferror(join("","",index(sort(filter($F14:$F$392,$O14:$O$392>$O13,arrayformula(isnumber(FIND($E14:$E$392,AM13)))),2,false),0,1)))"),"")
A14: =A13+1 -> 13 | B14: =B2+1 -> 2 | C14: 1 | D14: =D13 -> Nick G. | E14: =if(F14<>"",VLOOKUP(F14,offset('Teams-Conference'!A:B,0,(counta('Draft Order'!B$2:B129)-10)*2),2,0),"") -> Sun Belt | F14: Troy | H14: =countif(E15:E24,E14) -> 3 | I14: =countif(E15:E36,E14) -> 4 | J14: =countif(E4:E13,E14) -> 2 | M14: =IFERROR(__xludf.DUMMYFUNCTION("counta(iferror(filter(L$2:L13,E$2:E13=E14,L$2:L13<L14)))"),0.0) -> 0 | N14: =IFERROR(__xludf.DUMMYFUNCTION("counta(iferror(filter(L15:L$129,E15:E$129=E14,L15:L$131>L14)))"),0.0) -> 0 | O14: {=XLOOKUP(F14,'Current Week'!B:B,'Current Week'!C:N)} -> 5 | P14: 7 | Q14: espn3 Video | R14: BYE | T14: bye | U14: bye | W14: 9999 | AA14: =$O14-max($O14:$O$392) -> -7 | AB14: =countif($O13:$O$2,"<"&$O14) -> 0 | AC14: =IFERROR(__xludf.DUMMYFUNCTION("iferror(COUNT(filter($O15:$O$392,$O15:$O$392>$O14)))"),66.0) -> 66 | AD14: =if(AA14=0,1,0) -> 0 | AE14: =$O14-min($O$2:$O14) -> 0 | AF14: =IFERROR(__xludf.DUMMYFUNCTION("iferror(join("","",index(sort(filter($F15:$F$393,$O15:$O$393>$O14),2,false),0,1)))"),"Utah,Toledo,Michigan,Texas,Oregon,Western Michigan,Georgia Southern,Washington State,Notre Dame,San Diego State,Utah State,Air Force,Cincinnati,Nevada,Miami,Florida Atlantic,Wyoming,EMU,Temple,Hawaii,Florida Intl,Buffalo,SMU,Miami-OH,Navy,Tulane,Iowa Stat"&"e,Virginia Tech,LSU,Marshall,Wisconsin,Penn State,Georgia State,USC,Oklahoma State,Auburn,Louisiana Tech,Southern Mississippi,Florida,Baylor,UAB,Arizona State,California,Michigan State,BYU,Iowa,Texas A&M,Minnesota,Kansas State,Indiana,Florida State,Wake F"&"orest,Western Kentucky,Virginia,Charlotte,Pittsburgh,Missouri,Boston College,Mississippi State,Tennessee,Kent State,Kentucky,Central Michigan,North Carolina,Louisville,Illinois") -> Utah,Toledo,Michigan,Texas,Oregon,Western Michigan,Georgia Southern,Washington State,Notre Dame,San Diego State,Utah State,Air Force,Cincinnati,Nevada,Miami,Florida Atlantic,Wyoming,EMU,Temple,Hawaii,Florida Intl,Buffalo,SMU,Miami-OH,Navy,Tulane,Iowa State,Virginia Tech,LSU,Marshall,Wisconsin,Penn State,Georgia State,USC,Oklahoma State,Auburn,Louisiana Tech,Southern Mississippi,Florida,Baylor,UAB,Arizona State,California,Michigan State,BYU,Iowa,Texas A&M,Minnesota,Kansas State,Indiana,Florida State,Wake Forest,Western Kentucky,Virginia,Charlotte,Pittsburgh,Missouri,Boston College,Mississippi State,Tennessee,Kent State,Kentucky,Central Michigan,North Carolina,Louisville,Illinois | AG14: =IFERROR(__xludf.DUMMYFUNCTION("iferror($O14-max(filter($O14:$O$392,$E14:$E$392=$E$2)))"),-7.0) -> -7 | AH14: =countifs($O13:$O$2,"<"&$O14,$E13:$E$2,$E$2) -> 0 | AI14: =IFERROR(__xludf.DUMMYFUNCTION("iferror(COUNT(filter($O15:$O$392,$O15:$O$392>$O14,$E14:$E$392=$E$2)))"),0.0) -> 0 | AJ14: =if(AG14=0,1,0) -> 0 | AK14: =IFERROR(__xludf.DUMMYFUNCTION("iferror($O14-min(filter($O14:$O$392,$E14:$E$392=$E$2)))"),3.0) -> 3 | AL14: =IFERROR(__xludf.DUMMYFUNCTION("iferror(join("","",index(sort(filter($F15:$F$392,$O15:$O$392>$O14,$E15:$E$392=$E$2),2,false),0,1)))"),"LSU,Auburn,Florida,Texas A&M,Missouri,Mississippi State,Tennessee,Kentucky") -> LSU,Auburn,Florida,Texas A&M,Missouri,Mississippi State,Tennessee,Kentucky | AM14: =IFERROR(__xludf.DUMMYFUNCTION("REGEXREPLACE(join("","",unique({let(conf_picked,filter(E$1:E13,D$1:D13=D14), byrow(unique(TRANSPOSe(Teams!$1:$1)),lambda(rw,if(ISERROR(match(rw,conf_picked,0)),rw,))));iferror(if(#REF!,,transpose(split(#REF!,"","",1,1))))})), ""^,"", """")"),"AAC,ACC,Big 12,,CUSA,MAC,MWC,Pac12,SEC,Sun Belt,Independent") -> AAC,ACC,Big 12,,CUSA,MAC,MWC,Pac12,SEC,Sun Belt,Independent | AN14: =IFERROR(__xludf.DUMMYFUNCTION("iferror($O14-max(filter($O14:$O$392,arrayformula(isnumber(FIND($E14:$E$392,AM14))))))"),-7.0) -> -7 | AO14: {=countifs($O$2:$O13,"<"&$O14,isnumber(FIND($E$2:$E13,AM14)),TRUE)} -> 0 | AP14: =IFERROR(__xludf.DUMMYFUNCTION("iferror(COUNT(filter($O15:$O$392,$O15:$O$392>$O14,arrayformula(isnumber(FIND($E15:$E$392,AM14))))))"),58.0) -> 58 | AQ14: =if(AN14=0,1,0) -> 0 | AR14: =IFERROR(__xludf.DUMMYFUNCTION("iferror($O14-min(filter($O14:$O$392,arrayformula(isnumber(FIND($E14:$E$392,AM14))))))"),5.0) -> 5 | AS14: =IFERROR(__xludf.DUMMYFUNCTION("iferror(join("","",index(sort(filter($F15:$F$392,$O15:$O$392>$O14,arrayformula(isnumber(FIND($E15:$E$392,AM14)))),2,false),0,1)))"),"Utah,Toledo,Texas,Oregon,Western Michigan,Georgia Southern,Washington State,Notre Dame,San Diego State,Utah State,Air Force,Cincinnati,Nevada,Miami,Florida Atlantic,Wyoming,EMU,Temple,Hawaii,Florida Intl,Buffalo,SMU,Miami-OH,Navy,Tulane,Iowa State,Virgini"&"a Tech,LSU,Marshall,Georgia State,USC,Oklahoma State,Auburn,Louisiana Tech,Southern Mississippi,Florida,Baylor,UAB,Arizona State,California,BYU,Texas A&M,Kansas State,Florida State,Wake Forest,Western Kentucky,Virginia,Charlotte,Pittsburgh,Missouri,Boston"&" College,Mississippi State,Tennessee,Kent State,Kentucky,Central Michigan,North Carolina,Louisville") -> Utah,Toledo,Texas,Oregon,Western Michigan,Georgia Southern,Washington State,Notre Dame,San Diego State,Utah State,Air Force,Cincinnati,Nevada,Miami,Florida Atlantic,Wyoming,EMU,Temple,Hawaii,Florida Intl,Buffalo,SMU,Miami-OH,Navy,Tulane,Iowa State,Virginia Tech,LSU,Marshall,Georgia State,USC,Oklahoma State,Auburn,Louisiana Tech,Southern Mississippi,Florida,Baylor,UAB,Arizona State,California,BYU,Texas A&M,Kansas State,Florida State,Wake Forest,Western Kentucky,Virginia,Charlotte,Pittsburgh,Missouri,Boston College,Mississippi State,Tennessee,Kent State,Kentucky,Central Michigan,North Carolina,Louisville
A15: =A14+1 -> 14 | B15: =B3+1 -> 2 | C15: 2 | D15: =D12 -> Brad | E15: =if(F15<>"",VLOOKUP(F15,offset('Teams-Conference'!A:B,0,(counta('Draft Order'!B$2:B129)-10)*2),2,0),"") -> Pac12 | F15: Utah | H15: =countif(E16:E25,E15) -> 2 | I15: =countif(E16:E37,E15) -> 2 | J15: =countif(E5:E14,E15) -> 1 | M15: =IFERROR(__xludf.DUMMYFUNCTION("counta(iferror(filter(L$2:L14,E$2:E14=E15,L$2:L14<L15)))"),0.0) -> 0 | N15: =IFERROR(__xludf.DUMMYFUNCTION("counta(iferror(filter(L16:L$129,E16:E$129=E15,L16:L$131>L15)))"),0.0) -> 0 | O15: {=XLOOKUP(F15,'Current Week'!B:B,'Current Week'!C:N)} -> 11 | P15: 1 | Q15: FOX | R15: (5) Utah at (13) Oregon | S15: FRI, DEC 6 8:00 PM ET | T15: -6½ | U15: 47½ | V15: Justin | W15: FRI, DEC 6 8:00 PM ET | AA15: =$O15-max($O15:$O$392) -> -1 | AB15: =countif($O14:$O$2,"<"&$O15) -> 6 | AC15: =IFERROR(__xludf.DUMMYFUNCTION("iferror(COUNT(filter($O16:$O$392,$O16:$O$392>$O15)))"),1.0) -> 1 | AD15: =if(AA15=0,1,0) -> 0 | AE15: =$O15-min($O$2:$O15) -> 6 | AF15: =IFERROR(__xludf.DUMMYFUNCTION("iferror(join("","",index(sort(filter($F16:$F$393,$O16:$O$393>$O15),2,false),0,1)))"),"LSU") -> LSU | AG15: =IFERROR(__xludf.DUMMYFUNCTION("iferror($O15-max(filter($O15:$O$392,$E15:$E$392=$E$2)))"),-1.0) -> -1 | AH15: =countifs($O14:$O$2,"<"&$O15,$E14:$E$2,$E$2) -> 1 | AI15: =IFERROR(__xludf.DUMMYFUNCTION("iferror(COUNT(filter($O16:$O$392,$O16:$O$392>$O15,$E15:$E$392=$E$2)))"),0.0) -> 0 | AJ15: =if(AG15=0,1,0) -> 0 | AK15: =IFERROR(__xludf.DUMMYFUNCTION("iferror($O15-min(filter($O15:$O$392,$E15:$E$392=$E$2)))"),9.0) -> 9 | AL15: =IFERROR(__xludf.DUMMYFUNCTION("iferror(join("","",index(sort(filter($F16:$F$392,$O16:$O$392>$O15,$E16:$E$392=$E$2),2,false),0,1)))"),"LSU") -> LSU | AM15: =IFERROR(__xludf.DUMMYFUNCTION("REGEXREPLACE(join("","",unique({let(conf_picked,filter(E$1:E14,D$1:D14=D15), byrow(unique(TRANSPOSe(Teams!$1:$1)),lambda(rw,if(ISERROR(match(rw,conf_picked,0)),rw,))));iferror(if(#REF!,,transpose(split(#REF!,"","",1,1))))})), ""^,"", """")"),"ACC,Big 12,Big Ten,CUSA,MAC,MWC,Pac12,SEC,Sun Belt,Independent") -> ACC,Big 12,Big Ten,CUSA,MAC,MWC,Pac12,SEC,Sun Belt,Independent | AN15: =IFERROR(__xludf.DUMMYFUNCTION("iferror($O15-max(filter($O15:$O$392,arrayformula(isnumber(FIND($E15:$E$392,AM15))))))"),-1.0) -> -1 | AO15: {=countifs($O$2:$O14,"<"&$O15,isnumber(FIND($E$2:$E14,AM15)),TRUE)} -> 5 | AP15: =IFERROR(__xludf.DUMMYFUNCTION("iferror(COUNT(filter($O16:$O$392,$O16:$O$392>$O15,arrayformula(isnumber(FIND($E16:$E$392,AM15))))))"),1.0) -> 1 | AQ15: =if(AN15=0,1,0) -> 0 | AR15: =IFERROR(__xludf.DUMMYFUNCTION("iferror($O15-min(filter($O15:$O$392,arrayformula(isnumber(FIND($E15:$E$392,AM15))))))"),11.0) -> 11 | AS15: =IFERROR(__xludf.DUMMYFUNCTION("iferror(join("","",index(sort(filter($F16:$F$392,$O16:$O$392>$O15,arrayformula(isnumber(FIND($E16:$E$392,AM15)))),2,false),0,1)))"),"LSU") -> LSU
A16: =A15+1 -> 15 | B16: =B4+1 -> 2 | C16: 3 | D16: =D11 -> Josh R. | E16: =if(F16<>"",VLOOKUP(F16,offset('Teams-Conference'!A:B,0,(counta('Draft Order'!B$2:B129)-10)*2),2,0),"") -> MAC | F16: Toledo | H16: =countif(E17:E26,E16) -> 1 | I16: =countif(E17:E38,E16) -> 2 | J16: =countif(E6:E15,E16) -> 0 | M16: =IFERROR(__xludf.DUMMYFUNCTION("counta(iferror(filter(L$2:L15,E$2:E15=E16,L$2:L15<L16)))"),0.0) -> 0 | N16: =IFERROR(__xludf.DUMMYFUNCTION("counta(iferror(filter(L17:L$129,E17:E$129=E16,L17:L$131>L16)))"),0.0) -> 0 | O16: {=XLOOKUP(F16,'Current Week'!B:B,'Current Week'!C:N)} -> 6 | P16: 6 | Q16: ESPNU | R16: BYE | T16: bye | U16: bye | W16: 9999 | AA16: =$O16-max($O16:$O$392) -> -6 | AB16: =countif($O15:$O$2,"<"&$O16) -> 2 | AC16: =IFERROR(__xludf.DUMMYFUNCTION("iferror(COUNT(filter($O17:$O$392,$O17:$O$392>$O16)))"),51.0) -> 51 | AD16: =if(AA16=0,1,0) -> 0 | AE16: =$O16-min($O$2:$O16) -> 1 | AF16: =IFERROR(__xludf.DUMMYFUNCTION("iferror(join("","",index(sort(filter($F17:$F$393,$O17:$O$393>$O16),2,false),0,1)))"),"Michigan,Texas,Oregon,Western Michigan,Georgia Southern,Notre Dame,San Diego State,Utah State,Air Force,Cincinnati,Nevada,Florida Atlantic,Wyoming,Temple,Hawaii,Buffalo,SMU,Miami-OH,Navy,Iowa State,Virginia Tech,LSU,Marshall,Wisconsin,Penn State,Georgia S"&"tate,USC,Oklahoma State,Auburn,Louisiana Tech,Southern Mississippi,Florida,Baylor,UAB,Arizona State,California,BYU,Iowa,Texas A&M,Minnesota,Kansas State,Indiana,Wake Forest,Western Kentucky,Virginia,Charlotte,Pittsburgh,Tennessee,Kentucky,Central Michigan"&",Louisville") -> Michigan,Texas,Oregon,Western Michigan,Georgia Southern,Notre Dame,San Diego State,Utah State,Air Force,Cincinnati,Nevada,Florida Atlantic,Wyoming,Temple,Hawaii,Buffalo,SMU,Miami-OH,Navy,Iowa State,Virginia Tech,LSU,Marshall,Wisconsin,Penn State,Georgia State,USC,Oklahoma State,Auburn,Louisiana Tech,Southern Mississippi,Florida,Baylor,UAB,Arizona State,California,BYU,Iowa,Texas A&M,Minnesota,Kansas State,Indiana,Wake Forest,Western Kentucky,Virginia,Charlotte,Pittsburgh,Tennessee,Kentucky,Central Michigan,Louisville | AG16: =IFERROR(__xludf.DUMMYFUNCTION("iferror($O16-max(filter($O16:$O$392,$E16:$E$392=$E$2)))"),-6.0) -> -6 | AH16: =countifs($O15:$O$2,"<"&$O16,$E15:$E$2,$E$2) -> 0 | AI16: =IFERROR(__xludf.DUMMYFUNCTION("iferror(COUNT(filter($O17:$O$392,$O17:$O$392>$O16,$E16:$E$392=$E$2)))"),0.0) -> 0 | AJ16: =if(AG16=0,1,0) -> 0 | AK16: =IFERROR(__xludf.DUMMYFUNCTION("iferror($O16-min(filter($O16:$O$392,$E16:$E$392=$E$2)))"),4.0) -> 4 | AL16: =IFERROR(__xludf.DUMMYFUNCTION("iferror(join("","",index(sort(filter($F17:$F$392,$O17:$O$392>$O16,$E17:$E$392=$E$2),2,false),0,1)))"),"LSU,Auburn,Florida,Texas A&M,Tennessee,Kentucky") -> LSU,Auburn,Florida,Texas A&M,Tennessee,Kentucky | AM16: =IFERROR(__xludf.DUMMYFUNCTION("REGEXREPLACE(join("","",unique({let(conf_picked,filter(E$1:E15,D$1:D15=D16), byrow(unique(TRANSPOSe(Teams!$1:$1)),lambda(rw,if(ISERROR(match(rw,conf_picked,0)),rw,))));iferror(if(#REF!,,transpose(split(#REF!,"","",1,1))))})), ""^,"", """")"),"AAC,ACC,Big 12,Big Ten,CUSA,MAC,MWC,Pac12,SEC,,Independent") -> AAC,ACC,Big 12,Big Ten,CUSA,MAC,MWC,Pac12,SEC,,Independent | AN16: =IFERROR(__xludf.DUMMYFUNCTION("iferror($O16-max(filter($O16:$O$392,arrayformula(isnumber(FIND($E16:$E$392,AM16))))))"),-6.0) -> -6 | AO16: {=countifs($O$2:$O15,"<"&$O16,isnumber(FIND($E$2:$E15,AM16)),TRUE)} -> 0 | AP16: =IFERROR(__xludf.DUMMYFUNCTION("iferror(COUNT(filter($O17:$O$392,$O17:$O$392>$O16,arrayformula(isnumber(FIND($E17:$E$392,AM16))))))"),49.0) -> 49 | AQ16: =if(AN16=0,1,0) -> 0 | AR16: =IFERROR(__xludf.DUMMYFUNCTION("iferror($O16-min(filter($O16:$O$392,arrayformula(isnumber(FIND($E16:$E$392,AM16))))))"),6.0) -> 6 | AS16: =IFERROR(__xludf.DUMMYFUNCTION("iferror(join("","",index(sort(filter($F17:$F$392,$O17:$O$392>$O16,arrayformula(isnumber(FIND($E17:$E$392,AM16)))),2,false),0,1)))"),"Michigan,Texas,Oregon,Western Michigan,Notre Dame,San Diego State,Utah State,Air Force,Cincinnati,Nevada,Florida Atlantic,Wyoming,Temple,Hawaii,Buffalo,SMU,Miami-OH,Navy,Iowa State,Virginia Tech,LSU,Marshall,Wisconsin,Penn State,USC,Oklahoma State,Auburn,"&"Louisiana Tech,Southern Mississippi,Florida,Baylor,UAB,Arizona State,California,BYU,Iowa,Texas A&M,Minnesota,Kansas State,Indiana,Wake Forest,Western Kentucky,Virginia,Charlotte,Pittsburgh,Tennessee,Kentucky,Central Michigan,Louisville") -> Michigan,Texas,Oregon,Western Michigan,Notre Dame,San Diego State,Utah State,Air Force,Cincinnati,Nevada,Florida Atlantic,Wyoming,Temple,Hawaii,Buffalo,SMU,Miami-OH,Navy,Iowa State,Virginia Tech,LSU,Marshall,Wisconsin,Penn State,USC,Oklahoma State,Auburn,Louisiana Tech,Southern Mississippi,Florida,Baylor,UAB,Arizona State,California,BYU,Iowa,Texas A&M,Minnesota,Kansas State,Indiana,Wake Forest,Western Kentucky,Virginia,Charlotte,Pittsburgh,Tennessee,Kentucky,Central Michigan,Louisville
