Workbook

Sheet Standings
A1: =HYPERLINK("https://docs.google.com/document/d/1-e84tTr9zFoIfOR2Z7Z-1lI4YO7v6GoaThMqj1UrcXE/edit","Rules") -> Rules | B1: Season | F1: Current Week (Projections based on most recent Consensus) | M1: Actaul + Chalk Projections
A2: Players | B2: Wins | C2: Losses | D2: P5 Ws | E2: G5 Ws | F2: Games | G2: Games Played | H2: Wins | I2: Games Left | J2: Expected Wins | K2: Upsets Won | L2: Upsets Lost
A3: {=sort(A17:M29,2,false,3,true,7,false,8,true,1,true)} -> Gary | B3: 74 | C3: 46 | D3: 42 | E3: 32 | F3: 2 | G3: 0 | H3: 0 | I3: 2 | J3: 2 | K3: 0 | L3: 0 | M3: 2
A4: Nick A. | B4: 72 | C4: 48 | D4: 37 | E4: 35 | F4: 1 | G4: 0 | H4: 0 | I4: 1 | J4: 1 | K4: 0 | L4: 0 | M4: 1
A5: Vu | B5: 72 | C5: 48 | D5: 35 | E5: 37 | F5: 3 | G5: 0 | H5: 0 | I5: 3 | J5: 2 | K5: 0 | L5: 0 | M5: 2
A6: Josh | B6: 69 | C6: 52 | D6: 30 | E6: 39 | F6: 2 | G6: 0 | H6: 0 | I6: 2 | J6: 0 | K6: 0 | L6: 0 | M6: 0
A7: Janice/Mike | B7: 67 | C7: 53 | D7: 29 | E7: 38 | F7: 1 | G7: 0 | H7: 0 | I7: 1 | J7: 2 | K7: 0 | L7: 0 | M7: 2
A8: Nico | B8: 66 | C8: 54 | D8: 39 | E8: 27 | F8: 2 | G8: 0 | H8: 0 | I8: 2 | J8: 2 | K8: 0 | L8: 0 | M8: 2
A9: DavEmily | B9: 66 | C9: 55 | D9: 38 | E9: 28 | F9: 3 | G9: 0 | H9: 0 | I9: 3 | J9: 0 | K9: 0 | L9: 0 | M9: 0
A10: Justin | B10: 64 | C10: 56 | D10: 40 | E10: 24 | F10: 2 | G10: 0 | H10: 0 | I10: 2 | J10: 1 | K10: 0 | L10: 0 | M10: 1
A11: Brad | B11: 62 | C11: 58 | D11: 29 | E11: 33 | F11: 1 | G11: 0 | H11: 0 | I11: 1 | J11: 0 | K11: 0 | L11: 0 | M11: 0
A12: Nick G. | B12: 62 | C12: 58 | D12: 43 | E12: 19 | F12: 3 | G12: 0 | H12: 0 | I12: 3 | J12: 2 | K12: 0 | L12: 0 | M12: 2
A13: Masa | B13: 60 | C13: 60 | D13: 36 | E13: 24 | F13: 0 | G13: 0 | H13: 0 | I13: 0 | J13: 0 | K13: 0 | L13: 0 | M13: 0
A14: Jeannine | B14: 57 | C14: 63 | D14: 31 | E14: 26 | F14: 0 | G14: 0 | H14: 0 | I14: 0 | J14: 0 | K14: 0 | L14: 0 | M14: 0
A15: Dan | B15: 50 | C15: 70 | D15: 29 | E15: 21 | F15: 0 | G15: 0 | H15: 0 | I15: 0 | J15: 0 | K15: 0 | L15: 0 | M15: 0
A17: {='Draft Order'!B2:B29} -> Nick G. | B17: =sumif('Current Week'!$B:$B,$A17,'Current Week'!D:D) -> 62 | C17: =sumif('Current Week'!$B:$B,$A17,'Current Week'!E:E) -> 58 | D17: =sumifs('Current Week'!D:D,'Current Week'!$B:$B,$A17,'Current Week'!T:T,"Power 5") -> 43 | E17: =sumifs('Current Week'!D:D,'Current Week'!$B:$B,$A17,'Current Week'!T:T,"Group of 5") -> 19 | F17: =10-countifs('Current Week'!B:B,A17,'Current Week'!G:G,"") -> 3 | G17: =IFERROR(__xludf.DUMMYFUNCTION("COUNTA(iferror(filter('Current Week'!B:B,'Current Week'!B:B=A17,left('Current Week'!G:G,5)=""FINAL"")))"),0.0) -> 0 | H17: =countifs('Current Week'!B:B,A17,'Current Week'!U:U,"=TRUE") -> 0 | I17: =F17-G17 -> 3 | J17: =IFERROR(__xludf.DUMMYFUNCTION("countifs('Current Week'!B:B,A17,'Current Week'!K:K,""<0"")+counta(iferror(filter('Current Week'!B:B,'Current Week'!B:B=A17,'Current Week'!F:F<>"""",'Current Week'!K:K="""",'Current Week'!H:H="""")))"),2.0) -> 2 | K17: =IFERROR(__xludf.DUMMYFUNCTION("counta(iferror(filter('Current Week'!B:B,'Current Week'!B:B=A17,'Current Week'!K:K>0,not(iserror(find(""FINAL"",'Current Week'!G:G))),'Current Week'!U:U=TRUE)))+counta(iferror(filter('Current Week'!B:B,'Current Week'!B:B=A17,'Current Week'!K:K="""",not(is"&"error(find(""FINAL"",'Current Week'!G:G))),'Current Week'!U:U=TRUE,'Current Week'!H:H="""")))"),0.0) -> 0 | L17: =IFERROR(__xludf.DUMMYFUNCTION("counta(iferror(filter('Current Week'!B:B,'Current Week'!B:B=A17,'Current Week'!K:K<0,not(iserror(find(""FINAL"",'Current Week'!G:G))),'Current Week'!U:U<>TRUE)))"),0.0) -> 0 | M17: =IFERROR(__xludf.DUMMYFUNCTION("H17+counta(iferror(filter('Current Week'!B:B,'Current Week'!B:B=A17,'Current Week'!K:K<0,iserror(find(""FINAL"",'Current Week'!G:G)))))+counta(iferror(filter('Current Week'!B:B,'Current Week'!B:B=A17,'Current Week'!F:F<>"""",'Current Week'!J:J="""",'Curre"&"nt Week'!H:H="""",iserror(find(""FINAL"",'Current Week'!G:G)))))"),2.0) -> 2
A18: Janice/Mike | B18: =sumif('Current Week'!$B:$B,$A18,'Current Week'!D:D) -> 67 | C18: =sumif('Current Week'!$B:$B,$A18,'Current Week'!E:E) -> 53 | D18: =sumifs('Current Week'!D:D,'Current Week'!$B:$B,$A18,'Current Week'!T:T,"Power 5") -> 29 | E18: =sumifs('Current Week'!D:D,'Current Week'!$B:$B,$A18,'Current Week'!T:T,"Group of 5") -> 38 | F18: =10-countifs('Current Week'!B:B,A18,'Current Week'!G:G,"") -> 1 | G18: =IFERROR(__xludf.DUMMYFUNCTION("COUNTA(iferror(filter('Current Week'!B:B,'Current Week'!B:B=A18,left('Current Week'!G:G,5)=""FINAL"")))"),0.0) -> 0 | H18: =countifs('Current Week'!B:B,A18,'Current Week'!U:U,"=TRUE") -> 0 | I18: =F18-G18 -> 1 | J18: =IFERROR(__xludf.DUMMYFUNCTION("countifs('Current Week'!B:B,A18,'Current Week'!K:K,""<0"")+counta(iferror(filter('Current Week'!B:B,'Current Week'!B:B=A18,'Current Week'!F:F<>"""",'Current Week'!K:K="""",'Current Week'!H:H="""")))"),2.0) -> 2 | K18: =IFERROR(__xludf.DUMMYFUNCTION("counta(iferror(filter('Current Week'!B:B,'Current Week'!B:B=A18,'Current Week'!K:K>0,not(iserror(find(""FINAL"",'Current Week'!G:G))),'Current Week'!U:U=TRUE)))+counta(iferror(filter('Current Week'!B:B,'Current Week'!B:B=A18,'Current Week'!K:K="""",not(is"&"error(find(""FINAL"",'Current Week'!G:G))),'Current Week'!U:U=TRUE,'Current Week'!H:H="""")))"),0.0) -> 0 | L18: =IFERROR(__xludf.DUMMYFUNCTION("counta(iferror(filter('Current Week'!B:B,'Current Week'!B:B=A18,'Current Week'!K:K<0,not(iserror(find(""FINAL"",'Current Week'!G:G))),'Current Week'!U:U<>TRUE)))"),0.0) -> 0 | M18: =IFERROR(__xludf.DUMMYFUNCTION("H18+counta(iferror(filter('Current Week'!B:B,'Current Week'!B:B=A18,'Current Week'!K:K<0,iserror(find(""FINAL"",'Current Week'!G:G)))))+counta(iferror(filter('Current Week'!B:B,'Current Week'!B:B=A18,'Current Week'!F:F<>"""",'Current Week'!J:J="""",'Curre"&"nt Week'!H:H="""",iserror(find(""FINAL"",'Current Week'!G:G)))))"),2.0) -> 2
A19: Nick A. | B19: =sumif('Current Week'!$B:$B,$A19,'Current Week'!D:D) -> 72 | C19: =sumif('Current Week'!$B:$B,$A19,'Current Week'!E:E) -> 48 | D19: =sumifs('Current Week'!D:D,'Current Week'!$B:$B,$A19,'Current Week'!T:T,"Power 5") -> 37 | E19: =sumifs('Current Week'!D:D,'Current Week'!$B:$B,$A19,'Current Week'!T:T,"Group of 5") -> 35 | F19: =10-countifs('Current Week'!B:B,A19,'Current Week'!G:G,"") -> 1 | G19: =IFERROR(__xludf.DUMMYFUNCTION("COUNTA(iferror(filter('Current Week'!B:B,'Current Week'!B:B=A19,left('Current Week'!G:G,5)=""FINAL"")))"),0.0) -> 0 | H19: =countifs('Current Week'!B:B,A19,'Current Week'!U:U,"=TRUE") -> 0 | I19: =F19-G19 -> 1 | J19: =IFERROR(__xludf.DUMMYFUNCTION("countifs('Current Week'!B:B,A19,'Current Week'!K:K,""<0"")+counta(iferror(filter('Current Week'!B:B,'Current Week'!B:B=A19,'Current Week'!F:F<>"""",'Current Week'!K:K="""",'Current Week'!H:H="""")))"),1.0) -> 1 | K19: =IFERROR(__xludf.DUMMYFUNCTION("counta(iferror(filter('Current Week'!B:B,'Current Week'!B:B=A19,'Current Week'!K:K>0,not(iserror(find(""FINAL"",'Current Week'!G:G))),'Current Week'!U:U=TRUE)))+counta(iferror(filter('Current Week'!B:B,'Current Week'!B:B=A19,'Current Week'!K:K="""",not(is"&"error(find(""FINAL"",'Current Week'!G:G))),'Current Week'!U:U=TRUE,'Current Week'!H:H="""")))"),0.0) -> 0 | L19: =IFERROR(__xludf.DUMMYFUNCTION("counta(iferror(filter('Current Week'!B:B,'Current Week'!B:B=A19,'Current Week'!K:K<0,not(iserror(find(""FINAL"",'Current Week'!G:G))),'Current Week'!U:U<>TRUE)))"),0.0) -> 0 | M19: =IFERROR(__xludf.DUMMYFUNCTION("H19+counta(iferror(filter('Current Week'!B:B,'Current Week'!B:B=A19,'Current Week'!K:K<0,iserror(find(""FINAL"",'Current Week'!G:G)))))+counta(iferror(filter('Current Week'!B:B,'Current Week'!B:B=A19,'Current Week'!F:F<>"""",'Current Week'!J:J="""",'Curre"&"nt Week'!H:H="""",iserror(find(""FINAL"",'Current Week'!G:G)))))"),1.0) -> 1
A20: DavEmily | B20: =sumif('Current Week'!$B:$B,$A20,'Current Week'!D:D) -> 66 | C20: =sumif('Current Week'!$B:$B,$A20,'Current Week'!E:E) -> 55 | D20: =sumifs('Current Week'!D:D,'Current Week'!$B:$B,$A20,'Current Week'!T:T,"Power 5") -> 38 | E20: =sumifs('Current Week'!D:D,'Current Week'!$B:$B,$A20,'Current Week'!T:T,"Group of 5") -> 28 | F20: =10-countifs('Current Week'!B:B,A20,'Current Week'!G:G,"") -> 3 | G20: =IFERROR(__xludf.DUMMYFUNCTION("COUNTA(iferror(filter('Current Week'!B:B,'Current Week'!B:B=A20,left('Current Week'!G:G,5)=""FINAL"")))"),0.0) -> 0 | H20: =countifs('Current Week'!B:B,A20,'Current Week'!U:U,"=TRUE") -> 0 | I20: =F20-G20 -> 3 | J20: =IFERROR(__xludf.DUMMYFUNCTION("countifs('Current Week'!B:B,A20,'Current Week'!K:K,""<0"")+counta(iferror(filter('Current Week'!B:B,'Current Week'!B:B=A20,'Current Week'!F:F<>"""",'Current Week'!K:K="""",'Current Week'!H:H="""")))"),0.0) -> 0 | K20: =IFERROR(__xludf.DUMMYFUNCTION("counta(iferror(filter('Current Week'!B:B,'Current Week'!B:B=A20,'Current Week'!K:K>0,not(iserror(find(""FINAL"",'Current Week'!G:G))),'Current Week'!U:U=TRUE)))+counta(iferror(filter('Current Week'!B:B,'Current Week'!B:B=A20,'Current Week'!K:K="""",not(is"&"error(find(""FINAL"",'Current Week'!G:G))),'Current Week'!U:U=TRUE,'Current Week'!H:H="""")))"),0.0) -> 0 | L20: =IFERROR(__xludf.DUMMYFUNCTION("counta(iferror(filter('Current Week'!B:B,'Current Week'!B:B=A20,'Current Week'!K:K<0,not(iserror(find(""FINAL"",'Current Week'!G:G))),'Current Week'!U:U<>TRUE)))"),0.0) -> 0 | M20: =IFERROR(__xludf.DUMMYFUNCTION("H20+counta(iferror(filter('Current Week'!B:B,'Current Week'!B:B=A20,'Current Week'!K:K<0,iserror(find(""FINAL"",'Current Week'!G:G)))))+counta(iferror(filter('Current Week'!B:B,'Current Week'!B:B=A20,'Current Week'!F:F<>"""",'Current Week'!J:J="""",'Curre"&"nt Week'!H:H="""",iserror(find(""FINAL"",'Current Week'!G:G)))))"),0.0) -> 0
A21: Vu | B21: =sumif('Current Week'!$B:$B,$A21,'Current Week'!D:D) -> 72 | C21: =sumif('Current Week'!$B:$B,$A21,'Current Week'!E:E) -> 48 | D21: =sumifs('Current Week'!D:D,'Current Week'!$B:$B,$A21,'Current Week'!T:T,"Power 5") -> 35 | E21: =sumifs('Current Week'!D:D,'Current Week'!$B:$B,$A21,'Current Week'!T:T,"Group of 5") -> 37 | F21: =10-countifs('Current Week'!B:B,A21,'Current Week'!G:G,"") -> 3 | G21: =IFERROR(__xludf.DUMMYFUNCTION("COUNTA(iferror(filter('Current Week'!B:B,'Current Week'!B:B=A21,left('Current Week'!G:G,5)=""FINAL"")))"),0.0) -> 0 | H21: =countifs('Current Week'!B:B,A21,'Current Week'!U:U,"=TRUE") -> 0 | I21: =F21-G21 -> 3 | J21: =IFERROR(__xludf.DUMMYFUNCTION("countifs('Current Week'!B:B,A21,'Current Week'!K:K,""<0"")+counta(iferror(filter('Current Week'!B:B,'Current Week'!B:B=A21,'Current Week'!F:F<>"""",'Current Week'!K:K="""",'Current Week'!H:H="""")))"),2.0) -> 2 | K21: =IFERROR(__xludf.DUMMYFUNCTION("counta(iferror(filter('Current Week'!B:B,'Current Week'!B:B=A21,'Current Week'!K:K>0,not(iserror(find(""FINAL"",'Current Week'!G:G))),'Current Week'!U:U=TRUE)))+counta(iferror(filter('Current Week'!B:B,'Current Week'!B:B=A21,'Current Week'!K:K="""",not(is"&"error(find(""FINAL"",'Current Week'!G:G))),'Current Week'!U:U=TRUE,'Current Week'!H:H="""")))"),0.0) -> 0 | L21: =IFERROR(__xludf.DUMMYFUNCTION("counta(iferror(filter('Current Week'!B:B,'Current Week'!B:B=A21,'Current Week'!K:K<0,not(iserror(find(""FINAL"",'Current Week'!G:G))),'Current Week'!U:U<>TRUE)))"),0.0) -> 0 | M21: =IFERROR(__xludf.DUMMYFUNCTION("H21+counta(iferror(filter('Current Week'!B:B,'Current Week'!B:B=A21,'Current Week'!K:K<0,iserror(find(""FINAL"",'Current Week'!G:G)))))+counta(iferror(filter('Current Week'!B:B,'Current Week'!B:B=A21,'Current Week'!F:F<>"""",'Current Week'!J:J="""",'Curre"&"nt Week'!H:H="""",iserror(find(""FINAL"",'Current Week'!G:G)))))"),2.0) -> 2
A22: Dan | B22: =sumif('Current Week'!$B:$B,$A22,'Current Week'!D:D) -> 50 | C22: =sumif('Current Week'!$B:$B,$A22,'Current Week'!E:E) -> 70 | D22: =sumifs('Current Week'!D:D,'Current Week'!$B:$B,$A22,'Current Week'!T:T,"Power 5") -> 29 | E22: =sumifs('Current Week'!D:D,'Current Week'!$B:$B,$A22,'Current Week'!T:T,"Group of 5") -> 21 | F22: =10-countifs('Current Week'!B:B,A22,'Current Week'!G:G,"") -> 0 | G22: =IFERROR(__xludf.DUMMYFUNCTION("COUNTA(iferror(filter('Current Week'!B:B,'Current Week'!B:B=A22,left('Current Week'!G:G,5)=""FINAL"")))"),0.0) -> 0 | H22: =countifs('Current Week'!B:B,A22,'Current Week'!U:U,"=TRUE") -> 0 | I22: =F22-G22 -> 0 | J22: =IFERROR(__xludf.DUMMYFUNCTION("countifs('Current Week'!B:B,A22,'Current Week'!K:K,""<0"")+counta(iferror(filter('Current Week'!B:B,'Current Week'!B:B=A22,'Current Week'!F:F<>"""",'Current Week'!K:K="""",'Current Week'!H:H="""")))"),0.0) -> 0 | K22: =IFERROR(__xludf.DUMMYFUNCTION("counta(iferror(filter('Current Week'!B:B,'Current Week'!B:B=A22,'Current Week'!K:K>0,not(iserror(find(""FINAL"",'Current Week'!G:G))),'Current Week'!U:U=TRUE)))+counta(iferror(filter('Current Week'!B:B,'Current Week'!B:B=A22,'Current Week'!K:K="""",not(is"&"error(find(""FINAL"",'Current Week'!G:G))),'Current Week'!U:U=TRUE,'Current Week'!H:H="""")))"),0.0) -> 0 | L22: =IFERROR(__xludf.DUMMYFUNCTION("counta(iferror(filter('Current Week'!B:B,'Current Week'!B:B=A22,'Current Week'!K:K<0,not(iserror(find(""FINAL"",'Current Week'!G:G))),'Current Week'!U:U<>TRUE)))"),0.0) -> 0 | M22: =IFERROR(__xludf.DUMMYFUNCTION("H22+counta(iferror(filter('Current Week'!B:B,'Current Week'!B:B=A22,'Current Week'!K:K<0,iserror(find(""FINAL"",'Current Week'!G:G)))))+counta(iferror(filter('Current Week'!B:B,'Current Week'!B:B=A22,'Current Week'!F:F<>"""",'Current Week'!J:J="""",'Curre"&"nt Week'!H:H="""",iserror(find(""FINAL"",'Current Week'!G:G)))))"),0.0) -> 0
A23: Josh | B23: =sumif('Current Week'!$B:$B,$A23,'Current Week'!D:D) -> 69 | C23: =sumif('Current Week'!$B:$B,$A23,'Current Week'!E:E) -> 52 | D23: =sumifs('Current Week'!D:D,'Current Week'!$B:$B,$A23,'Current Week'!T:T,"Power 5") -> 30 | E23: =sumifs('Current Week'!D:D,'Current Week'!$B:$B,$A23,'Current Week'!T:T,"Group of 5") -> 39 | F23: =10-countifs('Current Week'!B:B,A23,'Current Week'!G:G,"") -> 2 | G23: =IFERROR(__xludf.DUMMYFUNCTION("COUNTA(iferror(filter('Current Week'!B:B,'Current Week'!B:B=A23,left('Current Week'!G:G,5)=""FINAL"")))"),0.0) -> 0 | H23: =countifs('Current Week'!B:B,A23,'Current Week'!U:U,"=TRUE") -> 0 | I23: =F23-G23 -> 2 | J23: =IFERROR(__xludf.DUMMYFUNCTION("countifs('Current Week'!B:B,A23,'Current Week'!K:K,""<0"")+counta(iferror(filter('Current Week'!B:B,'Current Week'!B:B=A23,'Current Week'!F:F<>"""",'Current Week'!K:K="""",'Current Week'!H:H="""")))"),0.0) -> 0 | K23: =IFERROR(__xludf.DUMMYFUNCTION("counta(iferror(filter('Current Week'!B:B,'Current Week'!B:B=A23,'Current Week'!K:K>0,not(iserror(find(""FINAL"",'Current Week'!G:G))),'Current Week'!U:U=TRUE)))+counta(iferror(filter('Current Week'!B:B,'Current Week'!B:B=A23,'Current Week'!K:K="""",not(is"&"error(find(""FINAL"",'Current Week'!G:G))),'Current Week'!U:U=TRUE,'Current Week'!H:H="""")))"),0.0) -> 0 | L23: =IFERROR(__xludf.DUMMYFUNCTION("counta(iferror(filter('Current Week'!B:B,'Current Week'!B:B=A23,'Current Week'!K:K<0,not(iserror(find(""FINAL"",'Current Week'!G:G))),'Current Week'!U:U<>TRUE)))"),0.0) -> 0 | M23: =IFERROR(__xludf.DUMMYFUNCTION("H23+counta(iferror(filter('Current Week'!B:B,'Current Week'!B:B=A23,'Current Week'!K:K<0,iserror(find(""FINAL"",'Current Week'!G:G)))))+counta(iferror(filter('Current Week'!B:B,'Current Week'!B:B=A23,'Current Week'!F:F<>"""",'Current Week'!J:J="""",'Curre"&"nt Week'!H:H="""",iserror(find(""FINAL"",'Current Week'!G:G)))))"),0.0) -> 0
A24: Masa | B24: =sumif('Current Week'!$B:$B,$A24,'Current Week'!D:D) -> 60 | C24: =sumif('Current Week'!$B:$B,$A24,'Current Week'!E:E) -> 60 | D24: =sumifs('Current Week'!D:D,'Current Week'!$B:$B,$A24,'Current Week'!T:T,"Power 5") -> 36 | E24: =sumifs('Current Week'!D:D,'Current Week'!$B:$B,$A24,'Current Week'!T:T,"Group of 5") -> 24 | F24: =10-countifs('Current Week'!B:B,A24,'Current Week'!G:G,"") -> 0 | G24: =IFERROR(__xludf.DUMMYFUNCTION("COUNTA(iferror(filter('Current Week'!B:B,'Current Week'!B:B=A24,left('Current Week'!G:G,5)=""FINAL"")))"),0.0) -> 0 | H24: =countifs('Current Week'!B:B,A24,'Current Week'!U:U,"=TRUE") -> 0 | I24: =F24-G24 -> 0 | J24: =IFERROR(__xludf.DUMMYFUNCTION("countifs('Current Week'!B:B,A24,'Current Week'!K:K,""<0"")+counta(iferror(filter('Current Week'!B:B,'Current Week'!B:B=A24,'Current Week'!F:F<>"""",'Current Week'!K:K="""",'Current Week'!H:H="""")))"),0.0) -> 0 | K24: =IFERROR(__xludf.DUMMYFUNCTION("counta(iferror(filter('Current Week'!B:B,'Current Week'!B:B=A24,'Current Week'!K:K>0,not(iserror(find(""FINAL"",'Current Week'!G:G))),'Current Week'!U:U=TRUE)))+counta(iferror(filter('Current Week'!B:B,'Current Week'!B:B=A24,'Current Week'!K:K="""",not(is"&"error(find(""FINAL"",'Current Week'!G:G))),'Current Week'!U:U=TRUE,'Current Week'!H:H="""")))"),0.0) -> 0 | L24: =IFERROR(__xludf.DUMMYFUNCTION("counta(iferror(filter('Current Week'!B:B,'Current Week'!B:B=A24,'Current Week'!K:K<0,not(iserror(find(""FINAL"",'Current Week'!G:G))),'Current Week'!U:U<>TRUE)))"),0.0) -> 0 | M24: =IFERROR(__xludf.DUMMYFUNCTION("H24+counta(iferror(filter('Current Week'!B:B,'Current Week'!B:B=A24,'Current Week'!K:K<0,iserror(find(""FINAL"",'Current Week'!G:G)))))+counta(iferror(filter('Current Week'!B:B,'Current Week'!B:B=A24,'Current Week'!F:F<>"""",'Current Week'!J:J="""",'Curre"&"nt Week'!H:H="""",iserror(find(""FINAL"",'Current Week'!G:G)))))"),0.0) -> 0
A25: Nico | B25: =sumif('Current Week'!$B:$B,$A25,'Current Week'!D:D) -> 66 | C25: =sumif('Current Week'!$B:$B,$A25,'Current Week'!E:E) -> 54 | D25: =sumifs('Current Week'!D:D,'Current Week'!$B:$B,$A25,'Current Week'!T:T,"Power 5") -> 39 | E25: =sumifs('Current Week'!D:D,'Current Week'!$B:$B,$A25,'Current Week'!T:T,"Group of 5") -> 27 | F25: =10-countifs('Current Week'!B:B,A25,'Current Week'!G:G,"") -> 2 | G25: =IFERROR(__xludf.DUMMYFUNCTION("COUNTA(iferror(filter('Current Week'!B:B,'Current Week'!B:B=A25,left('Current Week'!G:G,5)=""FINAL"")))"),0.0) -> 0 | H25: =countifs('Current Week'!B:B,A25,'Current Week'!U:U,"=TRUE") -> 0 | I25: =F25-G25 -> 2 | J25: =IFERROR(__xludf.DUMMYFUNCTION("countifs('Current Week'!B:B,A25,'Current Week'!K:K,""<0"")+counta(iferror(filter('Current Week'!B:B,'Current Week'!B:B=A25,'Current Week'!F:F<>"""",'Current Week'!K:K="""",'Current Week'!H:H="""")))"),2.0) -> 2 | K25: =IFERROR(__xludf.DUMMYFUNCTION("counta(iferror(filter('Current Week'!B:B,'Current Week'!B:B=A25,'Current Week'!K:K>0,not(iserror(find(""FINAL"",'Current Week'!G:G))),'Current Week'!U:U=TRUE)))+counta(iferror(filter('Current Week'!B:B,'Current Week'!B:B=A25,'Current Week'!K:K="""",not(is"&"error(find(""FINAL"",'Current Week'!G:G))),'Current Week'!U:U=TRUE,'Current Week'!H:H="""")))"),0.0) -> 0 | L25: =IFERROR(__xludf.DUMMYFUNCTION("counta(iferror(filter('Current Week'!B:B,'Current Week'!B:B=A25,'Current Week'!K:K<0,not(iserror(find(""FINAL"",'Current Week'!G:G))),'Current Week'!U:U<>TRUE)))"),0.0) -> 0 | M25: =IFERROR(__xludf.DUMMYFUNCTION("H25+counta(iferror(filter('Current Week'!B:B,'Current Week'!B:B=A25,'Current Week'!K:K<0,iserror(find(""FINAL"",'Current Week'!G:G)))))+counta(iferror(filter('Current Week'!B:B,'Current Week'!B:B=A25,'Current Week'!F:F<>"""",'Current Week'!J:J="""",'Curre"&"nt Week'!H:H="""",iserror(find(""FINAL"",'Current Week'!G:G)))))"),2.0) -> 2
A26: Brad | B26: =sumif('Current Week'!$B:$B,$A26,'Current Week'!D:D) -> 62 | C26: =sumif('Current Week'!$B:$B,$A26,'Current Week'!E:E) -> 58 | D26: =sumifs('Current Week'!D:D,'Current Week'!$B:$B,$A26,'Current Week'!T:T,"Power 5") -> 29 | E26: =sumifs('Current Week'!D:D,'Current Week'!$B:$B,$A26,'Current Week'!T:T,"Group of 5") -> 33 | F26: =10-countifs('Current Week'!B:B,A26,'Current Week'!G:G,"") -> 1 | G26: =IFERROR(__xludf.DUMMYFUNCTION("COUNTA(iferror(filter('Current Week'!B:B,'Current Week'!B:B=A26,left('Current Week'!G:G,5)=""FINAL"")))"),0.0) -> 0 | H26: =countifs('Current Week'!B:B,A26,'Current Week'!U:U,"=TRUE") -> 0 | I26: =F26-G26 -> 1 | J26: =IFERROR(__xludf.DUMMYFUNCTION("countifs('Current Week'!B:B,A26,'Current Week'!K:K,""<0"")+counta(iferror(filter('Current Week'!B:B,'Current Week'!B:B=A26,'Current Week'!F:F<>"""",'Current Week'!K:K="""",'Current Week'!H:H="""")))"),0.0) -> 0 | K26: =IFERROR(__xludf.DUMMYFUNCTION("counta(iferror(filter('Current Week'!B:B,'Current Week'!B:B=A26,'Current Week'!K:K>0,not(iserror(find(""FINAL"",'Current Week'!G:G))),'Current Week'!U:U=TRUE)))+counta(iferror(filter('Current Week'!B:B,'Current Week'!B:B=A26,'Current Week'!K:K="""",not(is"&"error(find(""FINAL"",'Current Week'!G:G))),'Current Week'!U:U=TRUE,'Current Week'!H:H="""")))"),0.0) -> 0 | L26: =IFERROR(__xludf.DUMMYFUNCTION("counta(iferror(filter('Current Week'!B:B,'Current Week'!B:B=A26,'Current Week'!K:K<0,not(iserror(find(""FINAL"",'Current Week'!G:G))),'Current Week'!U:U<>TRUE)))"),0.0) -> 0 | M26: =IFERROR(__xludf.DUMMYFUNCTION("H26+counta(iferror(filter('Current Week'!B:B,'Current Week'!B:B=A26,'Current Week'!K:K<0,iserror(find(""FINAL"",'Current Week'!G:G)))))+counta(iferror(filter('Current Week'!B:B,'Current Week'!B:B=A26,'Current Week'!F:F<>"""",'Current Week'!J:J="""",'Curre"&"nt Week'!H:H="""",iserror(find(""FINAL"",'Current Week'!G:G)))))"),0.0) -> 0
A27: Jeannine | B27: =sumif('Current Week'!$B:$B,$A27,'Current Week'!D:D) -> 57 | C27: =sumif('Current Week'!$B:$B,$A27,'Current Week'!E:E) -> 63 | D27: =sumifs('Current Week'!D:D,'Current Week'!$B:$B,$A27,'Current Week'!T:T,"Power 5") -> 31 | E27: =sumifs('Current Week'!D:D,'Current Week'!$B:$B,$A27,'Current Week'!T:T,"Group of 5") -> 26 | F27: =10-countifs('Current Week'!B:B,A27,'Current Week'!G:G,"") -> 0 | G27: =IFERROR(__xludf.DUMMYFUNCTION("COUNTA(iferror(filter('Current Week'!B:B,'Current Week'!B:B=A27,left('Current Week'!G:G,5)=""FINAL"")))"),0.0) -> 0 | H27: =countifs('Current Week'!B:B,A27,'Current Week'!U:U,"=TRUE") -> 0 | I27: =F27-G27 -> 0 | J27: =IFERROR(__xludf.DUMMYFUNCTION("countifs('Current Week'!B:B,A27,'Current Week'!K:K,""<0"")+counta(iferror(filter('Current Week'!B:B,'Current Week'!B:B=A27,'Current Week'!F:F<>"""",'Current Week'!K:K="""",'Current Week'!H:H="""")))"),0.0) -> 0 | K27: =IFERROR(__xludf.DUMMYFUNCTION("counta(iferror(filter('Current Week'!B:B,'Current Week'!B:B=A27,'Current Week'!K:K>0,not(iserror(find(""FINAL"",'Current Week'!G:G))),'Current Week'!U:U=TRUE)))+counta(iferror(filter('Current Week'!B:B,'Current Week'!B:B=A27,'Current Week'!K:K="""",not(is"&"error(find(""FINAL"",'Current Week'!G:G))),'Current Week'!U:U=TRUE,'Current Week'!H:H="""")))"),0.0) -> 0 | L27: =IFERROR(__xludf.DUMMYFUNCTION("counta(iferror(filter('Current Week'!B:B,'Current Week'!B:B=A27,'Current Week'!K:K<0,not(iserror(find(""FINAL"",'Current Week'!G:G))),'Current Week'!U:U<>TRUE)))"),0.0) -> 0 | M27: =IFERROR(__xludf.DUMMYFUNCTION("H27+counta(iferror(filter('Current Week'!B:B,'Current Week'!B:B=A27,'Current Week'!K:K<0,iserror(find(""FINAL"",'Current Week'!G:G)))))+counta(iferror(filter('Current Week'!B:B,'Current Week'!B:B=A27,'Current Week'!F:F<>"""",'Current Week'!J:J="""",'Curre"&"nt Week'!H:H="""",iserror(find(""FINAL"",'Current Week'!G:G)))))"),0.0) -> 0
A28: Gary | B28: =sumif('Current Week'!$B:$B,$A28,'Current Week'!D:D) -> 74 | C28: =sumif('Current Week'!$B:$B,$A28,'Current Week'!E:E) -> 46 | D28: =sumifs('Current Week'!D:D,'Current Week'!$B:$B,$A28,'Current Week'!T:T,"Power 5") -> 42 | E28: =sumifs('Current Week'!D:D,'Current Week'!$B:$B,$A28,'Current Week'!T:T,"Group of 5") -> 32 | F28: =10-countifs('Current Week'!B:B,A28,'Current Week'!G:G,"") -> 2 | G28: =IFERROR(__xludf.DUMMYFUNCTION("COUNTA(iferror(filter('Current Week'!B:B,'Current Week'!B:B=A28,left('Current Week'!G:G,5)=""FINAL"")))"),0.0) -> 0 | H28: =countifs('Current Week'!B:B,A28,'Current Week'!U:U,"=TRUE") -> 0 | I28: =F28-G28 -> 2 | J28: =IFERROR(__xludf.DUMMYFUNCTION("countifs('Current Week'!B:B,A28,'Current Week'!K:K,""<0"")+counta(iferror(filter('Current Week'!B:B,'Current Week'!B:B=A28,'Current Week'!F:F<>"""",'Current Week'!K:K="""",'Current Week'!H:H="""")))"),2.0) -> 2 | K28: =IFERROR(__xludf.DUMMYFUNCTION("counta(iferror(filter('Current Week'!B:B,'Current Week'!B:B=A28,'Current Week'!K:K>0,not(iserror(find(""FINAL"",'Current Week'!G:G))),'Current Week'!U:U=TRUE)))+counta(iferror(filter('Current Week'!B:B,'Current Week'!B:B=A28,'Current Week'!K:K="""",not(is"&"error(find(""FINAL"",'Current Week'!G:G))),'Current Week'!U:U=TRUE,'Current Week'!H:H="""")))"),0.0) -> 0 | L28: =IFERROR(__xludf.DUMMYFUNCTION("counta(iferror(filter('Current Week'!B:B,'Current Week'!B:B=A28,'Current Week'!K:K<0,not(iserror(find(""FINAL"",'Current Week'!G:G))),'Current Week'!U:U<>TRUE)))"),0.0) -> 0 | M28: =IFERROR(__xludf.DUMMYFUNCTION("H28+counta(iferror(filter('Current Week'!B:B,'Current Week'!B:B=A28,'Current Week'!K:K<0,iserror(find(""FINAL"",'Current Week'!G:G)))))+counta(iferror(filter('Current Week'!B:B,'Current Week'!B:B=A28,'Current Week'!F:F<>"""",'Current Week'!J:J="""",'Curre"&"nt Week'!H:H="""",iserror(find(""FINAL"",'Current Week'!G:G)))))"),2.0) -> 2
A29: Justin | B29: =sumif('Current Week'!$B:$B,$A29,'Current Week'!D:D) -> 64 | C29: =sumif('Current Week'!$B:$B,$A29,'Current Week'!E:E) -> 56 | D29: =sumifs('Current Week'!D:D,'Current Week'!$B:$B,$A29,'Current Week'!T:T,"Power 5") -> 40 | E29: =sumifs('Current Week'!D:D,'Current Week'!$B:$B,$A29,'Current Week'!T:T,"Group of 5") -> 24 | F29: =10-countifs('Current Week'!B:B,A29,'Current Week'!G:G,"") -> 2 | G29: =IFERROR(__xludf.DUMMYFUNCTION("COUNTA(iferror(filter('Current Week'!B:B,'Current Week'!B:B=A29,left('Current Week'!G:G,5)=""FINAL"")))"),0.0) -> 0 | H29: =countifs('Current Week'!B:B,A29,'Current Week'!U:U,"=TRUE") -> 0 | I29: =F29-G29 -> 2 | J29: =IFERROR(__xludf.DUMMYFUNCTION("countifs('Current Week'!B:B,A29,'Current Week'!K:K,""<0"")+counta(iferror(filter('Current Week'!B:B,'Current Week'!B:B=A29,'Current Week'!F:F<>"""",'Current Week'!K:K="""",'Current Week'!H:H="""")))"),1.0) -> 1 | K29: =IFERROR(__xludf.DUMMYFUNCTION("counta(iferror(filter('Current Week'!B:B,'Current Week'!B:B=A29,'Current Week'!K:K>0,not(iserror(find(""FINAL"",'Current Week'!G:G))),'Current Week'!U:U=TRUE)))+counta(iferror(filter('Current Week'!B:B,'Current Week'!B:B=A29,'Current Week'!K:K="""",not(is"&"error(find(""FINAL"",'Current Week'!G:G))),'Current Week'!U:U=TRUE,'Current Week'!H:H="""")))"),0.0) -> 0 | L29: =IFERROR(__xludf.DUMMYFUNCTION("counta(iferror(filter('Current Week'!B:B,'Current Week'!B:B=A29,'Current Week'!K:K<0,not(iserror(find(""FINAL"",'Current Week'!G:G))),'Current Week'!U:U<>TRUE)))"),0.0) -> 0 | M29: =IFERROR(__xludf.DUMMYFUNCTION("H29+counta(iferror(filter('Current Week'!B:B,'Current Week'!B:B=A29,'Current Week'!K:K<0,iserror(find(""FINAL"",'Current Week'!G:G)))))+counta(iferror(filter('Current Week'!B:B,'Current Week'!B:B=A29,'Current Week'!F:F<>"""",'Current Week'!J:J="""",'Curre"&"nt Week'!H:H="""",iserror(find(""FINAL"",'Current Week'!G:G)))))"),1.0) -> 1

Sheet Current Week
A1: 100 | B1: Player | C1: Team | D1: W | E1: L | F1: matchup | G1: Status (Time ET) | H1: opponent | I1: network | J1: Opening Spread | K1: Current Spread | L1: Current Total | M1: Money Lines | N1: PF | O1: PA | P1: sort2 | Q1: dupe | R1: activeSort | S1: Conf | T1: Conf type | U1: Win
A2: 101 | B2: Nick G. | C2: Oregon | D2: 11 | E2: 1 | F2: (5) Oregon at (3) Washington | G2: 45261.833 | H2: Vu | J2: -7.5 | K2: -9.5 | L2: -345 | M2: o65.5 | N2: 543 | O2: 191 | P2: 1 | Q2: FALSE | R2: 100 | S2: {=vlookup(C2,{DraftTracker!F:F,DraftTracker!E:E},2,0)} -> Pac12 | T2: =VLOOKUP(S2,P5G5!A:B,2,0) -> Power 5 | U2: =IFERROR(__xludf.DUMMYFUNCTION("iferror(if(not(iserror(find(""FINAL"",G2))),max(arrayformula(value(REGEXEXTRACT(F2,""^""&C2&"" ([\d]+)|[^a-zA-Z] ""&C2&"" ([\d]+)""))))=max(value(REGEXEXTRACT(F2,"" ([\d]+)"")),value(REGEXEXTRACT(F2,""([\d]+)$""))),""""))"),"")
A3: 101 | B3: Nick G. | C3: Georgia | D3: 12 | E3: 0 | F3: (1) Georgia at (8) Alabama | G3: 45262.667 | H3: DavEmily | J3: -4.5 | K3: -6.5 | L3: -220 | M3: o54.5 | N3: 475 | O3: 189 | P3: 1 | Q3: TRUE | R3: 100 | S3: {=vlookup(C3,{DraftTracker!F:F,DraftTracker!E:E},2,0)} -> SEC | T3: =VLOOKUP(S3,P5G5!A:B,2,0) -> Power 5 | U3: =IFERROR(__xludf.DUMMYFUNCTION("iferror(if(not(iserror(find(""FINAL"",G3))),max(arrayformula(value(REGEXEXTRACT(F3,""^""&C3&"" ([\d]+)|[^a-zA-Z] ""&C3&"" ([\d]+)""))))=max(value(REGEXEXTRACT(F3,"" ([\d]+)"")),value(REGEXEXTRACT(F3,""([\d]+)$""))),""""))"),"")
A4: 101 | B4: Nick G. | C4: Appalachian State | D4: 8 | E4: 4 | F4: Appalachian State at Troy | G4: 45262.667 | H4: Vu | J4: 6 | K4: 5.5 | L4: 198 | M4: o52.5 | N4: 429 | O4: 320 | P4: 1 | Q4: FALSE | R4: 100 | S4: {=vlookup(C4,{DraftTracker!F:F,DraftTracker!E:E},2,0)} -> Sun Belt | T4: =VLOOKUP(S4,P5G5!A:B,2,0) -> Group of 5 | U4: =IFERROR(__xludf.DUMMYFUNCTION("iferror(if(not(iserror(find(""FINAL"",G4))),max(arrayformula(value(REGEXEXTRACT(F4,""^""&C4&"" ([\d]+)|[^a-zA-Z] ""&C4&"" ([\d]+)""))))=max(value(REGEXEXTRACT(F4,"" ([\d]+)"")),value(REGEXEXTRACT(F4,""([\d]+)$""))),""""))"),"")
A5: 101 | B5: Nick G. | C5: Kansas State | D5: 8 | E5: 4 | N5: 454 | O5: 254 | P5: 3 | Q5: TRUE | R5: 100 | S5: {=vlookup(C5,{DraftTracker!F:F,DraftTracker!E:E},2,0)} -> Big 12 | T5: =VLOOKUP(S5,P5G5!A:B,2,0) -> Power 5 | U5: =IFERROR(__xludf.DUMMYFUNCTION("iferror(if(not(iserror(find(""FINAL"",G5))),max(arrayformula(value(REGEXEXTRACT(F5,""^""&C5&"" ([\d]+)|[^a-zA-Z] ""&C5&"" ([\d]+)""))))=max(value(REGEXEXTRACT(F5,"" ([\d]+)"")),value(REGEXEXTRACT(F5,""([\d]+)$""))),""""))"),"")
A6: 101 | B6: Nick G. | C6: Kent State | D6: 1 | E6: 11 | N6: 176 | O6: 415 | P6: 3 | Q6: TRUE | R6: 100 | S6: {=vlookup(C6,{DraftTracker!F:F,DraftTracker!E:E},2,0)} -> MAC | T6: =VLOOKUP(S6,P5G5!A:B,2,0) -> Group of 5 | U6: =IFERROR(__xludf.DUMMYFUNCTION("iferror(if(not(iserror(find(""FINAL"",G6))),max(arrayformula(value(REGEXEXTRACT(F6,""^""&C6&"" ([\d]+)|[^a-zA-Z] ""&C6&"" ([\d]+)""))))=max(value(REGEXEXTRACT(F6,"" ([\d]+)"")),value(REGEXEXTRACT(F6,""([\d]+)$""))),""""))"),"")
A7: 101 | B7: Nick G. | C7: Sam Houston | D7: 3 | E7: 9 | N7: 240 | O7: 314 | P7: 3 | Q7: TRUE | R7: 100 | S7: {=vlookup(C7,{DraftTracker!F:F,DraftTracker!E:E},2,0)} -> CUSA | T7: =VLOOKUP(S7,P5G5!A:B,2,0) -> Group of 5 | U7: =IFERROR(__xludf.DUMMYFUNCTION("iferror(if(not(iserror(find(""FINAL"",G7))),max(arrayformula(value(REGEXEXTRACT(F7,""^""&C7&"" ([\d]+)|[^a-zA-Z] ""&C7&"" ([\d]+)""))))=max(value(REGEXEXTRACT(F7,"" ([\d]+)"")),value(REGEXEXTRACT(F7,""([\d]+)$""))),""""))"),"")
A8: 101 | B8: Nick G. | C8: Miami | D8: 7 | E8: 5 | N8: 385 | O8: 265 | P8: 3 | Q8: TRUE | R8: 100 | S8: {=vlookup(C8,{DraftTracker!F:F,DraftTracker!E:E},2,0)} -> ACC | T8: =VLOOKUP(S8,P5G5!A:B,2,0) -> Power 5 | U8: =IFERROR(__xludf.DUMMYFUNCTION("iferror(if(not(iserror(find(""FINAL"",G8))),max(arrayformula(value(REGEXEXTRACT(F8,""^""&C8&"" ([\d]+)|[^a-zA-Z] ""&C8&"" ([\d]+)""))))=max(value(REGEXEXTRACT(F8,"" ([\d]+)"")),value(REGEXEXTRACT(F8,""([\d]+)$""))),""""))"),"")
A9: 101 | B9: Nick G. | C9: Nebraska | D9: 5 | E9: 7 | N9: 216 | O9: 219 | P9: 3 | Q9: TRUE | R9: 100 | S9: {=vlookup(C9,{DraftTracker!F:F,DraftTracker!E:E},2,0)} -> Big Ten | T9: =VLOOKUP(S9,P5G5!A:B,2,0) -> Power 5 | U9: =IFERROR(__xludf.DUMMYFUNCTION("iferror(if(not(iserror(find(""FINAL"",G9))),max(arrayformula(value(REGEXEXTRACT(F9,""^""&C9&"" ([\d]+)|[^a-zA-Z] ""&C9&"" ([\d]+)""))))=max(value(REGEXEXTRACT(F9,"" ([\d]+)"")),value(REGEXEXTRACT(F9,""([\d]+)$""))),""""))"),"")
A10: 101 | B10: Nick G. | C10: Temple | D10: 3 | E10: 9 | N10: 253 | O10: 428 | P10: 3 | Q10: TRUE | R10: 100 | S10: {=vlookup(C10,{DraftTracker!F:F,DraftTracker!E:E},2,0)} -> AAC | T10: =VLOOKUP(S10,P5G5!A:B,2,0) -> Group of 5 | U10: =IFERROR(__xludf.DUMMYFUNCTION("iferror(if(not(iserror(find(""FINAL"",G10))),max(arrayformula(value(REGEXEXTRACT(F10,""^""&C10&"" ([\d]+)|[^a-zA-Z] ""&C10&"" ([\d]+)""))))=max(value(REGEXEXTRACT(F10,"" ([\d]+)"")),value(REGEXEXTRACT(F10,""([\d]+)$""))),""""))"),"")
A11: 101 | B11: Nick G. | C11: New Mexico | D11: 4 | E11: 8 | N11: 327 | O11: 421 | P11: 3 | Q11: TRUE | R11: 100 | S11: {=vlookup(C11,{DraftTracker!F:F,DraftTracker!E:E},2,0)} -> MWC | T11: =VLOOKUP(S11,P5G5!A:B,2,0) -> Group of 5 | U11: =IFERROR(__xludf.DUMMYFUNCTION("iferror(if(not(iserror(find(""FINAL"",G11))),max(arrayformula(value(REGEXEXTRACT(F11,""^""&C11&"" ([\d]+)|[^a-zA-Z] ""&C11&"" ([\d]+)""))))=max(value(REGEXEXTRACT(F11,"" ([\d]+)"")),value(REGEXEXTRACT(F11,""([\d]+)$""))),""""))"),"")
A12: 102 | S12: {=vlookup(C12,{DraftTracker!F:F,DraftTracker!E:E},2,0)} -> #N/A | T12: =VLOOKUP(S12,P5G5!A:B,2,0) -> #N/A | U12: =IFERROR(__xludf.DUMMYFUNCTION("iferror(if(not(iserror(find(""FINAL"",G12))),max(arrayformula(value(REGEXEXTRACT(F12,""^""&C12&"" ([\d]+)|[^a-zA-Z] ""&C12&"" ([\d]+)""))))=max(value(REGEXEXTRACT(F12,"" ([\d]+)"")),value(REGEXEXTRACT(F12,""([\d]+)$""))),""""))"),"")
A13: 103 | B13: Janice/Mike | C13: Liberty | D13: 12 | E13: 0 | F13: New Mexico State at (22) Liberty | G13: 45261.792 | H13: Josh | I13: CBSSN | J13: -13.5 | K13: -10.5 | L13: 340 | M13: o56.5 | N13: 481 | O13: 260 | P13: 1 | Q13: TRUE | R13: 100 | S13: {=vlookup(C13,{DraftTracker!F:F,DraftTracker!E:E},2,0)} -> CUSA | T13: =VLOOKUP(S13,P5G5!A:B,2,0) -> Group of 5 | U13: =IFERROR(__xludf.DUMMYFUNCTION("iferror(if(not(iserror(find(""FINAL"",G13))),max(arrayformula(value(REGEXEXTRACT(F13,""^""&C13&"" ([\d]+)|[^a-zA-Z] ""&C13&"" ([\d]+)""))))=max(value(REGEXEXTRACT(F13,"" ([\d]+)"")),value(REGEXEXTRACT(F13,""([\d]+)$""))),""""))"),"")
A14: 103 | B14: Janice/Mike | C14: Colorado State | D14: 5 | E14: 7 | N14: 313 | O14: 355 | P14: 3 | Q14: TRUE | R14: 100 | S14: {=vlookup(C14,{DraftTracker!F:F,DraftTracker!E:E},2,0)} -> MWC | T14: =VLOOKUP(S14,P5G5!A:B,2,0) -> Group of 5 | U14: =IFERROR(__xludf.DUMMYFUNCTION("iferror(if(not(iserror(find(""FINAL"",G14))),max(arrayformula(value(REGEXEXTRACT(F14,""^""&C14&"" ([\d]+)|[^a-zA-Z] ""&C14&"" ([\d]+)""))))=max(value(REGEXEXTRACT(F14,"" ([\d]+)"")),value(REGEXEXTRACT(F14,""([\d]+)$""))),""""))"),"")
A15: 103 | B15: Janice/Mike | C15: UCLA | D15: 7 | E15: 5 | N15: 309 | O15: 217 | P15: 3 | Q15: TRUE | R15: 100 | S15: {=vlookup(C15,{DraftTracker!F:F,DraftTracker!E:E},2,0)} -> Pac12 | T15: =VLOOKUP(S15,P5G5!A:B,2,0) -> Power 5 | U15: =IFERROR(__xludf.DUMMYFUNCTION("iferror(if(not(iserror(find(""FINAL"",G15))),max(arrayformula(value(REGEXEXTRACT(F15,""^""&C15&"" ([\d]+)|[^a-zA-Z] ""&C15&"" ([\d]+)""))))=max(value(REGEXEXTRACT(F15,"" ([\d]+)"")),value(REGEXEXTRACT(F15,""([\d]+)$""))),""""))"),"")
A16: 103 | B16: Janice/Mike | C16: Marshall | D16: 6 | E16: 6 | N16: 279 | O16: 338 | P16: 3 | Q16: TRUE | R16: 100 | S16: {=vlookup(C16,{DraftTracker!F:F,DraftTracker!E:E},2,0)} -> Sun Belt | T16: =VLOOKUP(S16,P5G5!A:B,2,0) -> Group of 5 | U16: =IFERROR(__xludf.DUMMYFUNCTION("iferror(if(not(iserror(find(""FINAL"",G16))),max(arrayformula(value(REGEXEXTRACT(F16,""^""&C16&"" ([\d]+)|[^a-zA-Z] ""&C16&"" ([\d]+)""))))=max(value(REGEXEXTRACT(F16,"" ([\d]+)"")),value(REGEXEXTRACT(F16,""([\d]+)$""))),""""))"),"")
A17: 103 | B17: Janice/Mike | C17: Auburn | D17: 6 | E17: 6 | N17: 327 | O17: 263 | P17: 3 | Q17: TRUE | R17: 100 | S17: {=vlookup(C17,{DraftTracker!F:F,DraftTracker!E:E},2,0)} -> SEC | T17: =VLOOKUP(S17,P5G5!A:B,2,0) -> Power 5 | U17: =IFERROR(__xludf.DUMMYFUNCTION("iferror(if(not(iserror(find(""FINAL"",G17))),max(arrayformula(value(REGEXEXTRACT(F17,""^""&C17&"" ([\d]+)|[^a-zA-Z] ""&C17&"" ([\d]+)""))))=max(value(REGEXEXTRACT(F17,"" ([\d]+)"")),value(REGEXEXTRACT(F17,""([\d]+)$""))),""""))"),"")
A18: 103 | B18: Janice/Mike | C18: Virginia Tech | D18: 6 | E18: 6 | J18: -1.5 | K18: -1.5 | L18: -118 | M18: o53.5 | N18: 343 | O18: 291 | P18: 3 | Q18: TRUE | R18: 100 | S18: {=vlookup(C18,{DraftTracker!F:F,DraftTracker!E:E},2,0)} -> ACC | T18: =VLOOKUP(S18,P5G5!A:B,2,0) -> Power 5 | U18: =IFERROR(__xludf.DUMMYFUNCTION("iferror(if(not(iserror(find(""FINAL"",G18))),max(arrayformula(value(REGEXEXTRACT(F18,""^""&C18&"" ([\d]+)|[^a-zA-Z] ""&C18&"" ([\d]+)""))))=max(value(REGEXEXTRACT(F18,"" ([\d]+)"")),value(REGEXEXTRACT(F18,""([\d]+)$""))),""""))"),"")
A19: 103 | B19: Janice/Mike | C19: Minnesota | D19: 5 | E19: 7 | N19: 242 | O19: 323 | P19: 3 | Q19: TRUE | R19: 100 | S19: {=vlookup(C19,{DraftTracker!F:F,DraftTracker!E:E},2,0)} -> Big Ten | T19: =VLOOKUP(S19,P5G5!A:B,2,0) -> Power 5 | U19: =IFERROR(__xludf.DUMMYFUNCTION("iferror(if(not(iserror(find(""FINAL"",G19))),max(arrayformula(value(REGEXEXTRACT(F19,""^""&C19&"" ([\d]+)|[^a-zA-Z] ""&C19&"" ([\d]+)""))))=max(value(REGEXEXTRACT(F19,"" ([\d]+)"")),value(REGEXEXTRACT(F19,""([\d]+)$""))),""""))"),"")
A20: 103 | B20: Janice/Mike | C20: Northern Illinois | D20: 6 | E20: 6 | N20: 303 | O20: 254 | P20: 3 | Q20: TRUE | R20: 100 | S20: {=vlookup(C20,{DraftTracker!F:F,DraftTracker!E:E},2,0)} -> MAC | T20: =VLOOKUP(S20,P5G5!A:B,2,0) -> Group of 5 | U20: =IFERROR(__xludf.DUMMYFUNCTION("iferror(if(not(iserror(find(""FINAL"",G20))),max(arrayformula(value(REGEXEXTRACT(F20,""^""&C20&"" ([\d]+)|[^a-zA-Z] ""&C20&"" ([\d]+)""))))=max(value(REGEXEXTRACT(F20,"" ([\d]+)"")),value(REGEXEXTRACT(F20,""([\d]+)$""))),""""))"),"")
A21: 103 | B21: Janice/Mike | C21: Memphis | D21: 9 | E21: 3 | N21: 476 | O21: 348 | P21: 3 | Q21: TRUE | R21: 100 | S21: {=vlookup(C21,{DraftTracker!F:F,DraftTracker!E:E},2,0)} -> AAC | T21: =VLOOKUP(S21,P5G5!A:B,2,0) -> Group of 5 | U21: =IFERROR(__xludf.DUMMYFUNCTION("iferror(if(not(iserror(find(""FINAL"",G21))),max(arrayformula(value(REGEXEXTRACT(F21,""^""&C21&"" ([\d]+)|[^a-zA-Z] ""&C21&"" ([\d]+)""))))=max(value(REGEXEXTRACT(F21,"" ([\d]+)"")),value(REGEXEXTRACT(F21,""([\d]+)$""))),""""))"),"")
A22: 103 | B22: Janice/Mike | C22: BYU | D22: 5 | E22: 7 | N22: 277 | O22: 358 | P22: 3 | Q22: TRUE | R22: 100 | S22: {=vlookup(C22,{DraftTracker!F:F,DraftTracker!E:E},2,0)} -> Big 12 | T22: =VLOOKUP(S22,P5G5!A:B,2,0) -> Power 5 | U22: =IFERROR(__xludf.DUMMYFUNCTION("iferror(if(not(iserror(find(""FINAL"",G22))),max(arrayformula(value(REGEXEXTRACT(F22,""^""&C22&"" ([\d]+)|[^a-zA-Z] ""&C22&"" ([\d]+)""))))=max(value(REGEXEXTRACT(F22,"" ([\d]+)"")),value(REGEXEXTRACT(F22,""([\d]+)$""))),""""))"),"")
A23: 104 | S23: {=vlookup(C23,{DraftTracker!F:F,DraftTracker!E:E},2,0)} -> #N/A | T23: =VLOOKUP(S23,P5G5!A:B,2,0) -> #N/A | U23: =IFERROR(__xludf.DUMMYFUNCTION("iferror(if(not(iserror(find(""FINAL"",G23))),max(arrayformula(value(REGEXEXTRACT(F23,""^""&C23&"" ([\d]+)|[^a-zA-Z] ""&C23&"" ([\d]+)""))))=max(value(REGEXEXTRACT(F23,"" ([\d]+)"")),value(REGEXEXTRACT(F23,""([\d]+)$""))),""""))"),"")
A24: 105 | B24: Nick A. | C24: Toledo | D24: 11 | E24: 1 | F24: Miami-OH at Toledo | G24: 45262.5 | H24: Brad | I24: ESPN | J24: -9 | K24: -7.5 | L24: 255 | M24: o43.5 | N24: 423 | O24: 245 | P24: 1 | Q24: TRUE | R24: 100 | S24: {=vlookup(C24,{DraftTracker!F:F,DraftTracker!E:E},2,0)} -> MAC | T24: =VLOOKUP(S24,P5G5!A:B,2,0) -> Group of 5 | U24: =IFERROR(__xludf.DUMMYFUNCTION("iferror(if(not(iserror(find(""FINAL"",G24))),max(arrayformula(value(REGEXEXTRACT(F24,""^""&C24&"" ([\d]+)|[^a-zA-Z] ""&C24&"" ([\d]+)""))))=max(value(REGEXEXTRACT(F24,"" ([\d]+)"")),value(REGEXEXTRACT(F24,""([\d]+)$""))),""""))"),"")
A25: 105 | B25: Nick A. | C25: Army | D25: 6 | E25: 6 | N25: 229 | O25: 242 | P25: 3 | Q25: FALSE | R25: 100 | S25: {=vlookup(C25,{DraftTracker!F:F,DraftTracker!E:E},2,0)} -> CUSA | T25: =VLOOKUP(S25,P5G5!A:B,2,0) -> Group of 5 | U25: =IFERROR(__xludf.DUMMYFUNCTION("iferror(if(not(iserror(find(""FINAL"",G25))),max(arrayformula(value(REGEXEXTRACT(F25,""^""&C25&"" ([\d]+)|[^a-zA-Z] ""&C25&"" ([\d]+)""))))=max(value(REGEXEXTRACT(F25,"" ([\d]+)"")),value(REGEXEXTRACT(F25,""([\d]+)$""))),""""))"),"")
A26: 105 | B26: Nick A. | C26: Iowa State | D26: 7 | E26: 5 | N26: 315 | O26: 260 | P26: 3 | Q26: TRUE | R26: 100 | S26: {=vlookup(C26,{DraftTracker!F:F,DraftTracker!E:E},2,0)} -> Big 12 | T26: =VLOOKUP(S26,P5G5!A:B,2,0) -> Power 5 | U26: =IFERROR(__xludf.DUMMYFUNCTION("iferror(if(not(iserror(find(""FINAL"",G26))),max(arrayformula(value(REGEXEXTRACT(F26,""^""&C26&"" ([\d]+)|[^a-zA-Z] ""&C26&"" ([\d]+)""))))=max(value(REGEXEXTRACT(F26,"" ([\d]+)"")),value(REGEXEXTRACT(F26,""([\d]+)$""))),""""))"),"")
A27: 105 | B27: Nick A. | C27: Texas State | D27: 7 | E27: 5 | N27: 432 | O27: 406 | P27: 3 | Q27: TRUE | R27: 100 | S27: {=vlookup(C27,{DraftTracker!F:F,DraftTracker!E:E},2,0)} -> Sun Belt | T27: =VLOOKUP(S27,P5G5!A:B,2,0) -> Group of 5 | U27: =IFERROR(__xludf.DUMMYFUNCTION("iferror(if(not(iserror(find(""FINAL"",G27))),max(arrayformula(value(REGEXEXTRACT(F27,""^""&C27&"" ([\d]+)|[^a-zA-Z] ""&C27&"" ([\d]+)""))))=max(value(REGEXEXTRACT(F27,"" ([\d]+)"")),value(REGEXEXTRACT(F27,""([\d]+)$""))),""""))"),"")
A28: 105 | B28: Nick A. | C28: Florida | D28: 5 | E28: 7 | N28: 341 | O28: 331 | P28: 3 | Q28: TRUE | R28: 100 | S28: {=vlookup(C28,{DraftTracker!F:F,DraftTracker!E:E},2,0)} -> SEC | T28: =VLOOKUP(S28,P5G5!A:B,2,0) -> Power 5 | U28: =IFERROR(__xludf.DUMMYFUNCTION("iferror(if(not(iserror(find(""FINAL"",G28))),max(arrayformula(value(REGEXEXTRACT(F28,""^""&C28&"" ([\d]+)|[^a-zA-Z] ""&C28&"" ([\d]+)""))))=max(value(REGEXEXTRACT(F28,"" ([\d]+)"")),value(REGEXEXTRACT(F28,""([\d]+)$""))),""""))"),"")
A29: 105 | B29: Nick A. | C29: Notre Dame | D29: 9 | E29: 3 | N29: 469 | O29: 199 | P29: 3 | Q29: TRUE | R29: 100 | S29: {=vlookup(C29,{DraftTracker!F:F,DraftTracker!E:E},2,0)} -> Pac12 | T29: =VLOOKUP(S29,P5G5!A:B,2,0) -> Power 5 | U29: =IFERROR(__xludf.DUMMYFUNCTION("iferror(if(not(iserror(find(""FINAL"",G29))),max(arrayformula(value(REGEXEXTRACT(F29,""^""&C29&"" ([\d]+)|[^a-zA-Z] ""&C29&"" ([\d]+)""))))=max(value(REGEXEXTRACT(F29,"" ([\d]+)"")),value(REGEXEXTRACT(F29,""([\d]+)$""))),""""))"),"")
A30: 105 | B30: Nick A. | C30: San José State | D30: 7 | E30: 5 | N30: 400 | O30: 309 | P30: 3 | Q30: TRUE | R30: 100 | S30: {=vlookup(C30,{DraftTracker!F:F,DraftTracker!E:E},2,0)} -> MWC | T30: =VLOOKUP(S30,P5G5!A:B,2,0) -> Group of 5 | U30: =IFERROR(__xludf.DUMMYFUNCTION("iferror(if(not(iserror(find(""FINAL"",G30))),max(arrayformula(value(REGEXEXTRACT(F30,""^""&C30&"" ([\d]+)|[^a-zA-Z] ""&C30&"" ([\d]+)""))))=max(value(REGEXEXTRACT(F30,"" ([\d]+)"")),value(REGEXEXTRACT(F30,""([\d]+)$""))),""""))"),"")
A31: 105 | B31: Nick A. | C31: Syracuse | D31: 6 | E31: 6 | N31: 306 | O31: 285 | P31: 3 | Q31: TRUE | R31: 100 | S31: {=vlookup(C31,{DraftTracker!F:F,DraftTracker!E:E},2,0)} -> ACC | T31: =VLOOKUP(S31,P5G5!A:B,2,0) -> Power 5 | U31: =IFERROR(__xludf.DUMMYFUNCTION("iferror(if(not(iserror(find(""FINAL"",G31))),max(arrayformula(value(REGEXEXTRACT(F31,""^""&C31&"" ([\d]+)|[^a-zA-Z] ""&C31&"" ([\d]+)""))))=max(value(REGEXEXTRACT(F31,"" ([\d]+)"")),value(REGEXEXTRACT(F31,""([\d]+)$""))),""""))"),"")
A32: 105 | B32: Nick A. | C32: Florida Atlantic | D32: 4 | E32: 8 | N32: 285 | O32: 306 | P32: 3 | Q32: TRUE | R32: 100 | S32: {=vlookup(C32,{DraftTracker!F:F,DraftTracker!E:E},2,0)} -> AAC | T32: =VLOOKUP(S32,P5G5!A:B,2,0) -> Group of 5 | U32: =IFERROR(__xludf.DUMMYFUNCTION("iferror(if(not(iserror(find(""FINAL"",G32))),max(arrayformula(value(REGEXEXTRACT(F32,""^""&C32&"" ([\d]+)|[^a-zA-Z] ""&C32&"" ([\d]+)""))))=max(value(REGEXEXTRACT(F32,"" ([\d]+)"")),value(REGEXEXTRACT(F32,""([\d]+)$""))),""""))"),"")
A33: 105 | B33: Nick A. | C33: Penn State | D33: 10 | E33: 2 | N33: 446 | O33: 137 | P33: 3 | Q33: TRUE | R33: 100 | S33: {=vlookup(C33,{DraftTracker!F:F,DraftTracker!E:E},2,0)} -> Big Ten | T33: =VLOOKUP(S33,P5G5!A:B,2,0) -> Power 5 | U33: =IFERROR(__xludf.DUMMYFUNCTION("iferror(if(not(iserror(find(""FINAL"",G33))),max(arrayformula(value(REGEXEXTRACT(F33,""^""&C33&"" ([\d]+)|[^a-zA-Z] ""&C33&"" ([\d]+)""))))=max(value(REGEXEXTRACT(F33,"" ([\d]+)"")),value(REGEXEXTRACT(F33,""([\d]+)$""))),""""))"),"")
A34: 106 | S34: {=vlookup(C34,{DraftTracker!F:F,DraftTracker!E:E},2,0)} -> #N/A | T34: =VLOOKUP(S34,P5G5!A:B,2,0) -> #N/A | U34: =IFERROR(__xludf.DUMMYFUNCTION("iferror(if(not(iserror(find(""FINAL"",G34))),max(arrayformula(value(REGEXEXTRACT(F34,""^""&C34&"" ([\d]+)|[^a-zA-Z] ""&C34&"" ([\d]+)""))))=max(value(REGEXEXTRACT(F34,"" ([\d]+)"")),value(REGEXEXTRACT(F34,""([\d]+)$""))),""""))"),"")
A35: 107 | B35: DavEmily | C35: Alabama | D35: 11 | E35: 1 | F35: (1) Georgia at (8) Alabama | G35: 45262.667 | H35: Nick G. | J35: 4.5 | K35: 6.5 | L35: -220 | M35: o54.5 | N35: 429 | O35: 215 | P35: 1 | Q35: FALSE | R35: 100 | S35: {=vlookup(C35,{DraftTracker!F:F,DraftTracker!E:E},2,0)} -> SEC | T35: =VLOOKUP(S35,P5G5!A:B,2,0) -> Power 5 | U35: =IFERROR(__xludf.DUMMYFUNCTION("iferror(if(not(iserror(find(""FINAL"",G35))),max(arrayformula(value(REGEXEXTRACT(F35,""^""&C35&"" ([\d]+)|[^a-zA-Z] ""&C35&"" ([\d]+)""))))=max(value(REGEXEXTRACT(F35,"" ([\d]+)"")),value(REGEXEXTRACT(F35,""([\d]+)$""))),""""))"),"")
A36: 107 | B36: DavEmily | C36: SMU | D36: 10 | E36: 2 | F36: (24) SMU at (18) Tulane | G36: 45262.667 | H36: Vu | J36: 6 | K36: 3.5 | L36: 132 | M36: o47.5 | N36: 502 | O36: 212 | P36: 1 | Q36: FALSE | R36: 100 | S36: {=vlookup(C36,{DraftTracker!F:F,DraftTracker!E:E},2,0)} -> AAC | T36: =VLOOKUP(S36,P5G5!A:B,2,0) -> Group of 5 | U36: =IFERROR(__xludf.DUMMYFUNCTION("iferror(if(not(iserror(find(""FINAL"",G36))),max(arrayformula(value(REGEXEXTRACT(F36,""^""&C36&"" ([\d]+)|[^a-zA-Z] ""&C36&"" ([\d]+)""))))=max(value(REGEXEXTRACT(F36,"" ([\d]+)"")),value(REGEXEXTRACT(F36,""([\d]+)$""))),""""))"),"")
A37: 107 | B37: DavEmily | C37: Louisville | D37: 10 | E37: 2 | F37: (14) Louisville at (4) Florida State | G37: 45262.833 | H37: Gary | I37: ABC | J37: 6.5 | K37: 2.5 | L37: 118 | M37: o47.5 | N37: 396 | O37: 240 | P37: 1 | Q37: TRUE | R37: 100 | S37: {=vlookup(C37,{DraftTracker!F:F,DraftTracker!E:E},2,0)} -> ACC | T37: =VLOOKUP(S37,P5G5!A:B,2,0) -> Power 5 | U37: =IFERROR(__xludf.DUMMYFUNCTION("iferror(if(not(iserror(find(""FINAL"",G37))),max(arrayformula(value(REGEXEXTRACT(F37,""^""&C37&"" ([\d]+)|[^a-zA-Z] ""&C37&"" ([\d]+)""))))=max(value(REGEXEXTRACT(F37,"" ([\d]+)"")),value(REGEXEXTRACT(F37,""([\d]+)$""))),""""))"),"")
A38: 107 | B38: DavEmily | C38: Hawaii | D38: 5 | E38: 8 | N38: 278 | O38: 419 | P38: 3 | Q38: TRUE | R38: 100 | S38: {=vlookup(C38,{DraftTracker!F:F,DraftTracker!E:E},2,0)} -> MWC | T38: =VLOOKUP(S38,P5G5!A:B,2,0) -> Group of 5 | U38: =IFERROR(__xludf.DUMMYFUNCTION("iferror(if(not(iserror(find(""FINAL"",G38))),max(arrayformula(value(REGEXEXTRACT(F38,""^""&C38&"" ([\d]+)|[^a-zA-Z] ""&C38&"" ([\d]+)""))))=max(value(REGEXEXTRACT(F38,"" ([\d]+)"")),value(REGEXEXTRACT(F38,""([\d]+)$""))),""""))"),"")
A39: 107 | B39: DavEmily | C39: Arizona State | D39: 3 | E39: 9 | N39: 213 | O39: 382 | P39: 3 | Q39: TRUE | R39: 100 | S39: {=vlookup(C39,{DraftTracker!F:F,DraftTracker!E:E},2,0)} -> Pac12 | T39: =VLOOKUP(S39,P5G5!A:B,2,0) -> Power 5 | U39: =IFERROR(__xludf.DUMMYFUNCTION("iferror(if(not(iserror(find(""FINAL"",G39))),max(arrayformula(value(REGEXEXTRACT(F39,""^""&C39&"" ([\d]+)|[^a-zA-Z] ""&C39&"" ([\d]+)""))))=max(value(REGEXEXTRACT(F39,"" ([\d]+)"")),value(REGEXEXTRACT(F39,""([\d]+)$""))),""""))"),"")
A40: 107 | B40: DavEmily | C40: UL Lafayette | D40: 6 | E40: 6 | N40: 387 | O40: 338 | P40: 3 | Q40: TRUE | R40: 100 | S40: {=vlookup(C40,{DraftTracker!F:F,DraftTracker!E:E},2,0)} -> Sun Belt | T40: =VLOOKUP(S40,P5G5!A:B,2,0) -> Group of 5 | U40: =IFERROR(__xludf.DUMMYFUNCTION("iferror(if(not(iserror(find(""FINAL"",G40))),max(arrayformula(value(REGEXEXTRACT(F40,""^""&C40&"" ([\d]+)|[^a-zA-Z] ""&C40&"" ([\d]+)""))))=max(value(REGEXEXTRACT(F40,"" ([\d]+)"")),value(REGEXEXTRACT(F40,""([\d]+)$""))),""""))"),"")
...

Sheet Active Games
A1: Game | B1: Status | C1: Player Matchup | D1: Network | E1: Spread Comp | F1: Spread | G1: Total | H1: sort2 | I1: sort1 | J1: Comp | K1: other | L1: dif | M1: line
A2: =IFERROR(__xludf.DUMMYFUNCTION("iferror(sort({FILTER('Current Week'!F:G,'Current Week'!Q:Q=FALSE,'Current Week'!F:F<>"""",'Current Week'!R:R<100),ARRAYFORMULA(if(FILTER('Current Week'!H:H,'Current Week'!Q:Q=FALSE,'Current Week'!F:F<>"""",'Current Week'!R:R<100)="""","""",FILTER('Current"&" Week'!H:H,'Current Week'!Q:Q=FALSE,'Current Week'!F:F<>"""",'Current Week'!R:R<100)&"" vs "")&FILTER('Current Week'!B:B,'Current Week'!Q:Q=FALSE,'Current Week'!F:F<>"""",'Current Week'!R:R<100)),FILTER('Current Week'!I:I,'Current Week'!Q:Q=FALSE,'Current"&" Week'!F:F<>"""",'Current Week'!R:R<100),FILTER('Current Week'!C:C,'Current Week'!Q:Q=FALSE,'Current Week'!F:F<>"""",'Current Week'!R:R<100),FILTER('Current Week'!J:K,'Current Week'!Q:Q=FALSE,'Current Week'!F:F<>"""",'Current Week'!R:R<100),FILTER('Curren"&"t Week'!R:R,'Current Week'!Q:Q=FALSE,'Current Week'!F:F<>"""",'Current Week'!R:R<100),FILTER('Current Week'!P:P,'Current Week'!Q:Q=FALSE,'Current Week'!F:F<>"""",'Current Week'!R:R<100)},9,1,8,1,2,1),""No Active Games"")"),"No Active Games") -> No Active Games | B2: =IFERROR(__xludf.DUMMYFUNCTION("""COMPUTED_VALUE"""),"No Active Games") -> No Active Games | C2: =IFERROR(__xludf.DUMMYFUNCTION("""COMPUTED_VALUE"""),"No Active Games") -> No Active Games | D2: =IFERROR(__xludf.DUMMYFUNCTION("""COMPUTED_VALUE"""),"No Active Games") -> No Active Games | E2: =IFERROR(__xludf.DUMMYFUNCTION("""COMPUTED_VALUE"""),"No Active Games") -> No Active Games | F2: =IFERROR(__xludf.DUMMYFUNCTION("""COMPUTED_VALUE"""),"No Active Games") -> No Active Games | G2: =IFERROR(__xludf.DUMMYFUNCTION("""COMPUTED_VALUE"""),"No Active Games") -> No Active Games | J2: =IFERROR(__xludf.DUMMYFUNCTION("arrayformula(if(A2:A586="""","""",REGEXEXTRACT(A2:A586,E2:E586&"" (\d*)"")))"),"#N/A") -> #N/A | K2: =IFERROR(__xludf.DUMMYFUNCTION("arrayformula(if(A2:A586="""","""",REGEXEXTRACT(mid(A2:A586,if(FIND(E2:E586,A2:A586)=1,len(E2:E586)+1,1),99),""\w+ (\d+)"")))"),"#N/A") -> #N/A | L2: {=if(A2:A586="","",J2:J586-K2:K586)} -> #N/A | M2: {=if(A2:A586="","",if(F2:F586="",-30,F2:F586))} -> No Active Games
J3: =IFERROR(__xludf.DUMMYFUNCTION("""COMPUTED_VALUE"""),"") | K3: =IFERROR(__xludf.DUMMYFUNCTION("""COMPUTED_VALUE"""),"")
J4: =IFERROR(__xludf.DUMMYFUNCTION("""COMPUTED_VALUE"""),"") | K4: =IFERROR(__xludf.DUMMYFUNCTION("""COMPUTED_VALUE"""),"")
J5: =IFERROR(__xludf.DUMMYFUNCTION("""COMPUTED_VALUE"""),"") | K5: =IFERROR(__xludf.DUMMYFUNCTION("""COMPUTED_VALUE"""),"")
J6: =IFERROR(__xludf.DUMMYFUNCTION("""COMPUTED_VALUE"""),"") | K6: =IFERROR(__xludf.DUMMYFUNCTION("""COMPUTED_VALUE"""),"")
J7: =IFERROR(__xludf.DUMMYFUNCTION("""COMPUTED_VALUE"""),"") | K7: =IFERROR(__xludf.DUMMYFUNCTION("""COMPUTED_VALUE"""),"")
J8: =IFERROR(__xludf.DUMMYFUNCTION("""COMPUTED_VALUE"""),"") | K8: =IFERROR(__xludf.DUMMYFUNCTION("""COMPUTED_VALUE"""),"")
J9: =IFERROR(__xludf.DUMMYFUNCTION("""COMPUTED_VALUE"""),"") | K9: =IFERROR(__xludf.DUMMYFUNCTION("""COMPUTED_VALUE"""),"")
J10: =IFERROR(__xludf.DUMMYFUNCTION("""COMPUTED_VALUE"""),"") | K10: =IFERROR(__xludf.DUMMYFUNCTION("""COMPUTED_VALUE"""),"")
J11: =IFERROR(__xludf.DUMMYFUNCTION("""COMPUTED_VALUE"""),"") | K11: =IFERROR(__xludf.DUMMYFUNCTION("""COMPUTED_VALUE"""),"")
J12: =IFERROR(__xludf.DUMMYFUNCTION("""COMPUTED_VALUE"""),"") | K12: =IFERROR(__xludf.DUMMYFUNCTION("""COMPUTED_VALUE"""),"")
J13: =IFERROR(__xludf.DUMMYFUNCTION("""COMPUTED_VALUE"""),"") | K13: =IFERROR(__xludf.DUMMYFUNCTION("""COMPUTED_VALUE"""),"")
J14: =IFERROR(__xludf.DUMMYFUNCTION("""COMPUTED_VALUE"""),"") | K14: =IFERROR(__xludf.DUMMYFUNCTION("""COMPUTED_VALUE"""),"")
... J586: =IFERROR(__xludf.DUMMYFUNCTION("""COMPUTED_VALUE"""),"") | K586: =IFERROR(__xludf.DUMMYFUNCTION("""COMPUTED_VALUE"""),"")

Sheet Tuesday
A1: order | B1: Network | C1: 0.25 | D1: 0.27083333 | E1: 0.29166667 | F1: 0.3125 | G1: 0.33333333 | H1: 0.35416667 | I1: 0.375 | J1: 0.39583333 | K1: 0.41666667 | L1: 0.4375 | M1: 0.45833333 | N1: 0.47916667 | O1: 0.5 | P1: 0.52083333 | Q1: 0.54166667 | R1: 0.5625 | S1: 0.58333333 | T1: 0.60416667 | U1: 0.625 | V1: 0.64583333 | W1: 0.66666667 | X1: 0.6875 | Y1: 0.70833333 | Z1: 0.72916667 | AA1: 0.75 | AB1: 0.77083333 | AC1: 0.79166667 | AD1: 0.8125 | AE1: 0.83333333 | AF1: 0.85416667 | AG1: 0.875 | AH1: 0.89583333 | AI1: 0.91666667 | AJ1: 0.9375 | AK1: 0.95833333 | AL1: 0.97916667 | AM1: 0 | AN1: 0.020833333 | AO1: 0.041666667 | AP1: 0.0625 | AQ1: 0.083333333 | AR1: 0.10416667
A2: 7 | B2: ESPN2 | AB2: EMU 24 Buffalo 8 1:12 IN 3RD
A3: 8 | B3: ESPNU | AA3: Bowling Green 34 Western Michigan 10 0:00 IN 4TH

Sheet Wednesday
A1: order | B1: Network | C1: 0.25 | D1: 0.27083333 | E1: 0.29166667 | F1: 0.3125 | G1: 0.33333333 | H1: 0.35416667 | I1: 0.375 | J1: 0.39583333 | K1: 0.41666667 | L1: 0.4375 | M1: 0.45833333 | N1: 0.47916667 | O1: 0.5 | P1: 0.52083333 | Q1: 0.54166667 | R1: 0.5625 | S1: 0.58333333 | T1: 0.60416667 | U1: 0.625 | V1: 0.64583333 | W1: 0.66666667 | X1: 0.6875 | Y1: 0.70833333 | Z1: 0.72916667 | AA1: 0.75 | AB1: 0.77083333 | AC1: 0.79166667 | AD1: 0.8125 | AE1: 0.83333333 | AF1: 0.85416667 | AG1: 0.875 | AH1: 0.89583333 | AI1: 0.91666667 | AJ1: 0.9375 | AK1: 0.95833333 | AL1: 0.97916667 | AM1: 0 | AN1: 0.020833333 | AO1: 0.041666667 | AP1: 0.0625 | AQ1: 0.083333333 | AR1: 0.10416667
A2: 8 | B2: ESPNU | AA2: Central Michigan 20 Ohio 34 FINAL

Sheet Thursday
A1: order | B1: Network | C1: 0.25 | D1: 0.27083333 | E1: 0.29166667 | F1: 0.3125 | G1: 0.33333333 | H1: 0.35416667 | I1: 0.375 | J1: 0.39583333 | K1: 0.41666667 | L1: 0.4375 | M1: 0.45833333 | N1: 0.47916667 | O1: 0.5 | P1: 0.52083333 | Q1: 0.54166667 | R1: 0.5625 | S1: 0.58333333 | T1: 0.60416667 | U1: 0.625 | V1: 0.64583333 | W1: 0.66666667 | X1: 0.6875 | Y1: 0.70833333 | Z1: 0.72916667 | AA1: 0.75 | AB1: 0.77083333 | AC1: 0.79166667 | AD1: 0.8125 | AE1: 0.83333333 | AF1: 0.85416667 | AG1: 0.875 | AH1: 0.89583333 | AI1: 0.91666667 | AJ1: 0.9375 | AK1: 0.95833333 | AL1: 0.97916667 | AM1: 0 | AN1: 0.020833333 | AO1: 0.041666667 | AP1: 0.0625 | AQ1: 0.083333333 | AR1: 0.10416667
A2: 3 | B2: ESPN | AB2: (12) Ole Miss 17 Mississippi State 7 FINAL

Sheet Friday
A1: order | B1: Network | C1: 0.25 | D1: 0.27083333 | E1: 0.29166667 | F1: 0.3125 | G1: 0.33333333 | H1: 0.35416667 | I1: 0.375 | J1: 0.39583333 | K1: 0.41666667 | L1: 0.4375 | M1: 0.45833333 | N1: 0.47916667 | O1: 0.5 | P1: 0.52083333 | Q1: 0.54166667 | R1: 0.5625 | S1: 0.58333333 | T1: 0.60416667 | U1: 0.625 | V1: 0.64583333 | W1: 0.66666667 | X1: 0.6875 | Y1: 0.70833333 | Z1: 0.72916667 | AA1: 0.75 | AB1: 0.77083333 | AC1: 0.79166667 | AD1: 0.8125 | AE1: 0.83333333 | AF1: 0.85416667 | AG1: 0.875 | AH1: 0.89583333 | AI1: 0.91666667 | AJ1: 0.9375 | AK1: 0.95833333 | AL1: 0.97916667 | AM1: 0 | AN1: 0.020833333 | AO1: 0.041666667 | AP1: 0.0625 | AQ1: 0.083333333 | AR1: 0.10416667
A2: 1 | B2: ABC | M2: Miami 45 Boston College 20 FINAL | T2: UTSA 16 (18) Tulane 29 FINAL | AB2: Texas Tech 7 (7) Texas 57 FINAL
A3: 1 | B3: CBS | M3: (19) Iowa 13 Nebraska 10 FINAL | U3: (10) Missouri 48 Arkansas 14 FINAL
A4: 1 | B4: NBC | AB4: (11) Penn State 42 Michigan State 0 FINAL
A5: 2 | B5: FOX | M5: TCU 45 (13) Oklahoma 69 FINAL | AD5: (15) Oregon State 7 (6) Oregon 31 FINAL
A6: 3 | B6: ESPN | M6: Memphis 45 Temple 21 FINAL
A7: 4 | B7: FS1 | U7: Air Force 19 Boise State 27 FINAL
A8: 8 | B8: ESPNU | M8: Toledo 32 Central Michigan 17 FINAL
A9: 9 | B9: CBSSN | M9: Ohio 25 Akron 14 FINAL | T9: Utah State 44 New Mexico 41 FINAL - 2ND OT

Sheet Saturday
A1: order | B1: Network | C1: 0.25 | D1: 0.27083333 | E1: 0.29166667 | F1: 0.3125 | G1: 0.33333333 | H1: 0.35416667 | I1: 0.375 | J1: 0.39583333 | K1: 0.41666667 | L1: 0.4375 | M1: 0.45833333 | N1: 0.47916667 | O1: 0.5 | P1: 0.52083333 | Q1: 0.54166667 | R1: 0.5625 | S1: 0.58333333 | T1: 0.60416667 | U1: 0.625 | V1: 0.64583333 | W1: 0.66666667 | X1: 0.6875 | Y1: 0.70833333 | Z1: 0.72916667 | AA1: 0.75 | AB1: 0.77083333 | AC1: 0.79166667 | AD1: 0.8125 | AE1: 0.83333333 | AF1: 0.85416667 | AG1: 0.875 | AH1: 0.89583333 | AI1: 0.91666667 | AJ1: 0.9375 | AK1: 0.95833333 | AL1: 0.97916667 | AM1: 0 | AN1: 0.020833333 | AO1: 0.041666667 | AP1: 0.0625 | AQ1: 0.083333333 | AR1: 0.10416667
A2: 1 | B2: ABC | M2: (19) Oklahoma State at (7) Texas | U2: (24) SMU at (18) Tulane | AC2: (14) Louisville at (4) Florida State
A3: 2 | B3: FOX | S3: Boise State at UNLV

Sheet ESPN rankings import
B3: =IFERROR(__xludf.DUMMYFUNCTION("IMPORTHTML(""https://www.espn.com/college-football/fpi"",""table"",A1)"),"") | C3: =IFERROR(__xludf.DUMMYFUNCTION("""COMPUTED_VALUE"""),"POWER INDEX") -> POWER INDEX | F3: =IFERROR(__xludf.DUMMYFUNCTION("""COMPUTED_VALUE"""),"PROJECTIONS") -> PROJECTIONS | N3: =IFERROR(__xludf.DUMMYFUNCTION("IMPORTHTML(""https://www.espn.com/college-football/fpi"",""table"",1)"),"")
B4: =IFERROR(__xludf.DUMMYFUNCTION("""COMPUTED_VALUE"""),"W-L") -> W-L | C4: =IFERROR(__xludf.DUMMYFUNCTION("""COMPUTED_VALUE"""),"FPI") -> FPI | D4: =IFERROR(__xludf.DUMMYFUNCTION("""COMPUTED_VALUE"""),"RK") -> RK | E4: =IFERROR(__xludf.DUMMYFUNCTION("""COMPUTED_VALUE"""),"TREND") -> TREND | F4: =IFERROR(__xludf.DUMMYFUNCTION("""COMPUTED_VALUE"""),"PROJ W-L") -> PROJ W-L | G4: =IFERROR(__xludf.DUMMYFUNCTION("""COMPUTED_VALUE"""),"WIN OUT%") -> WIN OUT% | H4: =IFERROR(__xludf.DUMMYFUNCTION("""COMPUTED_VALUE"""),"6WINS%") -> 6WINS% | I4: =IFERROR(__xludf.DUMMYFUNCTION("""COMPUTED_VALUE"""),"WIN DIV%") -> WIN DIV% | J4: =IFERROR(__xludf.DUMMYFUNCTION("""COMPUTED_VALUE"""),"WIN CONF%") -> WIN CONF% | K4: =IFERROR(__xludf.DUMMYFUNCTION("""COMPUTED_VALUE"""),"PLAYOFF%") -> PLAYOFF% | L4: =IFERROR(__xludf.DUMMYFUNCTION("""COMPUTED_VALUE"""),"MAKE NC%") -> MAKE NC% | M4: =IFERROR(__xludf.DUMMYFUNCTION("""COMPUTED_VALUE"""),"WIN NC%") -> WIN NC% | N4: =IFERROR(__xludf.DUMMYFUNCTION("""COMPUTED_VALUE"""),"Team") -> Team | O4: =IFERROR(__xludf.DUMMYFUNCTION("""COMPUTED_VALUE"""),"CONF") -> CONF | P4: Proj W
B5: =IFERROR(__xludf.DUMMYFUNCTION("""COMPUTED_VALUE"""),"0-0") -> 0-0 | C5: =IFERROR(__xludf.DUMMYFUNCTION("""COMPUTED_VALUE"""),28.7) -> 28.7 | D5: =IFERROR(__xludf.DUMMYFUNCTION("""COMPUTED_VALUE"""),1.0) -> 1 | E5: =IFERROR(__xludf.DUMMYFUNCTION("""COMPUTED_VALUE"""),"--") -> -- | F5: =IFERROR(__xludf.DUMMYFUNCTION("""COMPUTED_VALUE"""),"10.2-2.4") -> 10.2-2.4 | G5: =IFERROR(__xludf.DUMMYFUNCTION("""COMPUTED_VALUE"""),9.2) -> 9.2 | H5: =IFERROR(__xludf.DUMMYFUNCTION("""COMPUTED_VALUE"""),99.4) -> 99.4 | I5: =IFERROR(__xludf.DUMMYFUNCTION("""COMPUTED_VALUE"""),0.0) -> 0 | J5: =IFERROR(__xludf.DUMMYFUNCTION("""COMPUTED_VALUE"""),38.8) -> 38.8 | K5: =IFERROR(__xludf.DUMMYFUNCTION("""COMPUTED_VALUE"""),75.7) -> 75.7 | L5: =IFERROR(__xludf.DUMMYFUNCTION("""COMPUTED_VALUE"""),28.0) -> 28 | M5: =IFERROR(__xludf.DUMMYFUNCTION("""COMPUTED_VALUE"""),17.0) -> 17 | N5: =IFERROR(__xludf.DUMMYFUNCTION("""COMPUTED_VALUE"""),"Ohio State Buckeyes") -> Ohio State Buckeyes | O5: =IFERROR(__xludf.DUMMYFUNCTION("""COMPUTED_VALUE"""),"Big Ten") -> Big Ten | P5: =IFERROR(__xludf.DUMMYFUNCTION("if(F5="""","""",indeX(split(F5,""-""),1)-J5/100)"),9.812) -> 9.812
B6: =IFERROR(__xludf.DUMMYFUNCTION("""COMPUTED_VALUE"""),"0-0") -> 0-0 | C6: =IFERROR(__xludf.DUMMYFUNCTION("""COMPUTED_VALUE"""),26.9) -> 26.9 | D6: =IFERROR(__xludf.DUMMYFUNCTION("""COMPUTED_VALUE"""),2.0) -> 2 | E6: =IFERROR(__xludf.DUMMYFUNCTION("""COMPUTED_VALUE"""),"--") -> -- | F6: =IFERROR(__xludf.DUMMYFUNCTION("""COMPUTED_VALUE"""),"9.8-2.7") -> 9.8-2.7 | G6: =IFERROR(__xludf.DUMMYFUNCTION("""COMPUTED_VALUE"""),6.8) -> 6.8 | H6: =IFERROR(__xludf.DUMMYFUNCTION("""COMPUTED_VALUE"""),98.0) -> 98 | I6: =IFERROR(__xludf.DUMMYFUNCTION("""COMPUTED_VALUE"""),0.0) -> 0 | J6: =IFERROR(__xludf.DUMMYFUNCTION("""COMPUTED_VALUE"""),29.7) -> 29.7 | K6: =IFERROR(__xludf.DUMMYFUNCTION("""COMPUTED_VALUE"""),70.2) -> 70.2 | L6: =IFERROR(__xludf.DUMMYFUNCTION("""COMPUTED_VALUE"""),22.5) -> 22.5 | M6: =IFERROR(__xludf.DUMMYFUNCTION("""COMPUTED_VALUE"""),12.8) -> 12.8 | N6: =IFERROR(__xludf.DUMMYFUNCTION("""COMPUTED_VALUE"""),"Texas Longhorns") -> Texas Longhorns | O6: =IFERROR(__xludf.DUMMYFUNCTION("""COMPUTED_VALUE"""),"SEC") -> SEC | P6: =IFERROR(__xludf.DUMMYFUNCTION("if(F6="""","""",indeX(split(F6,""-""),1)-J6/100)"),9.503) -> 9.503
