Workbook

Sheet Standings
A1: Players | B1: Wins | D1: Requested features:
A2: {=sort(A13:B22,2,false)} -> Jacob | B2: 82 | D2: add an "advice" button that always returned "hey nico, don't pick stanford" - you could change it each week to insult someone new
A3: Josh R. | B3: 72 | D3: bug fix: remove repeated games from day filtered views
A4: Nick A. | B4: 70
A5: Vu | B5: 65
A6: Justin | B6: 65
A7: Nico | B7: 65
A8: Frank | B8: 63
A9: Brad | B9: 63
A10: Josh T. | B10: 63
A11: Gary | B11: 58
A12: 50582 | B12: 0
A13: Frank | B13: =sumif('Current Week'!A:A,A13,'Current Week'!C:C) -> 63
A14: Brad | B14: =sumif('Current Week'!A:A,A14,'Current Week'!C:C) -> 63
A15: Vu | B15: =sumif('Current Week'!A:A,A15,'Current Week'!C:C) -> 65
A16: Nick A. | B16: =sumif('Current Week'!A:A,A16,'Current Week'!C:C) -> 70
A17: Jacob | B17: =sumif('Current Week'!A:A,A17,'Current Week'!C:C) -> 82
A18: Justin | B18: =sumif('Current Week'!A:A,A18,'Current Week'!C:C) -> 65
A19: Gary | B19: =sumif('Current Week'!A:A,A19,'Current Week'!C:C) -> 58
A20: Josh R. | B20: =sumif('Current Week'!A:A,A20,'Current Week'!C:C) -> 72
A21: Nico | B21: =sumif('Current Week'!A:A,A21,'Current Week'!C:C) -> 65
A22: Josh T. | B22: =sumif('Current Week'!A:A,A22,'Current Week'!C:C) -> 63

Sheet Draft Evaluation Work
A1: Team | B1: Conf | C1: Player | D1: Draft Positions | E1: Current Wins | F1: Front of Run Weighted | G1: End of Run Weighted
A2: Clemson | B2: ACC | C2: Gary | D2: 1 | E2: =VLOOKUP(A2,'Current Week'!B:C,2,0) -> 11 | F2: =iferror(VLOOKUP(A2,DraftTracker!F:AU,3,0)+if((VLOOKUP(A2,DraftTracker!F:AU,4,0)-VLOOKUP(A2,DraftTracker!F:AU,3,0))>0,(VLOOKUP(A2,DraftTracker!F:AU,4,0)-VLOOKUP(A2,DraftTracker!F:AU,3,0)),0)*0.5,"") -> 1.5 | G2: =iferror(VLOOKUP(A2,DraftTracker!F:AW,5,0)+if((VLOOKUP(A2,DraftTracker!F:AW,6,0)-VLOOKUP(A2,DraftTracker!F:AW,5,0))>0,(VLOOKUP(A2,DraftTracker!F:AW,6,0)-VLOOKUP(A2,DraftTracker!F:AW,5,0)),0)*0.5,"") -> 0
A3: Houston | B3: AAC | C3: Josh R. | D3: 2 | E3: =VLOOKUP(A3,'Current Week'!B:C,2,0) -> 9 | F3: =iferror(VLOOKUP(A3,DraftTracker!F:AU,3,0)+if((VLOOKUP(A3,DraftTracker!F:AU,4,0)-VLOOKUP(A3,DraftTracker!F:AU,3,0))>0,(VLOOKUP(A3,DraftTracker!F:AU,4,0)-VLOOKUP(A3,DraftTracker!F:AU,3,0)),0)*0.5,"") -> 0 | G3: =iferror(VLOOKUP(A3,DraftTracker!F:AW,5,0)+if((VLOOKUP(A3,DraftTracker!F:AW,6,0)-VLOOKUP(A3,DraftTracker!F:AW,5,0))>0,(VLOOKUP(A3,DraftTracker!F:AW,6,0)-VLOOKUP(A3,DraftTracker!F:AW,5,0)),0)*0.5,"") -> 0
A4: Alabama | B4: SEC | C4: Jacob | D4: 3 | E4: =VLOOKUP(A4,'Current Week'!B:C,2,0) -> 12 | F4: =iferror(VLOOKUP(A4,DraftTracker!F:AU,3,0)+if((VLOOKUP(A4,DraftTracker!F:AU,4,0)-VLOOKUP(A4,DraftTracker!F:AU,3,0))>0,(VLOOKUP(A4,DraftTracker!F:AU,4,0)-VLOOKUP(A4,DraftTracker!F:AU,3,0)),0)*0.5,"") -> 2 | G4: =iferror(VLOOKUP(A4,DraftTracker!F:AW,5,0)+if((VLOOKUP(A4,DraftTracker!F:AW,6,0)-VLOOKUP(A4,DraftTracker!F:AW,5,0))>0,(VLOOKUP(A4,DraftTracker!F:AW,6,0)-VLOOKUP(A4,DraftTracker!F:AW,5,0)),0)*0.5,"") -> 0
A5: Oklahoma | B5: Big 12 | C5: Brad | D5: 4 | E5: =VLOOKUP(A5,'Current Week'!B:C,2,0) -> 10 | F5: =iferror(VLOOKUP(A5,DraftTracker!F:AU,3,0)+if((VLOOKUP(A5,DraftTracker!F:AU,4,0)-VLOOKUP(A5,DraftTracker!F:AU,3,0))>0,(VLOOKUP(A5,DraftTracker!F:AU,4,0)-VLOOKUP(A5,DraftTracker!F:AU,3,0)),0)*0.5,"") -> 4 | G5: =iferror(VLOOKUP(A5,DraftTracker!F:AW,5,0)+if((VLOOKUP(A5,DraftTracker!F:AW,6,0)-VLOOKUP(A5,DraftTracker!F:AW,5,0))>0,(VLOOKUP(A5,DraftTracker!F:AW,6,0)-VLOOKUP(A5,DraftTracker!F:AW,5,0)),0)*0.5,"") -> 0
A6: Boise State | B6: MWC | C6: Nico | D6: 5 | E6: =VLOOKUP(A6,'Current Week'!B:C,2,0) -> 10 | F6: =iferror(VLOOKUP(A6,DraftTracker!F:AU,3,0)+if((VLOOKUP(A6,DraftTracker!F:AU,4,0)-VLOOKUP(A6,DraftTracker!F:AU,3,0))>0,(VLOOKUP(A6,DraftTracker!F:AU,4,0)-VLOOKUP(A6,DraftTracker!F:AU,3,0)),0)*0.5,"") -> 1.5 | G6: =iferror(VLOOKUP(A6,DraftTracker!F:AW,5,0)+if((VLOOKUP(A6,DraftTracker!F:AW,6,0)-VLOOKUP(A6,DraftTracker!F:AW,5,0))>0,(VLOOKUP(A6,DraftTracker!F:AW,6,0)-VLOOKUP(A6,DraftTracker!F:AW,5,0)),0)*0.5,"") -> 0
A7: Florida State | B7: ACC | C7: Vu | D7: 6 | E7: =VLOOKUP(A7,'Current Week'!B:C,2,0) -> 9 | F7: =iferror(VLOOKUP(A7,DraftTracker!F:AU,3,0)+if((VLOOKUP(A7,DraftTracker!F:AU,4,0)-VLOOKUP(A7,DraftTracker!F:AU,3,0))>0,(VLOOKUP(A7,DraftTracker!F:AU,4,0)-VLOOKUP(A7,DraftTracker!F:AU,3,0)),0)*0.5,"") -> 1 | G7: =iferror(VLOOKUP(A7,DraftTracker!F:AW,5,0)+if((VLOOKUP(A7,DraftTracker!F:AW,6,0)-VLOOKUP(A7,DraftTracker!F:AW,5,0))>0,(VLOOKUP(A7,DraftTracker!F:AW,6,0)-VLOOKUP(A7,DraftTracker!F:AW,5,0)),0)*0.5,"") -> 0
A8: LSU | B8: SEC | C8: Josh T. | D8: 7 | E8: =VLOOKUP(A8,'Current Week'!B:C,2,0) -> 7 | F8: =iferror(VLOOKUP(A8,DraftTracker!F:AU,3,0)+if((VLOOKUP(A8,DraftTracker!F:AU,4,0)-VLOOKUP(A8,DraftTracker!F:AU,3,0))>0,(VLOOKUP(A8,DraftTracker!F:AU,4,0)-VLOOKUP(A8,DraftTracker!F:AU,3,0)),0)*0.5,"") -> 1 | G8: =iferror(VLOOKUP(A8,DraftTracker!F:AW,5,0)+if((VLOOKUP(A8,DraftTracker!F:AW,6,0)-VLOOKUP(A8,DraftTracker!F:AW,5,0))>0,(VLOOKUP(A8,DraftTracker!F:AW,6,0)-VLOOKUP(A8,DraftTracker!F:AW,5,0)),0)*0.5,"") -> 0
A9: Ohio State | B9: Big Ten | C9: Justin | D9: 8 | E9: =VLOOKUP(A9,'Current Week'!B:C,2,0) -> 11 | F9: =iferror(VLOOKUP(A9,DraftTracker!F:AU,3,0)+if((VLOOKUP(A9,DraftTracker!F:AU,4,0)-VLOOKUP(A9,DraftTracker!F:AU,3,0))>0,(VLOOKUP(A9,DraftTracker!F:AU,4,0)-VLOOKUP(A9,DraftTracker!F:AU,3,0)),0)*0.5,"") -> 2 | G9: =iferror(VLOOKUP(A9,DraftTracker!F:AW,5,0)+if((VLOOKUP(A9,DraftTracker!F:AW,6,0)-VLOOKUP(A9,DraftTracker!F:AW,5,0))>0,(VLOOKUP(A9,DraftTracker!F:AW,6,0)-VLOOKUP(A9,DraftTracker!F:AW,5,0)),0)*0.5,"") -> 0
A10: Stanford | B10: Pac12 | C10: Frank | D10: 9 | E10: =VLOOKUP(A10,'Current Week'!B:C,2,0) -> 9 | F10: =iferror(VLOOKUP(A10,DraftTracker!F:AU,3,0)+if((VLOOKUP(A10,DraftTracker!F:AU,4,0)-VLOOKUP(A10,DraftTracker!F:AU,3,0))>0,(VLOOKUP(A10,DraftTracker!F:AU,4,0)-VLOOKUP(A10,DraftTracker!F:AU,3,0)),0)*0.5,"") -> 1 | G10: =iferror(VLOOKUP(A10,DraftTracker!F:AW,5,0)+if((VLOOKUP(A10,DraftTracker!F:AW,6,0)-VLOOKUP(A10,DraftTracker!F:AW,5,0))>0,(VLOOKUP(A10,DraftTracker!F:AW,6,0)-VLOOKUP(A10,DraftTracker!F:AW,5,0)),0)*0.5,"") -> 0
A11: Baylor | B11: Big 12 | C11: Nick A. | D11: 10 | E11: =VLOOKUP(A11,'Current Week'!B:C,2,0) -> 6 | F11: =iferror(VLOOKUP(A11,DraftTracker!F:AU,3,0)+if((VLOOKUP(A11,DraftTracker!F:AU,4,0)-VLOOKUP(A11,DraftTracker!F:AU,3,0))>0,(VLOOKUP(A11,DraftTracker!F:AU,4,0)-VLOOKUP(A11,DraftTracker!F:AU,3,0)),0)*0.5,"") -> 3.5 | G11: =iferror(VLOOKUP(A11,DraftTracker!F:AW,5,0)+if((VLOOKUP(A11,DraftTracker!F:AW,6,0)-VLOOKUP(A11,DraftTracker!F:AW,5,0))>0,(VLOOKUP(A11,DraftTracker!F:AW,6,0)-VLOOKUP(A11,DraftTracker!F:AW,5,0)),0)*0.5,"") -> 0
A12: Michigan | B12: Big Ten | C12: Nick A. | D12: 11 | E12: =VLOOKUP(A12,'Current Week'!B:C,2,0) -> 10 | F12: =iferror(VLOOKUP(A12,DraftTracker!F:AU,3,0)+if((VLOOKUP(A12,DraftTracker!F:AU,4,0)-VLOOKUP(A12,DraftTracker!F:AU,3,0))>0,(VLOOKUP(A12,DraftTracker!F:AU,4,0)-VLOOKUP(A12,DraftTracker!F:AU,3,0)),0)*0.5,"") -> 1.5 | G12: =iferror(VLOOKUP(A12,DraftTracker!F:AW,5,0)+if((VLOOKUP(A12,DraftTracker!F:AW,6,0)-VLOOKUP(A12,DraftTracker!F:AW,5,0))>0,(VLOOKUP(A12,DraftTracker!F:AW,6,0)-VLOOKUP(A12,DraftTracker!F:AW,5,0)),0)*0.5,"") -> 1
A13: Tennessee | B13: SEC | C13: Frank | D13: 12 | E13: =VLOOKUP(A13,'Current Week'!B:C,2,0) -> 8 | F13: =iferror(VLOOKUP(A13,DraftTracker!F:AU,3,0)+if((VLOOKUP(A13,DraftTracker!F:AU,4,0)-VLOOKUP(A13,DraftTracker!F:AU,3,0))>0,(VLOOKUP(A13,DraftTracker!F:AU,4,0)-VLOOKUP(A13,DraftTracker!F:AU,3,0)),0)*0.5,"") -> 0 | G13: =iferror(VLOOKUP(A13,DraftTracker!F:AW,5,0)+if((VLOOKUP(A13,DraftTracker!F:AW,6,0)-VLOOKUP(A13,DraftTracker!F:AW,5,0))>0,(VLOOKUP(A13,DraftTracker!F:AW,6,0)-VLOOKUP(A13,DraftTracker!F:AW,5,0)),0)*0.5,"") -> 2
... A101: Kent State | B101: MAC | C101: Gary | D101: 100 | E101: =VLOOKUP(A101,'Current Week'!B:C,2,0) -> 3 | F101: =iferror(VLOOKUP(A101,DraftTracker!F:AU,3,0)+if((VLOOKUP(A101,DraftTracker!F:AU,4,0)-VLOOKUP(A101,DraftTracker!F:AU,3,0))>0,(VLOOKUP(A101,DraftTracker!F:AU,4,0)-VLOOKUP(A101,DraftTracker!F:AU,3,0)),0)*0.5,"") -> 2 | G101: =iferror(VLOOKUP(A101,DraftTracker!F:AW,5,0)+if((VLOOKUP(A101,DraftTracker!F:AW,6,0)-VLOOKUP(A101,DraftTracker!F:AW,5,0))>0,(VLOOKUP(A101,DraftTracker!F:AW,6,0)-VLOOKUP(A101,DraftTracker!F:AW,5,0)),0)*0.5,"") -> 1.5

Sheet Current Week
A1: Player | B1: Team | C1: W | D1: L | E1: Network | F1: Match Up | G1: Time Left/Start | H1: Line | I1: Over/Under | J1: Opponent | K1: Sort
A2: Gary | B2: TCU | C2: 6 | D2: =IFERROR(__xludf.DUMMYFUNCTION("index(split(FILTER(Sheet34!B:B,arrayformula(not(iserror(find(B2,Sheet34!A:A)))),arrayformula(value(iferror(REGEXEXTRACT(Sheet34!E:E,""(\d{1,2})-""),99))=value(C2))),""-""),1,2)"),5.0) -> 5 | E2: ESPN | F2: BYE | H2: 1 | I2: No Line | K2: 9999
A3: Gary | B3: Florida | C3: 8 | D3: 4 | E3: CBS | F3: BYE | H3: -2½ | I3: No Line | K3: 9999
A4: Gary | B4: Texas State | C4: 2 | D4: =IFERROR(__xludf.DUMMYFUNCTION("index(split(FILTER(Sheet34!B:B,arrayformula(not(iserror(find(B4,Sheet34!A:A)))),arrayformula(value(iferror(REGEXEXTRACT(Sheet34!E:E,""(\d{1,2})-""),99))=value(C4))),""-""),1,2)"),8.0) -> 8 | E4: NA | F4: BYE | H4: bye | I4: bye | K4: 9999
A5: Gary | B5: Clemson | C5: 11 | D5: 1 | E5: ACC | F5: BYE | H5: -3½ | I5: No Line | K5: 9999
A6: Gary | B6: Kent State | C6: 3 | D6: =IFERROR(__xludf.DUMMYFUNCTION("index(split(FILTER(Sheet34!B:B,arrayformula(not(iserror(find(B6,Sheet34!A:A)))),arrayformula(value(iferror(REGEXEXTRACT(Sheet34!E:E,""(\d{1,2})-""),99))=value(C6))),""-""),1,2)"),6.0) -> 6 | E6: ESPN3 | F6: BYE | H6: bye | I6: bye | K6: 9999
A7: Gary | B7: Iowa | C7: 8 | D7: =IFERROR(__xludf.DUMMYFUNCTION("index(split(FILTER(Sheet34!B:B,arrayformula(not(iserror(find(B7,Sheet34!A:A)))),arrayformula(value(iferror(REGEXEXTRACT(Sheet34!E:E,""(\d{1,2})-""),99))=value(C7))),""-""),1,2)"),3.0) -> 3 | E7: BTN | F7: BYE | H7: 2½ | I7: No Line | K7: 9999
A8: Gary | B8: Cincinnati | C8: 4 | D8: =IFERROR(__xludf.DUMMYFUNCTION("index(split(FILTER(Sheet34!B:B,arrayformula(not(iserror(find(B8,Sheet34!A:A)))),arrayformula(value(iferror(REGEXEXTRACT(Sheet34!E:E,""(\d{1,2})-""),99))=value(C8))),""-""),1,2)"),7.0) -> 7 | E8: BTN | F8: BYE | H8: bye | I8: bye | K8: 9999
A9: Gary | B9: Arizona State | C9: 5 | D9: =IFERROR(__xludf.DUMMYFUNCTION("index(split(FILTER(Sheet34!B:B,arrayformula(not(iserror(find(B9,Sheet34!A:A)))),arrayformula(value(iferror(REGEXEXTRACT(Sheet34!E:E,""(\d{1,2})-""),99))=value(C9))),""-""),1,2)"),7.0) -> 7 | E9: FS1 | F9: BYE | H9: bye | I9: bye | K9: 9999
A10: Gary | B10: Marshall | C10: 3 | D10: =IFERROR(__xludf.DUMMYFUNCTION("index(split(FILTER(Sheet34!B:B,arrayformula(not(iserror(find(B10,Sheet34!A:A)))),arrayformula(value(iferror(REGEXEXTRACT(Sheet34!E:E,""(\d{1,2})-""),99))=value(C10))),""-""),1,2)"),6.0) -> 6 | E10: beIN Sports | F10: BYE | H10: bye | I10: bye | K10: 9999
A11: Gary | B11: New Mexico | C11: 8 | D11: 4 | E11: AggieVision | F11: BYE | H11: -7 | I11: No Line | K11: 9999
A12: Player | B12: Team | C12: W | E12: Network | F12: Match Up | G12: Time Left/Start | H12: Line | I12: Over/Under | J12: Opponent | K12: Sort
A13: Josh R. | B13: Troy | C13: 9 | D13: 3 | E13: ACC | F13: BYE | H13: -3½ | I13: No Line | K13: 9999
A14: Josh R. | B14: Akron | C14: 5 | D14: =IFERROR(__xludf.DUMMYFUNCTION("index(split(FILTER(Sheet34!B:B,arrayformula(not(iserror(find(B14,Sheet34!A:A)))),arrayformula(value(iferror(REGEXEXTRACT(Sheet34!E:E,""(\d{1,2})-""),99))=value(C14))),""-""),1,2)"),5.0) -> 5 | E14: BTN | F14: BYE | H14: bye | I14: bye | K14: 9999
A15: Josh R. | B15: Houston | C15: 9 | D15: =IFERROR(__xludf.DUMMYFUNCTION("index(split(FILTER(Sheet34!B:B,arrayformula(not(iserror(find(B15,Sheet34!A:A)))),arrayformula(value(iferror(REGEXEXTRACT(Sheet34!E:E,""(\d{1,2})-""),99))=value(C15))),""-""),1,2)"),3.0) -> 3 | E15: American Sports | F15: BYE | H15: 3 | I15: No Line | K15: 9999
A16: Josh R. | B16: Air Force | C16: 9 | D16: =IFERROR(__xludf.DUMMYFUNCTION("iferror(index(split(FILTER(Sheet34!B:B,arrayformula(not(iserror(find(B16,Sheet34!A:A)))),arrayformula(value(iferror(REGEXEXTRACT(Sheet34!E:E,""(\d{1,2})-""),99))=value(C16))),""-""),1,2),12-C16)"),3.0) -> 3 | E16: Campus Insiders | F16: BYE | H16: -12½ | I16: No Line | K16: 9999
A17: Josh R. | B17: Texas | C17: 5 | D17: =IFERROR(__xludf.DUMMYFUNCTION("iferror(index(split(FILTER(Sheet34!B:B,arrayformula(not(iserror(find(B17,Sheet34!A:A)))),arrayformula(value(iferror(REGEXEXTRACT(Sheet34!E:E,""(\d{1,2})-""),99))=value(C17))),""-""),1,2),12-C17)"),6.0) -> 6 | E17: Longhorn | F17: BYE | H17: bye | I17: bye | K17: 9999
A18: Josh R. | B18: Arizona | C18: 3 | D18: =IFERROR(__xludf.DUMMYFUNCTION("iferror(index(split(FILTER(Sheet34!B:B,arrayformula(not(iserror(find(B18,Sheet34!A:A)))),arrayformula(value(iferror(REGEXEXTRACT(Sheet34!E:E,""(\d{1,2})-""),99))=value(C18))),""-""),1,2),12-C18)"),8.0) -> 8 | E18: Pac-12 | F18: BYE | H18: bye | I18: bye | K18: 9999
A19: Josh R. | B19: Auburn | C19: 8 | D19: =IFERROR(__xludf.DUMMYFUNCTION("iferror(index(split(FILTER(Sheet34!B:B,arrayformula(not(iserror(find(B19,Sheet34!A:A)))),arrayformula(value(iferror(REGEXEXTRACT(Sheet34!E:E,""(\d{1,2})-""),99))=value(C19))),""-""),1,2),12-C19)"),3.0) -> 3 | E19: SEC | F19: BYE | H19: 4½ | I19: No Line | K19: 9999
A20: Josh R. | B20: Minnesota | C20: 8 | D20: =IFERROR(__xludf.DUMMYFUNCTION("iferror(index(split(FILTER(Sheet34!B:B,arrayformula(not(iserror(find(B20,Sheet34!A:A)))),arrayformula(value(iferror(REGEXEXTRACT(Sheet34!E:E,""(\d{1,2})-""),99))=value(C20))),""-""),1,2),12-C20)"),4.0) -> 4 | E20: ESPNEWS | F20: BYE | H20: -6½ | I20: No Line | K20: 9999
A21: Josh R. | B21: Miami | C21: 8 | D21: =IFERROR(__xludf.DUMMYFUNCTION("iferror(index(split(FILTER(Sheet34!B:B,arrayformula(not(iserror(find(B21,Sheet34!A:A)))),arrayformula(value(iferror(REGEXEXTRACT(Sheet34!E:E,""(\d{1,2})-""),99))=value(C21))),""-""),1,2),12-C21)"),4.0) -> 4 | E21: ACC Extra | F21: BYE | H21: bye | I21: bye | K21: 9999
A22: Josh R. | B22: Middle Tennessee | C22: 8 | D22: =IFERROR(__xludf.DUMMYFUNCTION("iferror(index(split(FILTER(Sheet34!B:B,arrayformula(not(iserror(find(B22,Sheet34!A:A)))),arrayformula(value(iferror(REGEXEXTRACT(Sheet34!E:E,""(\d{1,2})-""),99))=value(C22))),""-""),1,2),12-C22)"),3.0) -> 3 | E22: SEC Alternate | F22: BYE | I22: No Line | K22: 9999
A23: Player | B23: Team | C23: W | E23: Network | F23: Match Up | G23: Time Left/Start | H23: Line | I23: Over/Under | J23: Opponent | K23: Sort
A24: Jacob | B24: Louisiana Lafayette | C24: 6 | D24: =IFERROR(__xludf.DUMMYFUNCTION("iferror(index(split(FILTER(Sheet34!B:B,arrayformula(not(iserror(find(B24,Sheet34!A:A)))),arrayformula(value(iferror(REGEXEXTRACT(Sheet34!E:E,""(\d{1,2})-""),99))=value(C24))),""-""),1,2),12-C24)"),6.0) -> 6 | E24: KLAF | F24: BYE | H24: -3 | I24: No Line | K24: 9999
A25: Jacob | B25: West Virginia | C25: 10 | D25: =IFERROR(__xludf.DUMMYFUNCTION("iferror(index(split(FILTER(Sheet34!B:B,arrayformula(not(iserror(find(B25,Sheet34!A:A)))),arrayformula(value(iferror(REGEXEXTRACT(Sheet34!E:E,""(\d{1,2})-""),99))=value(C25))),""-""),1,2),12-C25)"),2.0) -> 2 | E25: ROOT Sports Pittsburgh | F25: BYE | H25: 3 | I25: No Line | K25: 9999
A26: Jacob | B26: Alabama | C26: 12 | D26: =IFERROR(__xludf.DUMMYFUNCTION("iferror(index(split(FILTER(Sheet34!B:B,arrayformula(not(iserror(find(B26,Sheet34!A:A)))),arrayformula(value(iferror(REGEXEXTRACT(Sheet34!E:E,""(\d{1,2})-""),99))=value(C26))),""-""),1,2),12-C26)"),0.0) -> 0 | E26: ESPN2 | F26: BYE | H26: -16½ | I26: No Line | K26: 9999
A27: Jacob | B27: Penn State | C27: 10 | D27: =IFERROR(__xludf.DUMMYFUNCTION("iferror(index(split(FILTER(Sheet34!B:B,arrayformula(not(iserror(find(B27,Sheet34!A:A)))),arrayformula(value(iferror(REGEXEXTRACT(Sheet34!E:E,""(\d{1,2})-""),99))=value(C27))),""-""),1,2),12-C27)"),2.0) -> 2 | E27: ESPN | F27: BYE | H27: -7 | I27: No Line | K27: 9999
A28: Jacob | B28: Southern Mississippi | C28: 6 | D28: =IFERROR(__xludf.DUMMYFUNCTION("iferror(index(split(FILTER(Sheet34!B:B,arrayformula(not(iserror(find(B28,Sheet34!A:A)))),arrayformula(value(iferror(REGEXEXTRACT(Sheet34!E:E,""(\d{1,2})-""),99))=value(C28))),""-""),1,2),12-C28)"),6.0) -> 6 | E28: NA | F28: BYE | H28: bye | I28: bye | K28: 9999
A29: Jacob | B29: Toledo | C29: 9 | D29: =IFERROR(__xludf.DUMMYFUNCTION("iferror(index(split(FILTER(Sheet34!B:B,arrayformula(not(iserror(find(B29,Sheet34!A:A)))),arrayformula(value(iferror(REGEXEXTRACT(Sheet34!E:E,""(\d{1,2})-""),99))=value(C29))),""-""),1,2),12-C29)"),2.0) -> 2 | E29: ESPN3 | F29: BYE | H29: -1 | I29: No Line | K29: 9999
A30: Jacob | B30: Tulsa | C30: 9 | D30: =IFERROR(__xludf.DUMMYFUNCTION("iferror(index(split(FILTER(Sheet34!B:B,arrayformula(not(iserror(find(B30,Sheet34!A:A)))),arrayformula(value(iferror(REGEXEXTRACT(Sheet34!E:E,""(\d{1,2})-""),99))=value(C30))),""-""),1,2),12-C30)"),3.0) -> 3 | E30: ABC | F30: BYE | H30: -12 | I30: No Line | K30: 9999
A31: Jacob | B31: Georgia Tech | C31: 8 | D31: =IFERROR(__xludf.DUMMYFUNCTION("iferror(index(split(FILTER(Sheet34!B:B,arrayformula(not(iserror(find(B31,Sheet34!A:A)))),arrayformula(value(iferror(REGEXEXTRACT(Sheet34!E:E,""(\d{1,2})-""),99))=value(C31))),""-""),1,2),12-C31)"),4.0) -> 4 | E31: ACC Extra | F31: BYE | H31: -4 | I31: No Line | K31: 9999
A32: Jacob | B32: California | C32: 5 | D32: =IFERROR(__xludf.DUMMYFUNCTION("iferror(index(split(FILTER(Sheet34!B:B,arrayformula(not(iserror(find(B32,Sheet34!A:A)))),arrayformula(value(iferror(REGEXEXTRACT(Sheet34!E:E,""(\d{1,2})-""),99))=value(C32))),""-""),1,2),12-C32)"),6.0) -> 6 | E32: CBS Sports | F32: BYE | H32: bye | I32: bye | K32: 9999
A33: Jacob | B33: Colorado State | C33: 7 | D33: =IFERROR(__xludf.DUMMYFUNCTION("iferror(index(split(FILTER(Sheet34!B:B,arrayformula(not(iserror(find(B33,Sheet34!A:A)))),arrayformula(value(iferror(REGEXEXTRACT(Sheet34!E:E,""(\d{1,2})-""),99))=value(C33))),""-""),1,2),12-C33)"),3.0) -> 3 | E33: Campus Insiders | F33: BYE | H33: 13½ | I33: No Line | K33: 9999
A34: Player | B34: Team | C34: W | E34: Network | F34: Match Up | G34: Time Left/Start | H34: Line | I34: Over/Under | J34: Opponent | K34: Sort
A35: Brad | B35: Western Kentucky | C35: 9 | D35: =IFERROR(__xludf.DUMMYFUNCTION("iferror(index(split(FILTER(Sheet34!B:B,arrayformula(not(iserror(find(B35,Sheet34!A:A)))),arrayformula(value(iferror(REGEXEXTRACT(Sheet34!E:E,""(\d{1,2})-""),99))=value(C35))),""-""),1,2),12-C35)"),3.0) -> 3 | E35: ESPN2 | F35: BYE | H35: -4 | I35: No Line | K35: 9999
A36: Brad | B36: Oklahoma | C36: 10 | D36: =IFERROR(__xludf.DUMMYFUNCTION("iferror(index(split(FILTER(Sheet34!B:B,arrayformula(not(iserror(find(B36,Sheet34!A:A)))),arrayformula(value(iferror(REGEXEXTRACT(Sheet34!E:E,""(\d{1,2})-""),99))=value(C36))),""-""),1,2),12-C36)"),2.0) -> 2 | E36: FSN PPV | F36: BYE | H36: -4½ | I36: No Line | K36: 9999
A37: Brad | B37: Idaho | C37: 8 | D37: =IFERROR(__xludf.DUMMYFUNCTION("iferror(index(split(FILTER(Sheet34!B:B,arrayformula(not(iserror(find(B37,Sheet34!A:A)))),arrayformula(value(iferror(REGEXEXTRACT(Sheet34!E:E,""(\d{1,2})-""),99))=value(C37))),""-""),1,2),12-C37)"),4.0) -> 4 | E37: Pac-12 | F37: BYE | H37: -13½ | I37: No Line | K37: 9999
A38: Brad | B38: Bowling Green | C38: 4 | D38: =IFERROR(__xludf.DUMMYFUNCTION("iferror(index(split(FILTER(Sheet34!B:B,arrayformula(not(iserror(find(B38,Sheet34!A:A)))),arrayformula(value(iferror(REGEXEXTRACT(Sheet34!E:E,""(\d{1,2})-""),99))=value(C38))),""-""),1,2),12-C38)"),5.0) -> 5 | E38: American Sports | F38: BYE | H38: bye | I38: bye | K38: 9999
A39: Brad | B39: Nebraska | C39: 9 | D39: =IFERROR(__xludf.DUMMYFUNCTION("iferror(index(split(FILTER(Sheet34!B:B,arrayformula(not(iserror(find(B39,Sheet34!A:A)))),arrayformula(value(iferror(REGEXEXTRACT(Sheet34!E:E,""(\d{1,2})-""),99))=value(C39))),""-""),1,2),12-C39)"),3.0) -> 3 | E39: ESPN2 | F39: BYE | H39: 3 | I39: No Line | K39: 9999
A40: Brad | B40: Georgia | C40: 7 | D40: =IFERROR(__xludf.DUMMYFUNCTION("iferror(index(split(FILTER(Sheet34!B:B,arrayformula(not(iserror(find(B40,Sheet34!A:A)))),arrayformula(value(iferror(REGEXEXTRACT(Sheet34!E:E,""(\d{1,2})-""),99))=value(C40))),""-""),1,2),12-C40)"),5.0) -> 5 | E40: SEC | F40: BYE | H40: -1 | I40: No Line | K40: 9999
...

Sheet Sheet34
A1: American Conference
B2: Conference | E2: Overall | K2: Polls
A3: East | B3: W-L | C3: PF | D3: PA | E3: W-L | F3: PF | G3: PA | H3: HOME | I3: AWAY | J3: STRK | K3: AP | L3: USA
A4: Temple Owls | B4: 7-1 | C4: 267 | D4: 132 | E4: 10-4 | F4: 453 | G4: 258 | H4: 45809 | I4: 45749 | J4: L1 | K4: 45658 | L4: 45658
A5: 19South Florida Bulls | B5: 7-1 | C5: 339 | D5: 260 | E5: 11-2 | F5: 569 | G5: 411 | H5: 45809 | I5: 45748 | J5: W5 | K5: 0-2 | L5: 0-2
A6: UCF Knights | B6: 4-4 | C6: 232 | D6: 194 | E6: 6-7 | F6: 374 | G6: 320 | H6: 45720 | I6: 45719 | J6: L3 | K6: 0-3 | L6: 0-3
A7: Cincinnati Bearcats | B7: 1-7 | C7: 136 | D7: 256 | E7: 4-8 | F7: 232 | G7: 323 | H7: 45720 | I7: 45661 | J7: L5 | K7: 0-1 | L7: 0-1
A8: East Carolina Pirates | B8: 1-7 | C8: 207 | D8: 322 | E8: 3-9 | F8: 324 | G8: 433 | H8: 45719 | I8: 0-6 | J8: L4 | K8: 0-1 | L8: 0-1
A9: Connecticut Huskies | B9: 1-7 | C9: 117 | D9: 245 | E9: 3-9 | F9: 178 | G9: 337 | H9: 45720 | I9: 0-5 | J9: L6 | K9: 0-1 | L9: 0-1
A10: West | B10: W-L | C10: PF | D10: PA | E10: W-L | F10: PF | G10: PA | H10: HOME | I10: AWAY | J10: STRK | K10: AP | L10: USA
A11: Navy Midshipmen | B11: 7-1 | C11: 365 | D11: 260 | E11: 9-5 | F11: 531 | G11: 434 | H11: 45778 | I11: 45718 | J11: L3 | K11: 0-2 | L11: 0-2
A12: Tulsa Golden Hurricane | B12: 6-2 | C12: 343 | D12: 258 | E12: 10-3 | F12: 552 | G12: 388 | H12: 6-0 | I12: 45719 | J12: W3 | K12: 0-1 | L12: 0-1
A13: Memphis Tigers | B13: 5-3 | C13: 291 | D13: 249 | E13: 8-5 | F13: 505 | G13: 375 | H13: 45779 | I13: 45718 | J13: L1 | K13: 45658 | L13: 45658
A14: Houston Cougars | B14: 5-3 | C14: 281 | D14: 235 | E14: 9-4 | F14: 466 | G14: 305 | H14: 6-0 | I14: 45691 | J14: L2 | K14: 2-0 | L14: 2-0
A15: SMU Mustangs | B15: 3-5 | C15: 253 | D15: 327 | E15: 5-7 | F15: 332 | G15: 435 | H15: 45692 | I15: 45719 | J15: L2 | K15: 1-0 | L15: 1-0
A16: Tulane Green Wave | B16: 1-7 | C16: 148 | D16: 241 | E16: 4-8 | F16: 289 | G16: 332 | H16: 45692 | I16: 45692 | J16: W1 | K16: 0-1 | L16: 0-1
A17: Atlantic Coast Conference
B18: Conference | E18: Overall | K18: Polls
A19: Atlantic | B19: W-L | C19: PF | D19: PA | E19: W-L | F19: PF | G19: PA | H19: HOME | I19: AWAY | J19: STRK | K19: AP | L19: USA
A20: 1Clemson Tigers | B20: 7-1 | C20: 316 | D20: 160 | E20: 14-1 | F20: 588 | G20: 270 | H20: 45809 | I20: 5-0 | J20: W5 | K20: 45809 | L20: 6-0
A21: 21Louisville Cardinals | B21: 7-1 | C21: 367 | D21: 161 | E21: 9-4 | F21: 553 | G21: 309 | H21: 45778 | I21: 45749 | J21: L3 | K21: 45659 | L21: 45659
A22: 8Florida State Seminoles | B22: 5-3 | C22: 240 | D22: 203 | E22: 10-3 | F22: 456 | G22: 325 | H22: 45749 | I22: 45748 | J22: W5 | K22: 45718 | L22: 45718
A23: NC State Wolfpack | B23: 3-5 | C23: 173 | D23: 207 | E23: 7-6 | F23: 351 | G23: 296 | H23: 45750 | I23: 45691 | J23: W2 | K23: 0-3 | L23: 0-3
A24: Wake Forest Demon Deacons | B24: 3-5 | C24: 140 | D24: 189 | E24: 7-6 | F24: 265 | G24: 288 | H24: 45750 | I24: 45691 | J24: W1 | K24: 45660 | L24: 45660
A25: Syracuse Orange | B25: 2-6 | C25: 191 | D25: 337 | E25: 4-8 | F25: 308 | G25: 463 | H25: 45692 | I25: 45691 | J25: L4 | K25: 0-3 | L25: 0-3
A26: Boston College Eagles | B26: 2-6 | C26: 96 | D26: 275 | E26: 7-6 | F26: 265 | G26: 325 | H26: 45719 | I26: 45718 | J26: W3 | K26: 0-4 | L26: 0-4
A27: Coastal | B27: W-L | C27: PF | D27: PA | E27: W-L | F27: PF | G27: PA | H27: HOME | I27: AWAY | J27: STRK | K27: AP | L27: USA
A28: 16Virginia Tech Hokies | B28: 6-2 | C28: 272 | D28: 147 | E28: 10-4 | F28: 490 | G28: 319 | H28: 45778 | I28: 45748 | J28: W1 | K28: 45658 | L28: 0-1
A29: North Carolina Tar Heels | B29: 5-3 | C29: 228 | D29: 208 | E29: 8-5 | F29: 420 | G29: 324 | H29: 45749 | I29: 45748 | J29: L2 | K29: 45690 | L29: 45659
A30: 20Miami Hurricanes | B30: 5-3 | C30: 235 | D30: 174 | E30: 9-4 | F30: 446 | G30: 241 | H30: 45749 | I30: 45749 | J30: W5 | K30: 45690 | L30: 45659
A31: Pittsburgh Panthers | B31: 5-3 | C31: 357 | D31: 309 | E31: 8-5 | F31: 532 | G31: 458 | H31: 45809 | I31: 45691 | J31: L1 | K31: 45690 | L31: 45690
A32: Georgia Tech Yellow Jackets | B32: 4-4 | C32: 198 | D32: 232 | E32: 9-4 | F32: 367 | G32: 318 | H32: 45779 | I32: 45690 | J32: W4 | K32: 45659 | L32: 45658
A33: Virginia Cavaliers | B33: 1-7 | C33: 165 | D33: 276 | E33: 2-10 | F33: 270 | G33: 405 | H33: 45662 | I33: 45662 | J33: L7 | K33: 0-1 | L33: 0-2
A34: Duke Blue Devils | B34: 1-7 | C34: 167 | D34: 267 | E34: 4-8 | F34: 280 | G34: 338 | H34: 45719 | I34: 45662 | J34: L2 | K34: 0-1 | L34: 45658
A35: Big 12 Conference
B36: Conference | E36: Overall | K36: Polls
B37: W-L | C37: PF | D37: PA | E37: W-L | F37: PF | G37: PA | H37: HOME | I37: AWAY | J37: STRK | K37: AP | L37: USA
A38: 5Oklahoma Sooners | B38: 9-0 | C38: 430 | D38: 261 | E38: 11-2 | F38: 571 | G38: 375 | H38: 45778 | I38: 4-0 | J38: W10 | K38: 45717 | L38: 45717
A39: 11Oklahoma State Cowboys | B39: 7-2 | C39: 331 | D39: 262 | E39: 10-3 | F39: 502 | G39: 345 | H39: 45809 | I39: 45718 | J39: W1 | K39: 45717 | L39: 45689
A40: 18West Virginia Mountaineers | B40: 7-2 | C40: 292 | D40: 217 | E40: 10-3 | F40: 405 | G40: 312 | H40: 45809 | I40: 45717 | J40: L1 | K40: 0-2 | L40: 0-2
...

Sheet Tuesday
A1: 0 | B1: Network | C1: 0.29166667 | D1: 0.3125 | E1: 0.33333333 | F1: 0.35416667 | G1: 0.375 | H1: 0.39583333 | I1: 0.41666667 | J1: 0.4375 | K1: 0.45833333 | L1: 0.47916667 | M1: 0.5 | N1: 0.52083333 | O1: 0.54166667 | P1: 0.5625 | Q1: 0.58333333 | R1: 0.60416667 | S1: 0.625 | T1: 0.64583333 | U1: 0.66666667 | V1: 0.6875 | W1: 0.70833333 | X1: 0.72916667 | Y1: 0.75 | Z1: 0.77083333 | AA1: 0.79166667 | AB1: 0.8125 | AC1: 0.83333333 | AD1: 0.85416667 | AE1: 0.875 | AF1: 0.89583333 | AG1: 0.91666667 | AH1: 0.9375 | AI1: 0.95833333 | AJ1: 0.97916667 | AK1: 0 | AL1: 0.020833333 | AM1: 0.041666667 | AN1: 0.0625 | AO1: 0.083333333 | AP1: 0.10416667 | AQ1: 0.125 | AR1: 0.14583333
A2: 9 | B2: ESPNU | AA2: =HYPERLINK("http://www.espn.com/college-football/game?gameId=400869335","Akron 3 at Ohio 9") -> Akron 3 at Ohio 9
A3: 17.5 | B3: ESPN3 | AA3: =HYPERLINK("http://www.espn.com/college-football/game?gameId=400869337","CMU 21 at EMU 26") -> CMU 21 at EMU 26
A4: 17.5 | B4: ESPN3~01 | AA4: =HYPERLINK("http://www.espn.com/college-football/game?gameId=400869336","Ball St. 20 at Miami (OH) 21") -> Ball St. 20 at Miami (OH) 21

Sheet Translation
A1: South FloridaUSF | B1: East CarolinaECU | C1: TempleTEM | D1: CincinnatiCIN | E1: ConnecticutCONN | F1: UCFUCF | G1: TulsaTLSA | H1: MemphisMEM | I1: HoustonHOU | J1: NavyNAVY | K1: SMUSMU | L1: TulaneTULN | M1: SyracuseSYR | N1: ClemsonCLEM | O1: Florida StateFSU | P1: LouisvilleLOU | Q1: Boston CollegeBC | R1: NC StateNCST | S1: Wake ForestWAKE | T1: PittsburghPITT | U1: VirginiaUVA | V1: Virginia TechVT | W1: Miami (FL)MIA | X1: Georgia TechGT | Y1: DukeDUKE | Z1: North CarolinaUNC | AA1: Texas TechTTU | AB1: Iowa StateISU | AC1: OklahomaOKLA | AD1: BaylorBAY | AE1: TexasTEX | AF1: West VirginiaWVU | AG1: KansasKU | AH1: Kansas StateKSU | AI1: Oklahoma StateOKST | AJ1: TCUTCU | AK1: IndianaIND | AL1: MarylandMD | AM1: Michigan StateMSU | AN1: RutgersRUTG | AO1: Ohio StateOSU | AP1: Penn StatePSU | AQ1: MichiganMICH | AR1: NebraskaNEB | AS1: WisconsinWIS | AT1: IllinoisILL | AU1: IowaIOWA | AV1: PurduePUR | AW1: NorthwesternNW | AX1: MinnesotaMINN | AY1: MarshallMRSH | AZ1: Old DominionODU | BA1: Florida AtlanticFAU | BB1: Middle TennesseeMTSU | BC1: Florida IntlFIU | BD1: CharlotteCHAR | BE1: Western KentuckyWestern Kentucky | BF1: RiceRICE | BG1: North TexasUNT | BH1: Louisiana TechLT | BI1: Southern MississippiissippiUSM | BJ1: UTEPUTEP | BK1: Texas San AntonioUTSA | BL1: Notre DameND | BM1: BYUBYU | BN1: ArmyARMY | BO1: AkronAKR | BP1: BuffaloBUFF | BQ1: Kent StateKENT | BR1: MassachusettsUMASS | BS1: Bowling GreenBGSU | BT1: Miami (OH)M-OH | BU1: OhioOHIO | BV1: Eastern MichiganEMU | BW1: Northern IllinoisNIU | BX1: ToledoTOL | BY1: Western MichiganWMU | BZ1: Ball StateBALL | CA1: Central MichiganCMU | CB1: StanfordSTAN | CC1: CaliforniaCAL | CD1: Oregon StateORST | CE1: WashingtonWASH | CF1: Washington StateWSU | CG1: OregonORE | CH1: Arizona StateASU | CI1: UCLAUCLA | CJ1: USCUSC | CK1: ArizonaARIZ | CL1: UtahUTAH | CM1: ColoradoCOLO | CN1: TennesseeTENN | CO1: FloridaFLA | CP1: GeorgiaUGA | CQ1: KentuckyUK | CR1: MissouriMIZZ | CS1: South CarolinaSC | CT1: VanderbiltVAN | CU1: AuburnAUB | CV1: ArkansasARK | CW1: LSULSU | CX1: Ole MissMISS | CY1: Texas A&MTAM | CZ1: AlabamaALA | DA1: Mississippi StateMSST | DB1: New Mexico StateNMSU | DC1: Georgia SouthernGASO | DD1: Louisiana LafayetteULL | DE1: Texas StateTXST | DF1: Appalachian StateAPP | DG1: Arkansas StateARST | DH1: South AlabamaUSA | DI1: Louisiana MonroeULM | DJ1: TroyTROY | DK1: Georgia StateGAST | DL1: IdahoIDHO | DM1: Air ForceAFA | DN1: WyomingWYO | DO1: Colorado StateCSU | DP1: Boise StateBSU | DQ1: New MexicoUNM | DR1: Utah StateUSU | DS1: UNLVUNLV | DT1: San Diego StateSDSU | DU1: San José StateSJSU | DV1: Fresno StateFRES | DW1: NevadaNEV | DX1: HawaiiHAW
A2: South Florida | B2: East Carolina | C2: Temple | D2: Cincinnati | E2: UCON | F2: UCF | G2: Tulsa | H2: Memphis | I2: Houston | J2: Navy | K2: SMU | L2: Tulane | M2: Syracuse | N2: Clemson | O2: Florida State | P2: Louisville | Q2: Boston College | R2: NC State | S2: Wake Forest | T2: Pittsburgh | U2: Virfinia | V2: Virginia Tech | W2: Miami (FL) | X2: Georgia Tech | Y2: Duke | Z2: North Carolina | AA2: Texas Tech | AB2: Iowa State | AC2: Oklahoma | AD2: Baylor | AE2: Texas | AF2: West Virginia | AG2: Kansas | AH2: Kansas State | AI2: Oklahoma State | AJ2: TCU | AK2: Indiana | AL2: Maryland | AM2: Michigan State | AN2: Rutgers | AO2: Ohio State | AP2: Penn State | AQ2: Michigan | AR2: Nebraska | AS2: Wisconsin | AT2: Illinois | AU2: Iowa | AV2: Purdue | AW2: Northwestern | AX2: Minnesota | AY2: Marshall | AZ2: Old Dominion | BA2: Florida Atlantic | BB2: Middle Tennessee | BC2: Florida Intl | BD2: Charlotte | BE2: Western Kentucky | BF2: Rice | BG2: North Texas | BH2: Louisiana Tech | BI2: Southern Mississippiissippi | BJ2: UTEP | BK2: UTSA | BL2: Notre Dame | BM2: BYU | BN2: Army | BO2: Akron | BP2: Buffalo | BQ2: Kent State | BR2: Massachusetts | BS2: Bowling Green | BT2: Miami (OH) | BU2: Ohio | BV2: Eastern Michigan | BW2: Northern Illinois | BX2: Toledo | BY2: Western Michigan | BZ2: Ball State | CA2: Central Michigan | CB2: Stanford | CC2: California | CD2: Oregon State | CE2: Washington | CF2: Washington State | CG2: Oregon | CH2: Arizona State | CI2: UCLA | CJ2: USC | CK2: Arizona | CL2: Utah | CM2: Colorado | CN2: Tennessee | CO2: Florida | CP2: Georgia | CQ2: Kentucky | CR2: Missouri | CS2: South Carolina | CT2: Vanderbilt | CU2: Auburn | CV2: Arkansas | CW2: LSU | CX2: Ole Miss | CY2: Texas A&M | CZ2: Alabama | DA2: Mississippi State | DB2: New Mexico State | DC2: Georgia Southern | DD2: Louisiana Lafayette | DE2: Texas State | DF2: Appalachian State | DG2: Arkansas State | DH2: South Alabama | DI2: Louisiana Monroe | DJ2: Troy | DK2: Georgia State | DL2: Idaho | DM2: Air Force | DN2: Wyoming | DO2: Colorado State | DP2: Boise State | DQ2: New Mexico | DR2: Utah State | DS2: UNLV | DT2: San Diego State | DU2: San José State | DV2: Fresno State | DW2: Nevada | DX2: Hawaii

Sheet DraftTracker
A1: draft | B1: rnd | C1: pick | D1: player | E1: conf | F1: team | G1: Error Check | H1: Same confs picked within 10 after | I1: Same confs picked within 20 after | J1: Same confs picked within 10 before | K1: Same confs picked within 20 before | L1: wins | M1: picks_better_than | N1: no_teams_slept_on | O1: W | P1: L | Q1: matchup | R1: Status (Time ET) | S1: opponent | T1: network | U1: Opening Spread | V1: Spread | W1: Current Total | X1: Total | Y1: PF | Z1: PA | AA1: wins_missed | AB1: picks_better_than | AC1: no_teams_slept_on | AD1: bestpick | AE1: wins_gained | AF1: teams_slept_on | AG1: wins_missed_conf | AH1: picks_better_than_conf | AI1: no_teams_slept_on_conf | AJ1: bestpick_conf | AK1: wins_gained_conf | AL1: teams_slept_on_conf | AM1: confs_avail | AN1: wins_missed_confs_avail | AO1: picks_better_than_confs_avail | AP1: no_teams_slept_on_confs_avail | AQ1: bestpick_confs_avail | AR1: wins_gained_confs_avail | AS1: teams_slept_on_confs_avail
A2: 1 | B2: 1 | C2: 1 | D2: ='Draft Order'!B2 -> Gary | E2: =if(F2<>"",VLOOKUP(F2,'Teams-Conference, for lookup'!A:B,2,0),"") -> ACC | F2: Clemson | G2: =if(F2<>"",if(match(F2,F:F,0)<ROW(F2),"ERROR: Team already selected in row " & ROW(F2)&". ","")&if(COUNTIFS(E:E,"="&E2,D:D,"="&D2)>1,"ERROR: Player picked from conference more than once.",""),"") | H2: =countif(E3:E12,E2) -> 1 | I2: =countif(E3:E24,E2) -> 2 | L2: {=iferror(VLOOKUP(F2:F124,'Current Week'!C:E,2,0),"")} | M2: =IFERROR(__xludf.DUMMYFUNCTION("counta(iferror(filter(L1:L$2,E1:E$2=E2,L1:L$2<L2)))"),0.0) -> 0 | N2: =IFERROR(__xludf.DUMMYFUNCTION("counta(iferror(filter(L3:L$124,E3:E$124=E2,L3:L$125>L2)))"),0.0) -> 0 | O2: {=XLOOKUP(F2,'Current Week'!B:B,'Current Week'!C:O)} -> 11 | P2: 1 | Q2: ACC | R2: BYE | T2: -3½ | U2: No Line | W2: 9999 | AA2: =$O2-max($O2:$O$386) -> -1 | AB2: =countif($O1:$O$2,"<"&$O2) -> 0 | AC2: =IFERROR(__xludf.DUMMYFUNCTION("iferror(COUNT(filter($O3:$O$386,$O3:$O$386>$O2)))"),2.0) -> 2 | AD2: =if(AA2=0,1,0) -> 0 | AE2: =$O2-min($O$2:$O2) -> 0 | AF2: =IFERROR(__xludf.DUMMYFUNCTION("iferror(join("","",index(sort(filter($F3:$F$386,$O3:$O$386>$O2),2,false),0,1)))"),"Alabama,Western Michigan") -> Alabama,Western Michigan | AG2: =IFERROR(__xludf.DUMMYFUNCTION("iferror($O2-max(filter($O2:$O$386,$E2:$E$386=$E$2)))"),0.0) -> 0 | AH2: =countifs($O1:$O$2,"<"&$O2,$E1:$E$2,$E$2) -> 0 | AI2: =IFERROR(__xludf.DUMMYFUNCTION("iferror(COUNT(filter($O3:$O$386,$O3:$O$386>$O2,$E2:$E$386=$E$2)))"),0.0) -> 0 | AJ2: =if(AG2=0,1,0) -> 1 | AK2: =IFERROR(__xludf.DUMMYFUNCTION("iferror($O2-min(filter($O2:$O$386,$E2:$E$386=$E$2)))"),9.0) -> 9 | AL2: =IFERROR(__xludf.DUMMYFUNCTION("iferror(join("","",index(sort(filter($F3:$F$386,$O3:$O$386>$O2,$E3:$E$386=$E$2),2,false),0,1)))"),"") | AM2: =IFERROR(__xludf.DUMMYFUNCTION("REGEXREPLACE(join("","",unique({let(conf_picked,filter(E$1:E1,D$1:D1=D2), byrow(unique(TRANSPOSe(Teams!$1:$1)),lambda(rw,if(ISERROR(match(rw,conf_picked,0)),rw,))));iferror(if(#REF!,,transpose(split(#REF!,"","",1,1))))})), ""^,"", """")"),"AAC,ACC,Big 12,Big Ten,CUSA,MAC,MWC,Pac12,SEC,Sun Belt,") -> AAC,ACC,Big 12,Big Ten,CUSA,MAC,MWC,Pac12,SEC,Sun Belt, | AN2: =IFERROR(__xludf.DUMMYFUNCTION("iferror($O2-max(filter($O2:$O$386,arrayformula(isnumber(FIND($E2:$E$386,AM2))))))"),-1.0) -> -1 | AO2: {=countifs($O1:$O$2,"<"&$O2,isnumber(FIND($E1:$E$2,AM2)),TRUE)} -> 0 | AP2: =IFERROR(__xludf.DUMMYFUNCTION("iferror(COUNT(filter($O3:$O$386,$O3:$O$386>$O2,arrayformula(isnumber(FIND($E3:$E$386,AM2))))))"),2.0) -> 2 | AQ2: =if(AN2=0,1,0) -> 0 | AR2: =IFERROR(__xludf.DUMMYFUNCTION("iferror($O2-min(filter($O2:$O$386,arrayformula(isnumber(FIND($E2:$E$386,AM2))))))"),10.0) -> 10 | AS2: =IFERROR(__xludf.DUMMYFUNCTION("iferror(join("","",index(sort(filter($F3:$F$386,$O3:$O$386>$O2,arrayformula(isnumber(FIND($E3:$E$386,AM2)))),2,false),0,1)))"),"Alabama,Western Michigan") -> Alabama,Western Michigan
A3: =A2+1 -> 2 | B3: 1 | C3: 2 | D3: ='Draft Order'!B3 -> Josh R. | E3: =if(F3<>"",VLOOKUP(F3,'Teams-Conference, for lookup'!A:B,2,0),"") -> AAC | F3: Houston | G3: =if(F3<>"",if(match(F3,F:F,0)<ROW(F3),"ERROR: Team already selected in row " & ROW(F3)&". ","")&if(COUNTIFS(E:E,"="&E3,D:D,"="&D3)>1,"ERROR: Player picked from conference more than once.",""),"") | H3: =countif(E4:E13,E3) -> 0 | I3: =countif(E4:E25,E3) -> 0 | M3: =IFERROR(__xludf.DUMMYFUNCTION("counta(iferror(filter(L2:L$2,E2:E$2=E3,L2:L$2<L3)))"),0.0) -> 0 | N3: =IFERROR(__xludf.DUMMYFUNCTION("counta(iferror(filter(L4:L$124,E4:E$124=E3,L4:L$125>L3)))"),0.0) -> 0 | O3: {=XLOOKUP(F3,'Current Week'!B:B,'Current Week'!C:O)} -> 9 | P3: 3 | Q3: American Sports | R3: BYE | T3: 3 | U3: No Line | W3: 9999 | AA3: =$O3-max($O3:$O$386) -> -3 | AB3: =countif($O2:$O$2,"<"&$O3) -> 0 | AC3: =IFERROR(__xludf.DUMMYFUNCTION("iferror(COUNT(filter($O4:$O$386,$O4:$O$386>$O3)))"),12.0) -> 12 | AD3: =if(AA3=0,1,0) -> 0 | AE3: =$O3-min($O$2:$O3) -> 0 | AF3: =IFERROR(__xludf.DUMMYFUNCTION("iferror(join("","",index(sort(filter($F4:$F$387,$O4:$O$387>$O3),2,false),0,1)))"),"Alabama,Oklahoma,Boise State,Ohio State,Michigan,West Virginia,Western Michigan,Washington,South Florida,Wisconsin,Penn State,Colorado") -> Alabama,Oklahoma,Boise State,Ohio State,Michigan,West Virginia,Western Michigan,Washington,South Florida,Wisconsin,Penn State,Colorado | AG3: =IFERROR(__xludf.DUMMYFUNCTION("iferror($O3-max(filter($O3:$O$386,$E3:$E$386=$E$2)))"),0.0) -> 0 | AH3: =countifs($O2:$O$2,"<"&$O3,$E2:$E$2,$E$2) -> 0 | AI3: =IFERROR(__xludf.DUMMYFUNCTION("iferror(COUNT(filter($O4:$O$386,$O4:$O$386>$O3,$E3:$E$386=$E$2)))"),0.0) -> 0 | AJ3: =if(AG3=0,1,0) -> 1 | AK3: =IFERROR(__xludf.DUMMYFUNCTION("iferror($O3-min(filter($O3:$O$386,$E3:$E$386=$E$2)))"),7.0) -> 7 | AL3: =IFERROR(__xludf.DUMMYFUNCTION("iferror(join("","",index(sort(filter($F4:$F$386,$O4:$O$386>$O3,$E4:$E$386=$E$2),2,false),0,1)))"),"") | AM3: =IFERROR(__xludf.DUMMYFUNCTION("REGEXREPLACE(join("","",unique({let(conf_picked,filter(E$1:E2,D$1:D2=D3), byrow(unique(TRANSPOSe(Teams!$1:$1)),lambda(rw,if(ISERROR(match(rw,conf_picked,0)),rw,))));iferror(if(#REF!,,transpose(split(#REF!,"","",1,1))))})), ""^,"", """")"),"AAC,ACC,Big 12,Big Ten,CUSA,MAC,MWC,Pac12,SEC,Sun Belt,") -> AAC,ACC,Big 12,Big Ten,CUSA,MAC,MWC,Pac12,SEC,Sun Belt, | AN3: =IFERROR(__xludf.DUMMYFUNCTION("iferror($O3-max(filter($O3:$O$386,arrayformula(isnumber(FIND($E3:$E$386,AM3))))))"),-3.0) -> -3 | AO3: {=countifs($O2:$O$2,"<"&$O3,isnumber(FIND($E2:$E$2,AM3)),TRUE)} -> 0 | AP3: =IFERROR(__xludf.DUMMYFUNCTION("iferror(COUNT(filter($O4:$O$386,$O4:$O$386>$O3,arrayformula(isnumber(FIND($E4:$E$386,AM3))))))"),12.0) -> 12 | AQ3: =if(AN3=0,1,0) -> 0 | AR3: =IFERROR(__xludf.DUMMYFUNCTION("iferror($O3-min(filter($O3:$O$386,arrayformula(isnumber(FIND($E3:$E$386,AM3))))))"),8.0) -> 8 | AS3: =IFERROR(__xludf.DUMMYFUNCTION("iferror(join("","",index(sort(filter($F4:$F$386,$O4:$O$386>$O3,arrayformula(isnumber(FIND($E4:$E$386,AM3)))),2,false),0,1)))"),"Alabama,Oklahoma,Boise State,Ohio State,Michigan,West Virginia,Western Michigan,Washington,South Florida,Wisconsin,Penn State,Colorado") -> Alabama,Oklahoma,Boise State,Ohio State,Michigan,West Virginia,Western Michigan,Washington,South Florida,Wisconsin,Penn State,Colorado
A4: =A3+1 -> 3 | B4: 1 | C4: 3 | D4: ='Draft Order'!B4 -> Jacob | E4: =if(F4<>"",VLOOKUP(F4,'Teams-Conference, for lookup'!A:B,2,0),"") -> SEC | F4: Alabama | G4: =if(F4<>"",if(match(F4,F:F,0)<ROW(F4),"ERROR: Team already selected in row " & ROW(F4)&". ","")&if(COUNTIFS(E:E,"="&E4,D:D,"="&D4)>1,"ERROR: Player picked from conference more than once.",""),"") | H4: =countif(E5:E14,E4) -> 2 | I4: =countif(E5:E26,E4) -> 2 | M4: =IFERROR(__xludf.DUMMYFUNCTION("counta(iferror(filter(L$2:L3,E$2:E3=E4,L$2:L3<L4)))"),0.0) -> 0 | N4: =IFERROR(__xludf.DUMMYFUNCTION("counta(iferror(filter(L5:L$124,E5:E$124=E4,L5:L$125>L4)))"),0.0) -> 0 | O4: {=XLOOKUP(F4,'Current Week'!B:B,'Current Week'!C:O)} -> 12 | P4: 0 | Q4: ESPN2 | R4: BYE | T4: -16½ | U4: No Line | W4: 9999 | AA4: =$O4-max($O4:$O$386) -> 0 | AB4: =countif($O3:$O$2,"<"&$O4) -> 2 | AC4: =IFERROR(__xludf.DUMMYFUNCTION("iferror(COUNT(filter($O5:$O$386,$O5:$O$386>$O4)))"),0.0) -> 0 | AD4: =if(AA4=0,1,0) -> 1 | AE4: =$O4-min($O$2:$O4) -> 3 | AF4: =IFERROR(__xludf.DUMMYFUNCTION("iferror(join("","",index(sort(filter($F5:$F$387,$O5:$O$387>$O4),2,false),0,1)))"),"") | AG4: =IFERROR(__xludf.DUMMYFUNCTION("iferror($O4-max(filter($O4:$O$386,$E4:$E$386=$E$2)))"),3.0) -> 3 | AH4: =countifs($O3:$O$2,"<"&$O4,$E3:$E$2,$E$2) -> 1 | AI4: =IFERROR(__xludf.DUMMYFUNCTION("iferror(COUNT(filter($O5:$O$386,$O5:$O$386>$O4,$E4:$E$386=$E$2)))"),0.0) -> 0 | AJ4: =if(AG4=0,1,0) -> 0 | AK4: =IFERROR(__xludf.DUMMYFUNCTION("iferror($O4-min(filter($O4:$O$386,$E4:$E$386=$E$2)))"),10.0) -> 10 | AL4: =IFERROR(__xludf.DUMMYFUNCTION("iferror(join("","",index(sort(filter($F5:$F$386,$O5:$O$386>$O4,$E5:$E$386=$E$2),2,false),0,1)))"),"") | AM4: =IFERROR(__xludf.DUMMYFUNCTION("REGEXREPLACE(join("","",unique({let(conf_picked,filter(E$1:E3,D$1:D3=D4), byrow(unique(TRANSPOSe(Teams!$1:$1)),lambda(rw,if(ISERROR(match(rw,conf_picked,0)),rw,))));iferror(if(#REF!,,transpose(split(#REF!,"","",1,1))))})), ""^,"", """")"),"AAC,ACC,Big 12,Big Ten,CUSA,MAC,MWC,Pac12,SEC,Sun Belt,") -> AAC,ACC,Big 12,Big Ten,CUSA,MAC,MWC,Pac12,SEC,Sun Belt, | AN4: =IFERROR(__xludf.DUMMYFUNCTION("iferror($O4-max(filter($O4:$O$386,arrayformula(isnumber(FIND($E4:$E$386,AM4))))))"),0.0) -> 0 | AO4: {=countifs($O$2:$O3,"<"&$O4,isnumber(FIND($E$2:$E3,AM4)),TRUE)} -> 2 | AP4: =IFERROR(__xludf.DUMMYFUNCTION("iferror(COUNT(filter($O5:$O$386,$O5:$O$386>$O4,arrayformula(isnumber(FIND($E5:$E$386,AM4))))))"),0.0) -> 0 | AQ4: =if(AN4=0,1,0) -> 1 | AR4: =IFERROR(__xludf.DUMMYFUNCTION("iferror($O4-min(filter($O4:$O$386,arrayformula(isnumber(FIND($E4:$E$386,AM4))))))"),11.0) -> 11 | AS4: =IFERROR(__xludf.DUMMYFUNCTION("iferror(join("","",index(sort(filter($F5:$F$386,$O5:$O$386>$O4,arrayformula(isnumber(FIND($E5:$E$386,AM4)))),2,false),0,1)))"),"")
A5: =A4+1 -> 4 | B5: 1 | C5: 4 | D5: ='Draft Order'!B5 -> Brad | E5: =if(F5<>"",VLOOKUP(F5,'Teams-Conference, for lookup'!A:B,2,0),"") -> Big 12 | F5: Oklahoma | G5: =if(F5<>"",if(match(F5,F:F,0)<ROW(F5),"ERROR: Team already selected in row " & ROW(F5)&". ","")&if(COUNTIFS(E:E,"="&E5,D:D,"="&D5)>1,"ERROR: Player picked from conference more than once.",""),"") | H5: =countif(E6:E15,E5) -> 2 | I5: =countif(E6:E27,E5) -> 6 | M5: =IFERROR(__xludf.DUMMYFUNCTION("counta(iferror(filter(L$2:L4,E$2:E4=E5,L$2:L4<L5)))"),0.0) -> 0 | N5: =IFERROR(__xludf.DUMMYFUNCTION("counta(iferror(filter(L6:L$124,E6:E$124=E5,L6:L$125>L5)))"),0.0) -> 0 | O5: {=XLOOKUP(F5,'Current Week'!B:B,'Current Week'!C:O)} -> 10 | P5: 2 | Q5: FSN PPV | R5: BYE | T5: -4½ | U5: No Line | W5: 9999 | AA5: =$O5-max($O5:$O$386) -> -2 | AB5: =countif($O4:$O$2,"<"&$O5) -> 1 | AC5: =IFERROR(__xludf.DUMMYFUNCTION("iferror(COUNT(filter($O6:$O$386,$O6:$O$386>$O5)))"),3.0) -> 3 | AD5: =if(AA5=0,1,0) -> 0 | AE5: =$O5-min($O$2:$O5) -> 1 | AF5: =IFERROR(__xludf.DUMMYFUNCTION("iferror(join("","",index(sort(filter($F6:$F$387,$O6:$O$387>$O5),2,false),0,1)))"),"Ohio State,Western Michigan,Washington") -> Ohio State,Western Michigan,Washington | AG5: =IFERROR(__xludf.DUMMYFUNCTION("iferror($O5-max(filter($O5:$O$386,$E5:$E$386=$E$2)))"),1.0) -> 1 | AH5: =countifs($O4:$O$2,"<"&$O5,$E4:$E$2,$E$2) -> 0 | AI5: =IFERROR(__xludf.DUMMYFUNCTION("iferror(COUNT(filter($O6:$O$386,$O6:$O$386>$O5,$E5:$E$386=$E$2)))"),0.0) -> 0 | AJ5: =if(AG5=0,1,0) -> 0 | AK5: =IFERROR(__xludf.DUMMYFUNCTION("iferror($O5-min(filter($O5:$O$386,$E5:$E$386=$E$2)))"),8.0) -> 8 | AL5: =IFERROR(__xludf.DUMMYFUNCTION("iferror(join("","",index(sort(filter($F6:$F$386,$O6:$O$386>$O5,$E6:$E$386=$E$2),2,false),0,1)))"),"") | AM5: =IFERROR(__xludf.DUMMYFUNCTION("REGEXREPLACE(join("","",unique({let(conf_picked,filter(E$1:E4,D$1:D4=D5), byrow(unique(TRANSPOSe(Teams!$1:$1)),lambda(rw,if(ISERROR(match(rw,conf_picked,0)),rw,))));iferror(if(#REF!,,transpose(split(#REF!,"","",1,1))))})), ""^,"", """")"),"AAC,ACC,Big 12,Big Ten,CUSA,MAC,MWC,Pac12,SEC,Sun Belt,") -> AAC,ACC,Big 12,Big Ten,CUSA,MAC,MWC,Pac12,SEC,Sun Belt, | AN5: =IFERROR(__xludf.DUMMYFUNCTION("iferror($O5-max(filter($O5:$O$386,arrayformula(isnumber(FIND($E5:$E$386,AM5))))))"),-2.0) -> -2 | AO5: {=countifs($O$2:$O4,"<"&$O5,isnumber(FIND($E$2:$E4,AM5)),TRUE)} -> 1 | AP5: =IFERROR(__xludf.DUMMYFUNCTION("iferror(COUNT(filter($O6:$O$386,$O6:$O$386>$O5,arrayformula(isnumber(FIND($E6:$E$386,AM5))))))"),3.0) -> 3 | AQ5: =if(AN5=0,1,0) -> 0 | AR5: =IFERROR(__xludf.DUMMYFUNCTION("iferror($O5-min(filter($O5:$O$386,arrayformula(isnumber(FIND($E5:$E$386,AM5))))))"),9.0) -> 9 | AS5: =IFERROR(__xludf.DUMMYFUNCTION("iferror(join("","",index(sort(filter($F6:$F$386,$O6:$O$386>$O5,arrayformula(isnumber(FIND($E6:$E$386,AM5)))),2,false),0,1)))"),"Ohio State,Western Michigan,Washington") -> Ohio State,Western Michigan,Washington
A6: =A5+1 -> 5 | B6: 1 | C6: 5 | D6: ='Draft Order'!B6 -> Nico | E6: =if(F6<>"",VLOOKUP(F6,'Teams-Conference, for lookup'!A:B,2,0),"") -> MWC | F6: Boise State | G6: =if(F6<>"",if(match(F6,F:F,0)<ROW(F6),"ERROR: Team already selected in row " & ROW(F6)&". ","")&if(COUNTIFS(E:E,"="&E6,D:D,"="&D6)>1,"ERROR: Player picked from conference more than once.",""),"") | H6: =countif(E7:E16,E6) -> 1 | I6: =countif(E7:E28,E6) -> 2 | M6: =IFERROR(__xludf.DUMMYFUNCTION("counta(iferror(filter(L$2:L5,E$2:E5=E6,L$2:L5<L6)))"),0.0) -> 0 | N6: =IFERROR(__xludf.DUMMYFUNCTION("counta(iferror(filter(L7:L$124,E7:E$124=E6,L7:L$125>L6)))"),0.0) -> 0 | O6: {=XLOOKUP(F6,'Current Week'!B:B,'Current Week'!C:O)} -> 10 | P6: 2 | Q6: NA | R6: BYE | T6: -9 | U6: No Line | W6: 9999 | AA6: =$O6-max($O6:$O$386) -> -2 | AB6: =countif($O5:$O$2,"<"&$O6) -> 1 | AC6: =IFERROR(__xludf.DUMMYFUNCTION("iferror(COUNT(filter($O7:$O$386,$O7:$O$386>$O6)))"),3.0) -> 3 | AD6: =if(AA6=0,1,0) -> 0 | AE6: =$O6-min($O$2:$O6) -> 1 | AF6: =IFERROR(__xludf.DUMMYFUNCTION("iferror(join("","",index(sort(filter($F7:$F$387,$O7:$O$387>$O6),2,false),0,1)))"),"Ohio State,Western Michigan,Washington") -> Ohio State,Western Michigan,Washington | AG6: =IFERROR(__xludf.DUMMYFUNCTION("iferror($O6-max(filter($O6:$O$386,$E6:$E$386=$E$2)))"),1.0) -> 1 | AH6: =countifs($O5:$O$2,"<"&$O6,$E5:$E$2,$E$2) -> 0 | AI6: =IFERROR(__xludf.DUMMYFUNCTION("iferror(COUNT(filter($O7:$O$386,$O7:$O$386>$O6,$E6:$E$386=$E$2)))"),0.0) -> 0 | AJ6: =if(AG6=0,1,0) -> 0 | AK6: =IFERROR(__xludf.DUMMYFUNCTION("iferror($O6-min(filter($O6:$O$386,$E6:$E$386=$E$2)))"),8.0) -> 8 | AL6: =IFERROR(__xludf.DUMMYFUNCTION("iferror(join("","",index(sort(filter($F7:$F$386,$O7:$O$386>$O6,$E7:$E$386=$E$2),2,false),0,1)))"),"") | AM6: =IFERROR(__xludf.DUMMYFUNCTION("REGEXREPLACE(join("","",unique({let(conf_picked,filter(E$1:E5,D$1:D5=D6), byrow(unique(TRANSPOSe(Teams!$1:$1)),lambda(rw,if(ISERROR(match(rw,conf_picked,0)),rw,))));iferror(if(#REF!,,transpose(split(#REF!,"","",1,1))))})), ""^,"", """")"),"AAC,ACC,Big 12,Big Ten,CUSA,MAC,MWC,Pac12,SEC,Sun Belt,") -> AAC,ACC,Big 12,Big Ten,CUSA,MAC,MWC,Pac12,SEC,Sun Belt, | AN6: =IFERROR(__xludf.DUMMYFUNCTION("iferror($O6-max(filter($O6:$O$386,arrayformula(isnumber(FIND($E6:$E$386,AM6))))))"),-2.0) -> -2 | AO6: {=countifs($O$2:$O5,"<"&$O6,isnumber(FIND($E$2:$E5,AM6)),TRUE)} -> 1 | AP6: =IFERROR(__xludf.DUMMYFUNCTION("iferror(COUNT(filter($O7:$O$386,$O7:$O$386>$O6,arrayformula(isnumber(FIND($E7:$E$386,AM6))))))"),3.0) -> 3 | AQ6: =if(AN6=0,1,0) -> 0 | AR6: =IFERROR(__xludf.DUMMYFUNCTION("iferror($O6-min(filter($O6:$O$386,arrayformula(isnumber(FIND($E6:$E$386,AM6))))))"),9.0) -> 9 | AS6: =IFERROR(__xludf.DUMMYFUNCTION("iferror(join("","",index(sort(filter($F7:$F$386,$O7:$O$386>$O6,arrayformula(isnumber(FIND($E7:$E$386,AM6)))),2,false),0,1)))"),"Ohio State,Western Michigan,Washington") -> Ohio State,Western Michigan,Washington
A7: =A6+1 -> 6 | B7: 1 | C7: 6 | D7: ='Draft Order'!B7 -> Vu | E7: =if(F7<>"",VLOOKUP(F7,'Teams-Conference, for lookup'!A:B,2,0),"") -> ACC | F7: Florida State | G7: =if(F7<>"",if(match(F7,F:F,0)<ROW(F7),"ERROR: Team already selected in row " & ROW(F7)&". ","")&if(COUNTIFS(E:E,"="&E7,D:D,"="&D7)>1,"ERROR: Player picked from conference more than once.",""),"") | H7: =countif(E8:E17,E7) -> 1 | I7: =countif(E8:E29,E7) -> 1 | M7: =IFERROR(__xludf.DUMMYFUNCTION("counta(iferror(filter(L$2:L6,E$2:E6=E7,L$2:L6<L7)))"),0.0) -> 0 | N7: =IFERROR(__xludf.DUMMYFUNCTION("counta(iferror(filter(L8:L$124,E8:E$124=E7,L8:L$125>L7)))"),0.0) -> 0 | O7: {=XLOOKUP(F7,'Current Week'!B:B,'Current Week'!C:O)} -> 9 | P7: 3 | Q7: ACC RSNs | R7: BYE | T7: 7 | U7: No Line | W7: 9999 | AA7: =$O7-max($O7:$O$386) -> -3 | AB7: =countif($O6:$O$2,"<"&$O7) -> 0 | AC7: =IFERROR(__xludf.DUMMYFUNCTION("iferror(COUNT(filter($O8:$O$386,$O8:$O$386>$O7)))"),9.0) -> 9 | AD7: =if(AA7=0,1,0) -> 0 | AE7: =$O7-min($O$2:$O7) -> 0 | AF7: =IFERROR(__xludf.DUMMYFUNCTION("iferror(join("","",index(sort(filter($F8:$F$387,$O8:$O$387>$O7),2,false),0,1)))"),"Ohio State,Michigan,West Virginia,Western Michigan,Washington,South Florida,Wisconsin,Penn State,Colorado") -> Ohio State,Michigan,West Virginia,Western Michigan,Washington,South Florida,Wisconsin,Penn State,Colorado | AG7: =IFERROR(__xludf.DUMMYFUNCTION("iferror($O7-max(filter($O7:$O$386,$E7:$E$386=$E$2)))"),0.0) -> 0 | AH7: =countifs($O6:$O$2,"<"&$O7,$E6:$E$2,$E$2) -> 0 | AI7: =IFERROR(__xludf.DUMMYFUNCTION("iferror(COUNT(filter($O8:$O$386,$O8:$O$386>$O7,$E7:$E$386=$E$2)))"),0.0) -> 0 | AJ7: =if(AG7=0,1,0) -> 1 | AK7: =IFERROR(__xludf.DUMMYFUNCTION("iferror($O7-min(filter($O7:$O$386,$E7:$E$386=$E$2)))"),7.0) -> 7 | AL7: =IFERROR(__xludf.DUMMYFUNCTION("iferror(join("","",index(sort(filter($F8:$F$386,$O8:$O$386>$O7,$E8:$E$386=$E$2),2,false),0,1)))"),"") | AM7: =IFERROR(__xludf.DUMMYFUNCTION("REGEXREPLACE(join("","",unique({let(conf_picked,filter(E$1:E6,D$1:D6=D7), byrow(unique(TRANSPOSe(Teams!$1:$1)),lambda(rw,if(ISERROR(match(rw,conf_picked,0)),rw,))));iferror(if(#REF!,,transpose(split(#REF!,"","",1,1))))})), ""^,"", """")"),"AAC,ACC,Big 12,Big Ten,CUSA,MAC,MWC,Pac12,SEC,Sun Belt,") -> AAC,ACC,Big 12,Big Ten,CUSA,MAC,MWC,Pac12,SEC,Sun Belt, | AN7: =IFERROR(__xludf.DUMMYFUNCTION("iferror($O7-max(filter($O7:$O$386,arrayformula(isnumber(FIND($E7:$E$386,AM7))))))"),-3.0) -> -3 | AO7: {=countifs($O$2:$O6,"<"&$O7,isnumber(FIND($E$2:$E6,AM7)),TRUE)} -> 0 | AP7: =IFERROR(__xludf.DUMMYFUNCTION("iferror(COUNT(filter($O8:$O$386,$O8:$O$386>$O7,arrayformula(isnumber(FIND($E8:$E$386,AM7))))))"),9.0) -> 9 | AQ7: =if(AN7=0,1,0) -> 0 | AR7: =IFERROR(__xludf.DUMMYFUNCTION("iferror($O7-min(filter($O7:$O$386,arrayformula(isnumber(FIND($E7:$E$386,AM7))))))"),8.0) -> 8 | AS7: =IFERROR(__xludf.DUMMYFUNCTION("iferror(join("","",index(sort(filter($F8:$F$386,$O8:$O$386>$O7,arrayformula(isnumber(FIND($E8:$E$386,AM7)))),2,false),0,1)))"),"Ohio State,Michigan,West Virginia,Western Michigan,Washington,South Florida,Wisconsin,Penn State,Colorado") -> Ohio State,Michigan,West Virginia,Western Michigan,Washington,South Florida,Wisconsin,Penn State,Colorado
A8: =A7+1 -> 7 | B8: 1 | C8: 7 | D8: ='Draft Order'!B8 -> Josh T. | E8: =if(F8<>"",VLOOKUP(F8,'Teams-Conference, for lookup'!A:B,2,0),"") -> SEC | F8: LSU | G8: =if(F8<>"",if(match(F8,F:F,0)<ROW(F8),"ERROR: Team already selected in row " & ROW(F8)&". ","")&if(COUNTIFS(E:E,"="&E8,D:D,"="&D8)>1,"ERROR: Player picked from conference more than once.",""),"") | H8: =countif(E9:E18,E8) -> 1 | I8: =countif(E9:E30,E8) -> 1 | M8: =IFERROR(__xludf.DUMMYFUNCTION("counta(iferror(filter(L$2:L7,E$2:E7=E8,L$2:L7<L8)))"),0.0) -> 0 | N8: =IFERROR(__xludf.DUMMYFUNCTION("counta(iferror(filter(L9:L$124,E9:E$124=E8,L9:L$125>L8)))"),0.0) -> 0 | O8: {=XLOOKUP(F8,'Current Week'!B:B,'Current Week'!C:O)} -> 7 | P8: 5 | Q8: ESPNU | R8: BYE | T8: 3 | U8: No Line | W8: 9999 | AA8: =$O8-max($O8:$O$386) -> -5 | AB8: =countif($O7:$O$2,"<"&$O8) -> 0 | AC8: =IFERROR(__xludf.DUMMYFUNCTION("iferror(COUNT(filter($O9:$O$386,$O9:$O$386>$O8)))"),45.0) -> 45 | AD8: =if(AA8=0,1,0) -> 0 | AE8: =$O8-min($O$2:$O8) -> 0 | AF8: =IFERROR(__xludf.DUMMYFUNCTION("iferror(join("","",index(sort(filter($F9:$F$387,$O9:$O$387>$O8),2,false),0,1)))"),"Ohio State,Stanford,Michigan,Tennessee,Oklahoma State,Louisville,San Diego State,Appalachian State,Western Kentucky,Air Force,Iowa,West Virginia,Nebraska,Western Michigan,Washington,South Florida,North Carolina,Kansas State,Temple,Toledo,Troy,Middle Tenne"&"ssee,Wisconsin,Navy,USC,Louisiana Tech,Ohio,Virginia Tech,Washington State,Memphis,Utah,New Mexico,Florida,Miami,Tulsa,Pittsburgh,Idaho,Penn State,Minnesota,Georgia Tech,Texas A&M,Old Dominion,Auburn,Colorado,Wyoming") -> Ohio State,Stanford,Michigan,Tennessee,Oklahoma State,Louisville,San Diego State,Appalachian State,Western Kentucky,Air Force,Iowa,West Virginia,Nebraska,Western Michigan,Washington,South Florida,North Carolina,Kansas State,Temple,Toledo,Troy,Middle Tennessee,Wisconsin,Navy,USC,Louisiana Tech,Ohio,Virginia Tech,Washington State,Memphis,Utah,New Mexico,Florida,Miami,Tulsa,Pittsburgh,Idaho,Penn State,Minnesota,Georgia Tech,Texas A&M,Old Dominion,Auburn,Colorado,Wyoming | AG8: =IFERROR(__xludf.DUMMYFUNCTION("iferror($O8-max(filter($O8:$O$386,$E8:$E$386=$E$2)))"),-2.0) -> -2 | AH8: =countifs($O7:$O$2,"<"&$O8,$E7:$E$2,$E$2) -> 0 | AI8: =IFERROR(__xludf.DUMMYFUNCTION("iferror(COUNT(filter($O9:$O$386,$O9:$O$386>$O8,$E8:$E$386=$E$2)))"),0.0) -> 0 | AJ8: =if(AG8=0,1,0) -> 0 | AK8: =IFERROR(__xludf.DUMMYFUNCTION("iferror($O8-min(filter($O8:$O$386,$E8:$E$386=$E$2)))"),5.0) -> 5 | AL8: =IFERROR(__xludf.DUMMYFUNCTION("iferror(join("","",index(sort(filter($F9:$F$386,$O9:$O$386>$O8,$E9:$E$386=$E$2),2,false),0,1)))"),"Louisville,North Carolina,Virginia Tech,Miami,Pittsburgh,Georgia Tech") -> Louisville,North Carolina,Virginia Tech,Miami,Pittsburgh,Georgia Tech | AM8: =IFERROR(__xludf.DUMMYFUNCTION("REGEXREPLACE(join("","",unique({let(conf_picked,filter(E$1:E7,D$1:D7=D8), byrow(unique(TRANSPOSe(Teams!$1:$1)),lambda(rw,if(ISERROR(match(rw,conf_picked,0)),rw,))));iferror(if(#REF!,,transpose(split(#REF!,"","",1,1))))})), ""^,"", """")"),"AAC,ACC,Big 12,Big Ten,CUSA,MAC,MWC,Pac12,SEC,Sun Belt,") -> AAC,ACC,Big 12,Big Ten,CUSA,MAC,MWC,Pac12,SEC,Sun Belt, | AN8: =IFERROR(__xludf.DUMMYFUNCTION("iferror($O8-max(filter($O8:$O$386,arrayformula(isnumber(FIND($E8:$E$386,AM8))))))"),-5.0) -> -5 | AO8: {=countifs($O$2:$O7,"<"&$O8,isnumber(FIND($E$2:$E7,AM8)),TRUE)} -> 0 | AP8: =IFERROR(__xludf.DUMMYFUNCTION("iferror(COUNT(filter($O9:$O$386,$O9:$O$386>$O8,arrayformula(isnumber(FIND($E9:$E$386,AM8))))))"),45.0) -> 45 | AQ8: =if(AN8=0,1,0) -> 0 | AR8: =IFERROR(__xludf.DUMMYFUNCTION("iferror($O8-min(filter($O8:$O$386,arrayformula(isnumber(FIND($E8:$E$386,AM8))))))"),6.0) -> 6 | AS8: =IFERROR(__xludf.DUMMYFUNCTION("iferror(join("","",index(sort(filter($F9:$F$386,$O9:$O$386>$O8,arrayformula(isnumber(FIND($E9:$E$386,AM8)))),2,false),0,1)))"),"Ohio State,Stanford,Michigan,Tennessee,Oklahoma State,Louisville,San Diego State,Appalachian State,Western Kentucky,Air Force,Iowa,West Virginia,Nebraska,Western Michigan,Washington,South Florida,North Carolina,Kansas State,Temple,Toledo,Troy,Middle Tenne"&"ssee,Wisconsin,Navy,USC,Louisiana Tech,Ohio,Virginia Tech,Washington State,Memphis,Utah,New Mexico,Florida,Miami,Tulsa,Pittsburgh,Idaho,Penn State,Minnesota,Georgia Tech,Texas A&M,Old Dominion,Auburn,Colorado,Wyoming") -> Ohio State,Stanford,Michigan,Tennessee,Oklahoma State,Louisville,San Diego State,Appalachian State,Western Kentucky,Air Force,Iowa,West Virginia,Nebraska,Western Michigan,Washington,South Florida,North Carolina,Kansas State,Temple,Toledo,Troy,Middle Tennessee,Wisconsin,Navy,USC,Louisiana Tech,Ohio,Virginia Tech,Washington State,Memphis,Utah,New Mexico,Florida,Miami,Tulsa,Pittsburgh,Idaho,Penn State,Minnesota,Georgia Tech,Texas A&M,Old Dominion,Auburn,Colorado,Wyoming
A9: =A8+1 -> 8 | B9: 1 | C9: 8 | D9: ='Draft Order'!B9 -> Justin | E9: =if(F9<>"",VLOOKUP(F9,'Teams-Conference, for lookup'!A:B,2,0),"") -> Big Ten | F9: Ohio State | G9: =if(F9<>"",if(match(F9,F:F,0)<ROW(F9),"ERROR: Team already selected in row " & ROW(F9)&". ","")&if(COUNTIFS(E:E,"="&E9,D:D,"="&D9)>1,"ERROR: Player picked from conference more than once.",""),"") | H9: =countif(E10:E19,E9) -> 1 | I9: =countif(E10:E31,E9) -> 3 | M9: =IFERROR(__xludf.DUMMYFUNCTION("counta(iferror(filter(L$2:L8,E$2:E8=E9,L$2:L8<L9)))"),0.0) -> 0 | N9: =IFERROR(__xludf.DUMMYFUNCTION("counta(iferror(filter(L10:L$124,E10:E$124=E9,L10:L$125>L9)))"),0.0) -> 0 | O9: {=XLOOKUP(F9,'Current Week'!B:B,'Current Week'!C:O)} -> 11 | P9: 1 | Q9: ABC | R9: BYE | T9: 3½ | U9: No Line | W9: 9999 | AA9: =$O9-max($O9:$O$386) -> -1 | AB9: =countif($O8:$O$2,"<"&$O9) -> 5 | AC9: =IFERROR(__xludf.DUMMYFUNCTION("iferror(COUNT(filter($O10:$O$386,$O10:$O$386>$O9)))"),1.0) -> 1 | AD9: =if(AA9=0,1,0) -> 0 | AE9: =$O9-min($O$2:$O9) -> 4 | AF9: =IFERROR(__xludf.DUMMYFUNCTION("iferror(join("","",index(sort(filter($F10:$F$387,$O10:$O$387>$O9),2,false),0,1)))"),"Western Michigan") -> Western Michigan | AG9: =IFERROR(__xludf.DUMMYFUNCTION("iferror($O9-max(filter($O9:$O$386,$E9:$E$386=$E$2)))"),2.0) -> 2 | AH9: =countifs($O8:$O$2,"<"&$O9,$E8:$E$2,$E$2) -> 1 | AI9: =IFERROR(__xludf.DUMMYFUNCTION("iferror(COUNT(filter($O10:$O$386,$O10:$O$386>$O9,$E9:$E$386=$E$2)))"),0.0) -> 0 | AJ9: =if(AG9=0,1,0) -> 0 | AK9: =IFERROR(__xludf.DUMMYFUNCTION("iferror($O9-min(filter($O9:$O$386,$E9:$E$386=$E$2)))"),9.0) -> 9 | AL9: =IFERROR(__xludf.DUMMYFUNCTION("iferror(join("","",index(sort(filter($F10:$F$386,$O10:$O$386>$O9,$E10:$E$386=$E$2),2,false),0,1)))"),"") | AM9: =IFERROR(__xludf.DUMMYFUNCTION("REGEXREPLACE(join("","",unique({let(conf_picked,filter(E$1:E8,D$1:D8=D9), byrow(unique(TRANSPOSe(Teams!$1:$1)),lambda(rw,if(ISERROR(match(rw,conf_picked,0)),rw,))));iferror(if(#REF!,,transpose(split(#REF!,"","",1,1))))})), ""^,"", """")"),"AAC,ACC,Big 12,Big Ten,CUSA,MAC,MWC,Pac12,SEC,Sun Belt,") -> AAC,ACC,Big 12,Big Ten,CUSA,MAC,MWC,Pac12,SEC,Sun Belt, | AN9: =IFERROR(__xludf.DUMMYFUNCTION("iferror($O9-max(filter($O9:$O$386,arrayformula(isnumber(FIND($E9:$E$386,AM9))))))"),-1.0) -> -1 | AO9: {=countifs($O$2:$O8,"<"&$O9,isnumber(FIND($E$2:$E8,AM9)),TRUE)} -> 5 | AP9: =IFERROR(__xludf.DUMMYFUNCTION("iferror(COUNT(filter($O10:$O$386,$O10:$O$386>$O9,arrayformula(isnumber(FIND($E10:$E$386,AM9))))))"),1.0) -> 1 | AQ9: =if(AN9=0,1,0) -> 0 | AR9: =IFERROR(__xludf.DUMMYFUNCTION("iferror($O9-min(filter($O9:$O$386,arrayformula(isnumber(FIND($E9:$E$386,AM9))))))"),10.0) -> 10 | AS9: =IFERROR(__xludf.DUMMYFUNCTION("iferror(join("","",index(sort(filter($F10:$F$386,$O10:$O$386>$O9,arrayformula(isnumber(FIND($E10:$E$386,AM9)))),2,false),0,1)))"),"Western Michigan") -> Western Michigan
