Workbook

Sheet Standings
A1: =HYPERLINK("https://docs.google.com/document/d/1-e84tTr9zFoIfOR2Z7Z-1lI4YO7v6GoaThMqj1UrcXE/edit","Rules") -> Rules | B1: Season | F1: Current Week (Projections based on most recent Consensus) | M1: Actaul + Chalk Projections
A2: Players | B2: Wins | C2: Losses | D2: P5 Ws | E2: G5 Ws | F2: Games | G2: Games Played | H2: Wins | I2: Games Left | J2: Expected Wins | K2: Upsets Won | L2: Upsets Lost
A3: {=sort(A17:M29,2,false,3,true,7,false,8,true,1,true)} -> DavEmily | B3: 72 | C3: 49 | D3: 39 | E3: 33 | F3: 10 | G3: 10 | H3: 6 | I3: 0 | J3: 1 | K3: 0 | L3: 0 | M3: 6
A4: Janice/Mike | B4: 71 | C4: 49 | D4: 41 | E4: 30 | F4: 10 | G4: 10 | H4: 6 | I4: 0 | J4: 0 | K4: 0 | L4: 0 | M4: 6
A5: Brad | B5: 70 | C5: 50 | D5: 39 | E5: 31 | F5: 10 | G5: 10 | H5: 4 | I5: 0 | J5: 0 | K5: 0 | L5: 0 | M5: 4
A6: Justin | B6: 67 | C6: 52 | D6: 42 | E6: 25 | F6: 7 | G6: 7 | H6: 3 | I6: 0 | J6: 0 | K6: 0 | L6: 0 | M6: 3
A7: Nick G. | B7: 65 | C7: 55 | D7: 40 | E7: 25 | F7: 9 | G7: 9 | H7: 4 | I7: 0 | J7: 0 | K7: 0 | L7: 0 | M7: 4
A8: Dan | B8: 64 | C8: 56 | D8: 39 | E8: 25 | F8: 10 | G8: 10 | H8: 3 | I8: 0 | J8: 0 | K8: 0 | L8: 0 | M8: 3
A9: Masa | B9: 64 | C9: 56 | D9: 26 | E9: 38 | F9: 10 | G9: 10 | H9: 3 | I9: 0 | J9: 0 | K9: 0 | L9: 0 | M9: 3
A10: Josh | B10: 61 | C10: 58 | D10: 32 | E10: 29 | F10: 9 | G10: 9 | H10: 7 | I10: 0 | J10: 0 | K10: 0 | L10: 0 | M10: 7
A11: Gary | B11: 60 | C11: 59 | D11: 25 | E11: 35 | F11: 10 | G11: 10 | H11: 6 | I11: 0 | J11: 0 | K11: 0 | L11: 0 | M11: 6
A12: Vu | B12: 59 | C12: 60 | D12: 30 | E12: 29 | F12: 10 | G12: 9 | H12: 4 | I12: 1 | J12: 0 | K12: 0 | L12: 0 | M12: 4
A13: Nico | B13: 59 | C13: 61 | D13: 32 | E13: 27 | F13: 10 | G13: 10 | H13: 4 | I13: 0 | J13: 0 | K13: 0 | L13: 0 | M13: 4
A14: Jeannine | B14: 58 | C14: 60 | D14: 34 | E14: 24 | F14: 10 | G14: 9 | H14: 3 | I14: 1 | J14: 0 | K14: 0 | L14: 0 | M14: 3
A15: Nick A. | B15: 57 | C15: 64 | D15: 29 | E15: 28 | F15: 10 | G15: 10 | H15: 4 | I15: 0 | J15: 0 | K15: 0 | L15: 0 | M15: 4
A17: {='Draft Order'!B2:B29} -> Jeannine | B17: =sumif('Current Week'!$B:$B,$A17,'Current Week'!D:D) -> 58 | C17: =sumif('Current Week'!$B:$B,$A17,'Current Week'!E:E) -> 60 | D17: =sumifs('Current Week'!D:D,'Current Week'!$B:$B,$A17,'Current Week'!AN:AN,"Power 5") -> 34 | E17: =sumifs('Current Week'!D:D,'Current Week'!$B:$B,$A17,'Current Week'!AN:AN,"Group of 5") -> 24 | F17: =10-countifs('Current Week'!B:B,A17,'Current Week'!G:G,"") -> 10 | G17: =IFERROR(__xludf.DUMMYFUNCTION("COUNTA(iferror(filter('Current Week'!B:B,'Current Week'!B:B=A17,left('Current Week'!G:G,5)=""FINAL"")))"),9.0) -> 9 | H17: =countifs('Current Week'!B:B,A17,'Current Week'!AO:AO,"=TRUE") -> 3 | I17: =F17-G17 -> 1 | J17: =IFERROR(__xludf.DUMMYFUNCTION("countifs('Current Week'!B:B,A17,'Current Week'!K:K,""<0"")+counta(iferror(filter('Current Week'!B:B,'Current Week'!B:B=A17,'Current Week'!F:F<>"""",'Current Week'!K:K="""",'Current Week'!H:H="""")))"),0.0) -> 0 | K17: =IFERROR(__xludf.DUMMYFUNCTION("counta(iferror(filter('Current Week'!B:B,'Current Week'!B:B=A17,'Current Week'!K:K>0,not(iserror(find(""FINAL"",'Current Week'!G:G))),'Current Week'!AO:AO=TRUE)))+counta(iferror(filter('Current Week'!B:B,'Current Week'!B:B=A17,'Current Week'!K:K="""",not("&"iserror(find(""FINAL"",'Current Week'!G:G))),'Current Week'!AO:AO=TRUE,'Current Week'!H:H="""")))"),0.0) -> 0 | L17: =IFERROR(__xludf.DUMMYFUNCTION("counta(iferror(filter('Current Week'!B:B,'Current Week'!B:B=A17,'Current Week'!K:K<0,not(iserror(find(""FINAL"",'Current Week'!G:G))),'Current Week'!AO:AO<>TRUE)))"),0.0) -> 0 | M17: =IFERROR(__xludf.DUMMYFUNCTION("H17+counta(iferror(filter('Current Week'!B:B,'Current Week'!B:B=A17,'Current Week'!K:K<0,iserror(find(""FINAL"",'Current Week'!G:G)))))+counta(iferror(filter('Current Week'!B:B,'Current Week'!B:B=A17,'Current Week'!F:F<>"""",'Current Week'!J:J="""",'Curre"&"nt Week'!H:H="""",iserror(find(""FINAL"",'Current Week'!G:G)))))"),3.0) -> 3
A18: Dan | B18: =sumif('Current Week'!$B:$B,$A18,'Current Week'!D:D) -> 64 | C18: =sumif('Current Week'!$B:$B,$A18,'Current Week'!E:E) -> 56 | D18: =sumifs('Current Week'!D:D,'Current Week'!$B:$B,$A18,'Current Week'!AN:AN,"Power 5") -> 39 | E18: =sumifs('Current Week'!D:D,'Current Week'!$B:$B,$A18,'Current Week'!AN:AN,"Group of 5") -> 25 | F18: =10-countifs('Current Week'!B:B,A18,'Current Week'!G:G,"") -> 10 | G18: =IFERROR(__xludf.DUMMYFUNCTION("COUNTA(iferror(filter('Current Week'!B:B,'Current Week'!B:B=A18,left('Current Week'!G:G,5)=""FINAL"")))"),10.0) -> 10 | H18: =countifs('Current Week'!B:B,A18,'Current Week'!AO:AO,"=TRUE") -> 3 | I18: =F18-G18 -> 0 | J18: =IFERROR(__xludf.DUMMYFUNCTION("countifs('Current Week'!B:B,A18,'Current Week'!K:K,""<0"")+counta(iferror(filter('Current Week'!B:B,'Current Week'!B:B=A18,'Current Week'!F:F<>"""",'Current Week'!K:K="""",'Current Week'!H:H="""")))"),0.0) -> 0 | K18: =IFERROR(__xludf.DUMMYFUNCTION("counta(iferror(filter('Current Week'!B:B,'Current Week'!B:B=A18,'Current Week'!K:K>0,not(iserror(find(""FINAL"",'Current Week'!G:G))),'Current Week'!AO:AO=TRUE)))+counta(iferror(filter('Current Week'!B:B,'Current Week'!B:B=A18,'Current Week'!K:K="""",not("&"iserror(find(""FINAL"",'Current Week'!G:G))),'Current Week'!AO:AO=TRUE,'Current Week'!H:H="""")))"),0.0) -> 0 | L18: =IFERROR(__xludf.DUMMYFUNCTION("counta(iferror(filter('Current Week'!B:B,'Current Week'!B:B=A18,'Current Week'!K:K<0,not(iserror(find(""FINAL"",'Current Week'!G:G))),'Current Week'!AO:AO<>TRUE)))"),0.0) -> 0 | M18: =IFERROR(__xludf.DUMMYFUNCTION("H18+counta(iferror(filter('Current Week'!B:B,'Current Week'!B:B=A18,'Current Week'!K:K<0,iserror(find(""FINAL"",'Current Week'!G:G)))))+counta(iferror(filter('Current Week'!B:B,'Current Week'!B:B=A18,'Current Week'!F:F<>"""",'Current Week'!J:J="""",'Curre"&"nt Week'!H:H="""",iserror(find(""FINAL"",'Current Week'!G:G)))))"),3.0) -> 3
A19: DavEmily | B19: =sumif('Current Week'!$B:$B,$A19,'Current Week'!D:D) -> 72 | C19: =sumif('Current Week'!$B:$B,$A19,'Current Week'!E:E) -> 49 | D19: =sumifs('Current Week'!D:D,'Current Week'!$B:$B,$A19,'Current Week'!AN:AN,"Power 5") -> 39 | E19: =sumifs('Current Week'!D:D,'Current Week'!$B:$B,$A19,'Current Week'!AN:AN,"Group of 5") -> 33 | F19: =10-countifs('Current Week'!B:B,A19,'Current Week'!G:G,"") -> 10 | G19: =IFERROR(__xludf.DUMMYFUNCTION("COUNTA(iferror(filter('Current Week'!B:B,'Current Week'!B:B=A19,left('Current Week'!G:G,5)=""FINAL"")))"),10.0) -> 10 | H19: =countifs('Current Week'!B:B,A19,'Current Week'!AO:AO,"=TRUE") -> 6 | I19: =F19-G19 -> 0 | J19: =IFERROR(__xludf.DUMMYFUNCTION("countifs('Current Week'!B:B,A19,'Current Week'!K:K,""<0"")+counta(iferror(filter('Current Week'!B:B,'Current Week'!B:B=A19,'Current Week'!F:F<>"""",'Current Week'!K:K="""",'Current Week'!H:H="""")))"),1.0) -> 1 | K19: =IFERROR(__xludf.DUMMYFUNCTION("counta(iferror(filter('Current Week'!B:B,'Current Week'!B:B=A19,'Current Week'!K:K>0,not(iserror(find(""FINAL"",'Current Week'!G:G))),'Current Week'!AO:AO=TRUE)))+counta(iferror(filter('Current Week'!B:B,'Current Week'!B:B=A19,'Current Week'!K:K="""",not("&"iserror(find(""FINAL"",'Current Week'!G:G))),'Current Week'!AO:AO=TRUE,'Current Week'!H:H="""")))"),0.0) -> 0 | L19: =IFERROR(__xludf.DUMMYFUNCTION("counta(iferror(filter('Current Week'!B:B,'Current Week'!B:B=A19,'Current Week'!K:K<0,not(iserror(find(""FINAL"",'Current Week'!G:G))),'Current Week'!AO:AO<>TRUE)))"),0.0) -> 0 | M19: =IFERROR(__xludf.DUMMYFUNCTION("H19+counta(iferror(filter('Current Week'!B:B,'Current Week'!B:B=A19,'Current Week'!K:K<0,iserror(find(""FINAL"",'Current Week'!G:G)))))+counta(iferror(filter('Current Week'!B:B,'Current Week'!B:B=A19,'Current Week'!F:F<>"""",'Current Week'!J:J="""",'Curre"&"nt Week'!H:H="""",iserror(find(""FINAL"",'Current Week'!G:G)))))"),6.0) -> 6
A20: Nick G. | B20: =sumif('Current Week'!$B:$B,$A20,'Current Week'!D:D) -> 65 | C20: =sumif('Current Week'!$B:$B,$A20,'Current Week'!E:E) -> 55 | D20: =sumifs('Current Week'!D:D,'Current Week'!$B:$B,$A20,'Current Week'!AN:AN,"Power 5") -> 40 | E20: =sumifs('Current Week'!D:D,'Current Week'!$B:$B,$A20,'Current Week'!AN:AN,"Group of 5") -> 25 | F20: =10-countifs('Current Week'!B:B,A20,'Current Week'!G:G,"") -> 9 | G20: =IFERROR(__xludf.DUMMYFUNCTION("COUNTA(iferror(filter('Current Week'!B:B,'Current Week'!B:B=A20,left('Current Week'!G:G,5)=""FINAL"")))"),9.0) -> 9 | H20: =countifs('Current Week'!B:B,A20,'Current Week'!AO:AO,"=TRUE") -> 4 | I20: =F20-G20 -> 0 | J20: =IFERROR(__xludf.DUMMYFUNCTION("countifs('Current Week'!B:B,A20,'Current Week'!K:K,""<0"")+counta(iferror(filter('Current Week'!B:B,'Current Week'!B:B=A20,'Current Week'!F:F<>"""",'Current Week'!K:K="""",'Current Week'!H:H="""")))"),0.0) -> 0 | K20: =IFERROR(__xludf.DUMMYFUNCTION("counta(iferror(filter('Current Week'!B:B,'Current Week'!B:B=A20,'Current Week'!K:K>0,not(iserror(find(""FINAL"",'Current Week'!G:G))),'Current Week'!AO:AO=TRUE)))+counta(iferror(filter('Current Week'!B:B,'Current Week'!B:B=A20,'Current Week'!K:K="""",not("&"iserror(find(""FINAL"",'Current Week'!G:G))),'Current Week'!AO:AO=TRUE,'Current Week'!H:H="""")))"),0.0) -> 0 | L20: =IFERROR(__xludf.DUMMYFUNCTION("counta(iferror(filter('Current Week'!B:B,'Current Week'!B:B=A20,'Current Week'!K:K<0,not(iserror(find(""FINAL"",'Current Week'!G:G))),'Current Week'!AO:AO<>TRUE)))"),0.0) -> 0 | M20: =IFERROR(__xludf.DUMMYFUNCTION("H20+counta(iferror(filter('Current Week'!B:B,'Current Week'!B:B=A20,'Current Week'!K:K<0,iserror(find(""FINAL"",'Current Week'!G:G)))))+counta(iferror(filter('Current Week'!B:B,'Current Week'!B:B=A20,'Current Week'!F:F<>"""",'Current Week'!J:J="""",'Curre"&"nt Week'!H:H="""",iserror(find(""FINAL"",'Current Week'!G:G)))))"),4.0) -> 4
A21: Masa | B21: =sumif('Current Week'!$B:$B,$A21,'Current Week'!D:D) -> 64 | C21: =sumif('Current Week'!$B:$B,$A21,'Current Week'!E:E) -> 56 | D21: =sumifs('Current Week'!D:D,'Current Week'!$B:$B,$A21,'Current Week'!AN:AN,"Power 5") -> 26 | E21: =sumifs('Current Week'!D:D,'Current Week'!$B:$B,$A21,'Current Week'!AN:AN,"Group of 5") -> 38 | F21: =10-countifs('Current Week'!B:B,A21,'Current Week'!G:G,"") -> 10 | G21: =IFERROR(__xludf.DUMMYFUNCTION("COUNTA(iferror(filter('Current Week'!B:B,'Current Week'!B:B=A21,left('Current Week'!G:G,5)=""FINAL"")))"),10.0) -> 10 | H21: =countifs('Current Week'!B:B,A21,'Current Week'!AO:AO,"=TRUE") -> 3 | I21: =F21-G21 -> 0 | J21: =IFERROR(__xludf.DUMMYFUNCTION("countifs('Current Week'!B:B,A21,'Current Week'!K:K,""<0"")+counta(iferror(filter('Current Week'!B:B,'Current Week'!B:B=A21,'Current Week'!F:F<>"""",'Current Week'!K:K="""",'Current Week'!H:H="""")))"),0.0) -> 0 | K21: =IFERROR(__xludf.DUMMYFUNCTION("counta(iferror(filter('Current Week'!B:B,'Current Week'!B:B=A21,'Current Week'!K:K>0,not(iserror(find(""FINAL"",'Current Week'!G:G))),'Current Week'!AO:AO=TRUE)))+counta(iferror(filter('Current Week'!B:B,'Current Week'!B:B=A21,'Current Week'!K:K="""",not("&"iserror(find(""FINAL"",'Current Week'!G:G))),'Current Week'!AO:AO=TRUE,'Current Week'!H:H="""")))"),0.0) -> 0 | L21: =IFERROR(__xludf.DUMMYFUNCTION("counta(iferror(filter('Current Week'!B:B,'Current Week'!B:B=A21,'Current Week'!K:K<0,not(iserror(find(""FINAL"",'Current Week'!G:G))),'Current Week'!AO:AO<>TRUE)))"),0.0) -> 0 | M21: =IFERROR(__xludf.DUMMYFUNCTION("H21+counta(iferror(filter('Current Week'!B:B,'Current Week'!B:B=A21,'Current Week'!K:K<0,iserror(find(""FINAL"",'Current Week'!G:G)))))+counta(iferror(filter('Current Week'!B:B,'Current Week'!B:B=A21,'Current Week'!F:F<>"""",'Current Week'!J:J="""",'Curre"&"nt Week'!H:H="""",iserror(find(""FINAL"",'Current Week'!G:G)))))"),3.0) -> 3
A22: Josh | B22: =sumif('Current Week'!$B:$B,$A22,'Current Week'!D:D) -> 61 | C22: =sumif('Current Week'!$B:$B,$A22,'Current Week'!E:E) -> 58 | D22: =sumifs('Current Week'!D:D,'Current Week'!$B:$B,$A22,'Current Week'!AN:AN,"Power 5") -> 32 | E22: =sumifs('Current Week'!D:D,'Current Week'!$B:$B,$A22,'Current Week'!AN:AN,"Group of 5") -> 29 | F22: =10-countifs('Current Week'!B:B,A22,'Current Week'!G:G,"") -> 9 | G22: =IFERROR(__xludf.DUMMYFUNCTION("COUNTA(iferror(filter('Current Week'!B:B,'Current Week'!B:B=A22,left('Current Week'!G:G,5)=""FINAL"")))"),9.0) -> 9 | H22: =countifs('Current Week'!B:B,A22,'Current Week'!AO:AO,"=TRUE") -> 7 | I22: =F22-G22 -> 0 | J22: =IFERROR(__xludf.DUMMYFUNCTION("countifs('Current Week'!B:B,A22,'Current Week'!K:K,""<0"")+counta(iferror(filter('Current Week'!B:B,'Current Week'!B:B=A22,'Current Week'!F:F<>"""",'Current Week'!K:K="""",'Current Week'!H:H="""")))"),0.0) -> 0 | K22: =IFERROR(__xludf.DUMMYFUNCTION("counta(iferror(filter('Current Week'!B:B,'Current Week'!B:B=A22,'Current Week'!K:K>0,not(iserror(find(""FINAL"",'Current Week'!G:G))),'Current Week'!AO:AO=TRUE)))+counta(iferror(filter('Current Week'!B:B,'Current Week'!B:B=A22,'Current Week'!K:K="""",not("&"iserror(find(""FINAL"",'Current Week'!G:G))),'Current Week'!AO:AO=TRUE,'Current Week'!H:H="""")))"),0.0) -> 0 | L22: =IFERROR(__xludf.DUMMYFUNCTION("counta(iferror(filter('Current Week'!B:B,'Current Week'!B:B=A22,'Current Week'!K:K<0,not(iserror(find(""FINAL"",'Current Week'!G:G))),'Current Week'!AO:AO<>TRUE)))"),0.0) -> 0 | M22: =IFERROR(__xludf.DUMMYFUNCTION("H22+counta(iferror(filter('Current Week'!B:B,'Current Week'!B:B=A22,'Current Week'!K:K<0,iserror(find(""FINAL"",'Current Week'!G:G)))))+counta(iferror(filter('Current Week'!B:B,'Current Week'!B:B=A22,'Current Week'!F:F<>"""",'Current Week'!J:J="""",'Curre"&"nt Week'!H:H="""",iserror(find(""FINAL"",'Current Week'!G:G)))))"),7.0) -> 7
A23: Brad | B23: =sumif('Current Week'!$B:$B,$A23,'Current Week'!D:D) -> 70 | C23: =sumif('Current Week'!$B:$B,$A23,'Current Week'!E:E) -> 50 | D23: =sumifs('Current Week'!D:D,'Current Week'!$B:$B,$A23,'Current Week'!AN:AN,"Power 5") -> 39 | E23: =sumifs('Current Week'!D:D,'Current Week'!$B:$B,$A23,'Current Week'!AN:AN,"Group of 5") -> 31 | F23: =10-countifs('Current Week'!B:B,A23,'Current Week'!G:G,"") -> 10 | G23: =IFERROR(__xludf.DUMMYFUNCTION("COUNTA(iferror(filter('Current Week'!B:B,'Current Week'!B:B=A23,left('Current Week'!G:G,5)=""FINAL"")))"),10.0) -> 10 | H23: =countifs('Current Week'!B:B,A23,'Current Week'!AO:AO,"=TRUE") -> 4 | I23: =F23-G23 -> 0 | J23: =IFERROR(__xludf.DUMMYFUNCTION("countifs('Current Week'!B:B,A23,'Current Week'!K:K,""<0"")+counta(iferror(filter('Current Week'!B:B,'Current Week'!B:B=A23,'Current Week'!F:F<>"""",'Current Week'!K:K="""",'Current Week'!H:H="""")))"),0.0) -> 0 | K23: =IFERROR(__xludf.DUMMYFUNCTION("counta(iferror(filter('Current Week'!B:B,'Current Week'!B:B=A23,'Current Week'!K:K>0,not(iserror(find(""FINAL"",'Current Week'!G:G))),'Current Week'!AO:AO=TRUE)))+counta(iferror(filter('Current Week'!B:B,'Current Week'!B:B=A23,'Current Week'!K:K="""",not("&"iserror(find(""FINAL"",'Current Week'!G:G))),'Current Week'!AO:AO=TRUE,'Current Week'!H:H="""")))"),0.0) -> 0 | L23: =IFERROR(__xludf.DUMMYFUNCTION("counta(iferror(filter('Current Week'!B:B,'Current Week'!B:B=A23,'Current Week'!K:K<0,not(iserror(find(""FINAL"",'Current Week'!G:G))),'Current Week'!AO:AO<>TRUE)))"),0.0) -> 0 | M23: =IFERROR(__xludf.DUMMYFUNCTION("H23+counta(iferror(filter('Current Week'!B:B,'Current Week'!B:B=A23,'Current Week'!K:K<0,iserror(find(""FINAL"",'Current Week'!G:G)))))+counta(iferror(filter('Current Week'!B:B,'Current Week'!B:B=A23,'Current Week'!F:F<>"""",'Current Week'!J:J="""",'Curre"&"nt Week'!H:H="""",iserror(find(""FINAL"",'Current Week'!G:G)))))"),4.0) -> 4
A24: Gary | B24: =sumif('Current Week'!$B:$B,$A24,'Current Week'!D:D) -> 60 | C24: =sumif('Current Week'!$B:$B,$A24,'Current Week'!E:E) -> 59 | D24: =sumifs('Current Week'!D:D,'Current Week'!$B:$B,$A24,'Current Week'!AN:AN,"Power 5") -> 25 | E24: =sumifs('Current Week'!D:D,'Current Week'!$B:$B,$A24,'Current Week'!AN:AN,"Group of 5") -> 35 | F24: =10-countifs('Current Week'!B:B,A24,'Current Week'!G:G,"") -> 10 | G24: =IFERROR(__xludf.DUMMYFUNCTION("COUNTA(iferror(filter('Current Week'!B:B,'Current Week'!B:B=A24,left('Current Week'!G:G,5)=""FINAL"")))"),10.0) -> 10 | H24: =countifs('Current Week'!B:B,A24,'Current Week'!AO:AO,"=TRUE") -> 6 | I24: =F24-G24 -> 0 | J24: =IFERROR(__xludf.DUMMYFUNCTION("countifs('Current Week'!B:B,A24,'Current Week'!K:K,""<0"")+counta(iferror(filter('Current Week'!B:B,'Current Week'!B:B=A24,'Current Week'!F:F<>"""",'Current Week'!K:K="""",'Current Week'!H:H="""")))"),0.0) -> 0 | K24: =IFERROR(__xludf.DUMMYFUNCTION("counta(iferror(filter('Current Week'!B:B,'Current Week'!B:B=A24,'Current Week'!K:K>0,not(iserror(find(""FINAL"",'Current Week'!G:G))),'Current Week'!AO:AO=TRUE)))+counta(iferror(filter('Current Week'!B:B,'Current Week'!B:B=A24,'Current Week'!K:K="""",not("&"iserror(find(""FINAL"",'Current Week'!G:G))),'Current Week'!AO:AO=TRUE,'Current Week'!H:H="""")))"),0.0) -> 0 | L24: =IFERROR(__xludf.DUMMYFUNCTION("counta(iferror(filter('Current Week'!B:B,'Current Week'!B:B=A24,'Current Week'!K:K<0,not(iserror(find(""FINAL"",'Current Week'!G:G))),'Current Week'!AO:AO<>TRUE)))"),0.0) -> 0 | M24: =IFERROR(__xludf.DUMMYFUNCTION("H24+counta(iferror(filter('Current Week'!B:B,'Current Week'!B:B=A24,'Current Week'!K:K<0,iserror(find(""FINAL"",'Current Week'!G:G)))))+counta(iferror(filter('Current Week'!B:B,'Current Week'!B:B=A24,'Current Week'!F:F<>"""",'Current Week'!J:J="""",'Curre"&"nt Week'!H:H="""",iserror(find(""FINAL"",'Current Week'!G:G)))))"),6.0) -> 6
A25: Nick A. | B25: =sumif('Current Week'!$B:$B,$A25,'Current Week'!D:D) -> 57 | C25: =sumif('Current Week'!$B:$B,$A25,'Current Week'!E:E) -> 64 | D25: =sumifs('Current Week'!D:D,'Current Week'!$B:$B,$A25,'Current Week'!AN:AN,"Power 5") -> 29 | E25: =sumifs('Current Week'!D:D,'Current Week'!$B:$B,$A25,'Current Week'!AN:AN,"Group of 5") -> 28 | F25: =10-countifs('Current Week'!B:B,A25,'Current Week'!G:G,"") -> 10 | G25: =IFERROR(__xludf.DUMMYFUNCTION("COUNTA(iferror(filter('Current Week'!B:B,'Current Week'!B:B=A25,left('Current Week'!G:G,5)=""FINAL"")))"),10.0) -> 10 | H25: =countifs('Current Week'!B:B,A25,'Current Week'!AO:AO,"=TRUE") -> 4 | I25: =F25-G25 -> 0 | J25: =IFERROR(__xludf.DUMMYFUNCTION("countifs('Current Week'!B:B,A25,'Current Week'!K:K,""<0"")+counta(iferror(filter('Current Week'!B:B,'Current Week'!B:B=A25,'Current Week'!F:F<>"""",'Current Week'!K:K="""",'Current Week'!H:H="""")))"),0.0) -> 0 | K25: =IFERROR(__xludf.DUMMYFUNCTION("counta(iferror(filter('Current Week'!B:B,'Current Week'!B:B=A25,'Current Week'!K:K>0,not(iserror(find(""FINAL"",'Current Week'!G:G))),'Current Week'!AO:AO=TRUE)))+counta(iferror(filter('Current Week'!B:B,'Current Week'!B:B=A25,'Current Week'!K:K="""",not("&"iserror(find(""FINAL"",'Current Week'!G:G))),'Current Week'!AO:AO=TRUE,'Current Week'!H:H="""")))"),0.0) -> 0 | L25: =IFERROR(__xludf.DUMMYFUNCTION("counta(iferror(filter('Current Week'!B:B,'Current Week'!B:B=A25,'Current Week'!K:K<0,not(iserror(find(""FINAL"",'Current Week'!G:G))),'Current Week'!AO:AO<>TRUE)))"),0.0) -> 0 | M25: =IFERROR(__xludf.DUMMYFUNCTION("H25+counta(iferror(filter('Current Week'!B:B,'Current Week'!B:B=A25,'Current Week'!K:K<0,iserror(find(""FINAL"",'Current Week'!G:G)))))+counta(iferror(filter('Current Week'!B:B,'Current Week'!B:B=A25,'Current Week'!F:F<>"""",'Current Week'!J:J="""",'Curre"&"nt Week'!H:H="""",iserror(find(""FINAL"",'Current Week'!G:G)))))"),4.0) -> 4
A26: Justin | B26: =sumif('Current Week'!$B:$B,$A26,'Current Week'!D:D) -> 67 | C26: =sumif('Current Week'!$B:$B,$A26,'Current Week'!E:E) -> 52 | D26: =sumifs('Current Week'!D:D,'Current Week'!$B:$B,$A26,'Current Week'!AN:AN,"Power 5") -> 42 | E26: =sumifs('Current Week'!D:D,'Current Week'!$B:$B,$A26,'Current Week'!AN:AN,"Group of 5") -> 25 | F26: =10-countifs('Current Week'!B:B,A26,'Current Week'!G:G,"") -> 7 | G26: =IFERROR(__xludf.DUMMYFUNCTION("COUNTA(iferror(filter('Current Week'!B:B,'Current Week'!B:B=A26,left('Current Week'!G:G,5)=""FINAL"")))"),7.0) -> 7 | H26: =countifs('Current Week'!B:B,A26,'Current Week'!AO:AO,"=TRUE") -> 3 | I26: =F26-G26 -> 0 | J26: =IFERROR(__xludf.DUMMYFUNCTION("countifs('Current Week'!B:B,A26,'Current Week'!K:K,""<0"")+counta(iferror(filter('Current Week'!B:B,'Current Week'!B:B=A26,'Current Week'!F:F<>"""",'Current Week'!K:K="""",'Current Week'!H:H="""")))"),0.0) -> 0 | K26: =IFERROR(__xludf.DUMMYFUNCTION("counta(iferror(filter('Current Week'!B:B,'Current Week'!B:B=A26,'Current Week'!K:K>0,not(iserror(find(""FINAL"",'Current Week'!G:G))),'Current Week'!AO:AO=TRUE)))+counta(iferror(filter('Current Week'!B:B,'Current Week'!B:B=A26,'Current Week'!K:K="""",not("&"iserror(find(""FINAL"",'Current Week'!G:G))),'Current Week'!AO:AO=TRUE,'Current Week'!H:H="""")))"),0.0) -> 0 | L26: =IFERROR(__xludf.DUMMYFUNCTION("counta(iferror(filter('Current Week'!B:B,'Current Week'!B:B=A26,'Current Week'!K:K<0,not(iserror(find(""FINAL"",'Current Week'!G:G))),'Current Week'!AO:AO<>TRUE)))"),0.0) -> 0 | M26: =IFERROR(__xludf.DUMMYFUNCTION("H26+counta(iferror(filter('Current Week'!B:B,'Current Week'!B:B=A26,'Current Week'!K:K<0,iserror(find(""FINAL"",'Current Week'!G:G)))))+counta(iferror(filter('Current Week'!B:B,'Current Week'!B:B=A26,'Current Week'!F:F<>"""",'Current Week'!J:J="""",'Curre"&"nt Week'!H:H="""",iserror(find(""FINAL"",'Current Week'!G:G)))))"),3.0) -> 3
A27: Vu | B27: =sumif('Current Week'!$B:$B,$A27,'Current Week'!D:D) -> 59 | C27: =sumif('Current Week'!$B:$B,$A27,'Current Week'!E:E) -> 60 | D27: =sumifs('Current Week'!D:D,'Current Week'!$B:$B,$A27,'Current Week'!AN:AN,"Power 5") -> 30 | E27: =sumifs('Current Week'!D:D,'Current Week'!$B:$B,$A27,'Current Week'!AN:AN,"Group of 5") -> 29 | F27: =10-countifs('Current Week'!B:B,A27,'Current Week'!G:G,"") -> 10 | G27: =IFERROR(__xludf.DUMMYFUNCTION("COUNTA(iferror(filter('Current Week'!B:B,'Current Week'!B:B=A27,left('Current Week'!G:G,5)=""FINAL"")))"),9.0) -> 9 | H27: =countifs('Current Week'!B:B,A27,'Current Week'!AO:AO,"=TRUE") -> 4 | I27: =F27-G27 -> 1 | J27: =IFERROR(__xludf.DUMMYFUNCTION("countifs('Current Week'!B:B,A27,'Current Week'!K:K,""<0"")+counta(iferror(filter('Current Week'!B:B,'Current Week'!B:B=A27,'Current Week'!F:F<>"""",'Current Week'!K:K="""",'Current Week'!H:H="""")))"),0.0) -> 0 | K27: =IFERROR(__xludf.DUMMYFUNCTION("counta(iferror(filter('Current Week'!B:B,'Current Week'!B:B=A27,'Current Week'!K:K>0,not(iserror(find(""FINAL"",'Current Week'!G:G))),'Current Week'!AO:AO=TRUE)))+counta(iferror(filter('Current Week'!B:B,'Current Week'!B:B=A27,'Current Week'!K:K="""",not("&"iserror(find(""FINAL"",'Current Week'!G:G))),'Current Week'!AO:AO=TRUE,'Current Week'!H:H="""")))"),0.0) -> 0 | L27: =IFERROR(__xludf.DUMMYFUNCTION("counta(iferror(filter('Current Week'!B:B,'Current Week'!B:B=A27,'Current Week'!K:K<0,not(iserror(find(""FINAL"",'Current Week'!G:G))),'Current Week'!AO:AO<>TRUE)))"),0.0) -> 0 | M27: =IFERROR(__xludf.DUMMYFUNCTION("H27+counta(iferror(filter('Current Week'!B:B,'Current Week'!B:B=A27,'Current Week'!K:K<0,iserror(find(""FINAL"",'Current Week'!G:G)))))+counta(iferror(filter('Current Week'!B:B,'Current Week'!B:B=A27,'Current Week'!F:F<>"""",'Current Week'!J:J="""",'Curre"&"nt Week'!H:H="""",iserror(find(""FINAL"",'Current Week'!G:G)))))"),4.0) -> 4
A28: Janice/Mike | B28: =sumif('Current Week'!$B:$B,$A28,'Current Week'!D:D) -> 71 | C28: =sumif('Current Week'!$B:$B,$A28,'Current Week'!E:E) -> 49 | D28: =sumifs('Current Week'!D:D,'Current Week'!$B:$B,$A28,'Current Week'!AN:AN,"Power 5") -> 41 | E28: =sumifs('Current Week'!D:D,'Current Week'!$B:$B,$A28,'Current Week'!AN:AN,"Group of 5") -> 30 | F28: =10-countifs('Current Week'!B:B,A28,'Current Week'!G:G,"") -> 10 | G28: =IFERROR(__xludf.DUMMYFUNCTION("COUNTA(iferror(filter('Current Week'!B:B,'Current Week'!B:B=A28,left('Current Week'!G:G,5)=""FINAL"")))"),10.0) -> 10 | H28: =countifs('Current Week'!B:B,A28,'Current Week'!AO:AO,"=TRUE") -> 6 | I28: =F28-G28 -> 0 | J28: =IFERROR(__xludf.DUMMYFUNCTION("countifs('Current Week'!B:B,A28,'Current Week'!K:K,""<0"")+counta(iferror(filter('Current Week'!B:B,'Current Week'!B:B=A28,'Current Week'!F:F<>"""",'Current Week'!K:K="""",'Current Week'!H:H="""")))"),0.0) -> 0 | K28: =IFERROR(__xludf.DUMMYFUNCTION("counta(iferror(filter('Current Week'!B:B,'Current Week'!B:B=A28,'Current Week'!K:K>0,not(iserror(find(""FINAL"",'Current Week'!G:G))),'Current Week'!AO:AO=TRUE)))+counta(iferror(filter('Current Week'!B:B,'Current Week'!B:B=A28,'Current Week'!K:K="""",not("&"iserror(find(""FINAL"",'Current Week'!G:G))),'Current Week'!AO:AO=TRUE,'Current Week'!H:H="""")))"),0.0) -> 0 | L28: =IFERROR(__xludf.DUMMYFUNCTION("counta(iferror(filter('Current Week'!B:B,'Current Week'!B:B=A28,'Current Week'!K:K<0,not(iserror(find(""FINAL"",'Current Week'!G:G))),'Current Week'!AO:AO<>TRUE)))"),0.0) -> 0 | M28: =IFERROR(__xludf.DUMMYFUNCTION("H28+counta(iferror(filter('Current Week'!B:B,'Current Week'!B:B=A28,'Current Week'!K:K<0,iserror(find(""FINAL"",'Current Week'!G:G)))))+counta(iferror(filter('Current Week'!B:B,'Current Week'!B:B=A28,'Current Week'!F:F<>"""",'Current Week'!J:J="""",'Curre"&"nt Week'!H:H="""",iserror(find(""FINAL"",'Current Week'!G:G)))))"),6.0) -> 6
A29: Nico | B29: =sumif('Current Week'!$B:$B,$A29,'Current Week'!D:D) -> 59 | C29: =sumif('Current Week'!$B:$B,$A29,'Current Week'!E:E) -> 61 | D29: =sumifs('Current Week'!D:D,'Current Week'!$B:$B,$A29,'Current Week'!AN:AN,"Power 5") -> 32 | E29: =sumifs('Current Week'!D:D,'Current Week'!$B:$B,$A29,'Current Week'!AN:AN,"Group of 5") -> 27 | F29: =10-countifs('Current Week'!B:B,A29,'Current Week'!G:G,"") -> 10 | G29: =IFERROR(__xludf.DUMMYFUNCTION("COUNTA(iferror(filter('Current Week'!B:B,'Current Week'!B:B=A29,left('Current Week'!G:G,5)=""FINAL"")))"),10.0) -> 10 | H29: =countifs('Current Week'!B:B,A29,'Current Week'!AO:AO,"=TRUE") -> 4 | I29: =F29-G29 -> 0 | J29: =IFERROR(__xludf.DUMMYFUNCTION("countifs('Current Week'!B:B,A29,'Current Week'!K:K,""<0"")+counta(iferror(filter('Current Week'!B:B,'Current Week'!B:B=A29,'Current Week'!F:F<>"""",'Current Week'!K:K="""",'Current Week'!H:H="""")))"),0.0) -> 0 | K29: =IFERROR(__xludf.DUMMYFUNCTION("counta(iferror(filter('Current Week'!B:B,'Current Week'!B:B=A29,'Current Week'!K:K>0,not(iserror(find(""FINAL"",'Current Week'!G:G))),'Current Week'!AO:AO=TRUE)))+counta(iferror(filter('Current Week'!B:B,'Current Week'!B:B=A29,'Current Week'!K:K="""",not("&"iserror(find(""FINAL"",'Current Week'!G:G))),'Current Week'!AO:AO=TRUE,'Current Week'!H:H="""")))"),0.0) -> 0 | L29: =IFERROR(__xludf.DUMMYFUNCTION("counta(iferror(filter('Current Week'!B:B,'Current Week'!B:B=A29,'Current Week'!K:K<0,not(iserror(find(""FINAL"",'Current Week'!G:G))),'Current Week'!AO:AO<>TRUE)))"),0.0) -> 0 | M29: =IFERROR(__xludf.DUMMYFUNCTION("H29+counta(iferror(filter('Current Week'!B:B,'Current Week'!B:B=A29,'Current Week'!K:K<0,iserror(find(""FINAL"",'Current Week'!G:G)))))+counta(iferror(filter('Current Week'!B:B,'Current Week'!B:B=A29,'Current Week'!F:F<>"""",'Current Week'!J:J="""",'Curre"&"nt Week'!H:H="""",iserror(find(""FINAL"",'Current Week'!G:G)))))"),4.0) -> 4

Sheet Current Week
A1: 100 | B1: 100 | C1: Team | D1: W | E1: L | F1: matchup | G1: Status (Time ET) | H1: opponent | I1: network | J1: Opening Spread | K1: Current Spread | L1: Current Total | M1: Money Lines | N1: MGM_spread | O1: MGM_total | P1: SI_spread | Q1: SI_total | R1: Wynn_spread | S1: Wynn_total | T1: Rivers_spread | U1: Rivers_total | V1: DraftKings_spread | W1: DraftKings_total | X1: FanDuel_spread | Y1: FanDuel_total | Z1: Fubu_spread | AA1: Fubu_total | AB1: Points_spread | AC1: Points_total | AD1: SugarHouse_spread | AE1: SugarHouse_total | AF1: UniBet_spread | AG1: UniBet_total | AH1: PF | AI1: PA | AJ1: sort2 | AK1: dupe | AL1: activeSort | AM1: Conf | AN1: Conf type | AO1: Win
A2: 101 | B2: Jeannine | C2: Oregon | D2: 9 | E2: 3 | F2: (9) Oregon 34 (22) Oregon State 38 | G2: FINAL | H2: Nick G. | I2: ABC | AH2: 442 | AI2: 291 | AJ2: 0 | AK2: FALSE | AL2: 7.1833333 | AM2: {=vlookup(C2,{DraftTracker!F:F,DraftTracker!E:E},2,0)} -> Pac12 | AN2: =VLOOKUP(AM2,P5G5!A:B,2,0) -> Power 5 | AO2: =IFERROR(__xludf.DUMMYFUNCTION("iferror(if(not(iserror(find(""FINAL"",G2))),max(arrayformula(value(REGEXEXTRACT(F2,""^""&C2&"" ([\d]+)|[^a-zA-Z] ""&C2&"" ([\d]+)""))))=max(value(REGEXEXTRACT(F2,"" ([\d]+)"")),value(REGEXEXTRACT(F2,""([\d]+)$""))),""""))"),FALSE) -> FALSE
A3: 101 | B3: Jeannine | C3: Nevada | D3: 2 | E3: 10 | F3: Nevada 13 UNLV 14 | G3: FINAL | H3: Nick G. | I3: MWC | AH3: 204 | AI3: 344 | AJ3: 0 | AK3: TRUE | AL3: 40.466667 | AM3: {=vlookup(C3,{DraftTracker!F:F,DraftTracker!E:E},2,0)} -> MWC | AN3: =VLOOKUP(AM3,P5G5!A:B,2,0) -> Group of 5 | AO3: =IFERROR(__xludf.DUMMYFUNCTION("iferror(if(not(iserror(find(""FINAL"",G3))),max(arrayformula(value(REGEXEXTRACT(F3,""^""&C3&"" ([\d]+)|[^a-zA-Z] ""&C3&"" ([\d]+)""))))=max(value(REGEXEXTRACT(F3,"" ([\d]+)"")),value(REGEXEXTRACT(F3,""([\d]+)$""))),""""))"),FALSE) -> FALSE
A4: 101 | B4: Jeannine | C4: Virginia | D4: 3 | E4: 7 | F4: Virginia 0 Virginia Tech 0 | G4: CANCELLED | H4: Vu | I4: Canceled | AH4: 170 | AI4: 240 | AJ4: 0 | AK4: TRUE | AL4: 59 | AM4: {=vlookup(C4,{DraftTracker!F:F,DraftTracker!E:E},2,0)} -> ACC | AN4: =VLOOKUP(AM4,P5G5!A:B,2,0) -> Power 5 | AO4: =IFERROR(__xludf.DUMMYFUNCTION("iferror(if(not(iserror(find(""FINAL"",G4))),max(arrayformula(value(REGEXEXTRACT(F4,""^""&C4&"" ([\d]+)|[^a-zA-Z] ""&C4&"" ([\d]+)""))))=max(value(REGEXEXTRACT(F4,"" ([\d]+)"")),value(REGEXEXTRACT(F4,""([\d]+)$""))),""""))"),"")
A5: 101 | B5: Jeannine | C5: Ohio State | D5: 11 | E5: 1 | F5: (3) Michigan 45 (2) Ohio State 23 | G5: FINAL | H5: Nick G. | AH5: 534 | AI5: 231 | AJ5: 2 | AK5: FALSE | AL5: 100 | AM5: {=vlookup(C5,{DraftTracker!F:F,DraftTracker!E:E},2,0)} -> Big Ten | AN5: =VLOOKUP(AM5,P5G5!A:B,2,0) -> Power 5 | AO5: =IFERROR(__xludf.DUMMYFUNCTION("iferror(if(not(iserror(find(""FINAL"",G5))),max(arrayformula(value(REGEXEXTRACT(F5,""^""&C5&"" ([\d]+)|[^a-zA-Z] ""&C5&"" ([\d]+)""))))=max(value(REGEXEXTRACT(F5,"" ([\d]+)"")),value(REGEXEXTRACT(F5,""([\d]+)$""))),""""))"),FALSE) -> FALSE
A6: 101 | B6: Jeannine | C6: Old Dominion | D6: 3 | E6: 9 | F6: Old Dominion 20 South Alabama 27 | G6: FINAL | H6: Masa | AH6: 234 | AI6: 319 | AJ6: 2 | AK6: TRUE | AL6: 100 | AM6: {=vlookup(C6,{DraftTracker!F:F,DraftTracker!E:E},2,0)} -> Sun Belt | AN6: =VLOOKUP(AM6,P5G5!A:B,2,0) -> Group of 5 | AO6: =IFERROR(__xludf.DUMMYFUNCTION("iferror(if(not(iserror(find(""FINAL"",G6))),max(arrayformula(value(REGEXEXTRACT(F6,""^""&C6&"" ([\d]+)|[^a-zA-Z] ""&C6&"" ([\d]+)""))))=max(value(REGEXEXTRACT(F6,"" ([\d]+)"")),value(REGEXEXTRACT(F6,""([\d]+)$""))),""""))"),FALSE) -> FALSE
A7: 101 | B7: Jeannine | C7: Missouri | D7: 6 | E7: 6 | F7: Arkansas 27 Missouri 29 | G7: FINAL | H7: Masa | AH7: 306 | AI7: 300 | AJ7: 2 | AK7: FALSE | AL7: 100 | AM7: {=vlookup(C7,{DraftTracker!F:F,DraftTracker!E:E},2,0)} -> SEC | AN7: =VLOOKUP(AM7,P5G5!A:B,2,0) -> Power 5 | AO7: =IFERROR(__xludf.DUMMYFUNCTION("iferror(if(not(iserror(find(""FINAL"",G7))),max(arrayformula(value(REGEXEXTRACT(F7,""^""&C7&"" ([\d]+)|[^a-zA-Z] ""&C7&"" ([\d]+)""))))=max(value(REGEXEXTRACT(F7,"" ([\d]+)"")),value(REGEXEXTRACT(F7,""([\d]+)$""))),""""))"),TRUE) -> TRUE
A8: 101 | B8: Jeannine | C8: Ohio | D8: 9 | E8: 3 | F8: Bowling Green 14 Ohio 38 | G8: FINAL | H8: Vu | AH8: 408 | AI8: 352 | AJ8: 2 | AK8: FALSE | AL8: 100 | AM8: {=vlookup(C8,{DraftTracker!F:F,DraftTracker!E:E},2,0)} -> MAC | AN8: =VLOOKUP(AM8,P5G5!A:B,2,0) -> Group of 5 | AO8: =IFERROR(__xludf.DUMMYFUNCTION("iferror(if(not(iserror(find(""FINAL"",G8))),max(arrayformula(value(REGEXEXTRACT(F8,""^""&C8&"" ([\d]+)|[^a-zA-Z] ""&C8&"" ([\d]+)""))))=max(value(REGEXEXTRACT(F8,"" ([\d]+)"")),value(REGEXEXTRACT(F8,""([\d]+)$""))),""""))"),TRUE) -> TRUE
A9: 101 | B9: Jeannine | C9: Florida Atlantic | D9: 5 | E9: 7 | F9: Western Kentucky 32 Florida Atlantic 31 | G9: FINAL | H9: DavEmily | AH9: 357 | AI9: 319 | AJ9: 2 | AK9: FALSE | AL9: 100 | AM9: {=vlookup(C9,{DraftTracker!F:F,DraftTracker!E:E},2,0)} -> CUSA | AN9: =VLOOKUP(AM9,P5G5!A:B,2,0) -> Group of 5 | AO9: =IFERROR(__xludf.DUMMYFUNCTION("iferror(if(not(iserror(find(""FINAL"",G9))),max(arrayformula(value(REGEXEXTRACT(F9,""^""&C9&"" ([\d]+)|[^a-zA-Z] ""&C9&"" ([\d]+)""))))=max(value(REGEXEXTRACT(F9,"" ([\d]+)"")),value(REGEXEXTRACT(F9,""([\d]+)$""))),""""))"),FALSE) -> FALSE
A10: 101 | B10: Jeannine | C10: Oklahoma | D10: 5 | E10: 7 | F10: Oklahoma 0 at Texas Tech 1 | G10: FINAL | H10: DavEmily | I10: FS1 | AH10: 347 | AI10: 304 | AJ10: 3 | AK10: FALSE | AL10: 100 | AM10: {=vlookup(C10,{DraftTracker!F:F,DraftTracker!E:E},2,0)} -> Big 12 | AN10: =VLOOKUP(AM10,P5G5!A:B,2,0) -> Power 5 | AO10: =IFERROR(__xludf.DUMMYFUNCTION("iferror(if(not(iserror(find(""FINAL"",G10))),max(arrayformula(value(REGEXEXTRACT(F10,""^""&C10&"" ([\d]+)|[^a-zA-Z] ""&C10&"" ([\d]+)""))))=max(value(REGEXEXTRACT(F10,"" ([\d]+)"")),value(REGEXEXTRACT(F10,""([\d]+)$""))),""""))"),"")
A11: 101 | B11: Jeannine | C11: Tulsa | D11: 5 | E11: 7 | F11: Tulsa 1 at Houston 0 | G11: FINAL | H11: Nico | I11: ESPNU | AH11: 330 | AI11: 367 | AJ11: 3 | AK11: FALSE | AL11: 100 | AM11: {=vlookup(C11,{DraftTracker!F:F,DraftTracker!E:E},2,0)} -> AAC | AN11: =VLOOKUP(AM11,P5G5!A:B,2,0) -> Group of 5 | AO11: =IFERROR(__xludf.DUMMYFUNCTION("iferror(if(not(iserror(find(""FINAL"",G11))),max(arrayformula(value(REGEXEXTRACT(F11,""^""&C11&"" ([\d]+)|[^a-zA-Z] ""&C11&"" ([\d]+)""))))=max(value(REGEXEXTRACT(F11,"" ([\d]+)"")),value(REGEXEXTRACT(F11,""([\d]+)$""))),""""))"),TRUE) -> TRUE
A12: 102 | AM12: {=vlookup(C12,{DraftTracker!F:F,DraftTracker!E:E},2,0)} -> #N/A | AN12: =VLOOKUP(AM12,P5G5!A:B,2,0) -> #N/A | AO12: =IFERROR(__xludf.DUMMYFUNCTION("iferror(if(not(iserror(find(""FINAL"",G12))),max(arrayformula(value(REGEXEXTRACT(F12,""^""&C12&"" ([\d]+)|[^a-zA-Z] ""&C12&"" ([\d]+)""))))=max(value(REGEXEXTRACT(F12,"" ([\d]+)"")),value(REGEXEXTRACT(F12,""([\d]+)$""))),""""))"),"")
A13: 103 | B13: Dan | C13: Wisconsin | D13: 6 | E13: 6 | F13: Minnesota 23 Wisconsin 16 | G13: FINAL | H13: DavEmily | I13: ESPN | AH13: 302 | AI13: 223 | AJ13: 0 | AK13: FALSE | AL13: 0.3 | AM13: {=vlookup(C13,{DraftTracker!F:F,DraftTracker!E:E},2,0)} -> Big Ten | AN13: =VLOOKUP(AM13,P5G5!A:B,2,0) -> Power 5 | AO13: =IFERROR(__xludf.DUMMYFUNCTION("iferror(if(not(iserror(find(""FINAL"",G13))),max(arrayformula(value(REGEXEXTRACT(F13,""^""&C13&"" ([\d]+)|[^a-zA-Z] ""&C13&"" ([\d]+)""))))=max(value(REGEXEXTRACT(F13,"" ([\d]+)"")),value(REGEXEXTRACT(F13,""([\d]+)$""))),""""))"),FALSE) -> FALSE
A14: 103 | B14: Dan | C14: UL Monroe | D14: 4 | E14: 8 | F14: Southern Mississippi 20 UL Monroe 10 | G14: FINAL | H14: Gary | I14: espn+ | AH14: 258 | AI14: 393 | AJ14: 0 | AK14: TRUE | AL14: 18.6 | AM14: {=vlookup(C14,{DraftTracker!F:F,DraftTracker!E:E},2,0)} -> Sun Belt | AN14: =VLOOKUP(AM14,P5G5!A:B,2,0) -> Group of 5 | AO14: =IFERROR(__xludf.DUMMYFUNCTION("iferror(if(not(iserror(find(""FINAL"",G14))),max(arrayformula(value(REGEXEXTRACT(F14,""^""&C14&"" ([\d]+)|[^a-zA-Z] ""&C14&"" ([\d]+)""))))=max(value(REGEXEXTRACT(F14,"" ([\d]+)"")),value(REGEXEXTRACT(F14,""([\d]+)$""))),""""))"),FALSE) -> FALSE
A15: 103 | B15: Dan | C15: North Texas | D15: 7 | E15: 5 | F15: Rice 17 North Texas 21 | G15: FINAL | H15: Justin | AH15: 414 | AI15: 361 | AJ15: 2 | AK15: TRUE | AL15: 100 | AM15: {=vlookup(C15,{DraftTracker!F:F,DraftTracker!E:E},2,0)} -> CUSA | AN15: =VLOOKUP(AM15,P5G5!A:B,2,0) -> Group of 5 | AO15: =IFERROR(__xludf.DUMMYFUNCTION("iferror(if(not(iserror(find(""FINAL"",G15))),max(arrayformula(value(REGEXEXTRACT(F15,""^""&C15&"" ([\d]+)|[^a-zA-Z] ""&C15&"" ([\d]+)""))))=max(value(REGEXEXTRACT(F15,"" ([\d]+)"")),value(REGEXEXTRACT(F15,""([\d]+)$""))),""""))"),TRUE) -> TRUE
A16: 103 | B16: Dan | C16: Clemson | D16: 10 | E16: 2 | F16: South Carolina 31 (8) Clemson 30 | G16: FINAL | H16: Nico | AH16: 412 | AI16: 251 | AJ16: 2 | AK16: TRUE | AL16: 100 | AM16: {=vlookup(C16,{DraftTracker!F:F,DraftTracker!E:E},2,0)} -> ACC | AN16: =VLOOKUP(AM16,P5G5!A:B,2,0) -> Power 5 | AO16: =IFERROR(__xludf.DUMMYFUNCTION("iferror(if(not(iserror(find(""FINAL"",G16))),max(arrayformula(value(REGEXEXTRACT(F16,""^""&C16&"" ([\d]+)|[^a-zA-Z] ""&C16&"" ([\d]+)""))))=max(value(REGEXEXTRACT(F16,"" ([\d]+)"")),value(REGEXEXTRACT(F16,""([\d]+)$""))),""""))"),FALSE) -> FALSE
A17: 103 | B17: Dan | C17: Miami-OH | D17: 6 | E17: 6 | F17: Ball State 17 Miami-OH 18 | G17: FINAL | H17: Justin | AH17: 243 | AI17: 270 | AJ17: 2 | AK17: TRUE | AL17: 100 | AM17: {=vlookup(C17,{DraftTracker!F:F,DraftTracker!E:E},2,0)} -> MAC | AN17: =VLOOKUP(AM17,P5G5!A:B,2,0) -> Group of 5 | AO17: =IFERROR(__xludf.DUMMYFUNCTION("iferror(if(not(iserror(find(""FINAL"",G17))),max(arrayformula(value(REGEXEXTRACT(F17,""^""&C17&"" ([\d]+)|[^a-zA-Z] ""&C17&"" ([\d]+)""))))=max(value(REGEXEXTRACT(F17,"" ([\d]+)"")),value(REGEXEXTRACT(F17,""([\d]+)$""))),""""))"),TRUE) -> TRUE
A18: 103 | B18: Dan | C18: South Florida | D18: 1 | E18: 11 | F18: UCF 1 at South Florida 0 | G18: FINAL | H18: Vu | I18: ESPN2 | AH18: 297 | AI18: 448 | AJ18: 3 | AK18: FALSE | AL18: 100 | AM18: {=vlookup(C18,{DraftTracker!F:F,DraftTracker!E:E},2,0)} -> AAC | AN18: =VLOOKUP(AM18,P5G5!A:B,2,0) -> Group of 5 | AO18: =IFERROR(__xludf.DUMMYFUNCTION("iferror(if(not(iserror(find(""FINAL"",G18))),max(arrayformula(value(REGEXEXTRACT(F18,""^""&C18&"" ([\d]+)|[^a-zA-Z] ""&C18&"" ([\d]+)""))))=max(value(REGEXEXTRACT(F18,"" ([\d]+)"")),value(REGEXEXTRACT(F18,""([\d]+)$""))),""""))"),"")
A19: 103 | B19: Dan | C19: Tennessee | D19: 10 | E19: 2 | F19: (11) Tennessee 50 at Vanderbilt 0 | G19: FINAL | H19: Masa | I19: SECN | AH19: 512 | AI19: 282 | AJ19: 3 | AK19: FALSE | AL19: 100 | AM19: {=vlookup(C19,{DraftTracker!F:F,DraftTracker!E:E},2,0)} -> SEC | AN19: =VLOOKUP(AM19,P5G5!A:B,2,0) -> Power 5 | AO19: =IFERROR(__xludf.DUMMYFUNCTION("iferror(if(not(iserror(find(""FINAL"",G19))),max(arrayformula(value(REGEXEXTRACT(F19,""^""&C19&"" ([\d]+)|[^a-zA-Z] ""&C19&"" ([\d]+)""))))=max(value(REGEXEXTRACT(F19,"" ([\d]+)"")),value(REGEXEXTRACT(F19,""([\d]+)$""))),""""))"),TRUE) -> TRUE
A20: 103 | B20: Dan | C20: Kansas | D20: 6 | E20: 6 | F20: Kansas 0 at (13) Kansas State 1 | G20: FINAL | H20: Nick G. | I20: FOX | AH20: 383 | AI20: 359 | AJ20: 3 | AK20: FALSE | AL20: 100 | AM20: {=vlookup(C20,{DraftTracker!F:F,DraftTracker!E:E},2,0)} -> Big 12 | AN20: =VLOOKUP(AM20,P5G5!A:B,2,0) -> Power 5 | AO20: =IFERROR(__xludf.DUMMYFUNCTION("iferror(if(not(iserror(find(""FINAL"",G20))),max(arrayformula(value(REGEXEXTRACT(F20,""^""&C20&"" ([\d]+)|[^a-zA-Z] ""&C20&"" ([\d]+)""))))=max(value(REGEXEXTRACT(F20,"" ([\d]+)"")),value(REGEXEXTRACT(F20,""([\d]+)$""))),""""))"),FALSE) -> FALSE
A21: 103 | B21: Dan | C21: San Diego State | D21: 7 | E21: 5 | F21: Air Force 1 at San Diego State 0 | G21: FINAL | H21: Janice/Mike | I21: CBSSN | AH21: 253 | AI21: 229 | AJ21: 3 | AK21: TRUE | AL21: 100 | AM21: {=vlookup(C21,{DraftTracker!F:F,DraftTracker!E:E},2,0)} -> MWC | AN21: =VLOOKUP(AM21,P5G5!A:B,2,0) -> Group of 5 | AO21: =IFERROR(__xludf.DUMMYFUNCTION("iferror(if(not(iserror(find(""FINAL"",G21))),max(arrayformula(value(REGEXEXTRACT(F21,""^""&C21&"" ([\d]+)|[^a-zA-Z] ""&C21&"" ([\d]+)""))))=max(value(REGEXEXTRACT(F21,"" ([\d]+)"")),value(REGEXEXTRACT(F21,""([\d]+)$""))),""""))"),"")
A22: 103 | B22: Dan | C22: Washington State | D22: 7 | E22: 5 | F22: (12) Washington 54 at Washington State 33 | G22: FINAL | H22: Vu | I22: ESPN | AH22: 300 | AI22: 218 | AJ22: 3 | AK22: FALSE | AL22: 100 | AM22: {=vlookup(C22,{DraftTracker!F:F,DraftTracker!E:E},2,0)} -> Pac12 | AN22: =VLOOKUP(AM22,P5G5!A:B,2,0) -> Power 5 | AO22: =IFERROR(__xludf.DUMMYFUNCTION("iferror(if(not(iserror(find(""FINAL"",G22))),max(arrayformula(value(REGEXEXTRACT(F22,""^""&C22&"" ([\d]+)|[^a-zA-Z] ""&C22&"" ([\d]+)""))))=max(value(REGEXEXTRACT(F22,"" ([\d]+)"")),value(REGEXEXTRACT(F22,""([\d]+)$""))),""""))"),"")
A23: 104 | AM23: {=vlookup(C23,{DraftTracker!F:F,DraftTracker!E:E},2,0)} -> #N/A | AN23: =VLOOKUP(AM23,P5G5!A:B,2,0) -> #N/A | AO23: =IFERROR(__xludf.DUMMYFUNCTION("iferror(if(not(iserror(find(""FINAL"",G23))),max(arrayformula(value(REGEXEXTRACT(F23,""^""&C23&"" ([\d]+)|[^a-zA-Z] ""&C23&"" ([\d]+)""))))=max(value(REGEXEXTRACT(F23,"" ([\d]+)"")),value(REGEXEXTRACT(F23,""([\d]+)$""))),""""))"),"")
A24: 105 | B24: DavEmily | C24: Minnesota | D24: 8 | E24: 4 | F24: Minnesota 23 Wisconsin 16 | G24: FINAL | H24: Dan | I24: ESPN | AH24: 316 | AI24: 144 | AJ24: 0 | AK24: TRUE | AL24: 0.3 | AM24: {=vlookup(C24,{DraftTracker!F:F,DraftTracker!E:E},2,0)} -> Big Ten | AN24: =VLOOKUP(AM24,P5G5!A:B,2,0) -> Power 5 | AO24: =IFERROR(__xludf.DUMMYFUNCTION("iferror(if(not(iserror(find(""FINAL"",G24))),max(arrayformula(value(REGEXEXTRACT(F24,""^""&C24&"" ([\d]+)|[^a-zA-Z] ""&C24&"" ([\d]+)""))))=max(value(REGEXEXTRACT(F24,"" ([\d]+)"")),value(REGEXEXTRACT(F24,""([\d]+)$""))),""""))"),TRUE) -> TRUE
A25: 105 | B25: DavEmily | C25: Georgia Southern | D25: 6 | E25: 6 | F25: Appalachian State 13 Georgia Southern 14 | G25: FINAL | H25: Nick G. | I25: espn+ | AH25: 353 | AI25: 340 | AJ25: 0 | AK25: TRUE | AL25: 39.6 | AM25: {=vlookup(C25,{DraftTracker!F:F,DraftTracker!E:E},2,0)} -> Sun Belt | AN25: =VLOOKUP(AM25,P5G5!A:B,2,0) -> Group of 5 | AO25: =IFERROR(__xludf.DUMMYFUNCTION("iferror(if(not(iserror(find(""FINAL"",G25))),max(arrayformula(value(REGEXEXTRACT(F25,""^""&C25&"" ([\d]+)|[^a-zA-Z] ""&C25&"" ([\d]+)""))))=max(value(REGEXEXTRACT(F25,"" ([\d]+)"")),value(REGEXEXTRACT(F25,""([\d]+)$""))),""""))"),TRUE) -> TRUE
A26: 105 | B26: DavEmily | C26: Wake Forest | D26: 7 | E26: 5 | F26: Wake Forest 31 Duke 34 | G26: FINAL | AH26: 442 | AI26: 351 | AJ26: 2 | AK26: TRUE | AL26: 100 | AM26: {=vlookup(C26,{DraftTracker!F:F,DraftTracker!E:E},2,0)} -> ACC | AN26: =VLOOKUP(AM26,P5G5!A:B,2,0) -> Power 5 | AO26: =IFERROR(__xludf.DUMMYFUNCTION("iferror(if(not(iserror(find(""FINAL"",G26))),max(arrayformula(value(REGEXEXTRACT(F26,""^""&C26&"" ([\d]+)|[^a-zA-Z] ""&C26&"" ([\d]+)""))))=max(value(REGEXEXTRACT(F26,"" ([\d]+)"")),value(REGEXEXTRACT(F26,""([\d]+)$""))),""""))"),FALSE) -> FALSE
A27: 105 | B27: DavEmily | C27: UCLA | D27: 9 | E27: 3 | F27: (18) UCLA 35 California 28 | G27: FINAL | H27: Nick A. | AH27: 475 | AI27: 340 | AJ27: 2 | AK27: TRUE | AL27: 100 | AM27: {=vlookup(C27,{DraftTracker!F:F,DraftTracker!E:E},2,0)} -> Pac12 | AN27: =VLOOKUP(AM27,P5G5!A:B,2,0) -> Power 5 | AO27: =IFERROR(__xludf.DUMMYFUNCTION("iferror(if(not(iserror(find(""FINAL"",G27))),max(arrayformula(value(REGEXEXTRACT(F27,""^""&C27&"" ([\d]+)|[^a-zA-Z] ""&C27&"" ([\d]+)""))))=max(value(REGEXEXTRACT(F27,"" ([\d]+)"")),value(REGEXEXTRACT(F27,""([\d]+)$""))),""""))"),TRUE) -> TRUE
A28: 105 | B28: DavEmily | C28: New Mexico | D28: 2 | E28: 10 | F28: New Mexico 0 Colorado State 17 | G28: FINAL | H28: Justin | AH28: 157 | AI28: 312 | AJ28: 2 | AK28: FALSE | AL28: 100 | AM28: {=vlookup(C28,{DraftTracker!F:F,DraftTracker!E:E},2,0)} -> MWC | AN28: =VLOOKUP(AM28,P5G5!A:B,2,0) -> Group of 5 | AO28: =IFERROR(__xludf.DUMMYFUNCTION("iferror(if(not(iserror(find(""FINAL"",G28))),max(arrayformula(value(REGEXEXTRACT(F28,""^""&C28&"" ([\d]+)|[^a-zA-Z] ""&C28&"" ([\d]+)""))))=max(value(REGEXEXTRACT(F28,"" ([\d]+)"")),value(REGEXEXTRACT(F28,""([\d]+)$""))),""""))"),FALSE) -> FALSE
A29: 105 | B29: DavEmily | C29: Toledo | D29: 7 | E29: 5 | F29: Toledo 14 Western Michigan 20 | G29: FINAL | H29: Nico | AH29: 400 | AI29: 325 | AJ29: 2 | AK29: TRUE | AL29: 100 | AM29: {=vlookup(C29,{DraftTracker!F:F,DraftTracker!E:E},2,0)} -> MAC | AN29: =VLOOKUP(AM29,P5G5!A:B,2,0) -> Group of 5 | AO29: =IFERROR(__xludf.DUMMYFUNCTION("iferror(if(not(iserror(find(""FINAL"",G29))),max(arrayformula(value(REGEXEXTRACT(F29,""^""&C29&"" ([\d]+)|[^a-zA-Z] ""&C29&"" ([\d]+)""))))=max(value(REGEXEXTRACT(F29,"" ([\d]+)"")),value(REGEXEXTRACT(F29,""([\d]+)$""))),""""))"),FALSE) -> FALSE
A30: 105 | B30: DavEmily | C30: Tulane | D30: 10 | E30: 2 | F30: (20) Tulane 27 (21) Cincinnati 24 | G30: FINAL | H30: Masa | AH30: 413 | AI30: 238 | AJ30: 2 | AK30: FALSE | AL30: 100 | AM30: {=vlookup(C30,{DraftTracker!F:F,DraftTracker!E:E},2,0)} -> AAC | AN30: =VLOOKUP(AM30,P5G5!A:B,2,0) -> Group of 5 | AO30: =IFERROR(__xludf.DUMMYFUNCTION("iferror(if(not(iserror(find(""FINAL"",G30))),max(arrayformula(value(REGEXEXTRACT(F30,""^""&C30&"" ([\d]+)|[^a-zA-Z] ""&C30&"" ([\d]+)""))))=max(value(REGEXEXTRACT(F30,"" ([\d]+)"")),value(REGEXEXTRACT(F30,""([\d]+)$""))),""""))"),TRUE) -> TRUE
A31: 105 | B31: DavEmily | C31: Mississippi State | D31: 8 | E31: 4 | F31: Mississippi State 24 (19) Ole Miss 22 | G31: FINAL | H31: Janice/Mike | AH31: 392 | AI31: 290 | AJ31: 2 | AK31: TRUE | AL31: 100 | AM31: {=vlookup(C31,{DraftTracker!F:F,DraftTracker!E:E},2,0)} -> SEC | AN31: =VLOOKUP(AM31,P5G5!A:B,2,0) -> Power 5 | AO31: =IFERROR(__xludf.DUMMYFUNCTION("iferror(if(not(iserror(find(""FINAL"",G31))),max(arrayformula(value(REGEXEXTRACT(F31,""^""&C31&"" ([\d]+)|[^a-zA-Z] ""&C31&"" ([\d]+)""))))=max(value(REGEXEXTRACT(F31,"" ([\d]+)"")),value(REGEXEXTRACT(F31,""([\d]+)$""))),""""))"),TRUE) -> TRUE
A32: 105 | B32: DavEmily | C32: Western Kentucky | D32: 8 | E32: 5 | F32: Western Kentucky 32 Florida Atlantic 31 | G32: FINAL | H32: Jeannine | AH32: 466 | AI32: 305 | AJ32: 2 | AK32: TRUE | AL32: 100 | AM32: {=vlookup(C32,{DraftTracker!F:F,DraftTracker!E:E},2,0)} -> CUSA | AN32: =VLOOKUP(AM32,P5G5!A:B,2,0) -> Group of 5 | AO32: =IFERROR(__xludf.DUMMYFUNCTION("iferror(if(not(iserror(find(""FINAL"",G32))),max(arrayformula(value(REGEXEXTRACT(F32,""^""&C32&"" ([\d]+)|[^a-zA-Z] ""&C32&"" ([\d]+)""))))=max(value(REGEXEXTRACT(F32,"" ([\d]+)"")),value(REGEXEXTRACT(F32,""([\d]+)$""))),""""))"),TRUE) -> TRUE
A33: 105 | B33: DavEmily | C33: Texas Tech | D33: 7 | E33: 5 | F33: Oklahoma 0 at Texas Tech 1 | G33: FINAL | H33: Jeannine | I33: FS1 | AH33: 352 | AI33: 306 | AJ33: 3 | AK33: TRUE | AL33: 100 | AM33: {=vlookup(C33,{DraftTracker!F:F,DraftTracker!E:E},2,0)} -> Big 12 | AN33: =VLOOKUP(AM33,P5G5!A:B,2,0) -> Power 5 | AO33: =IFERROR(__xludf.DUMMYFUNCTION("iferror(if(not(iserror(find(""FINAL"",G33))),max(arrayformula(value(REGEXEXTRACT(F33,""^""&C33&"" ([\d]+)|[^a-zA-Z] ""&C33&"" ([\d]+)""))))=max(value(REGEXEXTRACT(F33,"" ([\d]+)"")),value(REGEXEXTRACT(F33,""([\d]+)$""))),""""))"),"")
A34: 106 | AM34: {=vlookup(C34,{DraftTracker!F:F,DraftTracker!E:E},2,0)} -> #N/A | AN34: =VLOOKUP(AM34,P5G5!A:B,2,0) -> #N/A | AO34: =IFERROR(__xludf.DUMMYFUNCTION("iferror(if(not(iserror(find(""FINAL"",G34))),max(arrayformula(value(REGEXEXTRACT(F34,""^""&C34&"" ([\d]+)|[^a-zA-Z] ""&C34&"" ([\d]+)""))))=max(value(REGEXEXTRACT(F34,"" ([\d]+)"")),value(REGEXEXTRACT(F34,""([\d]+)$""))),""""))"),"")
A35: 107 | B35: Nick G. | C35: Oregon State | D35: 9 | E35: 3 | F35: (9) Oregon 34 (22) Oregon State 38 | G35: FINAL | H35: Jeannine | I35: ABC | AH35: 351 | AI35: 223 | AJ35: 0 | AK35: TRUE | AL35: 7.1833333 | AM35: {=vlookup(C35,{DraftTracker!F:F,DraftTracker!E:E},2,0)} -> Pac12 | AN35: =VLOOKUP(AM35,P5G5!A:B,2,0) -> Power 5 | AO35: =IFERROR(__xludf.DUMMYFUNCTION("iferror(if(not(iserror(find(""FINAL"",G35))),max(arrayformula(value(REGEXEXTRACT(F35,""^""&C35&"" ([\d]+)|[^a-zA-Z] ""&C35&"" ([\d]+)""))))=max(value(REGEXEXTRACT(F35,"" ([\d]+)"")),value(REGEXEXTRACT(F35,""([\d]+)$""))),""""))"),TRUE) -> TRUE
A36: 107 | B36: Nick G. | C36: Florida Intl | D36: 4 | E36: 8 | F36: Middle Tennessee 13 Florida Intl 0 | G36: FINAL | H36: Brad | AH36: 196 | AI36: 414 | AJ36: 0 | AK36: FALSE | AL36: 36.933333 | AM36: {=vlookup(C36,{DraftTracker!F:F,DraftTracker!E:E},2,0)} -> CUSA | AN36: =VLOOKUP(AM36,P5G5!A:B,2,0) -> Group of 5 | AO36: =IFERROR(__xludf.DUMMYFUNCTION("iferror(if(not(iserror(find(""FINAL"",G36))),max(arrayformula(value(REGEXEXTRACT(F36,""^""&C36&"" ([\d]+)|[^a-zA-Z] ""&C36&"" ([\d]+)""))))=max(value(REGEXEXTRACT(F36,"" ([\d]+)"")),value(REGEXEXTRACT(F36,""([\d]+)$""))),""""))"),FALSE) -> FALSE
A37: 107 | B37: Nick G. | C37: Appalachian State | D37: 6 | E37: 6 | F37: Appalachian State 13 Georgia Southern 7 | G37: FINAL | H37: DavEmily | I37: espn+ | AH37: 371 | AI37: 270 | AJ37: 0 | AK37: FALSE | AL37: 39.6 | AM37: {=vlookup(C37,{DraftTracker!F:F,DraftTracker!E:E},2,0)} -> Sun Belt | AN37: =VLOOKUP(AM37,P5G5!A:B,2,0) -> Group of 5 | AO37: =IFERROR(__xludf.DUMMYFUNCTION("iferror(if(not(iserror(find(""FINAL"",G37))),max(arrayformula(value(REGEXEXTRACT(F37,""^""&C37&"" ([\d]+)|[^a-zA-Z] ""&C37&"" ([\d]+)""))))=max(value(REGEXEXTRACT(F37,"" ([\d]+)"")),value(REGEXEXTRACT(F37,""([\d]+)$""))),""""))"),TRUE) -> TRUE
A38: 107 | B38: Nick G. | C38: UNLV | D38: 5 | E38: 7 | F38: Nevada 15 UNLV 14 | G38: FINAL | H38: Jeannine | I38: MWC | AH38: 289 | AI38: 320 | AJ38: 0 | AK38: FALSE | AL38: 40.466667 | AM38: {=vlookup(C38,{DraftTracker!F:F,DraftTracker!E:E},2,0)} -> MWC | AN38: =VLOOKUP(AM38,P5G5!A:B,2,0) -> Group of 5 | AO38: =IFERROR(__xludf.DUMMYFUNCTION("iferror(if(not(iserror(find(""FINAL"",G38))),max(arrayformula(value(REGEXEXTRACT(F38,""^""&C38&"" ([\d]+)|[^a-zA-Z] ""&C38&"" ([\d]+)""))))=max(value(REGEXEXTRACT(F38,"" ([\d]+)"")),value(REGEXEXTRACT(F38,""([\d]+)$""))),""""))"),FALSE) -> FALSE
A39: 107 | B39: Nick G. | C39: UConn | D39: 6 | E39: 6 | AH39: 238 | AI39: 313 | AJ39: 0 | AK39: TRUE | AL39: 59 | AM39: {=vlookup(C39,{DraftTracker!F:F,DraftTracker!E:E},2,0)} -> AAC | AN39: =VLOOKUP(AM39,P5G5!A:B,2,0) -> Group of 5 | AO39: =IFERROR(__xludf.DUMMYFUNCTION("iferror(if(not(iserror(find(""FINAL"",G39))),max(arrayformula(value(REGEXEXTRACT(F39,""^""&C39&"" ([\d]+)|[^a-zA-Z] ""&C39&"" ([\d]+)""))))=max(value(REGEXEXTRACT(F39,"" ([\d]+)"")),value(REGEXEXTRACT(F39,""([\d]+)$""))),""""))"),"")
A40: 107 | B40: Nick G. | C40: Kentucky | D40: 7 | E40: 5 | G40: FINAL | H40: Josh | AH40: 265 | AI40: 229 | AJ40: 2 | AK40: FALSE | AL40: 100 | AM40: {=vlookup(C40,{DraftTracker!F:F,DraftTracker!E:E},2,0)} -> SEC | AN40: =VLOOKUP(AM40,P5G5!A:B,2,0) -> Power 5 | AO40: =IFERROR(__xludf.DUMMYFUNCTION("iferror(if(not(iserror(find(""FINAL"",G40))),max(arrayformula(value(REGEXEXTRACT(F40,""^""&C40&"" ([\d]+)|[^a-zA-Z] ""&C40&"" ([\d]+)""))))=max(value(REGEXEXTRACT(F40,"" ([\d]+)"")),value(REGEXEXTRACT(F40,""([\d]+)$""))),""""))"),"")
...

Sheet Active Games
A1: Game | B1: Status | C1: Player Matchup | D1: Network | E1: Spread Comp | F1: Spread | G1: Total | H1: sort2 | I1: sort1 | J1: Comp | K1: other | L1: dif | M1: line
A2: =IFERROR(__xludf.DUMMYFUNCTION("iferror(sort({FILTER('Current Week'!F:G,'Current Week'!AK:AK=FALSE,'Current Week'!F:F<>"""",'Current Week'!AL:AL<100),ARRAYFORMULA(if(FILTER('Current Week'!H:H,'Current Week'!AK:AK=FALSE,'Current Week'!F:F<>"""",'Current Week'!AL:AL<100)="""","""",FILTER("&"'Current Week'!H:H,'Current Week'!AK:AK=FALSE,'Current Week'!F:F<>"""",'Current Week'!AL:AL<100)&"" vs "")&FILTER('Current Week'!B:B,'Current Week'!AK:AK=FALSE,'Current Week'!F:F<>"""",'Current Week'!AL:AL<100)),FILTER('Current Week'!I:I,'Current Week'!AK"&":AK=FALSE,'Current Week'!F:F<>"""",'Current Week'!AL:AL<100),FILTER('Current Week'!C:C,'Current Week'!AK:AK=FALSE,'Current Week'!F:F<>"""",'Current Week'!AL:AL<100),FILTER('Current Week'!J:K,'Current Week'!AK:AK=FALSE,'Current Week'!F:F<>"""",'Current Wee"&"k'!AL:AL<100),FILTER('Current Week'!AL:AL,'Current Week'!AK:AK=FALSE,'Current Week'!F:F<>"""",'Current Week'!AL:AL<100),FILTER('Current Week'!AJ:AJ,'Current Week'!AK:AK=FALSE,'Current Week'!F:F<>"""",'Current Week'!AL:AL<100)},9,1,8,1,2,1),""No Active Gam"&"es"")"),"Memphis 31 SMU 34") -> Memphis 31 SMU 34 | B2: =IFERROR(__xludf.DUMMYFUNCTION("""COMPUTED_VALUE"""),"FINAL") -> FINAL | C2: =IFERROR(__xludf.DUMMYFUNCTION("""COMPUTED_VALUE"""),"Josh vs Brad") -> Josh vs Brad | D2: =IFERROR(__xludf.DUMMYFUNCTION("""COMPUTED_VALUE"""),"ESPN2") -> ESPN2 | E2: =IFERROR(__xludf.DUMMYFUNCTION("""COMPUTED_VALUE"""),"Memphis") -> Memphis | H2: =IFERROR(__xludf.DUMMYFUNCTION("""COMPUTED_VALUE"""),-0.20000000000000284) -> -0.2 | I2: =IFERROR(__xludf.DUMMYFUNCTION("""COMPUTED_VALUE"""),0.0) -> 0 | J2: =IFERROR(__xludf.DUMMYFUNCTION("arrayformula(if(A2:A586="""","""",REGEXEXTRACT(A2:A586,E2:E586&"" (\d*)"")))"),"31") -> 31 | K2: =IFERROR(__xludf.DUMMYFUNCTION("arrayformula(if(A2:A586="""","""",REGEXEXTRACT(mid(A2:A586,if(FIND(E2:E586,A2:A586)=1,len(E2:E586)+1,1),99),""\w+ (\d+)"")))"),"34") -> 34 | L2: {=if(A2:A586="","",J2:J586-K2:K586)} -> -3 | M2: {=if(A2:A586="","",if(F2:F586="",-30,F2:F586))} -> -30
A3: =IFERROR(__xludf.DUMMYFUNCTION("""COMPUTED_VALUE"""),"Minnesota 23 Wisconsin 16") -> Minnesota 23 Wisconsin 16 | B3: =IFERROR(__xludf.DUMMYFUNCTION("""COMPUTED_VALUE"""),"FINAL") -> FINAL | C3: =IFERROR(__xludf.DUMMYFUNCTION("""COMPUTED_VALUE"""),"DavEmily vs Dan") -> DavEmily vs Dan | D3: =IFERROR(__xludf.DUMMYFUNCTION("""COMPUTED_VALUE"""),"ESPN") -> ESPN | E3: =IFERROR(__xludf.DUMMYFUNCTION("""COMPUTED_VALUE"""),"Wisconsin") -> Wisconsin | H3: =IFERROR(__xludf.DUMMYFUNCTION("""COMPUTED_VALUE"""),0.29999999999999716) -> 0.3 | I3: =IFERROR(__xludf.DUMMYFUNCTION("""COMPUTED_VALUE"""),0.0) -> 0 | J3: =IFERROR(__xludf.DUMMYFUNCTION("""COMPUTED_VALUE"""),"16") -> 16 | K3: =IFERROR(__xludf.DUMMYFUNCTION("""COMPUTED_VALUE"""),"23") -> 23 | L3: -7 | M3: -30
A4: =IFERROR(__xludf.DUMMYFUNCTION("""COMPUTED_VALUE"""),"Auburn 27 (7) Alabama 42") -> Auburn 27 (7) Alabama 42 | B4: =IFERROR(__xludf.DUMMYFUNCTION("""COMPUTED_VALUE"""),"FINAL") -> FINAL | C4: =IFERROR(__xludf.DUMMYFUNCTION("""COMPUTED_VALUE"""),"Nick A. vs Josh") -> Nick A. vs Josh | D4: =IFERROR(__xludf.DUMMYFUNCTION("""COMPUTED_VALUE"""),"CBS") -> CBS | E4: =IFERROR(__xludf.DUMMYFUNCTION("""COMPUTED_VALUE"""),"Alabama") -> Alabama | H4: =IFERROR(__xludf.DUMMYFUNCTION("""COMPUTED_VALUE"""),1.06666666666667) -> 1.0666667 | I4: =IFERROR(__xludf.DUMMYFUNCTION("""COMPUTED_VALUE"""),0.0) -> 0 | J4: =IFERROR(__xludf.DUMMYFUNCTION("""COMPUTED_VALUE"""),"42") -> 42 | K4: =IFERROR(__xludf.DUMMYFUNCTION("""COMPUTED_VALUE"""),"27") -> 27 | L4: 15 | M4: -30
A5: =IFERROR(__xludf.DUMMYFUNCTION("""COMPUTED_VALUE"""),"UAB 37 Louisiana Tech 27") -> UAB 37 Louisiana Tech 27 | B5: =IFERROR(__xludf.DUMMYFUNCTION("""COMPUTED_VALUE"""),"FINAL ") -> FINAL | C5: =IFERROR(__xludf.DUMMYFUNCTION("""COMPUTED_VALUE"""),"Janice/Mike vs Nick A.") -> Janice/Mike vs Nick A. | D5: =IFERROR(__xludf.DUMMYFUNCTION("""COMPUTED_VALUE"""),"CBSSN") -> CBSSN | E5: =IFERROR(__xludf.DUMMYFUNCTION("""COMPUTED_VALUE"""),"Louisiana Tech") -> Louisiana Tech | H5: =IFERROR(__xludf.DUMMYFUNCTION("""COMPUTED_VALUE"""),1.1499999999999986) -> 1.15 | I5: =IFERROR(__xludf.DUMMYFUNCTION("""COMPUTED_VALUE"""),0.0) -> 0 | J5: =IFERROR(__xludf.DUMMYFUNCTION("""COMPUTED_VALUE"""),"27") -> 27 | K5: =IFERROR(__xludf.DUMMYFUNCTION("""COMPUTED_VALUE"""),"37") -> 37 | L5: -10 | M5: -30
A6: =IFERROR(__xludf.DUMMYFUNCTION("""COMPUTED_VALUE"""),"(9) Oregon 34 (22) Oregon State 38") -> (9) Oregon 34 (22) Oregon State 38 | B6: =IFERROR(__xludf.DUMMYFUNCTION("""COMPUTED_VALUE"""),"FINAL") -> FINAL | C6: =IFERROR(__xludf.DUMMYFUNCTION("""COMPUTED_VALUE"""),"Nick G. vs Jeannine") -> Nick G. vs Jeannine | D6: =IFERROR(__xludf.DUMMYFUNCTION("""COMPUTED_VALUE"""),"ABC") -> ABC | E6: =IFERROR(__xludf.DUMMYFUNCTION("""COMPUTED_VALUE"""),"Oregon") -> Oregon | H6: =IFERROR(__xludf.DUMMYFUNCTION("""COMPUTED_VALUE"""),7.18333333333333) -> 7.1833333 | I6: =IFERROR(__xludf.DUMMYFUNCTION("""COMPUTED_VALUE"""),0.0) -> 0 | J6: =IFERROR(__xludf.DUMMYFUNCTION("""COMPUTED_VALUE"""),"34") -> 34 | K6: =IFERROR(__xludf.DUMMYFUNCTION("""COMPUTED_VALUE"""),"34") -> 34 | L6: 0 | M6: -30
A7: =IFERROR(__xludf.DUMMYFUNCTION("""COMPUTED_VALUE"""),"Michigan State 16 (10) Penn State 21") -> Michigan State 16 (10) Penn State 21 | B7: =IFERROR(__xludf.DUMMYFUNCTION("""COMPUTED_VALUE"""),"FINAL") -> FINAL | C7: =IFERROR(__xludf.DUMMYFUNCTION("""COMPUTED_VALUE"""),"Masa vs Brad") -> Masa vs Brad | D7: =IFERROR(__xludf.DUMMYFUNCTION("""COMPUTED_VALUE"""),"FS1") -> FS1 | E7: =IFERROR(__xludf.DUMMYFUNCTION("""COMPUTED_VALUE"""),"Penn State") -> Penn State | H7: =IFERROR(__xludf.DUMMYFUNCTION("""COMPUTED_VALUE"""),9.866666666666667) -> 9.8666667 | I7: =IFERROR(__xludf.DUMMYFUNCTION("""COMPUTED_VALUE"""),0.0) -> 0 | J7: =IFERROR(__xludf.DUMMYFUNCTION("""COMPUTED_VALUE"""),"21") -> 21 | K7: =IFERROR(__xludf.DUMMYFUNCTION("""COMPUTED_VALUE"""),"16") -> 16 | L7: 5 | M7: -30
A8: =IFERROR(__xludf.DUMMYFUNCTION("""COMPUTED_VALUE"""),"Iowa State 7 (4) TCU 55") -> Iowa State 7 (4) TCU 55 | B8: =IFERROR(__xludf.DUMMYFUNCTION("""COMPUTED_VALUE"""),"FINAL") -> FINAL | C8: =IFERROR(__xludf.DUMMYFUNCTION("""COMPUTED_VALUE"""),"Janice/Mike vs Vu") -> Janice/Mike vs Vu | D8: =IFERROR(__xludf.DUMMYFUNCTION("""COMPUTED_VALUE"""),"FOX") -> FOX | E8: =IFERROR(__xludf.DUMMYFUNCTION("""COMPUTED_VALUE"""),"Iowa State") -> Iowa State | H8: =IFERROR(__xludf.DUMMYFUNCTION("""COMPUTED_VALUE"""),13.833333333333336) -> 13.833333 | I8: =IFERROR(__xludf.DUMMYFUNCTION("""COMPUTED_VALUE"""),0.0) -> 0 | J8: =IFERROR(__xludf.DUMMYFUNCTION("""COMPUTED_VALUE"""),"7") -> 7 | K8: =IFERROR(__xludf.DUMMYFUNCTION("""COMPUTED_VALUE"""),"55") -> 55 | L8: -48 | M8: -30
A9: =IFERROR(__xludf.DUMMYFUNCTION("""COMPUTED_VALUE"""),"Southern Mississippi 11 UL Monroe 10") -> Southern Mississippi 11 UL Monroe 10 | B9: =IFERROR(__xludf.DUMMYFUNCTION("""COMPUTED_VALUE"""),"FINAL ") -> FINAL | C9: =IFERROR(__xludf.DUMMYFUNCTION("""COMPUTED_VALUE"""),"Dan vs Gary") -> Dan vs Gary | D9: =IFERROR(__xludf.DUMMYFUNCTION("""COMPUTED_VALUE"""),"espn+") -> espn+ | E9: =IFERROR(__xludf.DUMMYFUNCTION("""COMPUTED_VALUE"""),"Southern Mississippi") -> Southern Mississippi | H9: =IFERROR(__xludf.DUMMYFUNCTION("""COMPUTED_VALUE"""),18.6) -> 18.6 | I9: =IFERROR(__xludf.DUMMYFUNCTION("""COMPUTED_VALUE"""),0.0) -> 0 | J9: =IFERROR(__xludf.DUMMYFUNCTION("""COMPUTED_VALUE"""),"11") -> 11 | K9: =IFERROR(__xludf.DUMMYFUNCTION("""COMPUTED_VALUE"""),"10") -> 10 | L9: 1 | M9: -30
A10: =IFERROR(__xludf.DUMMYFUNCTION("""COMPUTED_VALUE"""),"UL Lafayette 26 Texas State 6") -> UL Lafayette 26 Texas State 6 | B10: =IFERROR(__xludf.DUMMYFUNCTION("""COMPUTED_VALUE"""),"FINAL") -> FINAL | C10: =IFERROR(__xludf.DUMMYFUNCTION("""COMPUTED_VALUE"""),"Vu vs Brad") -> Vu vs Brad | D10: =IFERROR(__xludf.DUMMYFUNCTION("""COMPUTED_VALUE"""),"espn+") -> espn+ | E10: =IFERROR(__xludf.DUMMYFUNCTION("""COMPUTED_VALUE"""),"UL Lafayette") -> UL Lafayette | H10: =IFERROR(__xludf.DUMMYFUNCTION("""COMPUTED_VALUE"""),26.583333333333336) -> 26.583333 | I10: =IFERROR(__xludf.DUMMYFUNCTION("""COMPUTED_VALUE"""),0.0) -> 0 | J10: =IFERROR(__xludf.DUMMYFUNCTION("""COMPUTED_VALUE"""),"26") -> 26 | K10: =IFERROR(__xludf.DUMMYFUNCTION("""COMPUTED_VALUE"""),"6") -> 6 | L10: 20 | M10: -30
A11: =IFERROR(__xludf.DUMMYFUNCTION("""COMPUTED_VALUE"""),"Middle Tennessee 13 Florida Intl 0") -> Middle Tennessee 13 Florida Intl 0 | B11: =IFERROR(__xludf.DUMMYFUNCTION("""COMPUTED_VALUE"""),"FINAL ") -> FINAL | C11: =IFERROR(__xludf.DUMMYFUNCTION("""COMPUTED_VALUE"""),"Brad vs Nick G.") -> Brad vs Nick G. | E11: =IFERROR(__xludf.DUMMYFUNCTION("""COMPUTED_VALUE"""),"Florida Intl") -> Florida Intl | H11: =IFERROR(__xludf.DUMMYFUNCTION("""COMPUTED_VALUE"""),36.93333333333334) -> 36.933333 | I11: =IFERROR(__xludf.DUMMYFUNCTION("""COMPUTED_VALUE"""),0.0) -> 0 | J11: =IFERROR(__xludf.DUMMYFUNCTION("""COMPUTED_VALUE"""),"0") -> 0 | K11: =IFERROR(__xludf.DUMMYFUNCTION("""COMPUTED_VALUE"""),"13") -> 13 | L11: -13 | M11: -30
A12: =IFERROR(__xludf.DUMMYFUNCTION("""COMPUTED_VALUE"""),"Appalachian State 13 Georgia Southern 7") -> Appalachian State 13 Georgia Southern 7 | B12: =IFERROR(__xludf.DUMMYFUNCTION("""COMPUTED_VALUE"""),"FINAL ") -> FINAL | C12: =IFERROR(__xludf.DUMMYFUNCTION("""COMPUTED_VALUE"""),"DavEmily vs Nick G.") -> DavEmily vs Nick G. | D12: =IFERROR(__xludf.DUMMYFUNCTION("""COMPUTED_VALUE"""),"espn+") -> espn+ | E12: =IFERROR(__xludf.DUMMYFUNCTION("""COMPUTED_VALUE"""),"Appalachian State") -> Appalachian State | H12: =IFERROR(__xludf.DUMMYFUNCTION("""COMPUTED_VALUE"""),39.6) -> 39.6 | I12: =IFERROR(__xludf.DUMMYFUNCTION("""COMPUTED_VALUE"""),0.0) -> 0 | J12: =IFERROR(__xludf.DUMMYFUNCTION("""COMPUTED_VALUE"""),"13") -> 13 | K12: =IFERROR(__xludf.DUMMYFUNCTION("""COMPUTED_VALUE"""),"7") -> 7 | L12: 6 | M12: -30
