Workbook

Sheet ReadMe & Sources
A1: NCAA Wins Pool — 2026 Preview Workbook
A2: Three-layer model (per Annual Rebuild Playbook): A = raw data (numbers) · B = supplemental (pod writeups) · C = governance (source docs). The Layer A tab below is the SOURCED numeric store.
A5: MEASURE | B5: SOURCE (captured 2026-08-03)
A6: Market win total (O/U) | B6: SportsBettingDime 2026 CFB win totals — sportsbettingdime.com/college-football/futures/win-totals-best-odds/ (captured 2026-08-03, preseason O/U)
A7: SP+ rank & rating | B7: ESPN Bill Connelly 2026 preseason SP+, all 138 FBS — espn.com id 48306284 (captured 2026-08-03, August final-roster refresh)
A8: Returning production (ovr/off/def) | B8: ESPN Bill Connelly 2026 returning production — espn.com id 48259759 (captured 2026-08-03)
A9: TARP net/off/def | B9: Three Straight (Collin Wilson) 2026 TARP = Transfer Activity + Returning Production. Underlying data: PFF (2025 stats) + 247Sports (portal source/destination); measures end-2025 roster vs 2026 spring roster incl. Jan 2-16 portal window. Off weights OLsnaps40/recyds35/passyds22/rush3; Def weights snaps66/tackles19/stops5/pressures5/PBU5. FBS benchmark: off returned 63%, def 56%. Values here = the 'PR Adjustments' sheet (off modified vs 63%, def vs 56%; Net=Off+Def, pool ±6/±5 scale). FULL-FBS (136) captured 2026-08-04 from the published sheet at projectthreestraight.com/2026-tarp-transfer-activity-returning-production/. See TARP_source_2026.md.
A10: Collin/Action projected wins | B10: Collin Wilson's projected wins. PRIMARY SOURCES: projectthreestraight.com (his model output) AND stated by Collin himself on the 2026 BBOC pod (see src_2026/pac12_2026_transcript.txt + Sun Belt pod). Pac-12 + Sun Belt captured; other conferences as pods drop / from projectthreestraight.
A11: 6-Win % | B11: ESPN 6-Win% — NOT yet published/collected for 2026 (2025-only historically; recheck)
A12: SOS rank | B12: SP+ SOS column — pending (not in the captured SP+ article body)
A14: COVERAGE | B14: market/SP+/RetProd = full-FBS (138). TARP/Collin = only teams whose 2026 pod has been extracted (Pac-12 12, Sun Belt 14); remainder await pod extraction or an Action full-FBS paste. 6-Win%/SOS/Miles pending.

Sheet Layer A — raw data (SOURCED)
A1: Team | B1: Mkt O/U | C1: SP+ Rk | D1: SP+ Rtg | E1: RetProd% | F1: Ret Off% | G1: Ret Def% | H1: TARP net | I1: TARP off | J1: TARP def | K1: Collin Proj | L1: Proj−Mkt | M1: 6-Win% | N1: SOS Rk | O1: Pool Conf
A2: Ohio State | B2: 9.5 | C2: 1 | D2: 31.8 | E2: 60 | F2: 71 | G2: 50 | H2: 10.5 | I2: 6 | J2: 4.5 | L2: =IF(OR(K2="",B2=""),"",K2-B2) | O2: Big Ten
A3: Oregon | B3: 10.5 | C3: 2 | D3: 28.3 | E3: 66 | F3: 65 | G3: 66 | H3: 11 | I3: 6 | J3: 5 | L3: =IF(OR(K3="",B3=""),"",K3-B3) | O3: Big Ten
A4: Notre Dame | B4: 11.5 | C4: 3 | D4: 25.8 | E4: 72 | F4: 67 | G4: 77 | H4: 5.5 | I4: 0.5 | J4: 5 | L4: =IF(OR(K4="",B4=""),"",K4-B4) | O4: CUSA
A5: Georgia | B5: 9.5 | C5: 4 | D5: 25.5 | E5: 68 | F5: 63 | G5: 72 | H5: 8 | I5: 3 | J5: 5 | L5: =IF(OR(K5="",B5=""),"",K5-B5) | O5: SEC
A6: Indiana | B6: 10.5 | C6: 5 | D6: 24.5 | E6: 56 | F6: 54 | G6: 58 | H6: 7.5 | I6: 5 | J6: 2.5 | L6: =IF(OR(K6="",B6=""),"",K6-B6) | O6: Big Ten
A7: Texas | B7: 9.5 | C7: 6 | D7: 23.7 | E7: 68 | F7: 73 | G7: 63 | H7: 10.5 | I7: 6 | J7: 4.5 | L7: =IF(OR(K7="",B7=""),"",K7-B7) | O7: SEC
A8: Texas Tech | B8: 10.5 | C8: 7 | D8: 23.1 | E8: 65 | F8: 67 | G8: 64 | H8: 11 | I8: 6 | J8: 5 | L8: =IF(OR(K8="",B8=""),"",K8-B8) | O8: Big 12
A9: Miami FL | B9: 10.5 | C9: 8 | D9: 21 | E9: 49 | F9: 48 | G9: 51 | H9: 4.5 | I9: 3 | J9: 1.5 | L9: =IF(OR(K9="",B9=""),"",K9-B9) | O9: ACC
A10: Texas A&M | B10: 8.5 | C10: 9 | D10: 20.3 | E10: 65 | F10: 67 | G10: 63 | H10: 8.5 | I10: 3.5 | J10: 5 | L10: =IF(OR(K10="",B10=""),"",K10-B10) | O10: SEC
A11: LSU | B11: 8.5 | C11: 10 | D11: 20.2 | E11: 61 | F11: 61 | G11: 60 | H11: 10.5 | I11: 6 | J11: 4.5 | L11: =IF(OR(K11="",B11=""),"",K11-B11) | O11: SEC
A12: Alabama | B12: 8.5 | C12: 11 | D12: 18.2 | E12: 48 | F12: 35 | G12: 61 | H12: -2 | I12: -4 | J12: 2 | L12: =IF(OR(K12="",B12=""),"",K12-B12) | O12: SEC
A13: Oklahoma | B13: 7.5 | C13: 12 | D13: 17.2 | E13: 65 | F13: 75 | G13: 55 | H13: 8 | I13: 6 | J13: 2 | L13: =IF(OR(K13="",B13=""),"",K13-B13) | O13: SEC
... A39: Oklahoma State | B39: 6.5 | C39: 38 | D39: 7.1 | E39: 58 | F39: 62 | G39: 53 | H39: 10 | I39: 6 | J39: 4 | L39: =IF(OR(K39="",B39=""),"",K39-B39) | O39: Pac12
A40: Boise State | B40: 7.5 | C40: 39 | D40: 6.8 | E40: 57 | F40: 60 | G40: 55 | H40: -0.5 | I40: 0 | J40: -0.5 | K40: 7 | L40: =IF(OR(K40="",B40=""),"",K40-B40) -> -0.5 | O40: Pac12
A41: Virginia | B41: 7.5 | C41: 40 | D41: 6.6 | E41: 59 | F41: 55 | G41: 62 | H41: 0.5 | I41: -1.5 | J41: 2 | L41: =IF(OR(K41="",B41=""),"",K41-B41) | O41: ACC
A42: Pittsburgh | B42: 7.5 | C42: 41 | D42: 6.5 | E42: 58 | F42: 60 | G42: 56 | H42: -1 | I42: -1 | J42: 0 | L42: =IF(OR(K42="",B42=""),"",K42-B42) | O42: ACC
A43: Arizona State | B43: 6.5 | C43: 42 | D43: 6.4 | E43: 51 | F43: 53 | G43: 49 | H43: 2 | I43: 2 | J43: 0 | L43: =IF(OR(K43="",B43=""),"",K43-B43) | O43: Big 12
A44: Georgia Tech | B44: 6.5 | C44: 43 | D44: 6 | E44: 49 | F44: 37 | G44: 61 | H44: 0.5 | I44: -4 | J44: 4.5 | L44: =IF(OR(K44="",B44=""),"",K44-B44) | O44: ACC
A45: Duke | B45: 5.5 | C45: 44 | D45: 5.7 | E45: 49 | F45: 48 | G45: 51 | H45: -3 | I45: -3 | J45: 0 | L45: =IF(OR(K45="",B45=""),"",K45-B45) | O45: ACC
A46: Minnesota | B46: 6.5 | C46: 45 | D46: 5.2 | E46: 68 | F46: 71 | G46: 65 | H46: 8 | I46: 3.5 | J46: 4.5 | L46: =IF(OR(K46="",B46=""),"",K46-B46) | O46: Big Ten
A47: UCLA | B47: 6.5 | C47: 46 | D47: 5.1 | E47: 67 | F47: 73 | G47: 61 | H47: 11 | I47: 6 | J47: 5 | L47: =IF(OR(K47="",B47=""),"",K47-B47) | O47: Big Ten
A48: Arkansas | B48: 4.5 | C48: 47 | D48: 5 | E48: 55 | F48: 55 | G48: 55 | H48: 6.5 | I48: 3 | J48: 3.5 | L48: =IF(OR(K48="",B48=""),"",K48-B48) | O48: Pac12
A49: NC State | B49: 7.5 | C49: 48 | D49: 4.9 | E49: 54 | F49: 62 | G49: 46 | H49: 2.5 | I49: 3.5 | J49: -1 | L49: =IF(OR(K49="",B49=""),"",K49-B49) | O49: ACC
A50: Northwestern | B50: 5.5 | C50: 49 | D50: 4.6 | E50: 57 | F50: 57 | G50: 58 | H50: 3.5 | I50: 2 | J50: 1.5 | L50: =IF(OR(K50="",B50=""),"",K50-B50) | O50: Big Ten
A51: Cincinnati | B51: 5.5 | C51: 50 | D51: 4.5 | E51: 57 | F51: 57 | G51: 56 | H51: 2.5 | I51: 1 | J51: 1.5 | L51: =IF(OR(K51="",B51=""),"",K51-B51) | O51: Big 12
A52: Baylor | B52: 6.5 | C52: 51 | D52: 4.5 | E52: 53 | F52: 44 | G52: 62 | H52: 1.5 | I52: -0.5 | J52: 2 | L52: =IF(OR(K52="",B52=""),"",K52-B52) | O52: Big 12
... A72: San Diego State | B72: 6.5 | C72: 71 | D72: -1.3 | E72: 59 | F72: 76 | G72: 43 | H72: 0 | I72: 2.5 | J72: -2.5 | L72: =IF(OR(K72="",B72=""),"",K72-B72) | O72: Pac12
A73: North Dakota State | C73: 72 | D73: -1.4 | E73: 52 | F73: 45 | G73: 60 | L73: =IF(OR(K73="",B73=""),"",K73-B73) | O73: MWC
A74: UTSA | B74: 7.5 | C74: 73 | D74: -1.5 | E74: 54 | F74: 64 | G74: 44 | H74: 3 | I74: 3 | J74: 0 | L74: =IF(OR(K74="",B74=""),"",K74-B74) | O74: AAC
A75: Boston College | B75: 3.5 | C75: 74 | D75: -1.5 | E75: 50 | F75: 44 | G75: 57 | H75: -0.5 | I75: -3 | J75: 2.5 | L75: =IF(OR(K75="",B75=""),"",K75-B75) | O75: MWC
A76: Stanford | B76: 3.5 | C76: 75 | D76: -1.9 | E76: 60 | F76: 58 | G76: 62 | H76: -3.5 | I76: -2 | J76: -1.5 | L76: =IF(OR(K76="",B76=""),"",K76-B76) | O76: ACC
A77: East Carolina | B77: 7.5 | C77: 76 | D77: -2 | E77: 42 | F77: 33 | G77: 50 | H77: -8 | I77: -6 | J77: -2 | L77: =IF(OR(K77="",B77=""),"",K77-B77) | O77: AAC
A78: James Madison | B78: 8.5 | C78: 77 | D78: -2.1 | E78: 30 | F78: 27 | G78: 32 | H78: -10 | I78: -6 | J78: -4 | K78: 8 | L78: =IF(OR(K78="",B78=""),"",K78-B78) -> -0.5 | O78: Sun Belt
A79: Fresno State | B79: 6.5 | C79: 78 | D79: -2.3 | E79: 53 | F79: 52 | G79: 54 | H79: -3 | I79: -2 | J79: -1 | K79: 4.5 | L79: =IF(OR(K79="",B79=""),"",K79-B79) -> -2 | O79: Pac12
A80: Air Force | B80: 7.5 | C80: 79 | D80: -2.4 | E80: 59 | F80: 42 | G80: 75 | H80: 3 | I80: -1.5 | J80: 4.5 | L80: =IF(OR(K80="",B80=""),"",K80-B80) | O80: MWC
A81: South Florida | B81: 8.5 | C81: 80 | D81: -2.8 | E81: 41 | F81: 47 | G81: 36 | H81: -9 | I81: -6 | J81: -3 | L81: =IF(OR(K81="",B81=""),"",K81-B81) | O81: AAC
A82: Miami OH | B82: 7.5 | C82: 81 | D82: -2.9 | E82: 49 | F82: 45 | G82: 52 | H82: -1.5 | I82: -1 | J82: -0.5 | L82: =IF(OR(K82="",B82=""),"",K82-B82) | O82: MAC
A83: Purdue | B83: 3.5 | C83: 82 | D83: -2.9 | E83: 58 | F83: 61 | G83: 55 | H83: 3 | I83: 3 | J83: 0 | L83: =IF(OR(K83="",B83=""),"",K83-B83) | O83: Pac12
A84: Army | B84: 7.5 | C84: 83 | D84: -3 | E84: 50 | F84: 67 | G84: 33 | H84: -1 | I84: 2 | J84: -3 | L84: =IF(OR(K84="",B84=""),"",K84-B84) | O84: AAC
...

Sheet Layer B — pod writeups
A1: Team | B1: QB status | C1: New HC | D1: New OC | E1: New DC | F1: Host Lean | G1: Dark Horse | H1: Fade | I1: Split | J1: Variance | K1: Sched Tag | L1: Key Avoids/Draws | M1: Key Injury | N1: BBOC Notes
A2: Appalachian State | B2: Battle — Malachi Singleton (transfer from Purdue, ex-'MAC legend'/dual-threat) likely QB1 / Tommy Ulatowski (transfer from Kent State) / Henry Hasselbeck [lead: hope is Singleton, may use multiple; the 2024 room bled out — 40+ portal departures] | F2: Lean Under | K2: Favorable | L2: Conducive slate — 4 home wins likely (Maine, Charlotte, Georgia State, ULM), winnables on the road (at Coastal, at South Alabama). Easy West crossover (ULM + at South Alabama). HOSTS JMU + ODU in Boone. Only ~3 games as a double-digit dog. | N2: Under lean but a soft one (Stuckey ~5.0, right on market, passes; Duck leans under but the schedule is too winnable to fire). Program on the decline — 127th in returning production, 40+ portal losses, lost 9 of top-10 tacklers; hosts are not Dowell Loggins believers (rode the one good LaNorris-Sellers-fueled year at South Carolina). QB unsettled (Singleton the hope). Trench help: RT Poindexter back from injury + LT Manuel (Florida/Arkansas) should steady the tackles; RB room has pop (Jaquez Cross from Ark State, Jaquari Lewis). Pass D was shredded in 2024 and the FCS DB imports don't obviously fix it. Bowl needs a road steal or two.
A3: Arkansas | L3: [from SEC pod] | N3: [BBOC pending — covered in SEC pod, not Pac-12.] Edge read: SP+ #47, TARP +6.5 — grades better than its 4.5 market; possible value if underrated as its real-conf self.
A4: Arkansas State | B4: Battle — Trey Owens (transfer from Texas, So, 6-5/225, high ceiling/physical tools, Super-Troopers mustache) — Stuckey's WANT and the projected UPGRADE [incumbent 3-yr starter Jaylen Raynor left for Iowa State; Owens the higher-ceiling swing over Raynor's win-games-lose-games profile] | D4: Garrett Altman (from Vanderbilt, QB coach — slow-pace/Pavia-style) | F4: Lean Over | G4: Y | J4: Y | K4: Favorable | L4: Manageable slate — dream East crossover (Coastal + Georgia State). HOSTS Troy in the finale (likely division-decider). Road-heavy winnables (at Southern Miss, at Louisiana, at Coastal, at La Tech) but they're 9-27 SU on the road since 2020. | N4: Stuckey's West flyer (~11-1 vs Louisiana's 8-1 — the value play). Rare Belt team that RISES in returning production (100th → 82nd); nearly the whole OL back. The upside is the QB swing to Trey Owens (Texas) + new OC Garrett Altman (Vandy QB coach — expect a much SLOWER pace to protect a resetting D, which Duck flags as an unders angle vs Memphis/TCU/Kennesaw early). WR reload needed (Chancy Cobb, 70 catches, back). The DL that was decent graduated; the back-seven that returns (safeties) was BAD and gave up a ton of explosives (110th). Butch Jones' teams win a pile of one-score games (9 in 2 years) + elite special teams — the reason to buy in a coin-flip division. Duck: 'we won't go under.'
A5: Boise State | B5: Returning — Maddox Madsen | D5: Zach Hill | E5: Terrence Brown | F5: Lean Under | K5: Neutral | L5: Full round-robin (plays all 7 other members) — no in-conf avoids. Wk13 FLEX (projected): vs Utah State (may not count). Non-con: @ Oregon, Memphis, @ W. Michigan, South Dakota (FCS). | N5: Conference anchor by the market. QB Maddox Madsen returns but is flagged hard: ~35 turnover-worthy plays and poor when tied/trailing (54% comp, 7 picks in those spots); over-reliant on the run. Two new coordinators (Hill OC, Brown DC). RBs Dylan Riley & Sire Gaines both ~4.2 yds after contact — best rushing tandem in the league. Collin ~7, below the 7.5 line — the QB downgrade + coordinator turnover is why. Anchor-tier by SP+ (#39) but not a clean over.
A6: Coastal Carolina | B6: Battle (wide open, no FBS starting experience) — [Trey] Bailey (transfer from Missouri State, wasn't the starter) / Tanner Lopez (freshman) / Jackson (freshman) / Trey Garra-Warren (JUCO All-American, was P4-recruited as a backup — LSU/FSU/Arkansas/Texas Tech interest — chose Coastal to play for Petrino) [lead: unsettled; Beard says all four in the mix; incumbent gone, full reset] | C6: Ryan Beard (from Missouri State) | D6: (Bobby Petrino coaching tree — brought both coordinators) | F6: Hard Under | H6: Y | K6: Brutal | L6: 3rd-toughest Sun Belt schedule (Duck). Beats Fordham; crushed by West Virginia (Duck fades wk1, -17.5 → played to 22.5); at Delaware (dog), Liberty home. Horrific West draw (Louisiana + Arkansas State). Fade spots at Marshall, at Louisiana, at JMU. Four coin-flips (Georgia Southern home, App State, Georgia State, Ark State). | N6: A FADE — both under (Stuckey projects 4.2, pays for under 5.5 / under 4.5 plus-money; Duck fades wk1). Full reset under new HC Ryan Beard (the Petrino-tree hire from Missouri State — Stuckey is skeptical of the nepotism-heavy staff and the 'lucked into Jacob Clark' Mizzou run; they didn't bring Clark). No FBS starting experience in a 4-way QB battle, a bad OL (both 2024 tackles left for Duke + Oklahoma State), and skill positions void of talent. The 2024 D was awful (474 yд/gm in conf, 130th in explosives allowed) and now leans on Missouri State DL transfers. Would need to sweep 4 coin-flips + steal one for 5 wins — unlikely. Calabrese's lone silver lining: watch JUCO All-American Trey Garra.
A7: Colorado State | B7: Battle — Haas Haney (OK St transfer) vs Darius Curry | C7: Jim Mora Jr. | D7: Price Tracy | F7: Hard Under | H7: Y | J7: Y | K7: Neutral | L7: Full round-robin (plays all 7 other members) — no in-conf avoids. Wk13 FLEX (projected): vs Texas State (may not count). Non-con: Wyoming, Southern Utah, BYU, @ UTSA. | N7: Bottom of the bucket. New HC Jim Mora Jr. (from UConn) + new OC Price Tracy = full offensive reset; QB battle unsettled. Collin: first six games a 'soul-search,' ceiling ~5 wins, projects ~2.8 — hard under. High variance from the staff/QB turnover.
A8: Fresno State | B8: Transfer — Christian Martin (from Maryland) | F8: Hard Under | H8: Y | I8: Y | K8: Neutral | L8: Full round-robin (plays all 7 other members) — no in-conf avoids. Wk13 FLEX (projected): vs San Diego State (may not count). Non-con: @ USC (Fri opener), Sacramento St, @ San Jose St, Rice. | N8: HOST SPLIT — Collin very bearish (~4.5, hard under), Duck bullish. New QB Christian Martin (Maryland) replacing EJ Warner. Secondary is a strength (borderline-elite MW last year, ~20 INTs) but turnovers may regress. SP+ (#78) sides with the bearish read against the market. Fade candidate despite the board total.
A9: Georgia Southern | B9: Transfer — Max Johnson (transfer, Super-Sr, started at LSU in 2020 then Texas A&M/UNC; journeyman on his last stop, injury-prone) [backups: Turner/Tor Helton — the HC's son — plus Wes Brian, a short-yardage/wildcat runner; 'one play away from a disastrous offense'] | E9: Mike Mutz (from Stephen F. Austin) | F9: No Play | H9: Y | K9: Brutal | L9: 2nd-toughest Sun Belt schedule (Duck). Non-con at Clemson, at Jacksonville State, Houston home; brutal East draw. HOSTS JMU + Marshall but goes to ODU. Could be 2-5 before it gets deeper. | N9: A fade lean (Duck under 5.5 since spring; Stuckey/Calabrese pass, no path to the division). The offense was DECIMATED — all 11 players with 400+ snaps gone (QB JC French to Cincinnati, 3-yr RB Arnold, 3-yr WR Cobb, RT to Michigan State, C to North Texas). 108th in returning production (was top-50). They're rebuilding the O with P4 transfers (didn't pan out) and the D with FCS plug-ins. New DC Mike Mutz (SFA) is a pressure guy for a D that had 9 sacks all of 2024 (dead-last-ish pass rush) — the one real upside. QB is Max Johnson, who 'absolutely cannot stay healthy.' OL/DL maybe the worst aggregate trenches in the Belt. Not a bowl team.
A10: Georgia State | B10: Returning — Christian Brown (incumbent, steadier option; 13:1 TD:INT in limited 2024 action, the clear best option over Finley — hosts puzzled he didn't play more; battled OL injuries around him) [QB play should be steadier + healthier in 2026] | D10: Hugh Jackson (returns) | E10: (new co-DCs, from FCS) | F10: Lean Over | J10: Y | K10: Neutral | L10: Winnable slate — opens FCS NC A&T (Duck's over play, 'shred them'); swaps Ole Miss/Memphis/Vandy off the 2024 non-con for Kennesaw, UCF, NIU (much softer). Draws JMU/ODU/Marshall run-heavy fronts that could 'run through them like tissue paper.' | N10: Year 3 of Dell McGee — Calabrese + Duck lean OVER 3.5 (Stuckey ~3.9, wants to bet the over but the DEFENSE scares him). Coming off a 1-win year, but the OFFENSE should be much better: QB Christian Brown (13:1 in limited time) over Finley, a healthier/upgraded OL, and OC Hugh Jackson back — projects top-20 in pace + improved 3rd-down (81st in 2024). The problem is the defense — 9 new starters, still adding low-level bodies, could be one of the worst run Ds in the league (they lost 13 of top-16 snaps, oddly 7 to P4). Expect shootouts → a lot of Georgia State OVERS early before the market corrects (Duck's angle).
A11: James Madison | B11: Battle (4-way, all new) — Camden Coleman (transfer, prev. multi-yr starter at Richmond, dual-threat game-manager) / J.C. Evans (transfer, mobile, had committed to Rich Rod at Jax State) / Matthew Maiden (transfer from Memphis) / Alonza Arrington [lead: hosts split — Evans favored by some, Stuckey + Calabrese think/hope Coleman wins; incumbent Alonzo Barnett left for UCF; Davis Belfort moved to WR] | C11: Billy Napier | D11: Cam Akins (from East Tennessee State) | E11: Robert Bala | F11: Lean Under | I11: Y | J11: Y | K11: Neutral | L11: Opens Liberty (~TD fav) + Wagner (cakewalk), then back-to-back roadies at San Diego State + at Old Dominion (the early test); HOSTS Marshall (home/away split matters in the East race). After ODU, arguably favored in every game. | N11: HOST SPLIT on the total — Calabrese OVER 8.5 (Billy Napier rehab hire, 33 wins in his last 3 Louisiana years, best resources in the league via ~$60M student-fee athletic funding; 2nd-rated G6 portal class; road-grader OL rebuild + deep RB room incl. Nick Herman, a 1,000-yд Drake back), Stuckey UNDER (+125) — downgraded them ~13 pts from year-end after Chesney left for UCLA and stripped the roster: 136th in returning production, 18 of the top-28 offensive+defensive snaps gone to P4/NFL, secondary a question. Duck: wait-and-see, need to see the offense; front-doors the East if they beat ODU + Marshall. 3-1 to win the conference.
A12: Louisiana | B12: Returning — Walker 'Lunch' Winfield (incumbent, dual-threat/run-first; wasn't the planned 2024 starter but took over midseason and the offense averaged 34 ppg over the last 4 games once they balanced him; must develop as a passer) [ZERO QB depth — 'if Lunch runs and gets hurt, it's over'; the ONLY Sun Belt team with the same HC + both coordinators + QB] | F12: Lean Over | K12: Favorable | L12: EASIEST Sun Belt schedule (Duck) — AVOIDS JMU, ODU AND Marshall; dream East draw (Coastal + Georgia State). HOSTS South Alabama, Arkansas State, Troy (huge in the West race); road at Southern Miss, ULM, La Tech. 3 winnable non-cons (Lamar, UAB, Charlotte). | N12: The West favorite (~8-1, Calabrese's 7-1 pick to win it) — Duck + Calabrese lean OVER 7.5. A 'grown-in-a-lab' develop-your-own roster: 81st in returning production (high for the Belt), 3rd in returning starts. Full offseason for Lunch Winfield + WR Shelton Sampson (a possible star capped by 46% catch rate on inaccurate 2024 QB play) + a big rebuilt OL (6 players back with 25%+ snaps, but most injury-plagued line in the country in 2024). The DEFENSE is the drag — DC Jim Salgado's unit was 100th+ in scoring/total D and returns only 2 starters; leaned on FCS imports (Tito Chikwelu, Broderick Stewart) to fix a 121st pass rush + 85th run D. Desormeaux is poor in one-possession games — situational execution is the swing. Stuckey out on Desormeaux + not sold on Lunch's arm.
A13: Louisiana Tech | B13: Battle — Trey Kucuk (Kukuk) (incumbent-ish, returning from injury, should be healthy) vs a lean into the run/option [2024 became an option team out of necessity — only 8 passing TD all year; no clear WR talent to throw to, so the new OL-coach OC may just run it] | D13: (new OC — an offensive-line coach; expect run-heavy) | F13: Lean Under | K13: Brutal | L13: Steps UP into the Sun Belt from CUSA (but travel drops from ~5,500 to ~2,050 miles). Tough open (at LSU, at Baylor, Army home, then Louisiana) — a likely 1-3 start. 4-27 SU on the road since 2021; road at Troy, at South Alabama, at Georgia Southern not assured. | N13: Lean under (both ~market; Duck likes the DK ALT under 6.5 at -166 as value). #1 in the Sun Belt in returning production, but a hollow-looking group: 2024's 8 wins came against a parade of bad teams (Sela, NMSU, USM, UTEP, Sam Houston, an overtime Liberty, backups-vs-Coastal in the bowl) — a Cumby job-saving mirage. The passing attack never materialized under Sonny Cumby (only 8 pass TD); the new OC is an OL coach → likely full run commitment, but the interior OL (RG/RT/C) is a question and there's no WR talent. The D loses 8 of the top-10 tacklers + real star power. A real step up in competition; Duck projects a 1-3 start.
A14: Marshall | B14: Returning — Carlos del Rio-Wilson 'CDRW' (incumbent, mobile; went 5-3 when he started AND finished games in 2024; hosts call him possibly the BEST QB in the conference) [backups Zion Turner + Khalil Wilkins limit the drop-off if he's hurt; RB-committee offense, only 119th in pass rate] | E14: Brad Lambert (2nd stint; former Broyles nominee) | F14: Lean Over | G14: Y | K14: Brutal | L14: Non-con at Penn State (+24.5, hang-around spot) then should blast Middle Tennessee + Gardner-Webb (Missouri State a red-ink revenge game). Great WEST draw (South Alabama + ULM). BUT plays BOTH JMU and ODU on the ROAD — must split to reach the tiebreaker. | N14: Stuckey's + Calabrese's dark-horse to win the East (~10-1; both take a shot; over 7.5). 2024 was a year-zero (Gibson took over after the whole team followed Charles Huff to Southern Miss — 75 new players) and they STILL went 5-7 with a 1-4 one-score record while out-gaining JMU/ULL/App State in losses — easily an 8-win team. Now a senior-laden offense in Gibson yr2, CDRW back, new DC Brad Lambert (a Broyles nominee in his first Marshall stint, elite situational D). 88th in returning production (highest in the East). The 2024 D was horrendous (bottom-10 in explosives allowed) — Donnie Smith (11 sacks) back + portal DL should help. Could be 6-1 before the ODU game.
A15: Michigan State | L15: [from Big Ten pod] | N15: [BBOC pending — covered in Big Ten pod, not Pac-12.] Edge read: SP+ #67, low ret prod 46%, TARP -3.5.
A16: Oklahoma State | L16: [from Big 12 pod] | N16: [BBOC pending — covered in Big 12 pod, not Pac-12.] Edge read: SP+ #38 and Net TARP +10.0 (highest in bucket) grade out well — possible pool value if drafters underrate as weak real-conf self.
A17: Old Dominion | B17: Returning backup — Colton 'Heinecke' (played some in 2024 incl. a shaky bowl vs USF; must develop as a passer — 'a mix of the old ODU Heineke throwing it around and Colton Joseph') [incumbent Colton Joseph left for Wisconsin; QB1 is unproven as a passer] | D17: Cody Cook (internal, ex-WR coach; first-time play-caller) | F17: Lean Under | K17: Neutral | L17: Opens Norfolk State; at Virginia Tech (won 3 of last 7 vs Hokies — noise chance); ECU home (sneaky tough); then JMU; downspot at Georgia State after Va Tech. All five remaining road games winnable (Georgia State, App State, La Tech, Coastal, UConn). Weird late UConn trip (has a bye before it). | N17: Both lean UNDER 7.5 (Stuckey projects 7.4-ish, no bet; Calabrese under). Ricky Rahne has built the culture, but the OFFENSE is the worry: lost QB Colton Joseph (Wisconsin), 3 WRs to P4, and the ENTIRE OL (all five started every game, 7,500+ career FBS snaps) — the 2026 line has ZERO career FBS starts (Elon C Braylan Walker + a JUCO LT). New first-time play-caller Cody Cook (Decker left for Memphis). Fell from 66th → 114th in returning production. Defense returns 8 of top-15 snaps (maybe the best LB group in the Belt) but the havoc creators/turnover luck (25 takeaways, 9th) may regress. 2024's 10 wins were schedule-timed; a real step back likely.
A18: Oregon State | B18: Unsettled | C18: Trent Bray | F18: No Play | K18: Neutral | L18: Full round-robin (plays all 7 other members) — no in-conf avoids. Wk13 FLEX (projected): vs Washington State (may not count). Non-con: @ Houston, Texas Tech, Montana (FCS semifinalist), @ UTEP. | N18: Bottom-tier anchor. New HC Trent Bray back in a DC-suited role — pod likes him as a defensive play-caller (architect of the 2022 double-digit-win OSU defense) despite flaming out as HC. D-line adds Zunk & McLean; FCS transfer Jeremy Bernard into a potentially good secondary; 5 starters back on D. Offense is the drag — ~90th in returning OL experience, two new tackles. Proud home program, low ceiling. Rebuild year.
A19: Purdue | L19: [from Big Ten pod] | N19: [BBOC pending — covered in Big Ten pod, not Pac-12.] Edge read: market lowest (3.5) but ret prod 58%, TARP +3.0, SP+ #82.
A20: San Diego State | B20: Returning — Jayden Denegal (health-dep.) | E20: Demetrius Sumler (promoted) | F20: No Play | K20: Neutral | L20: Full round-robin (plays all 7 other members) — no in-conf avoids. Wk13 FLEX (projected): vs Fresno State (may not count). Non-con: Portland St, @ UCLA, James Madison, @ Toledo. | M20: Denegal — repaired shoulder (health is the swing variable) | N20: Market/SP+ disagree sharply (mkt 6.5 vs SP+ #71). Highest returning production in the bucket (59%). QB Jayden Denegal is a deep-ball arm coming off shoulder surgery; struggles vs cover 2/3. Sumler promoted to DC. QB health is the season's swing variable.
A21: South Alabama | B21: Returning — Bishop Davenport (incumbent; short/safe profile — 6.38 aDOT, 2.7% big-time-throw, 5% turnover-worthy: poor ratios even for a checkdown passer, doesn't push it deep) [freshman Hollins waiting in the wings — hosts would be MORE interested if Davenport struggles and Hollins takes over; not framed as an open battle] | E21: Todd Orlando | F21: Lean Under | H21: Y | K21: Favorable | L21: 3rd-easiest Sun Belt schedule (Duck) — should beat Southeastern Louisiana + winnable home games. Losses at Tulane, Auburn/Kentucky-type non-con, at Marshall, at Louisiana. The question is whether they steal a road game they shouldn't to reach 6-6. | N21: A FADE — all three effectively under (Stuckey projects ~5.6, right on the number, wants the under; Calabrese under plus-money). Trend line down (10 → 7 → 7 → 4 wins). Major Applewhite hit the panic button — calls his own plays now + hired DC Todd Orlando (a blitz-heavy 'break-glass' hire whose FAU/USF Ds relied on fluky takeaway luck, not a sustainable calling card). Roster got worse basically everywhere (OL, RB, WR, TE, LB, DBs all downgraded; only ~2 assistants retained), no NIL money, and the passing game fell off a cliff post-Gio-Lopez. Red-zone D was horrific (41/43 trips scored on). Real chance of a midseason firing. Calabrese wants Southern Miss to cash his late-season fade tickets against them.
A22: Southern Miss | B22: Battle (unsettled, ~99% new roster) — multi-way incl. Ethan Hampton / Landry Lyle / a returning QB4 from 2024 [no established starter; possibly the most walk-on/replacement OL in the country — protection is the bigger problem than the QB] | C22: Blake Anderson (per pod; ASR-garbled — flag) | E22: (a special-teams coach elevated) | F22: Hard Under | H22: Y | K22: Brutal | L22: Bad crossover draw (JMU + at ODU). Favored vs Alcorn; likely loses at UConn (wk3). Home games (ULL, JMU, South Alabama, La Tech, Arkansas State) — most winnable is ULM but it's ON THE ROAD. Where are the 4 wins? | N22: A hard FADE — Stuckey UNDER 3.5 (plus money), Duck already in the app under 3.5. Roster is ~99% new: lost the top-15 defensive snaps (7 to Memphis, 3 to P4), and the entire senior-laden offense from the Charles-Huff year left (Huff's staff/players went to Memphis). [Transcript is ASR-garbled on the coaching picture — it names 'head coach Blake Anderson' for 2026, implying Anderson was elevated as Huff's group departed; flagged, not asserted with confidence.] The DC is an elevated special-teams coach handling total turnover. Most-walk-on OL in the country. No path to 4 wins on the board. Sell.
A23: Texas State | B23: Transfer — Malik Murphy | C23: G.J. Kinne era / McIntyre assoc. | F23: Lean Over | G23: Y | K23: Brutal (early) | L23: Full round-robin (plays all 7 other members) — no in-conf avoids. Wk13 FLEX (projected): vs Colorado State (may not count). Non-con gauntlet: @ Texas, UTSA, North Texas, Incarnate Word. | N23: FLEX-GAME CAVEAT BITES HARDEST: Collin's ~7.5 is explicitly on an 11-GAME schedule; prefers over 6.5 (+130) or the Pac-12 Championship-game bet (+200). Explosive offense is the identity ('when you watch the offense you'd think they win this league'); QB Malik Murphy. Defense is the question and the early schedule is brutal (Houston, Texas Tech, FCS-top-5 Montana). Dark-horse to make the title game.
A24: Troy | B24: Returning (both back) — Goose Crowder (incumbent, injury-prone, health the whole question; sub-7 YPA / <8.5 aDOT in 2024) + Tucker Kilcrease (returning; a bit better) [new veer-and-shoot scheme adds tempo/RPO/motion — can Goose hit the deep shots it needs?] | D24: (new OC from Tarleton State — veer-and-shoot) | F24: No Play | J24: Y | K24: Neutral | L24: Should win every conference HOME game (Southern Miss, ULM, La Tech, Georgia Southern). Starts 2-0 then tough road games; hosts Arkansas State in the finale (possible division decider). | M24: Goose Crowder — durability; hasn't been able to stay healthy | N24: A pass on the total (Stuckey ~market, no future; Duck projects 7.4-8 but doesn't love them). Contender in a WIDE-OPEN West (Stuckey has the top 5 within a field goal). Goes 19th → 119th in returning production but keeps BOTH QBs. New veer-and-shoot OC (from a high-scoring Tarleton State) with tight splits/slow-mesh RPOs — but the 2024 OL allowed a FBS-worst 59 sacks (injury-riddled; some guys who started at tackle project to 3rd-string now). Lost the top-6 WRs. The 2024 calling-card D graduated most of its front (Donnie Smith-type edge Chris Culliver-... gone; DE Donnie Smith-... ) — leans on DE Donnie Smith? no: keeps DE Donnie Smith equivalents + adds portal, but the DL basically graduated. High variance.
A25: ULM | B25: Battle (unsettled) — Aiden Armenta (returning) / Austin Carlyle (transfer from Houston) / Landon Graves [lead: unsettled — 'doesn't know what they want to be offensively'; QB health is huge] | F25: Lean Under | H25: Y | K25: Neutral | L25: Only remotely-competitive 2024 conf games were vs rivals Arkansas State (lost 15 straight to them before) + Louisiana. Slow-pace, ball-control to protect a bad D. | N25: Fade lean (Duck under; Stuckey pessimistic — 'no money at all' in the program). Brian Vincent's best team but that's a low bar: near-zero offensive explosiveness (scored ≤14 seven times, topped 200 pass yds only twice, 13 red-zone TD all year, ~100th in explosiveness), and RB Bam McReynolds leaving is huge. Unsettled QB battle (Armenta / Houston transfer Austin Carlyle / Graves). Lost 3 more OL starters. Special teams were 'the worst I've ever seen' in 2024 (couldn't hit a 20-yд FG — all the kickers got hurt); brought in 3 kickers, so it can only improve. LB is the lone bright spot. Slow tempo to hide the D. Surprised Vincent is still around.
A26: Utah State | B26: Battle — McKay Hillstead vs Grady Brosterhous | C26: Bronco Mendenhall | D26: Robert Anae | E26: Nick Howell | F26: Lean Under | J26: Y | K26: Neutral | L26: Full round-robin (plays all 7 other members) — no in-conf avoids. Wk13 FLEX (projected): vs Boise State (may not count). Non-con: Idaho St, @ Washington, @ Utah, Troy. | N26: Full staff turnover: new HC Bronco Mendenhall, new OC Robert Anae ('polarizing'), Nick Howell on D. QB battle Hillstead vs Brosterhous; last year's engine (Bryson Barnes) gone — he masked a garbage OL (42 sacks / 88 TFL allowed). SP+ near bottom of bucket (#97). Collin leans under 5.5. High variance from staff+QB reset.
A27: Washington State | B27: Unsettled | F27: No Play | K27: Neutral | L27: Full round-robin (plays all 7 other members) — no in-conf avoids. Wk13 FLEX (projected): vs Oregon State (may not count). Non-con: @ Washington (Apple Cup), @ Kansas St, Duquesne, Arizona. | N27: Lowest anchor in the bucket. Discussed only as a 'within-10 coin-flip' opponent the anchors beat, not a contender. Lowest returning production (42%) and lowest Net TARP (-4.0) in the conference. No positive signal from the pod. Forced-replacement lingerer — avoid as an anchor.

Sheet Dashboard (A+B join)
A1: Pool Conf | B1: Team | C1: Real Conf | D1: Mkt | E1: SP+ Rk | F1: SP+ Rtg | G1: RetProd% | H1: TARP net | I1: Collin | J1: Proj−Mkt | K1: QB status | L1: Coaching | M1: Host Lean | N1: Sched | O1: Flags | P1: Key Avoids/Draws | Q1: Notes
A2: ='Layer A — raw data (SOURCED)'!O2 -> Big Ten | B2: ='Layer A — raw data (SOURCED)'!A2 -> Ohio State | C2: ='Layer A — raw data (SOURCED)'!O2 -> Big Ten | D2: ='Layer A — raw data (SOURCED)'!B2 -> 9.5 | E2: ='Layer A — raw data (SOURCED)'!C2 -> 1 | F2: ='Layer A — raw data (SOURCED)'!D2 -> 31.8 | G2: ='Layer A — raw data (SOURCED)'!E2 -> 60 | H2: ='Layer A — raw data (SOURCED)'!H2 -> 10.5 | I2: ='Layer A — raw data (SOURCED)'!K2 -> 0 | J2: ='Layer A — raw data (SOURCED)'!L2 | K2: =IFERROR(INDEX('Layer B — pod writeups'!$B:$B,MATCH('Layer A — raw data (SOURCED)'!$A2,'Layer B — pod writeups'!$A:$A,0)),"") | L2: =IFERROR(textjoin(" | ",TRUE(),IF(INDEX('Layer B — pod writeups'!$C:$C,MATCH('Layer A — raw data (SOURCED)'!$A2,'Layer B — pod writeups'!$A:$A,0))="","","HC "&INDEX('Layer B — pod writeups'!$C:$C,MATCH('Layer A — raw data (SOURCED)'!$A2,'Layer B — pod writeups'!$A:$A,0))),IF(INDEX('Layer B — pod writeups'!$D:$D,MATCH('Layer A — raw data (SOURCED)'!$A2,'Layer B — pod writeups'!$A:$A,0))="","","OC "&INDEX('Layer B — pod writeups'!$D:$D,MATCH('Layer A — raw data (SOURCED)'!$A2,'Layer B — pod writeups'!$A:$A,0))),IF(INDEX('Layer B — pod writeups'!$E:$E,MATCH('Layer A — raw data (SOURCED)'!$A2,'Layer B — pod writeups'!$A:$A,0))="","","DC "&INDEX('Layer B — pod writeups'!$E:$E,MATCH('Layer A — raw data (SOURCED)'!$A2,'Layer B — pod writeups'!$A:$A,0)))),"") | M2: =IFERROR(INDEX('Layer B — pod writeups'!$F:$F,MATCH('Layer A — raw data (SOURCED)'!$A2,'Layer B — pod writeups'!$A:$A,0)),"") | N2: =IFERROR(INDEX('Layer B — pod writeups'!$K:$K,MATCH('Layer A — raw data (SOURCED)'!$A2,'Layer B — pod writeups'!$A:$A,0)),"") | O2: =IFERROR(textjoin(" ",TRUE(),IF(INDEX('Layer B — pod writeups'!$G:$G,MATCH('Layer A — raw data (SOURCED)'!$A2,'Layer B — pod writeups'!$A:$A,0))="Y","DH",""),IF(INDEX('Layer B — pod writeups'!$H:$H,MATCH('Layer A — raw data (SOURCED)'!$A2,'Layer B — pod writeups'!$A:$A,0))="Y","FADE",""),IF(INDEX('Layer B — pod writeups'!$I:$I,MATCH('Layer A — raw data (SOURCED)'!$A2,'Layer B — pod writeups'!$A:$A,0))="Y","SPLIT",""),IF(INDEX('Layer B — pod writeups'!$J:$J,MATCH('Layer A — raw data (SOURCED)'!$A2,'Layer B — pod writeups'!$A:$A,0))="Y","VAR","")),"") | P2: =IFERROR(INDEX('Layer B — pod writeups'!$L:$L,MATCH('Layer A — raw data (SOURCED)'!$A2,'Layer B — pod writeups'!$A:$A,0)),"") | Q2: =IFERROR(INDEX('Layer B — pod writeups'!$N:$N,MATCH('Layer A — raw data (SOURCED)'!$A2,'Layer B — pod writeups'!$A:$A,0)),"")
A3: ='Layer A — raw data (SOURCED)'!O3 -> Big Ten | B3: ='Layer A — raw data (SOURCED)'!A3 -> Oregon | C3: ='Layer A — raw data (SOURCED)'!O3 -> Big Ten | D3: ='Layer A — raw data (SOURCED)'!B3 -> 10.5 | E3: ='Layer A — raw data (SOURCED)'!C3 -> 2 | F3: ='Layer A — raw data (SOURCED)'!D3 -> 28.3 | G3: ='Layer A — raw data (SOURCED)'!E3 -> 66 | H3: ='Layer A — raw data (SOURCED)'!H3 -> 11 | I3: ='Layer A — raw data (SOURCED)'!K3 -> 0 | J3: ='Layer A — raw data (SOURCED)'!L3 | K3: =IFERROR(INDEX('Layer B — pod writeups'!$B:$B,MATCH('Layer A — raw data (SOURCED)'!$A3,'Layer B — pod writeups'!$A:$A,0)),"") | L3: =IFERROR(textjoin(" | ",TRUE(),IF(INDEX('Layer B — pod writeups'!$C:$C,MATCH('Layer A — raw data (SOURCED)'!$A3,'Layer B — pod writeups'!$A:$A,0))="","","HC "&INDEX('Layer B — pod writeups'!$C:$C,MATCH('Layer A — raw data (SOURCED)'!$A3,'Layer B — pod writeups'!$A:$A,0))),IF(INDEX('Layer B — pod writeups'!$D:$D,MATCH('Layer A — raw data (SOURCED)'!$A3,'Layer B — pod writeups'!$A:$A,0))="","","OC "&INDEX('Layer B — pod writeups'!$D:$D,MATCH('Layer A — raw data (SOURCED)'!$A3,'Layer B — pod writeups'!$A:$A,0))),IF(INDEX('Layer B — pod writeups'!$E:$E,MATCH('Layer A — raw data (SOURCED)'!$A3,'Layer B — pod writeups'!$A:$A,0))="","","DC "&INDEX('Layer B — pod writeups'!$E:$E,MATCH('Layer A — raw data (SOURCED)'!$A3,'Layer B — pod writeups'!$A:$A,0)))),"") | M3: =IFERROR(INDEX('Layer B — pod writeups'!$F:$F,MATCH('Layer A — raw data (SOURCED)'!$A3,'Layer B — pod writeups'!$A:$A,0)),"") | N3: =IFERROR(INDEX('Layer B — pod writeups'!$K:$K,MATCH('Layer A — raw data (SOURCED)'!$A3,'Layer B — pod writeups'!$A:$A,0)),"") | O3: =IFERROR(textjoin(" ",TRUE(),IF(INDEX('Layer B — pod writeups'!$G:$G,MATCH('Layer A — raw data (SOURCED)'!$A3,'Layer B — pod writeups'!$A:$A,0))="Y","DH",""),IF(INDEX('Layer B — pod writeups'!$H:$H,MATCH('Layer A — raw data (SOURCED)'!$A3,'Layer B — pod writeups'!$A:$A,0))="Y","FADE",""),IF(INDEX('Layer B — pod writeups'!$I:$I,MATCH('Layer A — raw data (SOURCED)'!$A3,'Layer B — pod writeups'!$A:$A,0))="Y","SPLIT",""),IF(INDEX('Layer B — pod writeups'!$J:$J,MATCH('Layer A — raw data (SOURCED)'!$A3,'Layer B — pod writeups'!$A:$A,0))="Y","VAR","")),"") | P3: =IFERROR(INDEX('Layer B — pod writeups'!$L:$L,MATCH('Layer A — raw data (SOURCED)'!$A3,'Layer B — pod writeups'!$A:$A,0)),"") | Q3: =IFERROR(INDEX('Layer B — pod writeups'!$N:$N,MATCH('Layer A — raw data (SOURCED)'!$A3,'Layer B — pod writeups'!$A:$A,0)),"")
A4: ='Layer A — raw data (SOURCED)'!O4 -> CUSA | B4: ='Layer A — raw data (SOURCED)'!A4 -> Notre Dame | C4: Independent | D4: ='Layer A — raw data (SOURCED)'!B4 -> 11.5 | E4: ='Layer A — raw data (SOURCED)'!C4 -> 3 | F4: ='Layer A — raw data (SOURCED)'!D4 -> 25.8 | G4: ='Layer A — raw data (SOURCED)'!E4 -> 72 | H4: ='Layer A — raw data (SOURCED)'!H4 -> 5.5 | I4: ='Layer A — raw data (SOURCED)'!K4 -> 0 | J4: ='Layer A — raw data (SOURCED)'!L4 | K4: =IFERROR(INDEX('Layer B — pod writeups'!$B:$B,MATCH('Layer A — raw data (SOURCED)'!$A4,'Layer B — pod writeups'!$A:$A,0)),"") | L4: =IFERROR(textjoin(" | ",TRUE(),IF(INDEX('Layer B — pod writeups'!$C:$C,MATCH('Layer A — raw data (SOURCED)'!$A4,'Layer B — pod writeups'!$A:$A,0))="","","HC "&INDEX('Layer B — pod writeups'!$C:$C,MATCH('Layer A — raw data (SOURCED)'!$A4,'Layer B — pod writeups'!$A:$A,0))),IF(INDEX('Layer B — pod writeups'!$D:$D,MATCH('Layer A — raw data (SOURCED)'!$A4,'Layer B — pod writeups'!$A:$A,0))="","","OC "&INDEX('Layer B — pod writeups'!$D:$D,MATCH('Layer A — raw data (SOURCED)'!$A4,'Layer B — pod writeups'!$A:$A,0))),IF(INDEX('Layer B — pod writeups'!$E:$E,MATCH('Layer A — raw data (SOURCED)'!$A4,'Layer B — pod writeups'!$A:$A,0))="","","DC "&INDEX('Layer B — pod writeups'!$E:$E,MATCH('Layer A — raw data (SOURCED)'!$A4,'Layer B — pod writeups'!$A:$A,0)))),"") | M4: =IFERROR(INDEX('Layer B — pod writeups'!$F:$F,MATCH('Layer A — raw data (SOURCED)'!$A4,'Layer B — pod writeups'!$A:$A,0)),"") | N4: =IFERROR(INDEX('Layer B — pod writeups'!$K:$K,MATCH('Layer A — raw data (SOURCED)'!$A4,'Layer B — pod writeups'!$A:$A,0)),"") | O4: =IFERROR(textjoin(" ",TRUE(),IF(INDEX('Layer B — pod writeups'!$G:$G,MATCH('Layer A — raw data (SOURCED)'!$A4,'Layer B — pod writeups'!$A:$A,0))="Y","DH",""),IF(INDEX('Layer B — pod writeups'!$H:$H,MATCH('Layer A — raw data (SOURCED)'!$A4,'Layer B — pod writeups'!$A:$A,0))="Y","FADE",""),IF(INDEX('Layer B — pod writeups'!$I:$I,MATCH('Layer A — raw data (SOURCED)'!$A4,'Layer B — pod writeups'!$A:$A,0))="Y","SPLIT",""),IF(INDEX('Layer B — pod writeups'!$J:$J,MATCH('Layer A — raw data (SOURCED)'!$A4,'Layer B — pod writeups'!$A:$A,0))="Y","VAR","")),"") | P4: =IFERROR(INDEX('Layer B — pod writeups'!$L:$L,MATCH('Layer A — raw data (SOURCED)'!$A4,'Layer B — pod writeups'!$A:$A,0)),"") | Q4: =IFERROR(INDEX('Layer B — pod writeups'!$N:$N,MATCH('Layer A — raw data (SOURCED)'!$A4,'Layer B — pod writeups'!$A:$A,0)),"")
A5: ='Layer A — raw data (SOURCED)'!O5 -> SEC | B5: ='Layer A — raw data (SOURCED)'!A5 -> Georgia | C5: ='Layer A — raw data (SOURCED)'!O5 -> SEC | D5: ='Layer A — raw data (SOURCED)'!B5 -> 9.5 | E5: ='Layer A — raw data (SOURCED)'!C5 -> 4 | F5: ='Layer A — raw data (SOURCED)'!D5 -> 25.5 | G5: ='Layer A — raw data (SOURCED)'!E5 -> 68 | H5: ='Layer A — raw data (SOURCED)'!H5 -> 8 | I5: ='Layer A — raw data (SOURCED)'!K5 -> 0 | J5: ='Layer A — raw data (SOURCED)'!L5 | K5: =IFERROR(INDEX('Layer B — pod writeups'!$B:$B,MATCH('Layer A — raw data (SOURCED)'!$A5,'Layer B — pod writeups'!$A:$A,0)),"") | L5: =IFERROR(textjoin(" | ",TRUE(),IF(INDEX('Layer B — pod writeups'!$C:$C,MATCH('Layer A — raw data (SOURCED)'!$A5,'Layer B — pod writeups'!$A:$A,0))="","","HC "&INDEX('Layer B — pod writeups'!$C:$C,MATCH('Layer A — raw data (SOURCED)'!$A5,'Layer B — pod writeups'!$A:$A,0))),IF(INDEX('Layer B — pod writeups'!$D:$D,MATCH('Layer A — raw data (SOURCED)'!$A5,'Layer B — pod writeups'!$A:$A,0))="","","OC "&INDEX('Layer B — pod writeups'!$D:$D,MATCH('Layer A — raw data (SOURCED)'!$A5,'Layer B — pod writeups'!$A:$A,0))),IF(INDEX('Layer B — pod writeups'!$E:$E,MATCH('Layer A — raw data (SOURCED)'!$A5,'Layer B — pod writeups'!$A:$A,0))="","","DC "&INDEX('Layer B — pod writeups'!$E:$E,MATCH('Layer A — raw data (SOURCED)'!$A5,'Layer B — pod writeups'!$A:$A,0)))),"") | M5: =IFERROR(INDEX('Layer B — pod writeups'!$F:$F,MATCH('Layer A — raw data (SOURCED)'!$A5,'Layer B — pod writeups'!$A:$A,0)),"") | N5: =IFERROR(INDEX('Layer B — pod writeups'!$K:$K,MATCH('Layer A — raw data (SOURCED)'!$A5,'Layer B — pod writeups'!$A:$A,0)),"") | O5: =IFERROR(textjoin(" ",TRUE(),IF(INDEX('Layer B — pod writeups'!$G:$G,MATCH('Layer A — raw data (SOURCED)'!$A5,'Layer B — pod writeups'!$A:$A,0))="Y","DH",""),IF(INDEX('Layer B — pod writeups'!$H:$H,MATCH('Layer A — raw data (SOURCED)'!$A5,'Layer B — pod writeups'!$A:$A,0))="Y","FADE",""),IF(INDEX('Layer B — pod writeups'!$I:$I,MATCH('Layer A — raw data (SOURCED)'!$A5,'Layer B — pod writeups'!$A:$A,0))="Y","SPLIT",""),IF(INDEX('Layer B — pod writeups'!$J:$J,MATCH('Layer A — raw data (SOURCED)'!$A5,'Layer B — pod writeups'!$A:$A,0))="Y","VAR","")),"") | P5: =IFERROR(INDEX('Layer B — pod writeups'!$L:$L,MATCH('Layer A — raw data (SOURCED)'!$A5,'Layer B — pod writeups'!$A:$A,0)),"") | Q5: =IFERROR(INDEX('Layer B — pod writeups'!$N:$N,MATCH('Layer A — raw data (SOURCED)'!$A5,'Layer B — pod writeups'!$A:$A,0)),"")
A6: ='Layer A — raw data (SOURCED)'!O6 -> Big Ten | B6: ='Layer A — raw data (SOURCED)'!A6 -> Indiana | C6: ='Layer A — raw data (SOURCED)'!O6 -> Big Ten | D6: ='Layer A — raw data (SOURCED)'!B6 -> 10.5 | E6: ='Layer A — raw data (SOURCED)'!C6 -> 5 | F6: ='Layer A — raw data (SOURCED)'!D6 -> 24.5 | G6: ='Layer A — raw data (SOURCED)'!E6 -> 56 | H6: ='Layer A — raw data (SOURCED)'!H6 -> 7.5 | I6: ='Layer A — raw data (SOURCED)'!K6 -> 0 | J6: ='Layer A — raw data (SOURCED)'!L6 | K6: =IFERROR(INDEX('Layer B — pod writeups'!$B:$B,MATCH('Layer A — raw data (SOURCED)'!$A6,'Layer B — pod writeups'!$A:$A,0)),"") | L6: =IFERROR(textjoin(" | ",TRUE(),IF(INDEX('Layer B — pod writeups'!$C:$C,MATCH('Layer A — raw data (SOURCED)'!$A6,'Layer B — pod writeups'!$A:$A,0))="","","HC "&INDEX('Layer B — pod writeups'!$C:$C,MATCH('Layer A — raw data (SOURCED)'!$A6,'Layer B — pod writeups'!$A:$A,0))),IF(INDEX('Layer B — pod writeups'!$D:$D,MATCH('Layer A — raw data (SOURCED)'!$A6,'Layer B — pod writeups'!$A:$A,0))="","","OC "&INDEX('Layer B — pod writeups'!$D:$D,MATCH('Layer A — raw data (SOURCED)'!$A6,'Layer B — pod writeups'!$A:$A,0))),IF(INDEX('Layer B — pod writeups'!$E:$E,MATCH('Layer A — raw data (SOURCED)'!$A6,'Layer B — pod writeups'!$A:$A,0))="","","DC "&INDEX('Layer B — pod writeups'!$E:$E,MATCH('Layer A — raw data (SOURCED)'!$A6,'Layer B — pod writeups'!$A:$A,0)))),"") | M6: =IFERROR(INDEX('Layer B — pod writeups'!$F:$F,MATCH('Layer A — raw data (SOURCED)'!$A6,'Layer B — pod writeups'!$A:$A,0)),"") | N6: =IFERROR(INDEX('Layer B — pod writeups'!$K:$K,MATCH('Layer A — raw data (SOURCED)'!$A6,'Layer B — pod writeups'!$A:$A,0)),"") | O6: =IFERROR(textjoin(" ",TRUE(),IF(INDEX('Layer B — pod writeups'!$G:$G,MATCH('Layer A — raw data (SOURCED)'!$A6,'Layer B — pod writeups'!$A:$A,0))="Y","DH",""),IF(INDEX('Layer B — pod writeups'!$H:$H,MATCH('Layer A — raw data (SOURCED)'!$A6,'Layer B — pod writeups'!$A:$A,0))="Y","FADE",""),IF(INDEX('Layer B — pod writeups'!$I:$I,MATCH('Layer A — raw data (SOURCED)'!$A6,'Layer B — pod writeups'!$A:$A,0))="Y","SPLIT",""),IF(INDEX('Layer B — pod writeups'!$J:$J,MATCH('Layer A — raw data (SOURCED)'!$A6,'Layer B — pod writeups'!$A:$A,0))="Y","VAR","")),"") | P6: =IFERROR(INDEX('Layer B — pod writeups'!$L:$L,MATCH('Layer A — raw data (SOURCED)'!$A6,'Layer B — pod writeups'!$A:$A,0)),"") | Q6: =IFERROR(INDEX('Layer B — pod writeups'!$N:$N,MATCH('Layer A — raw data (SOURCED)'!$A6,'Layer B — pod writeups'!$A:$A,0)),"")
A7: ='Layer A — raw data (SOURCED)'!O7 -> SEC | B7: ='Layer A — raw data (SOURCED)'!A7 -> Texas | C7: ='Layer A — raw data (SOURCED)'!O7 -> SEC | D7: ='Layer A — raw data (SOURCED)'!B7 -> 9.5 | E7: ='Layer A — raw data (SOURCED)'!C7 -> 6 | F7: ='Layer A — raw data (SOURCED)'!D7 -> 23.7 | G7: ='Layer A — raw data (SOURCED)'!E7 -> 68 | H7: ='Layer A — raw data (SOURCED)'!H7 -> 10.5 | I7: ='Layer A — raw data (SOURCED)'!K7 -> 0 | J7: ='Layer A — raw data (SOURCED)'!L7 | K7: =IFERROR(INDEX('Layer B — pod writeups'!$B:$B,MATCH('Layer A — raw data (SOURCED)'!$A7,'Layer B — pod writeups'!$A:$A,0)),"") | L7: =IFERROR(textjoin(" | ",TRUE(),IF(INDEX('Layer B — pod writeups'!$C:$C,MATCH('Layer A — raw data (SOURCED)'!$A7,'Layer B — pod writeups'!$A:$A,0))="","","HC "&INDEX('Layer B — pod writeups'!$C:$C,MATCH('Layer A — raw data (SOURCED)'!$A7,'Layer B — pod writeups'!$A:$A,0))),IF(INDEX('Layer B — pod writeups'!$D:$D,MATCH('Layer A — raw data (SOURCED)'!$A7,'Layer B — pod writeups'!$A:$A,0))="","","OC "&INDEX('Layer B — pod writeups'!$D:$D,MATCH('Layer A — raw data (SOURCED)'!$A7,'Layer B — pod writeups'!$A:$A,0))),IF(INDEX('Layer B — pod writeups'!$E:$E,MATCH('Layer A — raw data (SOURCED)'!$A7,'Layer B — pod writeups'!$A:$A,0))="","","DC "&INDEX('Layer B — pod writeups'!$E:$E,MATCH('Layer A — raw data (SOURCED)'!$A7,'Layer B — pod writeups'!$A:$A,0)))),"") | M7: =IFERROR(INDEX('Layer B — pod writeups'!$F:$F,MATCH('Layer A — raw data (SOURCED)'!$A7,'Layer B — pod writeups'!$A:$A,0)),"") | N7: =IFERROR(INDEX('Layer B — pod writeups'!$K:$K,MATCH('Layer A — raw data (SOURCED)'!$A7,'Layer B — pod writeups'!$A:$A,0)),"") | O7: =IFERROR(textjoin(" ",TRUE(),IF(INDEX('Layer B — pod writeups'!$G:$G,MATCH('Layer A — raw data (SOURCED)'!$A7,'Layer B — pod writeups'!$A:$A,0))="Y","DH",""),IF(INDEX('Layer B — pod writeups'!$H:$H,MATCH('Layer A — raw data (SOURCED)'!$A7,'Layer B — pod writeups'!$A:$A,0))="Y","FADE",""),IF(INDEX('Layer B — pod writeups'!$I:$I,MATCH('Layer A — raw data (SOURCED)'!$A7,'Layer B — pod writeups'!$A:$A,0))="Y","SPLIT",""),IF(INDEX('Layer B — pod writeups'!$J:$J,MATCH('Layer A — raw data (SOURCED)'!$A7,'Layer B — pod writeups'!$A:$A,0))="Y","VAR","")),"") | P7: =IFERROR(INDEX('Layer B — pod writeups'!$L:$L,MATCH('Layer A — raw data (SOURCED)'!$A7,'Layer B — pod writeups'!$A:$A,0)),"") | Q7: =IFERROR(INDEX('Layer B — pod writeups'!$N:$N,MATCH('Layer A — raw data (SOURCED)'!$A7,'Layer B — pod writeups'!$A:$A,0)),"")
A8: ='Layer A — raw data (SOURCED)'!O8 -> Big 12 | B8: ='Layer A — raw data (SOURCED)'!A8 -> Texas Tech | C8: ='Layer A — raw data (SOURCED)'!O8 -> Big 12 | D8: ='Layer A — raw data (SOURCED)'!B8 -> 10.5 | E8: ='Layer A — raw data (SOURCED)'!C8 -> 7 | F8: ='Layer A — raw data (SOURCED)'!D8 -> 23.1 | G8: ='Layer A — raw data (SOURCED)'!E8 -> 65 | H8: ='Layer A — raw data (SOURCED)'!H8 -> 11 | I8: ='Layer A — raw data (SOURCED)'!K8 -> 0 | J8: ='Layer A — raw data (SOURCED)'!L8 | K8: =IFERROR(INDEX('Layer B — pod writeups'!$B:$B,MATCH('Layer A — raw data (SOURCED)'!$A8,'Layer B — pod writeups'!$A:$A,0)),"") | L8: =IFERROR(textjoin(" | ",TRUE(),IF(INDEX('Layer B — pod writeups'!$C:$C,MATCH('Layer A — raw data (SOURCED)'!$A8,'Layer B — pod writeups'!$A:$A,0))="","","HC "&INDEX('Layer B — pod writeups'!$C:$C,MATCH('Layer A — raw data (SOURCED)'!$A8,'Layer B — pod writeups'!$A:$A,0))),IF(INDEX('Layer B — pod writeups'!$D:$D,MATCH('Layer A — raw data (SOURCED)'!$A8,'Layer B — pod writeups'!$A:$A,0))="","","OC "&INDEX('Layer B — pod writeups'!$D:$D,MATCH('Layer A — raw data (SOURCED)'!$A8,'Layer B — pod writeups'!$A:$A,0))),IF(INDEX('Layer B — pod writeups'!$E:$E,MATCH('Layer A — raw data (SOURCED)'!$A8,'Layer B — pod writeups'!$A:$A,0))="","","DC "&INDEX('Layer B — pod writeups'!$E:$E,MATCH('Layer A — raw data (SOURCED)'!$A8,'Layer B — pod writeups'!$A:$A,0)))),"") | M8: =IFERROR(INDEX('Layer B — pod writeups'!$F:$F,MATCH('Layer A — raw data (SOURCED)'!$A8,'Layer B — pod writeups'!$A:$A,0)),"") | N8: =IFERROR(INDEX('Layer B — pod writeups'!$K:$K,MATCH('Layer A — raw data (SOURCED)'!$A8,'Layer B — pod writeups'!$A:$A,0)),"") | O8: =IFERROR(textjoin(" ",TRUE(),IF(INDEX('Layer B — pod writeups'!$G:$G,MATCH('Layer A — raw data (SOURCED)'!$A8,'Layer B — pod writeups'!$A:$A,0))="Y","DH",""),IF(INDEX('Layer B — pod writeups'!$H:$H,MATCH('Layer A — raw data (SOURCED)'!$A8,'Layer B — pod writeups'!$A:$A,0))="Y","FADE",""),IF(INDEX('Layer B — pod writeups'!$I:$I,MATCH('Layer A — raw data (SOURCED)'!$A8,'Layer B — pod writeups'!$A:$A,0))="Y","SPLIT",""),IF(INDEX('Layer B — pod writeups'!$J:$J,MATCH('Layer A — raw data (SOURCED)'!$A8,'Layer B — pod writeups'!$A:$A,0))="Y","VAR","")),"") | P8: =IFERROR(INDEX('Layer B — pod writeups'!$L:$L,MATCH('Layer A — raw data (SOURCED)'!$A8,'Layer B — pod writeups'!$A:$A,0)),"") | Q8: =IFERROR(INDEX('Layer B — pod writeups'!$N:$N,MATCH('Layer A — raw data (SOURCED)'!$A8,'Layer B — pod writeups'!$A:$A,0)),"")
A9: ='Layer A — raw data (SOURCED)'!O9 -> ACC | B9: ='Layer A — raw data (SOURCED)'!A9 -> Miami FL | C9: ='Layer A — raw data (SOURCED)'!O9 -> ACC | D9: ='Layer A — raw data (SOURCED)'!B9 -> 10.5 | E9: ='Layer A — raw data (SOURCED)'!C9 -> 8 | F9: ='Layer A — raw data (SOURCED)'!D9 -> 21 | G9: ='Layer A — raw data (SOURCED)'!E9 -> 49 | H9: ='Layer A — raw data (SOURCED)'!H9 -> 4.5 | I9: ='Layer A — raw data (SOURCED)'!K9 -> 0 | J9: ='Layer A — raw data (SOURCED)'!L9 | K9: =IFERROR(INDEX('Layer B — pod writeups'!$B:$B,MATCH('Layer A — raw data (SOURCED)'!$A9,'Layer B — pod writeups'!$A:$A,0)),"") | L9: =IFERROR(textjoin(" | ",TRUE(),IF(INDEX('Layer B — pod writeups'!$C:$C,MATCH('Layer A — raw data (SOURCED)'!$A9,'Layer B — pod writeups'!$A:$A,0))="","","HC "&INDEX('Layer B — pod writeups'!$C:$C,MATCH('Layer A — raw data (SOURCED)'!$A9,'Layer B — pod writeups'!$A:$A,0))),IF(INDEX('Layer B — pod writeups'!$D:$D,MATCH('Layer A — raw data (SOURCED)'!$A9,'Layer B — pod writeups'!$A:$A,0))="","","OC "&INDEX('Layer B — pod writeups'!$D:$D,MATCH('Layer A — raw data (SOURCED)'!$A9,'Layer B — pod writeups'!$A:$A,0))),IF(INDEX('Layer B — pod writeups'!$E:$E,MATCH('Layer A — raw data (SOURCED)'!$A9,'Layer B — pod writeups'!$A:$A,0))="","","DC "&INDEX('Layer B — pod writeups'!$E:$E,MATCH('Layer A — raw data (SOURCED)'!$A9,'Layer B — pod writeups'!$A:$A,0)))),"") | M9: =IFERROR(INDEX('Layer B — pod writeups'!$F:$F,MATCH('Layer A — raw data (SOURCED)'!$A9,'Layer B — pod writeups'!$A:$A,0)),"") | N9: =IFERROR(INDEX('Layer B — pod writeups'!$K:$K,MATCH('Layer A — raw data (SOURCED)'!$A9,'Layer B — pod writeups'!$A:$A,0)),"") | O9: =IFERROR(textjoin(" ",TRUE(),IF(INDEX('Layer B — pod writeups'!$G:$G,MATCH('Layer A — raw data (SOURCED)'!$A9,'Layer B — pod writeups'!$A:$A,0))="Y","DH",""),IF(INDEX('Layer B — pod writeups'!$H:$H,MATCH('Layer A — raw data (SOURCED)'!$A9,'Layer B — pod writeups'!$A:$A,0))="Y","FADE",""),IF(INDEX('Layer B — pod writeups'!$I:$I,MATCH('Layer A — raw data (SOURCED)'!$A9,'Layer B — pod writeups'!$A:$A,0))="Y","SPLIT",""),IF(INDEX('Layer B — pod writeups'!$J:$J,MATCH('Layer A — raw data (SOURCED)'!$A9,'Layer B — pod writeups'!$A:$A,0))="Y","VAR","")),"") | P9: =IFERROR(INDEX('Layer B — pod writeups'!$L:$L,MATCH('Layer A — raw data (SOURCED)'!$A9,'Layer B — pod writeups'!$A:$A,0)),"") | Q9: =IFERROR(INDEX('Layer B — pod writeups'!$N:$N,MATCH('Layer A — raw data (SOURCED)'!$A9,'Layer B — pod writeups'!$A:$A,0)),"")
A10: ='Layer A — raw data (SOURCED)'!O10 -> SEC | B10: ='Layer A — raw data (SOURCED)'!A10 -> Texas A&M | C10: ='Layer A — raw data (SOURCED)'!O10 -> SEC | D10: ='Layer A — raw data (SOURCED)'!B10 -> 8.5 | E10: ='Layer A — raw data (SOURCED)'!C10 -> 9 | F10: ='Layer A — raw data (SOURCED)'!D10 -> 20.3 | G10: ='Layer A — raw data (SOURCED)'!E10 -> 65 | H10: ='Layer A — raw data (SOURCED)'!H10 -> 8.5 | I10: ='Layer A — raw data (SOURCED)'!K10 -> 0 | J10: ='Layer A — raw data (SOURCED)'!L10 | K10: =IFERROR(INDEX('Layer B — pod writeups'!$B:$B,MATCH('Layer A — raw data (SOURCED)'!$A10,'Layer B — pod writeups'!$A:$A,0)),"") | L10: =IFERROR(textjoin(" | ",TRUE(),IF(INDEX('Layer B — pod writeups'!$C:$C,MATCH('Layer A — raw data (SOURCED)'!$A10,'Layer B — pod writeups'!$A:$A,0))="","","HC "&INDEX('Layer B — pod writeups'!$C:$C,MATCH('Layer A — raw data (SOURCED)'!$A10,'Layer B — pod writeups'!$A:$A,0))),IF(INDEX('Layer B — pod writeups'!$D:$D,MATCH('Layer A — raw data (SOURCED)'!$A10,'Layer B — pod writeups'!$A:$A,0))="","","OC "&INDEX('Layer B — pod writeups'!$D:$D,MATCH('Layer A — raw data (SOURCED)'!$A10,'Layer B — pod writeups'!$A:$A,0))),IF(INDEX('Layer B — pod writeups'!$E:$E,MATCH('Layer A — raw data (SOURCED)'!$A10,'Layer B — pod writeups'!$A:$A,0))="","","DC "&INDEX('Layer B — pod writeups'!$E:$E,MATCH('Layer A — raw data (SOURCED)'!$A10,'Layer B — pod writeups'!$A:$A,0)))),"") | M10: =IFERROR(INDEX('Layer B — pod writeups'!$F:$F,MATCH('Layer A — raw data (SOURCED)'!$A10,'Layer B — pod writeups'!$A:$A,0)),"") | N10: =IFERROR(INDEX('Layer B — pod writeups'!$K:$K,MATCH('Layer A — raw data (SOURCED)'!$A10,'Layer B — pod writeups'!$A:$A,0)),"") | O10: =IFERROR(textjoin(" ",TRUE(),IF(INDEX('Layer B — pod writeups'!$G:$G,MATCH('Layer A — raw data (SOURCED)'!$A10,'Layer B — pod writeups'!$A:$A,0))="Y","DH",""),IF(INDEX('Layer B — pod writeups'!$H:$H,MATCH('Layer A — raw data (SOURCED)'!$A10,'Layer B — pod writeups'!$A:$A,0))="Y","FADE",""),IF(INDEX('Layer B — pod writeups'!$I:$I,MATCH('Layer A — raw data (SOURCED)'!$A10,'Layer B — pod writeups'!$A:$A,0))="Y","SPLIT",""),IF(INDEX('Layer B — pod writeups'!$J:$J,MATCH('Layer A — raw data (SOURCED)'!$A10,'Layer B — pod writeups'!$A:$A,0))="Y","VAR","")),"") | P10: =IFERROR(INDEX('Layer B — pod writeups'!$L:$L,MATCH('Layer A — raw data (SOURCED)'!$A10,'Layer B — pod writeups'!$A:$A,0)),"") | Q10: =IFERROR(INDEX('Layer B — pod writeups'!$N:$N,MATCH('Layer A — raw data (SOURCED)'!$A10,'Layer B — pod writeups'!$A:$A,0)),"")
A11: ='Layer A — raw data (SOURCED)'!O11 -> SEC | B11: ='Layer A — raw data (SOURCED)'!A11 -> LSU | C11: ='Layer A — raw data (SOURCED)'!O11 -> SEC | D11: ='Layer A — raw data (SOURCED)'!B11 -> 8.5 | E11: ='Layer A — raw data (SOURCED)'!C11 -> 10 | F11: ='Layer A — raw data (SOURCED)'!D11 -> 20.2 | G11: ='Layer A — raw data (SOURCED)'!E11 -> 61 | H11: ='Layer A — raw data (SOURCED)'!H11 -> 10.5 | I11: ='Layer A — raw data (SOURCED)'!K11 -> 0 | J11: ='Layer A — raw data (SOURCED)'!L11 | K11: =IFERROR(INDEX('Layer B — pod writeups'!$B:$B,MATCH('Layer A — raw data (SOURCED)'!$A11,'Layer B — pod writeups'!$A:$A,0)),"") | L11: =IFERROR(textjoin(" | ",TRUE(),IF(INDEX('Layer B — pod writeups'!$C:$C,MATCH('Layer A — raw data (SOURCED)'!$A11,'Layer B — pod writeups'!$A:$A,0))="","","HC "&INDEX('Layer B — pod writeups'!$C:$C,MATCH('Layer A — raw data (SOURCED)'!$A11,'Layer B — pod writeups'!$A:$A,0))),IF(INDEX('Layer B — pod writeups'!$D:$D,MATCH('Layer A — raw data (SOURCED)'!$A11,'Layer B — pod writeups'!$A:$A,0))="","","OC "&INDEX('Layer B — pod writeups'!$D:$D,MATCH('Layer A — raw data (SOURCED)'!$A11,'Layer B — pod writeups'!$A:$A,0))),IF(INDEX('Layer B — pod writeups'!$E:$E,MATCH('Layer A — raw data (SOURCED)'!$A11,'Layer B — pod writeups'!$A:$A,0))="","","DC "&INDEX('Layer B — pod writeups'!$E:$E,MATCH('Layer A — raw data (SOURCED)'!$A11,'Layer B — pod writeups'!$A:$A,0)))),"") | M11: =IFERROR(INDEX('Layer B — pod writeups'!$F:$F,MATCH('Layer A — raw data (SOURCED)'!$A11,'Layer B — pod writeups'!$A:$A,0)),"") | N11: =IFERROR(INDEX('Layer B — pod writeups'!$K:$K,MATCH('Layer A — raw data (SOURCED)'!$A11,'Layer B — pod writeups'!$A:$A,0)),"") | O11: =IFERROR(textjoin(" ",TRUE(),IF(INDEX('Layer B — pod writeups'!$G:$G,MATCH('Layer A — raw data (SOURCED)'!$A11,'Layer B — pod writeups'!$A:$A,0))="Y","DH",""),IF(INDEX('Layer B — pod writeups'!$H:$H,MATCH('Layer A — raw data (SOURCED)'!$A11,'Layer B — pod writeups'!$A:$A,0))="Y","FADE",""),IF(INDEX('Layer B — pod writeups'!$I:$I,MATCH('Layer A — raw data (SOURCED)'!$A11,'Layer B — pod writeups'!$A:$A,0))="Y","SPLIT",""),IF(INDEX('Layer B — pod writeups'!$J:$J,MATCH('Layer A — raw data (SOURCED)'!$A11,'Layer B — pod writeups'!$A:$A,0))="Y","VAR","")),"") | P11: =IFERROR(INDEX('Layer B — pod writeups'!$L:$L,MATCH('Layer A — raw data (SOURCED)'!$A11,'Layer B — pod writeups'!$A:$A,0)),"") | Q11: =IFERROR(INDEX('Layer B — pod writeups'!$N:$N,MATCH('Layer A — raw data (SOURCED)'!$A11,'Layer B — pod writeups'!$A:$A,0)),"")
